Workbook
Name ds: #REF!
Name ds: #REF!
Name ds: #REF!
Name ds: #REF!
Name ds: #REF!
Name ds: #REF!
Name InfImp22: #REF!
Name InfImp22: #REF!
Name InfImp22: #REF!
Name InfImp22: #REF!
Name InfImp22: '[1]Dados Complementares'!$F$11
Name InfImp22: #REF!
Name InfImp23: #REF!
Name InfImp23: #REF!
Name InfImp23: #REF!
Name InfImp23: #REF!
Name InfImp23: '[1]Dados Complementares'!$G$11
Name InfImp23: #REF!
Name InfImp24: #REF!
Name InfImp24: #REF!
Name InfImp24: #REF!
Name InfImp24: #REF!
Name InfImp24: '[1]Dados Complementares'!$H$11
Name InfImp24: #REF!
Name InfImp25: #REF!
Name InfImp25: #REF!
Name InfImp25: #REF!
Name InfImp25: #REF!
Name InfImp25: '[1]Dados Complementares'!$I$11
Name InfImp25: #REF!
Name InfImp26: #REF!
Name InfImp26: #REF!
Name InfImp26: #REF!
Name InfImp26: #REF!
Name InfImp26: '[1]Dados Complementares'!$J$11
Name InfImp26: #REF!
Name InfImp27: #REF!
Name InfImp27: #REF!
Name InfImp27: #REF!
Name InfImp27: #REF!
Name InfImp27: '[1]Dados Complementares'!$K$11
Name InfImp27: #REF!
Name InfImp28: #REF!
Name InfImp28: #REF!
Name InfImp28: #REF!
Name InfImp28: #REF!
Name InfImp28: '[1]Dados Complementares'!$L$11
Name InfImp28: #REF!
Name InfImp29: #REF!
Name InfImp29: #REF!
Name InfImp29: #REF!
Name InfImp29: #REF!
Name InfImp29: '[1]Dados Complementares'!$M$11
Name InfImp29: #REF!
Name InfImp30: #REF!
Name InfImp30: #REF!
Name InfImp30: #REF!
Name InfImp30: #REF!
Name InfImp30: '[1]Dados Complementares'!$N$11
Name InfImp30: #REF!

Sheet Dashboard
J4: Banco da Amazônia ($BAZA3)
A7: Páginas
A8: Dashboard
A9: Ke | E9: Trimestre Atual | F9: 2 | H9: Custo de Capital Próprio (Ke) | I9: =I10-0.5% -> 0.13949346 | J9: =1000*(SUM(NPV($I9,'DRE + DCF'!$N$36:$U$36,SUM('DRE + DCF'!$V$36,Perpetuidade!G10*(1+J$18)/($I9-J$18))),'DRE + DCF'!$L$36)/((1+$I9)^((5-$F$9)*3/12)))/$F$11 -> 193.66991 | K9: =1000*(SUM(NPV($I9,'DRE + DCF'!$N$36:$U$36,SUM('DRE + DCF'!$V$36,Perpetuidade!H10*(1+K$18)/($I9-K$18))),'DRE + DCF'!$L$36)/((1+$I9)^((5-$F$9)*3/12)))/$F$11 -> 194.53158 | L9: =1000*(SUM(NPV($I9,'DRE + DCF'!$N$36:$U$36,SUM('DRE + DCF'!$V$36,Perpetuidade!I10*(1+L$18)/($I9-L$18))),'DRE + DCF'!$L$36)/((1+$I9)^((5-$F$9)*3/12)))/$F$11 -> 195.43785 | M9: =1000*(SUM(NPV($I9,'DRE + DCF'!$N$36:$U$36,SUM('DRE + DCF'!$V$36,Perpetuidade!J10*(1+M$18)/($I9-M$18))),'DRE + DCF'!$L$36)/((1+$I9)^((5-$F$9)*3/12)))/$F$11 -> 196.39363 | N9: =1000*(SUM(NPV($I9,'DRE + DCF'!$N$36:$U$36,SUM('DRE + DCF'!$V$36,Perpetuidade!K10*(1+N$18)/($I9-N$18))),'DRE + DCF'!$L$36)/((1+$I9)^((5-$F$9)*3/12)))/$F$11 -> 197.40453 | O9: =1000*(SUM(NPV($I9,'DRE + DCF'!$N$36:$U$36,SUM('DRE + DCF'!$V$36,Perpetuidade!L10*(1+O$18)/($I9-O$18))),'DRE + DCF'!$L$36)/((1+$I9)^((5-$F$9)*3/12)))/$F$11 -> 198.47708 | P9: =1000*(SUM(NPV($I9,'DRE + DCF'!$N$36:$U$36,SUM('DRE + DCF'!$V$36,Perpetuidade!M10*(1+P$18)/($I9-P$18))),'DRE + DCF'!$L$36)/((1+$I9)^((5-$F$9)*3/12)))/$F$11 -> 199.61885 | Q9: =1000*(SUM(NPV($I9,'DRE + DCF'!$N$36:$U$36,SUM('DRE + DCF'!$V$36,Perpetuidade!N10*(1+Q$18)/($I9-Q$18))),'DRE + DCF'!$L$36)/((1+$I9)^((5-$F$9)*3/12)))/$F$11 -> 200.83874 | ... S9: =1000*(SUM(NPV($I9,'DRE + DCF'!$N$36:$U$36,SUM('DRE + DCF'!$V$36,Perpetuidade!P10*(1+S$18)/($I9-S$18))),'DRE + DCF'!$L$36)/((1+$I9)^((5-$F$9)*3/12)))/$F$11 -> 203.55671
A10: DRE + DCF | E10: Ticker | F10: BAZA3 | I10: =I11-0.5% -> 0.14449346 | J10: =1000*(SUM(NPV($I10,'DRE + DCF'!$N$36:$U$36,SUM('DRE + DCF'!$V$36,Perpetuidade!G11*(1+J$18)/($I10-J$18))),'DRE + DCF'!$L$36)/((1+$I10)^((5-$F$9)*3/12)))/$F$11 -> 181.64686 | K10: =1000*(SUM(NPV($I10,'DRE + DCF'!$N$36:$U$36,SUM('DRE + DCF'!$V$36,Perpetuidade!H11*(1+K$18)/($I10-K$18))),'DRE + DCF'!$L$36)/((1+$I10)^((5-$F$9)*3/12)))/$F$11 -> 182.30733 | L10: =1000*(SUM(NPV($I10,'DRE + DCF'!$N$36:$U$36,SUM('DRE + DCF'!$V$36,Perpetuidade!I11*(1+L$18)/($I10-L$18))),'DRE + DCF'!$L$36)/((1+$I10)^((5-$F$9)*3/12)))/$F$11 -> 182.99714 | M10: =1000*(SUM(NPV($I10,'DRE + DCF'!$N$36:$U$36,SUM('DRE + DCF'!$V$36,Perpetuidade!J11*(1+M$18)/($I10-M$18))),'DRE + DCF'!$L$36)/((1+$I10)^((5-$F$9)*3/12)))/$F$11 -> 183.71927 | N10: =1000*(SUM(NPV($I10,'DRE + DCF'!$N$36:$U$36,SUM('DRE + DCF'!$V$36,Perpetuidade!K11*(1+N$18)/($I10-N$18))),'DRE + DCF'!$L$36)/((1+$I10)^((5-$F$9)*3/12)))/$F$11 -> 184.47714 | O10: =1000*(SUM(NPV($I10,'DRE + DCF'!$N$36:$U$36,SUM('DRE + DCF'!$V$36,Perpetuidade!L11*(1+O$18)/($I10-O$18))),'DRE + DCF'!$L$36)/((1+$I10)^((5-$F$9)*3/12)))/$F$11 -> 185.27467 | P10: =1000*(SUM(NPV($I10,'DRE + DCF'!$N$36:$U$36,SUM('DRE + DCF'!$V$36,Perpetuidade!M11*(1+P$18)/($I10-P$18))),'DRE + DCF'!$L$36)/((1+$I10)^((5-$F$9)*3/12)))/$F$11 -> 186.11636 | Q10: =1000*(SUM(NPV($I10,'DRE + DCF'!$N$36:$U$36,SUM('DRE + DCF'!$V$36,Perpetuidade!N11*(1+Q$18)/($I10-Q$18))),'DRE + DCF'!$L$36)/((1+$I10)^((5-$F$9)*3/12)))/$F$11 -> 187.00744 | ... S10: =1000*(SUM(NPV($I10,'DRE + DCF'!$N$36:$U$36,SUM('DRE + DCF'!$V$36,Perpetuidade!P11*(1+S$18)/($I10-S$18))),'DRE + DCF'!$L$36)/((1+$I10)^((5-$F$9)*3/12)))/$F$11 -> 188.96312
A11: DRE - Cosif | E11: Ações Emitidas (Ex-Treasury) | F11: 56058315 | I11: =I12-0.5% -> 0.14949346 | J11: =1000*(SUM(NPV($I11,'DRE + DCF'!$N$36:$U$36,SUM('DRE + DCF'!$V$36,Perpetuidade!G12*(1+J$18)/($I11-J$18))),'DRE + DCF'!$L$36)/((1+$I11)^((5-$F$9)*3/12)))/$F$11 -> 170.8731 | K11: =1000*(SUM(NPV($I11,'DRE + DCF'!$N$36:$U$36,SUM('DRE + DCF'!$V$36,Perpetuidade!H12*(1+K$18)/($I11-K$18))),'DRE + DCF'!$L$36)/((1+$I11)^((5-$F$9)*3/12)))/$F$11 -> 171.37871 | L11: =1000*(SUM(NPV($I11,'DRE + DCF'!$N$36:$U$36,SUM('DRE + DCF'!$V$36,Perpetuidade!I12*(1+L$18)/($I11-L$18))),'DRE + DCF'!$L$36)/((1+$I11)^((5-$F$9)*3/12)))/$F$11 -> 171.90306 | M11: =1000*(SUM(NPV($I11,'DRE + DCF'!$N$36:$U$36,SUM('DRE + DCF'!$V$36,Perpetuidade!J12*(1+M$18)/($I11-M$18))),'DRE + DCF'!$L$36)/((1+$I11)^((5-$F$9)*3/12)))/$F$11 -> 172.44793 | N11: =1000*(SUM(NPV($I11,'DRE + DCF'!$N$36:$U$36,SUM('DRE + DCF'!$V$36,Perpetuidade!K12*(1+N$18)/($I11-N$18))),'DRE + DCF'!$L$36)/((1+$I11)^((5-$F$9)*3/12)))/$F$11 -> 173.01534 | O11: =1000*(SUM(NPV($I11,'DRE + DCF'!$N$36:$U$36,SUM('DRE + DCF'!$V$36,Perpetuidade!L12*(1+O$18)/($I11-O$18))),'DRE + DCF'!$L$36)/((1+$I11)^((5-$F$9)*3/12)))/$F$11 -> 173.60762 | P11: =1000*(SUM(NPV($I11,'DRE + DCF'!$N$36:$U$36,SUM('DRE + DCF'!$V$36,Perpetuidade!M12*(1+P$18)/($I11-P$18))),'DRE + DCF'!$L$36)/((1+$I11)^((5-$F$9)*3/12)))/$F$11 -> 174.22737 | Q11: =1000*(SUM(NPV($I11,'DRE + DCF'!$N$36:$U$36,SUM('DRE + DCF'!$V$36,Perpetuidade!N12*(1+Q$18)/($I11-Q$18))),'DRE + DCF'!$L$36)/((1+$I11)^((5-$F$9)*3/12)))/$F$11 -> 174.87761 | ... S11: =1000*(SUM(NPV($I11,'DRE + DCF'!$N$36:$U$36,SUM('DRE + DCF'!$V$36,Perpetuidade!P12*(1+S$18)/($I11-S$18))),'DRE + DCF'!$L$36)/((1+$I11)^((5-$F$9)*3/12)))/$F$11 -> 176.28398
A12: Balanço Patrimonial | E12: Valor do Equity (Em milhões) | F12: =SUM('DRE + DCF'!L38,'DRE + DCF'!N38:W38) -> 8775603.2 | I12: =I13-0.5% -> 0.15449346 | J12: =1000*(SUM(NPV($I12,'DRE + DCF'!$N$36:$U$36,SUM('DRE + DCF'!$V$36,Perpetuidade!G13*(1+J$18)/($I12-J$18))),'DRE + DCF'!$L$36)/((1+$I12)^((5-$F$9)*3/12)))/$F$11 -> 161.16517 | K12: =1000*(SUM(NPV($I12,'DRE + DCF'!$N$36:$U$36,SUM('DRE + DCF'!$V$36,Perpetuidade!H13*(1+K$18)/($I12-K$18))),'DRE + DCF'!$L$36)/((1+$I12)^((5-$F$9)*3/12)))/$F$11 -> 161.55055 | L12: =1000*(SUM(NPV($I12,'DRE + DCF'!$N$36:$U$36,SUM('DRE + DCF'!$V$36,Perpetuidade!I13*(1+L$18)/($I12-L$18))),'DRE + DCF'!$L$36)/((1+$I12)^((5-$F$9)*3/12)))/$F$11 -> 161.94726 | M12: =1000*(SUM(NPV($I12,'DRE + DCF'!$N$36:$U$36,SUM('DRE + DCF'!$V$36,Perpetuidade!J13*(1+M$18)/($I12-M$18))),'DRE + DCF'!$L$36)/((1+$I12)^((5-$F$9)*3/12)))/$F$11 -> 162.35632 | N12: =1000*(SUM(NPV($I12,'DRE + DCF'!$N$36:$U$36,SUM('DRE + DCF'!$V$36,Perpetuidade!K13*(1+N$18)/($I12-N$18))),'DRE + DCF'!$L$36)/((1+$I12)^((5-$F$9)*3/12)))/$F$11 -> 162.77887 | O12: =1000*(SUM(NPV($I12,'DRE + DCF'!$N$36:$U$36,SUM('DRE + DCF'!$V$36,Perpetuidade!L13*(1+O$18)/($I12-O$18))),'DRE + DCF'!$L$36)/((1+$I12)^((5-$F$9)*3/12)))/$F$11 -> 163.2162 | P12: =1000*(SUM(NPV($I12,'DRE + DCF'!$N$36:$U$36,SUM('DRE + DCF'!$V$36,Perpetuidade!M13*(1+P$18)/($I12-P$18))),'DRE + DCF'!$L$36)/((1+$I12)^((5-$F$9)*3/12)))/$F$11 -> 163.66977 | Q12: =1000*(SUM(NPV($I12,'DRE + DCF'!$N$36:$U$36,SUM('DRE + DCF'!$V$36,Perpetuidade!N13*(1+Q$18)/($I12-Q$18))),'DRE + DCF'!$L$36)/((1+$I12)^((5-$F$9)*3/12)))/$F$11 -> 164.14123 | ... S12: =1000*(SUM(NPV($I12,'DRE + DCF'!$N$36:$U$36,SUM('DRE + DCF'!$V$36,Perpetuidade!P13*(1+S$18)/($I12-S$18))),'DRE + DCF'!$L$36)/((1+$I12)^((5-$F$9)*3/12)))/$F$11 -> 165.14571
A13: Projeções - NIM | E13: Valor da Ação | F13: =F12*1000/F11 -> 156.54418 | I13: =AVERAGE(Ke!F16:O16) -> 0.15949346 | J13: =1000*(SUM(NPV($I13,'DRE + DCF'!$N$36:$U$36,SUM('DRE + DCF'!$V$36,Perpetuidade!G14*(1+J$18)/($I13-J$18))),'DRE + DCF'!$L$36)/((1+$I13)^((5-$F$9)*3/12)))/$F$11 -> 152.37465 | K13: =1000*(SUM(NPV($I13,'DRE + DCF'!$N$36:$U$36,SUM('DRE + DCF'!$V$36,Perpetuidade!H14*(1+K$18)/($I13-K$18))),'DRE + DCF'!$L$36)/((1+$I13)^((5-$F$9)*3/12)))/$F$11 -> 152.66603 | L13: =1000*(SUM(NPV($I13,'DRE + DCF'!$N$36:$U$36,SUM('DRE + DCF'!$V$36,Perpetuidade!I14*(1+L$18)/($I13-L$18))),'DRE + DCF'!$L$36)/((1+$I13)^((5-$F$9)*3/12)))/$F$11 -> 152.96354 | M13: =1000*(SUM(NPV($I13,'DRE + DCF'!$N$36:$U$36,SUM('DRE + DCF'!$V$36,Perpetuidade!J14*(1+M$18)/($I13-M$18))),'DRE + DCF'!$L$36)/((1+$I13)^((5-$F$9)*3/12)))/$F$11 -> 153.2677 | N13: =1000*(SUM(NPV($I13,'DRE + DCF'!$N$36:$U$36,SUM('DRE + DCF'!$V$36,Perpetuidade!K14*(1+N$18)/($I13-N$18))),'DRE + DCF'!$L$36)/((1+$I13)^((5-$F$9)*3/12)))/$F$11 -> 153.5791 | O13: =1000*(SUM(NPV($I13,'DRE + DCF'!$N$36:$U$36,SUM('DRE + DCF'!$V$36,Perpetuidade!L14*(1+O$18)/($I13-O$18))),'DRE + DCF'!$L$36)/((1+$I13)^((5-$F$9)*3/12)))/$F$11 -> 153.89838 | P13: =1000*(SUM(NPV($I13,'DRE + DCF'!$N$36:$U$36,SUM('DRE + DCF'!$V$36,Perpetuidade!M14*(1+P$18)/($I13-P$18))),'DRE + DCF'!$L$36)/((1+$I13)^((5-$F$9)*3/12)))/$F$11 -> 154.22628 | Q13: =1000*(SUM(NPV($I13,'DRE + DCF'!$N$36:$U$36,SUM('DRE + DCF'!$V$36,Perpetuidade!N14*(1+Q$18)/($I13-Q$18))),'DRE + DCF'!$L$36)/((1+$I13)^((5-$F$9)*3/12)))/$F$11 -> 154.56361 | ... S13: =1000*(SUM(NPV($I13,'DRE + DCF'!$N$36:$U$36,SUM('DRE + DCF'!$V$36,Perpetuidade!P14*(1+S$18)/($I13-S$18))),'DRE + DCF'!$L$36)/((1+$I13)^((5-$F$9)*3/12)))/$F$11 -> 155.27046
A14: Projeções Trimestrais | E14: Cotação | F14: 96.99 | I14: =I13+0.5% -> 0.16449346 | J14: =1000*(SUM(NPV($I14,'DRE + DCF'!$N$36:$U$36,SUM('DRE + DCF'!$V$36,Perpetuidade!G15*(1+J$18)/($I14-J$18))),'DRE + DCF'!$L$36)/((1+$I14)^((5-$F$9)*3/12)))/$F$11 -> 144.37998 | K14: =1000*(SUM(NPV($I14,'DRE + DCF'!$N$36:$U$36,SUM('DRE + DCF'!$V$36,Perpetuidade!H15*(1+K$18)/($I14-K$18))),'DRE + DCF'!$L$36)/((1+$I14)^((5-$F$9)*3/12)))/$F$11 -> 144.59743 | L14: =1000*(SUM(NPV($I14,'DRE + DCF'!$N$36:$U$36,SUM('DRE + DCF'!$V$36,Perpetuidade!I15*(1+L$18)/($I14-L$18))),'DRE + DCF'!$L$36)/((1+$I14)^((5-$F$9)*3/12)))/$F$11 -> 144.81737 | M14: =1000*(SUM(NPV($I14,'DRE + DCF'!$N$36:$U$36,SUM('DRE + DCF'!$V$36,Perpetuidade!J15*(1+M$18)/($I14-M$18))),'DRE + DCF'!$L$36)/((1+$I14)^((5-$F$9)*3/12)))/$F$11 -> 145.03999 | N14: =1000*(SUM(NPV($I14,'DRE + DCF'!$N$36:$U$36,SUM('DRE + DCF'!$V$36,Perpetuidade!K15*(1+N$18)/($I14-N$18))),'DRE + DCF'!$L$36)/((1+$I14)^((5-$F$9)*3/12)))/$F$11 -> 145.26552 | O14: =1000*(SUM(NPV($I14,'DRE + DCF'!$N$36:$U$36,SUM('DRE + DCF'!$V$36,Perpetuidade!L15*(1+O$18)/($I14-O$18))),'DRE + DCF'!$L$36)/((1+$I14)^((5-$F$9)*3/12)))/$F$11 -> 145.4942 | P14: =1000*(SUM(NPV($I14,'DRE + DCF'!$N$36:$U$36,SUM('DRE + DCF'!$V$36,Perpetuidade!M15*(1+P$18)/($I14-P$18))),'DRE + DCF'!$L$36)/((1+$I14)^((5-$F$9)*3/12)))/$F$11 -> 145.72631 | Q14: =1000*(SUM(NPV($I14,'DRE + DCF'!$N$36:$U$36,SUM('DRE + DCF'!$V$36,Perpetuidade!N15*(1+Q$18)/($I14-Q$18))),'DRE + DCF'!$L$36)/((1+$I14)^((5-$F$9)*3/12)))/$F$11 -> 145.96216 | ... S14: =1000*(SUM(NPV($I14,'DRE + DCF'!$N$36:$U$36,SUM('DRE + DCF'!$V$36,Perpetuidade!P15*(1+S$18)/($I14-S$18))),'DRE + DCF'!$L$36)/((1+$I14)^((5-$F$9)*3/12)))/$F$11 -> 146.4465
A15: Painel de Índices | E15: Upside | F15: =F13/F14-1 -> 0.61402396 | I15: =I14+0.5% -> 0.16949346 | J15: =1000*(SUM(NPV($I15,'DRE + DCF'!$N$36:$U$36,SUM('DRE + DCF'!$V$36,Perpetuidade!G16*(1+J$18)/($I15-J$18))),'DRE + DCF'!$L$36)/((1+$I15)^((5-$F$9)*3/12)))/$F$11 -> 137.0805 | K15: =1000*(SUM(NPV($I15,'DRE + DCF'!$N$36:$U$36,SUM('DRE + DCF'!$V$36,Perpetuidade!H16*(1+K$18)/($I15-K$18))),'DRE + DCF'!$L$36)/((1+$I15)^((5-$F$9)*3/12)))/$F$11 -> 137.23955 | L15: =1000*(SUM(NPV($I15,'DRE + DCF'!$N$36:$U$36,SUM('DRE + DCF'!$V$36,Perpetuidade!I16*(1+L$18)/($I15-L$18))),'DRE + DCF'!$L$36)/((1+$I15)^((5-$F$9)*3/12)))/$F$11 -> 137.39853 | M15: =1000*(SUM(NPV($I15,'DRE + DCF'!$N$36:$U$36,SUM('DRE + DCF'!$V$36,Perpetuidade!J16*(1+M$18)/($I15-M$18))),'DRE + DCF'!$L$36)/((1+$I15)^((5-$F$9)*3/12)))/$F$11 -> 137.55744 | N15: =1000*(SUM(NPV($I15,'DRE + DCF'!$N$36:$U$36,SUM('DRE + DCF'!$V$36,Perpetuidade!K16*(1+N$18)/($I15-N$18))),'DRE + DCF'!$L$36)/((1+$I15)^((5-$F$9)*3/12)))/$F$11 -> 137.71628 | O15: =1000*(SUM(NPV($I15,'DRE + DCF'!$N$36:$U$36,SUM('DRE + DCF'!$V$36,Perpetuidade!L16*(1+O$18)/($I15-O$18))),'DRE + DCF'!$L$36)/((1+$I15)^((5-$F$9)*3/12)))/$F$11 -> 137.87503 | P15: =1000*(SUM(NPV($I15,'DRE + DCF'!$N$36:$U$36,SUM('DRE + DCF'!$V$36,Perpetuidade!M16*(1+P$18)/($I15-P$18))),'DRE + DCF'!$L$36)/((1+$I15)^((5-$F$9)*3/12)))/$F$11 -> 138.0337 | Q15: =1000*(SUM(NPV($I15,'DRE + DCF'!$N$36:$U$36,SUM('DRE + DCF'!$V$36,Perpetuidade!N16*(1+Q$18)/($I15-Q$18))),'DRE + DCF'!$L$36)/((1+$I15)^((5-$F$9)*3/12)))/$F$11 -> 138.19227 | ... S15: =1000*(SUM(NPV($I15,'DRE + DCF'!$N$36:$U$36,SUM('DRE + DCF'!$V$36,Perpetuidade!P16*(1+S$18)/($I15-S$18))),'DRE + DCF'!$L$36)/((1+$I15)^((5-$F$9)*3/12)))/$F$11 -> 138.50909
E16: TIR | F16: =VLOOKUP(MIN(TIR!C13:C3382),TIR!C13:D3382,2,FALSE) -> 0.20785 | I16: =I15+0.5% -> 0.17449346 | J16: =1000*(SUM(NPV($I16,'DRE + DCF'!$N$36:$U$36,SUM('DRE + DCF'!$V$36,Perpetuidade!G17*(1+J$18)/($I16-J$18))),'DRE + DCF'!$L$36)/((1+$I16)^((5-$F$9)*3/12)))/$F$11 -> 130.39203 | K16: =1000*(SUM(NPV($I16,'DRE + DCF'!$N$36:$U$36,SUM('DRE + DCF'!$V$36,Perpetuidade!H17*(1+K$18)/($I16-K$18))),'DRE + DCF'!$L$36)/((1+$I16)^((5-$F$9)*3/12)))/$F$11 -> 130.50479 | L16: =1000*(SUM(NPV($I16,'DRE + DCF'!$N$36:$U$36,SUM('DRE + DCF'!$V$36,Perpetuidade!I17*(1+L$18)/($I16-L$18))),'DRE + DCF'!$L$36)/((1+$I16)^((5-$F$9)*3/12)))/$F$11 -> 130.61572 | M16: =1000*(SUM(NPV($I16,'DRE + DCF'!$N$36:$U$36,SUM('DRE + DCF'!$V$36,Perpetuidade!J17*(1+M$18)/($I16-M$18))),'DRE + DCF'!$L$36)/((1+$I16)^((5-$F$9)*3/12)))/$F$11 -> 130.72467 | N16: =1000*(SUM(NPV($I16,'DRE + DCF'!$N$36:$U$36,SUM('DRE + DCF'!$V$36,Perpetuidade!K17*(1+N$18)/($I16-N$18))),'DRE + DCF'!$L$36)/((1+$I16)^((5-$F$9)*3/12)))/$F$11 -> 130.83151 | O16: =1000*(SUM(NPV($I16,'DRE + DCF'!$N$36:$U$36,SUM('DRE + DCF'!$V$36,Perpetuidade!L17*(1+O$18)/($I16-O$18))),'DRE + DCF'!$L$36)/((1+$I16)^((5-$F$9)*3/12)))/$F$11 -> 130.93608 | P16: =1000*(SUM(NPV($I16,'DRE + DCF'!$N$36:$U$36,SUM('DRE + DCF'!$V$36,Perpetuidade!M17*(1+P$18)/($I16-P$18))),'DRE + DCF'!$L$36)/((1+$I16)^((5-$F$9)*3/12)))/$F$11 -> 131.03819 | Q16: =1000*(SUM(NPV($I16,'DRE + DCF'!$N$36:$U$36,SUM('DRE + DCF'!$V$36,Perpetuidade!N17*(1+Q$18)/($I16-Q$18))),'DRE + DCF'!$L$36)/((1+$I16)^((5-$F$9)*3/12)))/$F$11 -> 131.13765 | ... S16: =1000*(SUM(NPV($I16,'DRE + DCF'!$N$36:$U$36,SUM('DRE + DCF'!$V$36,Perpetuidade!P17*(1+S$18)/($I16-S$18))),'DRE + DCF'!$L$36)/((1+$I16)^((5-$F$9)*3/12)))/$F$11 -> 131.32773
I17: =I16+0.5% -> 0.17949346 | J17: =1000*(SUM(NPV($I17,'DRE + DCF'!$N$36:$U$36,SUM('DRE + DCF'!$V$36,Perpetuidade!G18*(1+J$18)/($I17-J$18))),'DRE + DCF'!$L$36)/((1+$I17)^((5-$F$9)*3/12)))/$F$11 -> 124.24361 | K17: =1000*(SUM(NPV($I17,'DRE + DCF'!$N$36:$U$36,SUM('DRE + DCF'!$V$36,Perpetuidade!H18*(1+K$18)/($I17-K$18))),'DRE + DCF'!$L$36)/((1+$I17)^((5-$F$9)*3/12)))/$F$11 -> 124.31959 | L17: =1000*(SUM(NPV($I17,'DRE + DCF'!$N$36:$U$36,SUM('DRE + DCF'!$V$36,Perpetuidade!I18*(1+L$18)/($I17-L$18))),'DRE + DCF'!$L$36)/((1+$I17)^((5-$F$9)*3/12)))/$F$11 -> 124.39254 | M17: =1000*(SUM(NPV($I17,'DRE + DCF'!$N$36:$U$36,SUM('DRE + DCF'!$V$36,Perpetuidade!J18*(1+M$18)/($I17-M$18))),'DRE + DCF'!$L$36)/((1+$I17)^((5-$F$9)*3/12)))/$F$11 -> 124.46223 | N17: =1000*(SUM(NPV($I17,'DRE + DCF'!$N$36:$U$36,SUM('DRE + DCF'!$V$36,Perpetuidade!K18*(1+N$18)/($I17-N$18))),'DRE + DCF'!$L$36)/((1+$I17)^((5-$F$9)*3/12)))/$F$11 -> 124.52843 | O17: =1000*(SUM(NPV($I17,'DRE + DCF'!$N$36:$U$36,SUM('DRE + DCF'!$V$36,Perpetuidade!L18*(1+O$18)/($I17-O$18))),'DRE + DCF'!$L$36)/((1+$I17)^((5-$F$9)*3/12)))/$F$11 -> 124.5909 | P17: =1000*(SUM(NPV($I17,'DRE + DCF'!$N$36:$U$36,SUM('DRE + DCF'!$V$36,Perpetuidade!M18*(1+P$18)/($I17-P$18))),'DRE + DCF'!$L$36)/((1+$I17)^((5-$F$9)*3/12)))/$F$11 -> 124.64936 | Q17: =1000*(SUM(NPV($I17,'DRE + DCF'!$N$36:$U$36,SUM('DRE + DCF'!$V$36,Perpetuidade!N18*(1+Q$18)/($I17-Q$18))),'DRE + DCF'!$L$36)/((1+$I17)^((5-$F$9)*3/12)))/$F$11 -> 124.7035 | ... S17: =1000*(SUM(NPV($I17,'DRE + DCF'!$N$36:$U$36,SUM('DRE + DCF'!$V$36,Perpetuidade!P18*(1+S$18)/($I17-S$18))),'DRE + DCF'!$L$36)/((1+$I17)^((5-$F$9)*3/12)))/$F$11 -> 124.79743
J18: =K18-0.25% -> 0.06355 | K18: =L18-0.25% -> 0.06605 | L18: =M18-0.25% -> 0.06855 | M18: =N18-0.25% -> 0.07105 | N18: ='DRE + DCF'!Y31 -> 0.07355 | O18: =N18+0.25% -> 0.07605 | P18: =O18+0.25% -> 0.07855 | Q18: =P18+0.25% -> 0.08105 | R18: =Q18+0.25% -> 0.08355 | S18: =R18+0.25% -> 0.08605
J19: Growth
E22: Preço Teto | F22: =TIR!E12 -> 145.17173

Sheet Ke
K4: =Dashboard!J4 -> Banco da Amazônia ($BAZA3)
A7: Páginas
A8: Dashboard
A9: Ke | E9: Atualizado em: 03/04/2024 | F9: =2024 -> 2024 | G9: =F9+1 -> 2025 | H9: =G9+1 -> 2026 | I9: =H9+1 -> 2027 | J9: =I9+1 -> 2028 | K9: =J9+1 -> 2029 | L9: =K9+1 -> 2030 | M9: =L9+1 -> 2031 | N9: =M9+1 -> 2032 | O9: =N9+1 -> 2033 | P9: Descrição
A10: DRE + DCF | E10: DI | F10: 0.1033 | G10: 0.10535 | H10: 0.1087 | I10: 0.1116 | J10: 0.11365 | K10: 0.115 | L10: 0.11584 | M10: 0.1163 | N10: 0.11651 | O10: 0.1166 | P10: A taxa livre de risco no Brasil pode partir do DI, que é equivalente ao prêmio de um titulo IPCA+ do governo de mesmo prazo somado à inflação implicita.
A11: DRE - Cosif | E11: CDS | F11: 0.003747246 | G11: 0.006508793 | H11: 0.009973829 | I11: 0.013900747 | J11: 0.018056148 | K11: 0.021600431 | L11: 0.024344638 | M11: 0.026174447 | N11: 0.026975536 | O11: 0.026633585 | P11: Credit Default Swap (CDS)
A12: Balanço Patrimonial | E12: Inflação Implícita | F12: 0.04052 | G12: 0.03862 | H12: 0.0437 | I12: 0.04665 | J12: 0.04879 | K12: 0.05009 | L12: 0.05168 | M12: 0.05226 | N12: 0.05233 | O12: 0.0525
A13: Projeções - NIM | E13: Taxa Livre de Risco | F13: =F10-F11 -> 0.099552754 | G13: =G10-G11 -> 0.098841207 | H13: =H10-H11 -> 0.098726171 | I13: =I10-I11 -> 0.097699253 | J13: =J10-J11 -> 0.095593852 | K13: =K10-K11 -> 0.093399569 | L13: =L10-L11 -> 0.091495362 | M13: =M10-M11 -> 0.090125553 | ... O13: =O10-O11 -> 0.089966415
A14: Projeções Trimestrais | E14: Beta | F14: 1 | G14: =F14 -> 1 | H14: =G14 -> 1 | I14: =H14 -> 1 | J14: =I14 -> 1 | K14: =J14 -> 1 | L14: =K14 -> 1 | M14: =L14 -> 1 | N14: =M14 -> 1 | O14: =N14 -> 1 | P14: Utilizamos Beta igual a 1 como forma conservadora. O Beta Clássico de BAZA3 é por volta de 0,2 e o Beta Clássico do setor é por volta de1,07.
A15: Painel de Índices | E15: Prêmio de Risco | F15: 0.065 | G15: 0.065 | H15: 0.065 | I15: 0.065 | J15: 0.065 | K15: 0.065 | L15: 0.065 | M15: 0.065 | N15: 0.065 | O15: 0.065 | P15: Dados Alternativos FGV: https://goo.gl/bBfwGq
E16: Custo de Capital Próprio (Ke) | F16: =F13+F14*F15 -> 0.16455275 | G16: =G13+G14*G15 -> 0.16384121 | H16: =H13+H14*H15 -> 0.16372617 | I16: =I13+I14*I15 -> 0.16269925 | J16: =J13+J14*J15 -> 0.16059385 | K16: =K13+K14*K15 -> 0.15839957 | L16: =L13+L14*L15 -> 0.15649536 | M16: =M13+M14*M15 -> 0.15512555 | ... O16: =O13+O14*O15 -> 0.15496641
E17: Desconto | F17: =(1+F16)^((5-Dashboard!$F$9)*3/12) -> 1.1210355 | G17: =F17*(1+G16) -> 1.3047073 | H17: =G17*(1+H16) -> 1.5183221 | I17: =H17*(1+I16) -> 1.7653519 | J17: =I17*(1+J16) -> 2.0488566 | K17: =J17*(1+K16) -> 2.3733946 | L17: =K17*(1+L16) -> 2.7448199 | M17: =L17*(1+M16) -> 3.1706116 | N17: =M17*(1+N16) -> 3.6605803 | O17: =N17*(1+O16) -> 4.2278473
E21: Data | F21: Preço BAZA3 | G21: IBOV | H21: Variação BAZA3 | I21: Variação IBOV | K21: Data | L21: Índice do setor (IFNC) | M21: IBOV | N21: Variação BAZA3 | O21: Variação IBOV
E22: 44333 | F22: 28.98008 | G22: 122938 | H22: - | I22: - | K22: 28.98008 | L22: 11770.95 | M22: 122938 | N22: - | O22: -
E23: 44334 | F23: 28.833345 | G23: 122980 | H23: =F23/F22-1 -> -0.0050633056 | I23: =G23/G22-1 -> 0.00034163562 | K23: 28.833345 | L23: 11776.55 | M23: 122980 | N23: =L23/L22-1 -> 0.0004757475 | O23: =M23/M22-1 -> 0.00034163562
E24: 44335 | F24: 29.346916 | G24: 122636 | H24: =F24/F23-1 -> 0.017811704 | I24: =G24/G23-1 -> -0.0027972028 | K24: 29.346916 | L24: 11835.54 | M24: 122636 | N24: =L24/L23-1 -> 0.0050091071 | O24: =M24/M23-1 -> -0.0027972028
E25: 44336 | F25: 29.376265 | G25: 122701 | H25: =F25/F24-1 -> 0.001000071 | I25: =G25/G24-1 -> 0.00053002381 | K25: 29.376265 | L25: 11948.15 | M25: 122701 | N25: =L25/L24-1 -> 0.0095145638 | O25: =M25/M24-1 -> 0.00053002381
E26: 44337 | F26: 29.346916 | G26: 122592 | H26: =F26/F25-1 -> -0.00099907187 | I26: =G26/G25-1 -> -0.00088833832 | K26: 29.346916 | L26: 11961.07 | M26: 122592 | N26: =L26/L25-1 -> 0.001081339 | O26: =M26/M25-1 -> -0.00088833832
E27: 44340 | F27: 29.346916 | G27: 124032 | H27: =F27/F26-1 -> 0 | I27: =G27/G26-1 -> 0.01174628 | K27: 29.346916 | L27: 12161.71 | M27: 124032 | N27: =L27/L26-1 -> 0.016774419 | O27: =M27/M26-1 -> 0.01174628
E28: 44341 | F28: 29.376265 | G28: 122988 | H28: =F28/F27-1 -> 0.001000071 | I28: =G28/G27-1 -> -0.0084171827 | K28: 29.376265 | L28: 11986.58 | M28: 122988 | N28: =L28/L27-1 -> -0.014400113 | O28: =M28/M27-1 -> -0.0084171827
E29: 44342 | F29: 29.302896 | G29: 123989 | H29: =F29/F28-1 -> -0.0024975605 | I29: =G29/G28-1 -> 0.0081390054 | K29: 29.302896 | L29: 12109.22 | M29: 123989 | N29: =L29/L28-1 -> 0.010231442 | O29: =M29/M28-1 -> 0.0081390054
E30: 44343 | F30: 29.412949 | G30: 124367 | H30: =F30/F29-1 -> 0.0037557039 | I30: =G30/G29-1 -> 0.0030486575 | K30: 29.412949 | L30: 12104.33 | M30: 124367 | N30: =L30/L29-1 -> -0.00040382452 | O30: =M30/M29-1 -> 0.0030486575
E31: 44344 | F31: 29.493652 | G31: 125561 | H31: =F31/F30-1 -> 0.0027437915 | I31: =G31/G30-1 -> 0.0096006175 | K31: 29.493652 | L31: 12227.83 | M31: 125561 | N31: =L31/L30-1 -> 0.01020296 | O31: =M31/M30-1 -> 0.0096006175
E32: 44347 | F32: 29.493652 | G32: 126216 | H32: =F32/F31-1 -> 0 | I32: =G32/G31-1 -> 0.005216588 | K32: 29.493652 | L32: 12248.19 | M32: 126216 | N32: =L32/L31-1 -> 0.0016650542 | O32: =M32/M31-1 -> 0.005216588
E33: 44348 | F33: 30.007223 | G33: 128267 | H33: =F33/F32-1 -> 0.017412933 | I33: =G33/G32-1 -> 0.016249921 | K33: 30.007223 | L33: 12466.89 | M33: 128267 | N33: =L33/L32-1 -> 0.017855699 | O33: =M33/M32-1 -> 0.016249921
E34: 44349 | F34: 30.080593 | G34: 129601 | H34: =F34/F33-1 -> 0.002445078 | I34: =G34/G33-1 -> 0.010400181 | K34: 30.080593 | L34: 12620.23 | M34: 129601 | N34: =L34/L33-1 -> 0.01229978 | O34: =M34/M33-1 -> 0.010400181
... E768: 45426 | F768: 99.949997 | G768: 128515 | H768: =F768/F767-1 -> -0.010298059 | I768: =G768/G767-1 -> 0.0028090984 | K768: 99.949997 | L768: 12815.96 | M768: 128515 | N768: =L768/L767-1 -> 0.0093325752 | O768: =M768/M767-1 -> 0.0028090984
E769: 45427 | F769: 100.4 | G769: 128028 | H769: =F769/F768-1 -> 0.0045023013 | I769: =G769/G768-1 -> -0.0037894409 | K769: 100.4 | L769: 12813.06 | M769: 128028 | N769: 0.0093325752 | O769: 0.0028090984
H770: Beta | I770: =SLOPE(H23:H769,I23:I769) -> 0.19471485 | N770: Beta | O770: =SLOPE(N23:N769,O23:O769) -> 1.0669481

Sheet Perpetuidade
I4: =Dashboard!I4 -> 0
A7: Páginas
A8: Dashboard
A9: Ke
A10: DRE + DCF | E10: Custo de Capital Próprio (Ke) | F10: =Dashboard!I9 -> 0.13949346 | G10: =AVERAGE(SUM('DRE + DCF'!$W$31,'DRE + DCF'!$W$32,-'DRE + DCF'!$W$32*('DRE + DCF'!$V$33+G$21)/'DRE + DCF'!$V$33,-'DRE + DCF'!$V$56*G$19),'DRE + DCF'!$W$31*(1-G$19/$F10)) -> 1639519.7 | H10: =AVERAGE(SUM('DRE + DCF'!$W$31,'DRE + DCF'!$W$32,-'DRE + DCF'!$W$32*('DRE + DCF'!$V$33+H$21)/'DRE + DCF'!$V$33,-'DRE + DCF'!$V$56*H$19),'DRE + DCF'!$W$31*(1-H$19/$F10)) -> 1593717.3 | I10: =AVERAGE(SUM('DRE + DCF'!$W$31,'DRE + DCF'!$W$32,-'DRE + DCF'!$W$32*('DRE + DCF'!$V$33+I$21)/'DRE + DCF'!$V$33,-'DRE + DCF'!$V$56*I$19),'DRE + DCF'!$W$31*(1-I$19/$F10)) -> 1547915 | J10: =AVERAGE(SUM('DRE + DCF'!$W$31,'DRE + DCF'!$W$32,-'DRE + DCF'!$W$32*('DRE + DCF'!$V$33+J$21)/'DRE + DCF'!$V$33,-'DRE + DCF'!$V$56*J$19),'DRE + DCF'!$W$31*(1-J$19/$F10)) -> 1502112.6 | K10: =AVERAGE(SUM('DRE + DCF'!$W$31,'DRE + DCF'!$W$32,-'DRE + DCF'!$W$32*('DRE + DCF'!$V$33+K$21)/'DRE + DCF'!$V$33,-'DRE + DCF'!$V$56*K$19),'DRE + DCF'!$W$31*(1-K$19/$F10)) -> 1456310.3 | L10: =AVERAGE(SUM('DRE + DCF'!$W$31,'DRE + DCF'!$W$32,-'DRE + DCF'!$W$32*('DRE + DCF'!$V$33+L$21)/'DRE + DCF'!$V$33,-'DRE + DCF'!$V$56*L$19),'DRE + DCF'!$W$31*(1-L$19/$F10)) -> 1410507.9 | M10: =AVERAGE(SUM('DRE + DCF'!$W$31,'DRE + DCF'!$W$32,-'DRE + DCF'!$W$32*('DRE + DCF'!$V$33+M$21)/'DRE + DCF'!$V$33,-'DRE + DCF'!$V$56*M$19),'DRE + DCF'!$W$31*(1-M$19/$F10)) -> 1364705.6 | N10: =AVERAGE(SUM('DRE + DCF'!$W$31,'DRE + DCF'!$W$32,-'DRE + DCF'!$W$32*('DRE + DCF'!$V$33+N$21)/'DRE + DCF'!$V$33,-'DRE + DCF'!$V$56*N$19),'DRE + DCF'!$W$31*(1-N$19/$F10)) -> 1318903.2 | ... P10: =AVERAGE(SUM('DRE + DCF'!$W$31,'DRE + DCF'!$W$32,-'DRE + DCF'!$W$32*('DRE + DCF'!$V$33+P$21)/'DRE + DCF'!$V$33,-'DRE + DCF'!$V$56*P$19),'DRE + DCF'!$W$31*(1-P$19/$F10)) -> 1227298.5
A11: DRE - Cosif | F11: =Dashboard!I10 -> 0.14449346 | G11: =AVERAGE(SUM('DRE + DCF'!$W$31,'DRE + DCF'!$W$32,-'DRE + DCF'!$W$32*('DRE + DCF'!$V$33+G$21)/'DRE + DCF'!$V$33,-'DRE + DCF'!$V$56*G$19),'DRE + DCF'!$W$31*(1-G$19/$F11)) -> 1661524.1 | H11: =AVERAGE(SUM('DRE + DCF'!$W$31,'DRE + DCF'!$W$32,-'DRE + DCF'!$W$32*('DRE + DCF'!$V$33+H$21)/'DRE + DCF'!$V$33,-'DRE + DCF'!$V$56*H$19),'DRE + DCF'!$W$31*(1-H$19/$F11)) -> 1616587.4 | I11: =AVERAGE(SUM('DRE + DCF'!$W$31,'DRE + DCF'!$W$32,-'DRE + DCF'!$W$32*('DRE + DCF'!$V$33+I$21)/'DRE + DCF'!$V$33,-'DRE + DCF'!$V$56*I$19),'DRE + DCF'!$W$31*(1-I$19/$F11)) -> 1571650.7 | J11: =AVERAGE(SUM('DRE + DCF'!$W$31,'DRE + DCF'!$W$32,-'DRE + DCF'!$W$32*('DRE + DCF'!$V$33+J$21)/'DRE + DCF'!$V$33,-'DRE + DCF'!$V$56*J$19),'DRE + DCF'!$W$31*(1-J$19/$F11)) -> 1526714 | K11: =AVERAGE(SUM('DRE + DCF'!$W$31,'DRE + DCF'!$W$32,-'DRE + DCF'!$W$32*('DRE + DCF'!$V$33+K$21)/'DRE + DCF'!$V$33,-'DRE + DCF'!$V$56*K$19),'DRE + DCF'!$W$31*(1-K$19/$F11)) -> 1481777.2 | L11: =AVERAGE(SUM('DRE + DCF'!$W$31,'DRE + DCF'!$W$32,-'DRE + DCF'!$W$32*('DRE + DCF'!$V$33+L$21)/'DRE + DCF'!$V$33,-'DRE + DCF'!$V$56*L$19),'DRE + DCF'!$W$31*(1-L$19/$F11)) -> 1436840.5 | M11: =AVERAGE(SUM('DRE + DCF'!$W$31,'DRE + DCF'!$W$32,-'DRE + DCF'!$W$32*('DRE + DCF'!$V$33+M$21)/'DRE + DCF'!$V$33,-'DRE + DCF'!$V$56*M$19),'DRE + DCF'!$W$31*(1-M$19/$F11)) -> 1391903.8 | N11: =AVERAGE(SUM('DRE + DCF'!$W$31,'DRE + DCF'!$W$32,-'DRE + DCF'!$W$32*('DRE + DCF'!$V$33+N$21)/'DRE + DCF'!$V$33,-'DRE + DCF'!$V$56*N$19),'DRE + DCF'!$W$31*(1-N$19/$F11)) -> 1346967.1 | ... P11: =AVERAGE(SUM('DRE + DCF'!$W$31,'DRE + DCF'!$W$32,-'DRE + DCF'!$W$32*('DRE + DCF'!$V$33+P$21)/'DRE + DCF'!$V$33,-'DRE + DCF'!$V$56*P$19),'DRE + DCF'!$W$31*(1-P$19/$F11)) -> 1257093.7
A12: Balanço Patrimonial | F12: =Dashboard!I11 -> 0.14949346 | G12: =AVERAGE(SUM('DRE + DCF'!$W$31,'DRE + DCF'!$W$32,-'DRE + DCF'!$W$32*('DRE + DCF'!$V$33+G$21)/'DRE + DCF'!$V$33,-'DRE + DCF'!$V$56*G$19),'DRE + DCF'!$W$31*(1-G$19/$F12)) -> 1682056.6 | H12: =AVERAGE(SUM('DRE + DCF'!$W$31,'DRE + DCF'!$W$32,-'DRE + DCF'!$W$32*('DRE + DCF'!$V$33+H$21)/'DRE + DCF'!$V$33,-'DRE + DCF'!$V$56*H$19),'DRE + DCF'!$W$31*(1-H$19/$F12)) -> 1637927.6 | I12: =AVERAGE(SUM('DRE + DCF'!$W$31,'DRE + DCF'!$W$32,-'DRE + DCF'!$W$32*('DRE + DCF'!$V$33+I$21)/'DRE + DCF'!$V$33,-'DRE + DCF'!$V$56*I$19),'DRE + DCF'!$W$31*(1-I$19/$F12)) -> 1593798.6 | J12: =AVERAGE(SUM('DRE + DCF'!$W$31,'DRE + DCF'!$W$32,-'DRE + DCF'!$W$32*('DRE + DCF'!$V$33+J$21)/'DRE + DCF'!$V$33,-'DRE + DCF'!$V$56*J$19),'DRE + DCF'!$W$31*(1-J$19/$F12)) -> 1549669.7 | K12: =AVERAGE(SUM('DRE + DCF'!$W$31,'DRE + DCF'!$W$32,-'DRE + DCF'!$W$32*('DRE + DCF'!$V$33+K$21)/'DRE + DCF'!$V$33,-'DRE + DCF'!$V$56*K$19),'DRE + DCF'!$W$31*(1-K$19/$F12)) -> 1505540.7 | L12: =AVERAGE(SUM('DRE + DCF'!$W$31,'DRE + DCF'!$W$32,-'DRE + DCF'!$W$32*('DRE + DCF'!$V$33+L$21)/'DRE + DCF'!$V$33,-'DRE + DCF'!$V$56*L$19),'DRE + DCF'!$W$31*(1-L$19/$F12)) -> 1461411.7 | M12: =AVERAGE(SUM('DRE + DCF'!$W$31,'DRE + DCF'!$W$32,-'DRE + DCF'!$W$32*('DRE + DCF'!$V$33+M$21)/'DRE + DCF'!$V$33,-'DRE + DCF'!$V$56*M$19),'DRE + DCF'!$W$31*(1-M$19/$F12)) -> 1417282.7 | N12: =AVERAGE(SUM('DRE + DCF'!$W$31,'DRE + DCF'!$W$32,-'DRE + DCF'!$W$32*('DRE + DCF'!$V$33+N$21)/'DRE + DCF'!$V$33,-'DRE + DCF'!$V$56*N$19),'DRE + DCF'!$W$31*(1-N$19/$F12)) -> 1373153.7 | ... P12: =AVERAGE(SUM('DRE + DCF'!$W$31,'DRE + DCF'!$W$32,-'DRE + DCF'!$W$32*('DRE + DCF'!$V$33+P$21)/'DRE + DCF'!$V$33,-'DRE + DCF'!$V$56*P$19),'DRE + DCF'!$W$31*(1-P$19/$F12)) -> 1284895.7
A13: Projeções - NIM | F13: =Dashboard!I12 -> 0.15449346 | G13: =AVERAGE(SUM('DRE + DCF'!$W$31,'DRE + DCF'!$W$32,-'DRE + DCF'!$W$32*('DRE + DCF'!$V$33+G$21)/'DRE + DCF'!$V$33,-'DRE + DCF'!$V$56*G$19),'DRE + DCF'!$W$31*(1-G$19/$F13)) -> 1701260.1 | H13: =AVERAGE(SUM('DRE + DCF'!$W$31,'DRE + DCF'!$W$32,-'DRE + DCF'!$W$32*('DRE + DCF'!$V$33+H$21)/'DRE + DCF'!$V$33,-'DRE + DCF'!$V$56*H$19),'DRE + DCF'!$W$31*(1-H$19/$F13)) -> 1657886.6 | I13: =AVERAGE(SUM('DRE + DCF'!$W$31,'DRE + DCF'!$W$32,-'DRE + DCF'!$W$32*('DRE + DCF'!$V$33+I$21)/'DRE + DCF'!$V$33,-'DRE + DCF'!$V$56*I$19),'DRE + DCF'!$W$31*(1-I$19/$F13)) -> 1614513 | J13: =AVERAGE(SUM('DRE + DCF'!$W$31,'DRE + DCF'!$W$32,-'DRE + DCF'!$W$32*('DRE + DCF'!$V$33+J$21)/'DRE + DCF'!$V$33,-'DRE + DCF'!$V$56*J$19),'DRE + DCF'!$W$31*(1-J$19/$F13)) -> 1571139.5 | K13: =AVERAGE(SUM('DRE + DCF'!$W$31,'DRE + DCF'!$W$32,-'DRE + DCF'!$W$32*('DRE + DCF'!$V$33+K$21)/'DRE + DCF'!$V$33,-'DRE + DCF'!$V$56*K$19),'DRE + DCF'!$W$31*(1-K$19/$F13)) -> 1527765.9 | L13: =AVERAGE(SUM('DRE + DCF'!$W$31,'DRE + DCF'!$W$32,-'DRE + DCF'!$W$32*('DRE + DCF'!$V$33+L$21)/'DRE + DCF'!$V$33,-'DRE + DCF'!$V$56*L$19),'DRE + DCF'!$W$31*(1-L$19/$F13)) -> 1484392.4 | M13: =AVERAGE(SUM('DRE + DCF'!$W$31,'DRE + DCF'!$W$32,-'DRE + DCF'!$W$32*('DRE + DCF'!$V$33+M$21)/'DRE + DCF'!$V$33,-'DRE + DCF'!$V$56*M$19),'DRE + DCF'!$W$31*(1-M$19/$F13)) -> 1441018.9 | N13: =AVERAGE(SUM('DRE + DCF'!$W$31,'DRE + DCF'!$W$32,-'DRE + DCF'!$W$32*('DRE + DCF'!$V$33+N$21)/'DRE + DCF'!$V$33,-'DRE + DCF'!$V$56*N$19),'DRE + DCF'!$W$31*(1-N$19/$F13)) -> 1397645.3 | ... P13: =AVERAGE(SUM('DRE + DCF'!$W$31,'DRE + DCF'!$W$32,-'DRE + DCF'!$W$32*('DRE + DCF'!$V$33+P$21)/'DRE + DCF'!$V$33,-'DRE + DCF'!$V$56*P$19),'DRE + DCF'!$W$31*(1-P$19/$F13)) -> 1310898.3
A14: Projeções Trimestrais | F14: =Dashboard!I13 -> 0.15949346 | G14: =AVERAGE(SUM('DRE + DCF'!$W$31,'DRE + DCF'!$W$32,-'DRE + DCF'!$W$32*('DRE + DCF'!$V$33+G$21)/'DRE + DCF'!$V$33,-'DRE + DCF'!$V$56*G$19),'DRE + DCF'!$W$31*(1-G$19/$F14)) -> 1719259.6 | H14: =AVERAGE(SUM('DRE + DCF'!$W$31,'DRE + DCF'!$W$32,-'DRE + DCF'!$W$32*('DRE + DCF'!$V$33+H$21)/'DRE + DCF'!$V$33,-'DRE + DCF'!$V$56*H$19),'DRE + DCF'!$W$31*(1-H$19/$F14)) -> 1676594.1 | I14: =AVERAGE(SUM('DRE + DCF'!$W$31,'DRE + DCF'!$W$32,-'DRE + DCF'!$W$32*('DRE + DCF'!$V$33+I$21)/'DRE + DCF'!$V$33,-'DRE + DCF'!$V$56*I$19),'DRE + DCF'!$W$31*(1-I$19/$F14)) -> 1633928.6 | J14: =AVERAGE(SUM('DRE + DCF'!$W$31,'DRE + DCF'!$W$32,-'DRE + DCF'!$W$32*('DRE + DCF'!$V$33+J$21)/'DRE + DCF'!$V$33,-'DRE + DCF'!$V$56*J$19),'DRE + DCF'!$W$31*(1-J$19/$F14)) -> 1591263.2 | K14: =AVERAGE(SUM('DRE + DCF'!$W$31,'DRE + DCF'!$W$32,-'DRE + DCF'!$W$32*('DRE + DCF'!$V$33+K$21)/'DRE + DCF'!$V$33,-'DRE + DCF'!$V$56*K$19),'DRE + DCF'!$W$31*(1-K$19/$F14)) -> 1548597.7 | L14: =AVERAGE(SUM('DRE + DCF'!$W$31,'DRE + DCF'!$W$32,-'DRE + DCF'!$W$32*('DRE + DCF'!$V$33+L$21)/'DRE + DCF'!$V$33,-'DRE + DCF'!$V$56*L$19),'DRE + DCF'!$W$31*(1-L$19/$F14)) -> 1505932.3 | M14: =AVERAGE(SUM('DRE + DCF'!$W$31,'DRE + DCF'!$W$32,-'DRE + DCF'!$W$32*('DRE + DCF'!$V$33+M$21)/'DRE + DCF'!$V$33,-'DRE + DCF'!$V$56*M$19),'DRE + DCF'!$W$31*(1-M$19/$F14)) -> 1463266.8 | N14: =AVERAGE(SUM('DRE + DCF'!$W$31,'DRE + DCF'!$W$32,-'DRE + DCF'!$W$32*('DRE + DCF'!$V$33+N$21)/'DRE + DCF'!$V$33,-'DRE + DCF'!$V$56*N$19),'DRE + DCF'!$W$31*(1-N$19/$F14)) -> 1420601.4 | ... P14: =AVERAGE(SUM('DRE + DCF'!$W$31,'DRE + DCF'!$W$32,-'DRE + DCF'!$W$32*('DRE + DCF'!$V$33+P$21)/'DRE + DCF'!$V$33,-'DRE + DCF'!$V$56*P$19),'DRE + DCF'!$W$31*(1-P$19/$F14)) -> 1335270.5
A15: Painel de Índices | F15: =Dashboard!I14 -> 0.16449346 | G15: =AVERAGE(SUM('DRE + DCF'!$W$31,'DRE + DCF'!$W$32,-'DRE + DCF'!$W$32*('DRE + DCF'!$V$33+G$21)/'DRE + DCF'!$V$33,-'DRE + DCF'!$V$56*G$19),'DRE + DCF'!$W$31*(1-G$19/$F15)) -> 1736164.8 | H15: =AVERAGE(SUM('DRE + DCF'!$W$31,'DRE + DCF'!$W$32,-'DRE + DCF'!$W$32*('DRE + DCF'!$V$33+H$21)/'DRE + DCF'!$V$33,-'DRE + DCF'!$V$56*H$19),'DRE + DCF'!$W$31*(1-H$19/$F15)) -> 1694164.4 | I15: =AVERAGE(SUM('DRE + DCF'!$W$31,'DRE + DCF'!$W$32,-'DRE + DCF'!$W$32*('DRE + DCF'!$V$33+I$21)/'DRE + DCF'!$V$33,-'DRE + DCF'!$V$56*I$19),'DRE + DCF'!$W$31*(1-I$19/$F15)) -> 1652163.9 | J15: =AVERAGE(SUM('DRE + DCF'!$W$31,'DRE + DCF'!$W$32,-'DRE + DCF'!$W$32*('DRE + DCF'!$V$33+J$21)/'DRE + DCF'!$V$33,-'DRE + DCF'!$V$56*J$19),'DRE + DCF'!$W$31*(1-J$19/$F15)) -> 1610163.5 | K15: =AVERAGE(SUM('DRE + DCF'!$W$31,'DRE + DCF'!$W$32,-'DRE + DCF'!$W$32*('DRE + DCF'!$V$33+K$21)/'DRE + DCF'!$V$33,-'DRE + DCF'!$V$56*K$19),'DRE + DCF'!$W$31*(1-K$19/$F15)) -> 1568163.1 | L15: =AVERAGE(SUM('DRE + DCF'!$W$31,'DRE + DCF'!$W$32,-'DRE + DCF'!$W$32*('DRE + DCF'!$V$33+L$21)/'DRE + DCF'!$V$33,-'DRE + DCF'!$V$56*L$19),'DRE + DCF'!$W$31*(1-L$19/$F15)) -> 1526162.7 | M15: =AVERAGE(SUM('DRE + DCF'!$W$31,'DRE + DCF'!$W$32,-'DRE + DCF'!$W$32*('DRE + DCF'!$V$33+M$21)/'DRE + DCF'!$V$33,-'DRE + DCF'!$V$56*M$19),'DRE + DCF'!$W$31*(1-M$19/$F15)) -> 1484162.3 | N15: =AVERAGE(SUM('DRE + DCF'!$W$31,'DRE + DCF'!$W$32,-'DRE + DCF'!$W$32*('DRE + DCF'!$V$33+N$21)/'DRE + DCF'!$V$33,-'DRE + DCF'!$V$56*N$19),'DRE + DCF'!$W$31*(1-N$19/$F15)) -> 1442161.8 | ... P15: =AVERAGE(SUM('DRE + DCF'!$W$31,'DRE + DCF'!$W$32,-'DRE + DCF'!$W$32*('DRE + DCF'!$V$33+P$21)/'DRE + DCF'!$V$33,-'DRE + DCF'!$V$56*P$19),'DRE + DCF'!$W$31*(1-P$19/$F15)) -> 1358161
F16: =Dashboard!I15 -> 0.16949346 | G16: =AVERAGE(SUM('DRE + DCF'!$W$31,'DRE + DCF'!$W$32,-'DRE + DCF'!$W$32*('DRE + DCF'!$V$33+G$21)/'DRE + DCF'!$V$33,-'DRE + DCF'!$V$56*G$19),'DRE + DCF'!$W$31*(1-G$19/$F16)) -> 1752072.6 | H16: =AVERAGE(SUM('DRE + DCF'!$W$31,'DRE + DCF'!$W$32,-'DRE + DCF'!$W$32*('DRE + DCF'!$V$33+H$21)/'DRE + DCF'!$V$33,-'DRE + DCF'!$V$56*H$19),'DRE + DCF'!$W$31*(1-H$19/$F16)) -> 1710698 | I16: =AVERAGE(SUM('DRE + DCF'!$W$31,'DRE + DCF'!$W$32,-'DRE + DCF'!$W$32*('DRE + DCF'!$V$33+I$21)/'DRE + DCF'!$V$33,-'DRE + DCF'!$V$56*I$19),'DRE + DCF'!$W$31*(1-I$19/$F16)) -> 1669323.4 | J16: =AVERAGE(SUM('DRE + DCF'!$W$31,'DRE + DCF'!$W$32,-'DRE + DCF'!$W$32*('DRE + DCF'!$V$33+J$21)/'DRE + DCF'!$V$33,-'DRE + DCF'!$V$56*J$19),'DRE + DCF'!$W$31*(1-J$19/$F16)) -> 1627948.7 | K16: =AVERAGE(SUM('DRE + DCF'!$W$31,'DRE + DCF'!$W$32,-'DRE + DCF'!$W$32*('DRE + DCF'!$V$33+K$21)/'DRE + DCF'!$V$33,-'DRE + DCF'!$V$56*K$19),'DRE + DCF'!$W$31*(1-K$19/$F16)) -> 1586574.1 | L16: =AVERAGE(SUM('DRE + DCF'!$W$31,'DRE + DCF'!$W$32,-'DRE + DCF'!$W$32*('DRE + DCF'!$V$33+L$21)/'DRE + DCF'!$V$33,-'DRE + DCF'!$V$56*L$19),'DRE + DCF'!$W$31*(1-L$19/$F16)) -> 1545199.5 | M16: =AVERAGE(SUM('DRE + DCF'!$W$31,'DRE + DCF'!$W$32,-'DRE + DCF'!$W$32*('DRE + DCF'!$V$33+M$21)/'DRE + DCF'!$V$33,-'DRE + DCF'!$V$56*M$19),'DRE + DCF'!$W$31*(1-M$19/$F16)) -> 1503824.9 | N16: =AVERAGE(SUM('DRE + DCF'!$W$31,'DRE + DCF'!$W$32,-'DRE + DCF'!$W$32*('DRE + DCF'!$V$33+N$21)/'DRE + DCF'!$V$33,-'DRE + DCF'!$V$56*N$19),'DRE + DCF'!$W$31*(1-N$19/$F16)) -> 1462450.3 | ... P16: =AVERAGE(SUM('DRE + DCF'!$W$31,'DRE + DCF'!$W$32,-'DRE + DCF'!$W$32*('DRE + DCF'!$V$33+P$21)/'DRE + DCF'!$V$33,-'DRE + DCF'!$V$56*P$19),'DRE + DCF'!$W$31*(1-P$19/$F16)) -> 1379701
F17: =Dashboard!I16 -> 0.17449346 | G17: =AVERAGE(SUM('DRE + DCF'!$W$31,'DRE + DCF'!$W$32,-'DRE + DCF'!$W$32*('DRE + DCF'!$V$33+G$21)/'DRE + DCF'!$V$33,-'DRE + DCF'!$V$56*G$19),'DRE + DCF'!$W$31*(1-G$19/$F17)) -> 1767068.8 | H17: =AVERAGE(SUM('DRE + DCF'!$W$31,'DRE + DCF'!$W$32,-'DRE + DCF'!$W$32*('DRE + DCF'!$V$33+H$21)/'DRE + DCF'!$V$33,-'DRE + DCF'!$V$56*H$19),'DRE + DCF'!$W$31*(1-H$19/$F17)) -> 1726284.1 | I17: =AVERAGE(SUM('DRE + DCF'!$W$31,'DRE + DCF'!$W$32,-'DRE + DCF'!$W$32*('DRE + DCF'!$V$33+I$21)/'DRE + DCF'!$V$33,-'DRE + DCF'!$V$56*I$19),'DRE + DCF'!$W$31*(1-I$19/$F17)) -> 1685499.4 | J17: =AVERAGE(SUM('DRE + DCF'!$W$31,'DRE + DCF'!$W$32,-'DRE + DCF'!$W$32*('DRE + DCF'!$V$33+J$21)/'DRE + DCF'!$V$33,-'DRE + DCF'!$V$56*J$19),'DRE + DCF'!$W$31*(1-J$19/$F17)) -> 1644714.7 | K17: =AVERAGE(SUM('DRE + DCF'!$W$31,'DRE + DCF'!$W$32,-'DRE + DCF'!$W$32*('DRE + DCF'!$V$33+K$21)/'DRE + DCF'!$V$33,-'DRE + DCF'!$V$56*K$19),'DRE + DCF'!$W$31*(1-K$19/$F17)) -> 1603930 | L17: =AVERAGE(SUM('DRE + DCF'!$W$31,'DRE + DCF'!$W$32,-'DRE + DCF'!$W$32*('DRE + DCF'!$V$33+L$21)/'DRE + DCF'!$V$33,-'DRE + DCF'!$V$56*L$19),'DRE + DCF'!$W$31*(1-L$19/$F17)) -> 1563145.3 | M17: =AVERAGE(SUM('DRE + DCF'!$W$31,'DRE + DCF'!$W$32,-'DRE + DCF'!$W$32*('DRE + DCF'!$V$33+M$21)/'DRE + DCF'!$V$33,-'DRE + DCF'!$V$56*M$19),'DRE + DCF'!$W$31*(1-M$19/$F17)) -> 1522360.7 | N17: =AVERAGE(SUM('DRE + DCF'!$W$31,'DRE + DCF'!$W$32,-'DRE + DCF'!$W$32*('DRE + DCF'!$V$33+N$21)/'DRE + DCF'!$V$33,-'DRE + DCF'!$V$56*N$19),'DRE + DCF'!$W$31*(1-N$19/$F17)) -> 1481576 | ... P17: =AVERAGE(SUM('DRE + DCF'!$W$31,'DRE + DCF'!$W$32,-'DRE + DCF'!$W$32*('DRE + DCF'!$V$33+P$21)/'DRE + DCF'!$V$33,-'DRE + DCF'!$V$56*P$19),'DRE + DCF'!$W$31*(1-P$19/$F17)) -> 1400006.6
F18: =Dashboard!I17 -> 0.17949346 | G18: =AVERAGE(SUM('DRE + DCF'!$W$31,'DRE + DCF'!$W$32,-'DRE + DCF'!$W$32*('DRE + DCF'!$V$33+G$21)/'DRE + DCF'!$V$33,-'DRE + DCF'!$V$56*G$19),'DRE + DCF'!$W$31*(1-G$19/$F18)) -> 1781229.5 | H18: =AVERAGE(SUM('DRE + DCF'!$W$31,'DRE + DCF'!$W$32,-'DRE + DCF'!$W$32*('DRE + DCF'!$V$33+H$21)/'DRE + DCF'!$V$33,-'DRE + DCF'!$V$56*H$19),'DRE + DCF'!$W$31*(1-H$19/$F18)) -> 1741001.8 | I18: =AVERAGE(SUM('DRE + DCF'!$W$31,'DRE + DCF'!$W$32,-'DRE + DCF'!$W$32*('DRE + DCF'!$V$33+I$21)/'DRE + DCF'!$V$33,-'DRE + DCF'!$V$56*I$19),'DRE + DCF'!$W$31*(1-I$19/$F18)) -> 1700774.2 | J18: =AVERAGE(SUM('DRE + DCF'!$W$31,'DRE + DCF'!$W$32,-'DRE + DCF'!$W$32*('DRE + DCF'!$V$33+J$21)/'DRE + DCF'!$V$33,-'DRE + DCF'!$V$56*J$19),'DRE + DCF'!$W$31*(1-J$19/$F18)) -> 1660546.6 | K18: =AVERAGE(SUM('DRE + DCF'!$W$31,'DRE + DCF'!$W$32,-'DRE + DCF'!$W$32*('DRE + DCF'!$V$33+K$21)/'DRE + DCF'!$V$33,-'DRE + DCF'!$V$56*K$19),'DRE + DCF'!$W$31*(1-K$19/$F18)) -> 1620319 | L18: =AVERAGE(SUM('DRE + DCF'!$W$31,'DRE + DCF'!$W$32,-'DRE + DCF'!$W$32*('DRE + DCF'!$V$33+L$21)/'DRE + DCF'!$V$33,-'DRE + DCF'!$V$56*L$19),'DRE + DCF'!$W$31*(1-L$19/$F18)) -> 1580091.4 | M18: =AVERAGE(SUM('DRE + DCF'!$W$31,'DRE + DCF'!$W$32,-'DRE + DCF'!$W$32*('DRE + DCF'!$V$33+M$21)/'DRE + DCF'!$V$33,-'DRE + DCF'!$V$56*M$19),'DRE + DCF'!$W$31*(1-M$19/$F18)) -> 1539863.8 | N18: =AVERAGE(SUM('DRE + DCF'!$W$31,'DRE + DCF'!$W$32,-'DRE + DCF'!$W$32*('DRE + DCF'!$V$33+N$21)/'DRE + DCF'!$V$33,-'DRE + DCF'!$V$56*N$19),'DRE + DCF'!$W$31*(1-N$19/$F18)) -> 1499636.2 | ... P18: =AVERAGE(SUM('DRE + DCF'!$W$31,'DRE + DCF'!$W$32,-'DRE + DCF'!$W$32*('DRE + DCF'!$V$33+P$21)/'DRE + DCF'!$V$33,-'DRE + DCF'!$V$56*P$19),'DRE + DCF'!$W$31*(1-P$19/$F18)) -> 1419180.9
G19: =Dashboard!J18 -> 0.06355 | H19: =Dashboard!K18 -> 0.06605 | I19: =Dashboard!L18 -> 0.06855 | J19: =Dashboard!M18 -> 0.07105 | K19: =Dashboard!N18 -> 0.07355 | L19: =Dashboard!O18 -> 0.07605 | M19: =Dashboard!P18 -> 0.07855 | N19: =Dashboard!Q18 -> 0.08105 | ... P19: =Dashboard!S18 -> 0.08605
G20: Growth
F21: Crescimento Real | G21: =(1+G19)/(1+Ke!$O$12)-1 -> 0.010498812 | H21: =(1+H19)/(1+Ke!$O$12)-1 -> 0.012874109 | I21: =(1+I19)/(1+Ke!$O$12)-1 -> 0.015249406 | J21: =(1+J19)/(1+Ke!$O$12)-1 -> 0.017624703 | K21: =(1+K19)/(1+Ke!$O$12)-1 -> 0.02 | L21: =(1+L19)/(1+Ke!$O$12)-1 -> 0.022375297 | M21: =(1+M19)/(1+Ke!$O$12)-1 -> 0.024750594 | N21: =(1+N19)/(1+Ke!$O$12)-1 -> 0.027125891 | ... P21: =(1+P19)/(1+Ke!$O$12)-1 -> 0.031876485

Sheet TIR
I4: =Dashboard!I4 -> 0
A7: Páginas
A8: Dashboard
A9: Ke
A10: DRE + DCF | C10: Delta | D10: TIR | E10: Preço Justo | F10: Valor da Perpetuidade | G10: Lucro Líquido | H10: Depreciação e Amortização | I10: CAPEX | J10: Capital Regulatório | K10: g real | L10: Growth
A11: DRE - Cosif | M11: 2024 | N11: 2025 | O11: 2026 | P11: 2027 | Q11: 2028 | R11: 2029 | S11: 2030 | T11: 2031 | U11: 2032 | V11: 2033
A12: Balanço Patrimonial | C12: Preço Teto | D12: =MAX(Ke!$F$16:$O$16) -> 0.16455275 | E12: {=1000*SUM('DRE + DCF'!$L$36/M12,'DRE + DCF'!$N$36:$V$36/N12:V12,F12/V12)/Dashboard!$F$11} -> 145.17173 | F12: =AVERAGE(SUM(G12:J12)*(1+L12)/(D12-L12),G12*(1+L12)*(1-L12/D12)/(D12-L12)) -> 18502110 | G12: ='DRE + DCF'!$W$31 -> 2791623.4 | H12: ='DRE + DCF'!$W$32 -> 81081.932 | I12: =-H12*('DRE + DCF'!$V$33+K12)/'DRE + DCF'!$V$33 -> -90858.802 | J12: =-'DRE + DCF'!$V$56*L12 -> -1188924.4 | K12: =(1+L12)/(1+Ke!$O$12)-1 -> 0.02 | L12: ='DRE + DCF'!$Y$31 -> 0.07355 | M12: =(1+D12)^((5-Dashboard!$F$9)*3/12) -> 1.1210355 | N12: =M12*(1+$D12) -> 1.305505 | O12: =N12*(1+$D12) -> 1.5203295 | P12: =O12*(1+$D12) -> 1.7705038 | Q12: =P12*(1+$D12) -> 2.0618451 | R12: =Q12*(1+$D12) -> 2.4011274 | S12: =R12*(1+$D12) -> 2.7962396 | T12: =S12*(1+$D12) -> 3.2563685 | U12: =T12*(1+$D12) -> 3.7922129 | V12: =U12*(1+$D12) -> 4.416232
A13: Projeções - NIM | C13: =ABS(E13-Dashboard!$F$14) -> 15394.386 | D13: ='DRE + DCF'!Y31+0.0005 -> 0.07405 | E13: {=1000*SUM('DRE + DCF'!$L$36/M13,'DRE + DCF'!$N$36:$V$36/N13:V13,F13/V13)/Dashboard!$F$11} -> 15491.376 | F13: =AVERAGE(SUM(G13:J13)*(1+L13)/(D13-L13),G13*(1+L13)*(1-L13/D13)/(D13-L13)) -> 1.7303174e+09 | G13: ='DRE + DCF'!$W$31 -> 2791623.4 | H13: ='DRE + DCF'!$W$32 -> 81081.932 | I13: =-H13*('DRE + DCF'!$V$33+K13)/'DRE + DCF'!$V$33 -> -90858.802 | J13: =-'DRE + DCF'!$V$56*L13 -> -1188924.4 | K13: =(1+L13)/(1+Ke!$O$12)-1 -> 0.02 | L13: ='DRE + DCF'!$Y$31 -> 0.07355 | M13: =(1+D13)^((5-Dashboard!$F$9)*3/12) -> 1.0550387 | N13: =M13*(1+$D13) -> 1.1331643 | O13: =N13*(1+$D13) -> 1.2170751 | P13: =O13*(1+$D13) -> 1.3071995 | Q13: =P13*(1+$D13) -> 1.4039976 | R13: =Q13*(1+$D13) -> 1.5079636 | S13: =R13*(1+$D13) -> 1.6196284 | T13: =S13*(1+$D13) -> 1.7395618 | U13: =T13*(1+$D13) -> 1.8683764 | V13: =U13*(1+$D13) -> 2.0067297
A14: Projeções Trimestrais | C14: =ABS(E14-Dashboard!$F$14) -> 12848.836 | D14: =D13+0.0001 -> 0.07415 | E14: {=1000*SUM('DRE + DCF'!$L$36/M14,'DRE + DCF'!$N$36:$V$36/N14:V14,F14/V14)/Dashboard!$F$11} -> 12945.826 | F14: =AVERAGE(SUM(G14:J14)*(1+L14)/(D14-L14),G14*(1+L14)*(1-L14/D14)/(D14-L14)) -> 1.4452766e+09 | G14: ='DRE + DCF'!$W$31 -> 2791623.4 | H14: ='DRE + DCF'!$W$32 -> 81081.932 | I14: =-H14*('DRE + DCF'!$V$33+K14)/'DRE + DCF'!$V$33 -> -90858.802 | J14: =-'DRE + DCF'!$V$56*L14 -> -1188924.4 | K14: =(1+L14)/(1+Ke!$O$12)-1 -> 0.02 | L14: ='DRE + DCF'!$Y$31 -> 0.07355 | M14: =(1+D14)^((5-Dashboard!$F$9)*3/12) -> 1.0551123 | N14: =M14*(1+$D14) -> 1.1333489 | O14: =N14*(1+$D14) -> 1.2173867 | P14: =O14*(1+$D14) -> 1.307656 | Q14: =P14*(1+$D14) -> 1.4046187 | R14: =Q14*(1+$D14) -> 1.5087711 | S14: =R14*(1+$D14) -> 1.6206465 | T14: =S14*(1+$D14) -> 1.7408174 | U14: =T14*(1+$D14) -> 1.8698991 | V14: =U14*(1+$D14) -> 2.0085521
A15: Painel de Índices | C15: =ABS(E15-Dashboard!$F$14) -> 11030.463 | D15: =D14+0.0001 -> 0.07425 | E15: {=1000*SUM('DRE + DCF'!$L$36/M15,'DRE + DCF'!$N$36:$V$36/N15:V15,F15/V15)/Dashboard!$F$11} -> 11127.453 | F15: =AVERAGE(SUM(G15:J15)*(1+L15)/(D15-L15),G15*(1+L15)*(1-L15/D15)/(D15-L15)) -> 1.2416682e+09 | G15: ='DRE + DCF'!$W$31 -> 2791623.4 | H15: ='DRE + DCF'!$W$32 -> 81081.932 | I15: =-H15*('DRE + DCF'!$V$33+K15)/'DRE + DCF'!$V$33 -> -90858.802 | J15: =-'DRE + DCF'!$V$56*L15 -> -1188924.4 | K15: =(1+L15)/(1+Ke!$O$12)-1 -> 0.02 | L15: ='DRE + DCF'!$Y$31 -> 0.07355 | M15: =(1+D15)^((5-Dashboard!$F$9)*3/12) -> 1.055186 | N15: =M15*(1+$D15) -> 1.1335336 | O15: =N15*(1+$D15) -> 1.2176984 | P15: =O15*(1+$D15) -> 1.3081125 | Q15: =P15*(1+$D15) -> 1.4052399 | R15: =Q15*(1+$D15) -> 1.509579 | S15: =R15*(1+$D15) -> 1.6216652 | T15: =S15*(1+$D15) -> 1.7420738 | U15: =T15*(1+$D15) -> 1.8714228 | V15: =U15*(1+$D15) -> 2.010376
C16: =ABS(E16-Dashboard!$F$14) -> 9666.5782 | D16: =D15+0.0001 -> 0.07435 | E16: {=1000*SUM('DRE + DCF'!$L$36/M16,'DRE + DCF'!$N$36:$V$36/N16:V16,F16/V16)/Dashboard!$F$11} -> 9763.5682 | F16: =AVERAGE(SUM(G16:J16)*(1+L16)/(D16-L16),G16*(1+L16)*(1-L16/D16)/(D16-L16)) -> 1.0889552e+09 | G16: ='DRE + DCF'!$W$31 -> 2791623.4 | H16: ='DRE + DCF'!$W$32 -> 81081.932 | I16: =-H16*('DRE + DCF'!$V$33+K16)/'DRE + DCF'!$V$33 -> -90858.802 | J16: =-'DRE + DCF'!$V$56*L16 -> -1188924.4 | K16: =(1+L16)/(1+Ke!$O$12)-1 -> 0.02 | L16: ='DRE + DCF'!$Y$31 -> 0.07355 | M16: =(1+D16)^((5-Dashboard!$F$9)*3/12) -> 1.0552597 | N16: =M16*(1+$D16) -> 1.1337182 | O16: =N16*(1+$D16) -> 1.2180102 | P16: =O16*(1+$D16) -> 1.3085692 | Q16: =P16*(1+$D16) -> 1.4058614 | R16: =Q16*(1+$D16) -> 1.5103871 | S16: =R16*(1+$D16) -> 1.6226844 | T16: =S16*(1+$D16) -> 1.743331 | U16: =T16*(1+$D16) -> 1.8729477 | V16: =U16*(1+$D16) -> 2.0122013
C17: =ABS(E17-Dashboard!$F$14) -> 8605.6848 | D17: =D16+0.0001 -> 0.07445 | E17: {=1000*SUM('DRE + DCF'!$L$36/M17,'DRE + DCF'!$N$36:$V$36/N17:V17,F17/V17)/Dashboard!$F$11} -> 8702.6748 | F17: =AVERAGE(SUM(G17:J17)*(1+L17)/(D17-L17),G17*(1+L17)*(1-L17/D17)/(D17-L17)) -> 9.7017251e+08 | G17: ='DRE + DCF'!$W$31 -> 2791623.4 | H17: ='DRE + DCF'!$W$32 -> 81081.932 | I17: =-H17*('DRE + DCF'!$V$33+K17)/'DRE + DCF'!$V$33 -> -90858.802 | J17: =-'DRE + DCF'!$V$56*L17 -> -1188924.4 | K17: =(1+L17)/(1+Ke!$O$12)-1 -> 0.02 | L17: ='DRE + DCF'!$Y$31 -> 0.07355 | M17: =(1+D17)^((5-Dashboard!$F$9)*3/12) -> 1.0553333 | N17: =M17*(1+$D17) -> 1.1339029 | O17: =N17*(1+$D17) -> 1.218322 | P17: =O17*(1+$D17) -> 1.309026 | Q17: =P17*(1+$D17) -> 1.406483 | R17: =Q17*(1+$D17) -> 1.5111957 | S17: =R17*(1+$D17) -> 1.6237042 | T17: =S17*(1+$D17) -> 1.744589 | U17: =T17*(1+$D17) -> 1.8744736 | V17: =U17*(1+$D17) -> 2.0140282
C18: =ABS(E18-Dashboard!$F$14) -> 7756.886 | D18: =D17+0.0001 -> 0.07455 | E18: {=1000*SUM('DRE + DCF'!$L$36/M18,'DRE + DCF'!$N$36:$V$36/N18:V18,F18/V18)/Dashboard!$F$11} -> 7853.876 | F18: =AVERAGE(SUM(G18:J18)*(1+L18)/(D18-L18),G18*(1+L18)*(1-L18/D18)/(D18-L18)) -> 8.7514099e+08 | G18: ='DRE + DCF'!$W$31 -> 2791623.4 | H18: ='DRE + DCF'!$W$32 -> 81081.932 | I18: =-H18*('DRE + DCF'!$V$33+K18)/'DRE + DCF'!$V$33 -> -90858.802 | J18: =-'DRE + DCF'!$V$56*L18 -> -1188924.4 | K18: =(1+L18)/(1+Ke!$O$12)-1 -> 0.02 | L18: ='DRE + DCF'!$Y$31 -> 0.07355 | M18: =(1+D18)^((5-Dashboard!$F$9)*3/12) -> 1.055407 | N18: =M18*(1+$D18) -> 1.1340876 | O18: =N18*(1+$D18) -> 1.2186338 | P18: =O18*(1+$D18) -> 1.309483 | Q18: =P18*(1+$D18) -> 1.4071049 | R18: =Q18*(1+$D18) -> 1.5120046 | S18: =R18*(1+$D18) -> 1.6247245 | T18: =S18*(1+$D18) -> 1.7458478 | U18: =T18*(1+$D18) -> 1.8760007 | V18: =U18*(1+$D18) -> 2.0158566
C19: =ABS(E19-Dashboard!$F$14) -> 7062.3382 | D19: =D18+0.0001 -> 0.07465 | E19: {=1000*SUM('DRE + DCF'!$L$36/M19,'DRE + DCF'!$N$36:$V$36/N19:V19,F19/V19)/Dashboard!$F$11} -> 7159.3282 | F19: =AVERAGE(SUM(G19:J19)*(1+L19)/(D19-L19),G19*(1+L19)*(1-L19/D19)/(D19-L19)) -> 7.9738309e+08 | G19: ='DRE + DCF'!$W$31 -> 2791623.4 | H19: ='DRE + DCF'!$W$32 -> 81081.932 | I19: =-H19*('DRE + DCF'!$V$33+K19)/'DRE + DCF'!$V$33 -> -90858.802 | J19: =-'DRE + DCF'!$V$56*L19 -> -1188924.4 | K19: =(1+L19)/(1+Ke!$O$12)-1 -> 0.02 | L19: ='DRE + DCF'!$Y$31 -> 0.07355 | M19: =(1+D19)^((5-Dashboard!$F$9)*3/12) -> 1.0554807 | N19: =M19*(1+$D19) -> 1.1342723 | O19: =N19*(1+$D19) -> 1.2189457 | P19: =O19*(1+$D19) -> 1.30994 | Q19: =P19*(1+$D19) -> 1.407727 | R19: =Q19*(1+$D19) -> 1.5128139 | S19: =R19*(1+$D19) -> 1.6257454 | T19: =S19*(1+$D19) -> 1.7471073 | U19: =T19*(1+$D19) -> 1.8775289 | V19: =U19*(1+$D19) -> 2.0176864
C20: =ABS(E20-Dashboard!$F$14) -> 6483.4789 | D20: =D19+0.0001 -> 0.07475 | E20: {=1000*SUM('DRE + DCF'!$L$36/M20,'DRE + DCF'!$N$36:$V$36/N20:V20,F20/V20)/Dashboard!$F$11} -> 6580.4689 | F20: =AVERAGE(SUM(G20:J20)*(1+L20)/(D20-L20),G20*(1+L20)*(1-L20/D20)/(D20-L20)) -> 7.3258042e+08 | G20: ='DRE + DCF'!$W$31 -> 2791623.4 | H20: ='DRE + DCF'!$W$32 -> 81081.932 | I20: =-H20*('DRE + DCF'!$V$33+K20)/'DRE + DCF'!$V$33 -> -90858.802 | J20: =-'DRE + DCF'!$V$56*L20 -> -1188924.4 | K20: =(1+L20)/(1+Ke!$O$12)-1 -> 0.02 | L20: ='DRE + DCF'!$Y$31 -> 0.07355 | M20: =(1+D20)^((5-Dashboard!$F$9)*3/12) -> 1.0555543 | N20: =M20*(1+$D20) -> 1.134457 | O20: =N20*(1+$D20) -> 1.2192577 | P20: =O20*(1+$D20) -> 1.3103972 | Q20: =P20*(1+$D20) -> 1.4083494 | R20: =Q20*(1+$D20) -> 1.5136235 | S20: =R20*(1+$D20) -> 1.6267668 | T20: =S20*(1+$D20) -> 1.7483677 | U20: =T20*(1+$D20) -> 1.8790582 | V20: =U20*(1+$D20) -> 2.0195177
C21: =ABS(E21-Dashboard!$F$14) -> 5993.6111 | D21: =D20+0.0001 -> 0.07485 | E21: {=1000*SUM('DRE + DCF'!$L$36/M21,'DRE + DCF'!$N$36:$V$36/N21:V21,F21/V21)/Dashboard!$F$11} -> 6090.6011 | F21: =AVERAGE(SUM(G21:J21)*(1+L21)/(D21-L21),G21*(1+L21)*(1-L21/D21)/(D21-L21)) -> 6.7774333e+08 | G21: ='DRE + DCF'!$W$31 -> 2791623.4 | H21: ='DRE + DCF'!$W$32 -> 81081.932 | I21: =-H21*('DRE + DCF'!$V$33+K21)/'DRE + DCF'!$V$33 -> -90858.802 | J21: =-'DRE + DCF'!$V$56*L21 -> -1188924.4 | K21: =(1+L21)/(1+Ke!$O$12)-1 -> 0.02 | L21: ='DRE + DCF'!$Y$31 -> 0.07355 | M21: =(1+D21)^((5-Dashboard!$F$9)*3/12) -> 1.055628 | N21: =M21*(1+$D21) -> 1.1346417 | O21: =N21*(1+$D21) -> 1.2195697 | P21: =O21*(1+$D21) -> 1.3108545 | Q21: =P21*(1+$D21) -> 1.4089719 | R21: =Q21*(1+$D21) -> 1.5144335 | S21: =R21*(1+$D21) -> 1.6277888 | T21: =S21*(1+$D21) -> 1.7496288 | U21: =T21*(1+$D21) -> 1.8805885 | V21: =U21*(1+$D21) -> 2.0213506
C22: =ABS(E22-Dashboard!$F$14) -> 5573.6654 | D22: =D21+0.0001 -> 0.07495 | E22: {=1000*SUM('DRE + DCF'!$L$36/M22,'DRE + DCF'!$N$36:$V$36/N22:V22,F22/V22)/Dashboard!$F$11} -> 5670.6554 | F22: =AVERAGE(SUM(G22:J22)*(1+L22)/(D22-L22),G22*(1+L22)*(1-L22/D22)/(D22-L22)) -> 6.3073636e+08 | G22: ='DRE + DCF'!$W$31 -> 2791623.4 | H22: ='DRE + DCF'!$W$32 -> 81081.932 | I22: =-H22*('DRE + DCF'!$V$33+K22)/'DRE + DCF'!$V$33 -> -90858.802 | J22: =-'DRE + DCF'!$V$56*L22 -> -1188924.4 | K22: =(1+L22)/(1+Ke!$O$12)-1 -> 0.02 | L22: ='DRE + DCF'!$Y$31 -> 0.07355 | M22: =(1+D22)^((5-Dashboard!$F$9)*3/12) -> 1.0557016 | N22: =M22*(1+$D22) -> 1.1348265 | O22: =N22*(1+$D22) -> 1.2198817 | P22: =O22*(1+$D22) -> 1.3113119 | Q22: =P22*(1+$D22) -> 1.4095947 | R22: =Q22*(1+$D22) -> 1.5152438 | S22: =R22*(1+$D22) -> 1.6288113 | T22: =S22*(1+$D22) -> 1.7508907 | U22: =T22*(1+$D22) -> 1.88212 | V22: =U22*(1+$D22) -> 2.0231849
C23: =ABS(E23-Dashboard!$F$14) -> 5209.6577 | D23: =D22+0.0001 -> 0.07505 | E23: {=1000*SUM('DRE + DCF'!$L$36/M23,'DRE + DCF'!$N$36:$V$36/N23:V23,F23/V23)/Dashboard!$F$11} -> 5306.6477 | F23: =AVERAGE(SUM(G23:J23)*(1+L23)/(D23-L23),G23*(1+L23)*(1-L23/D23)/(D23-L23)) -> 5.899935e+08 | G23: ='DRE + DCF'!$W$31 -> 2791623.4 | H23: ='DRE + DCF'!$W$32 -> 81081.932 | I23: =-H23*('DRE + DCF'!$V$33+K23)/'DRE + DCF'!$V$33 -> -90858.802 | J23: =-'DRE + DCF'!$V$56*L23 -> -1188924.4 | K23: =(1+L23)/(1+Ke!$O$12)-1 -> 0.02 | L23: ='DRE + DCF'!$Y$31 -> 0.07355 | M23: =(1+D23)^((5-Dashboard!$F$9)*3/12) -> 1.0557753 | N23: =M23*(1+$D23) -> 1.1350112 | O23: =N23*(1+$D23) -> 1.2201938 | P23: =O23*(1+$D23) -> 1.3117694 | Q23: =P23*(1+$D23) -> 1.4102177 | R23: =Q23*(1+$D23) -> 1.5160545 | S23: =R23*(1+$D23) -> 1.6298344 | T23: =S23*(1+$D23) -> 1.7521535 | U23: =T23*(1+$D23) -> 1.8836526 | V23: =U23*(1+$D23) -> 2.0250207
C24: =ABS(E24-Dashboard!$F$14) -> 4891.0997 | D24: =D23+0.0001 -> 0.07515 | E24: {=1000*SUM('DRE + DCF'!$L$36/M24,'DRE + DCF'!$N$36:$V$36/N24:V24,F24/V24)/Dashboard!$F$11} -> 4988.0897 | F24: =AVERAGE(SUM(G24:J24)*(1+L24)/(D24-L24),G24*(1+L24)*(1-L24/D24)/(D24-L24)) -> 5.5434023e+08 | G24: ='DRE + DCF'!$W$31 -> 2791623.4 | H24: ='DRE + DCF'!$W$32 -> 81081.932 | I24: =-H24*('DRE + DCF'!$V$33+K24)/'DRE + DCF'!$V$33 -> -90858.802 | J24: =-'DRE + DCF'!$V$56*L24 -> -1188924.4 | K24: =(1+L24)/(1+Ke!$O$12)-1 -> 0.02 | L24: ='DRE + DCF'!$Y$31 -> 0.07355 | M24: =(1+D24)^((5-Dashboard!$F$9)*3/12) -> 1.055849 | N24: =M24*(1+$D24) -> 1.135196 | O24: =N24*(1+$D24) -> 1.220506 | P24: =O24*(1+$D24) -> 1.312227 | Q24: =P24*(1+$D24) -> 1.4108409 | R24: =Q24*(1+$D24) -> 1.5168656 | S24: =R24*(1+$D24) -> 1.630858 | T24: =S24*(1+$D24) -> 1.753417 | U24: =T24*(1+$D24) -> 1.8851863 | V24: =U24*(1+$D24) -> 2.026858
C25: =ABS(E25-Dashboard!$F$14) -> 4609.9713 | D25: =D24+0.0001 -> 0.07525 | E25: {=1000*SUM('DRE + DCF'!$L$36/M25,'DRE + DCF'!$N$36:$V$36/N25:V25,F25/V25)/Dashboard!$F$11} -> 4706.9613 | F25: =AVERAGE(SUM(G25:J25)*(1+L25)/(D25-L25),G25*(1+L25)*(1-L25/D25)/(D25-L25)) -> 5.2287841e+08 | G25: ='DRE + DCF'!$W$31 -> 2791623.4 | H25: ='DRE + DCF'!$W$32 -> 81081.932 | I25: =-H25*('DRE + DCF'!$V$33+K25)/'DRE + DCF'!$V$33 -> -90858.802 | J25: =-'DRE + DCF'!$V$56*L25 -> -1188924.4 | K25: =(1+L25)/(1+Ke!$O$12)-1 -> 0.02 | L25: ='DRE + DCF'!$Y$31 -> 0.07355 | M25: =(1+D25)^((5-Dashboard!$F$9)*3/12) -> 1.0559226 | N25: =M25*(1+$D25) -> 1.1353808 | O25: =N25*(1+$D25) -> 1.2208182 | P25: =O25*(1+$D25) -> 1.3126848 | Q25: =P25*(1+$D25) -> 1.4114643 | R25: =Q25*(1+$D25) -> 1.517677 | S25: =R25*(1+$D25) -> 1.6318822 | T25: =S25*(1+$D25) -> 1.7546813 | U25: =T25*(1+$D25) -> 1.8867211 | V25: =U25*(1+$D25) -> 2.0286968
C26: =ABS(E26-Dashboard!$F$14) -> 4360.0342 | D26: =D25+0.0001 -> 0.07535 | E26: {=1000*SUM('DRE + DCF'!$L$36/M26,'DRE + DCF'!$N$36:$V$36/N26:V26,F26/V26)/Dashboard!$F$11} -> 4457.0242 | F26: =AVERAGE(SUM(G26:J26)*(1+L26)/(D26-L26),G26*(1+L26)*(1-L26/D26)/(D26-L26)) -> 4.9490948e+08 | G26: ='DRE + DCF'!$W$31 -> 2791623.4 | H26: ='DRE + DCF'!$W$32 -> 81081.932 | I26: =-H26*('DRE + DCF'!$V$33+K26)/'DRE + DCF'!$V$33 -> -90858.802 | J26: =-'DRE + DCF'!$V$56*L26 -> -1188924.4 | K26: =(1+L26)/(1+Ke!$O$12)-1 -> 0.02 | L26: ='DRE + DCF'!$Y$31 -> 0.07355 | M26: =(1+D26)^((5-Dashboard!$F$9)*3/12) -> 1.0559963 | N26: =M26*(1+$D26) -> 1.1355656 | O26: =N26*(1+$D26) -> 1.2211304 | P26: =O26*(1+$D26) -> 1.3131426 | Q26: =P26*(1+$D26) -> 1.4120879 | R26: =Q26*(1+$D26) -> 1.5184887 | S26: =R26*(1+$D26) -> 1.6329069 | T26: =S26*(1+$D26) -> 1.7559464 | U26: =T26*(1+$D26) -> 1.888257 | V26: =U26*(1+$D26) -> 2.0305371
C27: =ABS(E27-Dashboard!$F$14) -> 4136.3638 | D27: =D26+0.0001 -> 0.07545 | E27: {=1000*SUM('DRE + DCF'!$L$36/M27,'DRE + DCF'!$N$36:$V$36/N27:V27,F27/V27)/Dashboard!$F$11} -> 4233.3538 | F27: =AVERAGE(SUM(G27:J27)*(1+L27)/(D27-L27),G27*(1+L27)*(1-L27/D27)/(D27-L27)) -> 4.6988193e+08 | G27: ='DRE + DCF'!$W$31 -> 2791623.4 | H27: ='DRE + DCF'!$W$32 -> 81081.932 | I27: =-H27*('DRE + DCF'!$V$33+K27)/'DRE + DCF'!$V$33 -> -90858.802 | J27: =-'DRE + DCF'!$V$56*L27 -> -1188924.4 | K27: =(1+L27)/(1+Ke!$O$12)-1 -> 0.02 | L27: ='DRE + DCF'!$Y$31 -> 0.07355 | M27: =(1+D27)^((5-Dashboard!$F$9)*3/12) -> 1.0560699 | N27: =M27*(1+$D27) -> 1.1357504 | O27: =N27*(1+$D27) -> 1.2214427 | P27: =O27*(1+$D27) -> 1.3136006 | Q27: =P27*(1+$D27) -> 1.4127118 | R27: =Q27*(1+$D27) -> 1.5193009 | S27: =R27*(1+$D27) -> 1.6339321 | T27: =S27*(1+$D27) -> 1.7572123 | U27: =T27*(1+$D27) -> 1.889794 | V27: =U27*(1+$D27) -> 2.0323789
... C3382: =ABS(E3382-Dashboard!$F$14) -> 63.454932 | D3382: =D3381+0.0001 -> 0.41095 | E3382: {=1000*SUM('DRE + DCF'!$L$36/M3382,'DRE + DCF'!$N$36:$V$36/N3382:V3382,F3382/V3382)/Dashboard!$F$11} -> 33.535068 | F3382: =AVERAGE(SUM(G3382:J3382)*(1+L3382)/(D3382-L3382),G3382*(1+L3382)*(1-L3382/D3382)/(D3382-L3382)) -> 6180569.7 | G3382: ='DRE + DCF'!$W$31 -> 2791623.4 | H3382: ='DRE + DCF'!$W$32 -> 81081.932 | I3382: =-H3382*('DRE + DCF'!$V$33+K3382)/'DRE + DCF'!$V$33 -> -90858.802 | J3382: =-'DRE + DCF'!$V$56*L3382 -> -1188924.4 | K3382: =(1+L3382)/(1+Ke!$O$12)-1 -> 0.02 | L3382: ='DRE + DCF'!$Y$31 -> 0.07355 | M3382: =(1+D3382)^((5-Dashboard!$F$9)*3/12) -> 1.2945944 | N3382: =M3382*(1+$D3382) -> 1.8266079 | O3382: =N3382*(1+$D3382) -> 2.5772525 | P3382: =O3382*(1+$D3382) -> 3.6363744 | Q3382: =P3382*(1+$D3382) -> 5.1307424 | R3382: =Q3382*(1+$D3382) -> 7.239221 | S3382: =R3382*(1+$D3382) -> 10.214179 | T3382: =S3382*(1+$D3382) -> 14.411696 | U3382: =T3382*(1+$D3382) -> 20.334182 | V3382: =U3382*(1+$D3382) -> 28.690514

Sheet DRE + DCF
J4: =Dashboard!J4 -> Banco da Amazônia ($BAZA3)
A7: Páginas
A8: Dashboard
A9: Ke | F9: 2020 | G9: 2021 | H9: 2022 | I9: 2023 | J9: 1T24 | K9: YTD24 | L9: YTG24 | M9: 2024 | N9: 2025 | O9: 2026 | P9: 2027 | Q9: 2028 | R9: 2029 | S9: 2030 | T9: 2031 | U9: 2032 | V9: 2033
A10: DRE + DCF | E10: Margem Financeira Líquida | F10: ='Projeções - NIM'!F30 -> 360543 | G10: ='Projeções - NIM'!G30 -> 517628 | H10: ='Projeções - NIM'!H30 -> 1061209 | I10: ='Projeções - NIM'!I30 -> 1068160 | J10: ='Projeções - NIM'!J30 -> 90674.552 | K10: ='Projeções - NIM'!K30 -> 90674.552 | L10: ='Projeções - NIM'!L30 -> 1087904.2 | M10: ='Projeções - NIM'!M30 -> 1178578.7 | ... V10: ='Projeções - NIM'!V30 -> 2898419.4
A11: DRE - Cosif | E11: Crescimento da Margem Financeira Líquida (YoY)¹ | F11: - | G11: =G10/F10-1 -> 0.43569006 | H11: =H10/G10-1 -> 1.0501383 | I11: =I10/H10-1 -> 0.0065500764 | M11: =M10/I10-1 -> 0.10337285 | N11: =N10/M10-1 -> 0.37996689 | O11: =O10/N10-1 -> 0.096122128 | P11: =P10/O10-1 -> 0.089555928 | Q11: =Q10/P10-1 -> 0.081634904 | R11: =R10/Q10-1 -> 0.075126751 | S11: =S10/R10-1 -> 0.069621031 | T11: =T10/S10-1 -> 0.06593892 | U11: =U10/T10-1 -> 0.062341052 | V11: =V10/U10-1 -> 0.059397411
A12: Balanço Patrimonial | E12: Receitas de Prestação de Serviços | F12: ='DRE - Cosif'!F19 -> 1760424 | G12: ='DRE - Cosif'!G19 -> 2197525 | H12: ='DRE - Cosif'!H19 -> 2950511 | I12: ='DRE - Cosif'!I19 -> 2853777 | J12: ='DRE - Cosif'!J19 -> 708102.46 | K12: ='DRE - Cosif'!K19 -> 708102.46 | L12: ='DRE - Cosif'!L19 -> 2301613.6 | M12: ='DRE - Cosif'!M19 -> 3009716 | ... V12: ='DRE - Cosif'!V19 -> 6856155.8
A13: Projeções - NIM | E13: Crescimento das Receitas de Prestação de Serviços (YoY)¹ | F13: - | G13: =G12/F12-1 -> 0.24829302 | H13: =H12/G12-1 -> 0.34265185 | I13: =I12/H12-1 -> -0.032785507 | M13: =M12/I12-1 -> 0.054643035 | N13: =N12/M12-1 -> 0.12291021 | O13: =O12/N12-1 -> 0.10957454 | P13: =P12/O12-1 -> 0.10418411 | Q13: =Q12/P12-1 -> 0.098033888 | R13: =R12/Q12-1 -> 0.092903716 | S13: =S12/R12-1 -> 0.088353582 | T13: =T12/S12-1 -> 0.085355387 | U13: =U12/T12-1 -> 0.082168553 | V13: =V12/U12-1 -> 0.079388072
A14: Projeções Trimestrais | E14: Despesas Operacionais | F14: ='DRE - Cosif'!F47 -> -1037069 | G14: ='DRE - Cosif'!G47 -> -1092748 | H14: ='DRE - Cosif'!H47 -> -1292488 | I14: ='DRE - Cosif'!I47 -> -1649120 | J14: ='DRE - Cosif'!J47 -> -356691.89 | K14: ='DRE - Cosif'!K47 -> -356691.89 | L14: ='DRE - Cosif'!L47 -> -1210324.5 | M14: ='DRE - Cosif'!M47 -> -1567016.4 | ... V14: ='DRE - Cosif'!V47 -> -3104342.5
A15: Painel de Índices | E15: Crescimento das Despesas Operacionais (YoY)¹ | F15: - | G15: =G14/F14-1 -> 0.05368881 | H15: =H14/G14-1 -> 0.18278688 | I15: =I14/H14-1 -> 0.27592674 | M15: =M14/I14-1 -> -0.049786306 | N15: =N14/M14-1 -> 0.085094923 | O15: =O14/N14-1 -> 0.077326218 | P15: =P14/O14-1 -> 0.078404329 | Q15: =Q14/P14-1 -> 0.078715008 | R15: =R14/Q14-1 -> 0.078601805 | S15: =S14/R14-1 -> 0.078675326 | T15: =T14/S14-1 -> 0.078399049 | U15: =U14/T14-1 -> 0.077785188 | V15: =V14/U14-1 -> 0.077281478
E16: Despesas de Provisão | F16: ='DRE - Cosif'!F57 -> -679835 | G16: ='DRE - Cosif'!G57 -> -495926 | H16: ='DRE - Cosif'!H57 -> -768605 | I16: ='DRE - Cosif'!I57 -> -631744 | J16: ='DRE - Cosif'!J57 -> -180181.92 | K16: ='DRE - Cosif'!K57 -> -180181.92 | L16: ='DRE - Cosif'!L57 -> -522197.53 | M16: ='DRE - Cosif'!M57 -> -702379.45 | ... V16: ='DRE - Cosif'!V57 -> -1803437
