Workbook
Name InfImp22: #REF!
Name InfImp22: '[1]Dados Complementares'!$F$11
Name InfImp22: #REF!
Name InfImp23: #REF!
Name InfImp23: '[1]Dados Complementares'!$G$11
Name InfImp23: #REF!
Name InfImp24: #REF!
Name InfImp24: '[1]Dados Complementares'!$H$11
Name InfImp24: #REF!
Name InfImp25: #REF!
Name InfImp25: '[1]Dados Complementares'!$I$11
Name InfImp25: #REF!
Name InfImp26: #REF!
Name InfImp26: '[1]Dados Complementares'!$J$11
Name InfImp26: #REF!
Name InfImp27: #REF!
Name InfImp27: '[1]Dados Complementares'!$K$11
Name InfImp27: #REF!
Name InfImp28: #REF!
Name InfImp28: '[1]Dados Complementares'!$L$11
Name InfImp28: #REF!
Name InfImp29: #REF!
Name InfImp29: '[1]Dados Complementares'!$M$11
Name InfImp29: #REF!
Name InfImp30: #REF!
Name InfImp30: '[1]Dados Complementares'!$N$11
Name InfImp30: #REF!
Name InfImp31: #REF!
Name InfImp31: #REF!
Name InfImp32: #REF!
Name InfImp32: '[1]Dados Complementares'!$P$11
Name InfImp32: #REF!
Name PIB22_China: #REF!
Name PIB22_China: #REF!
Name PIB22_Mundo: #REF!
Name PIB22_Mundo: #REF!
Name PIB23_China: #REF!
Name PIB23_China: #REF!
Name PIB23_Mundo: #REF!
Name PIB23_Mundo: #REF!
Name PIB24_China: #REF!
Name PIB24_China: #REF!
Name PIB24_Mundo: #REF!
Name PIB24_Mundo: #REF!
Name PIB25_China: #REF!
Name PIB25_China: #REF!
Name PIB25_Mundo: #REF!
Name PIB25_Mundo: #REF!
Name PIB26_ARGENTINA: #REF!
Name PIB26_ARGENTINA: #REF!
Name PIB26_BRASIL: #REF!
Name PIB26_BRASIL: '[1]Dados Complementares'!$J$14
Name PIB26_BRASIL: #REF!
Name PIB26_CHINA: #REF!
Name PIB26_CHINA: '[1]Dados Complementares'!$J$15
Name PIB26_CHINA: #REF!
Name PIB26_EUA: #REF!
Name PIB26_EUA: #REF!
Name PIB26_EUROPA: #REF!
Name PIB26_EUROPA: #REF!

Sheet Dashboard
I4: Banco do Brasil ($BBAS3)
A7: Páginas
A8: Dashboard
A9: Ke | E9: Trimestre Atual | F9: 3 | H9: Custo de Capital Próprio (Ke) | I9: =I10-0.5% -> 0.14187028 | J9: =(NPV($I9,'DRE + DCF'!$U$41:$AC$41,SUM('DRE + DCF'!$AD$41,('DRE + DCF'!$AE$38*(1-(J$18/$I9))*(1+J$18))/($I9-J$18)))+'DRE + DCF'!$S$41)/((1+$I9)^((5-$F$9)*3/12)) -> 86.844515 | K9: =(NPV($I9,'DRE + DCF'!$U$41:$AC$41,SUM('DRE + DCF'!$AD$41,('DRE + DCF'!$AE$38*(1-(K$18/$I9))*(1+K$18))/($I9-K$18)))+'DRE + DCF'!$S$41)/((1+$I9)^((5-$F$9)*3/12)) -> 86.972075 | L9: =(NPV($I9,'DRE + DCF'!$U$41:$AC$41,SUM('DRE + DCF'!$AD$41,('DRE + DCF'!$AE$38*(1-(L$18/$I9))*(1+L$18))/($I9-L$18)))+'DRE + DCF'!$S$41)/((1+$I9)^((5-$F$9)*3/12)) -> 87.099634 | M9: =(NPV($I9,'DRE + DCF'!$U$41:$AC$41,SUM('DRE + DCF'!$AD$41,('DRE + DCF'!$AE$38*(1-(M$18/$I9))*(1+M$18))/($I9-M$18)))+'DRE + DCF'!$S$41)/((1+$I9)^((5-$F$9)*3/12)) -> 87.227194 | N9: =(NPV($I9,'DRE + DCF'!$U$41:$AC$41,SUM('DRE + DCF'!$AD$41,('DRE + DCF'!$AE$38*(1-(N$18/$I9))*(1+N$18))/($I9-N$18)))+'DRE + DCF'!$S$41)/((1+$I9)^((5-$F$9)*3/12)) -> 87.354754 | O9: =(NPV($I9,'DRE + DCF'!$U$41:$AC$41,SUM('DRE + DCF'!$AD$41,('DRE + DCF'!$AE$38*(1-(O$18/$I9))*(1+O$18))/($I9-O$18)))+'DRE + DCF'!$S$41)/((1+$I9)^((5-$F$9)*3/12)) -> 87.482314 | P9: =(NPV($I9,'DRE + DCF'!$U$41:$AC$41,SUM('DRE + DCF'!$AD$41,('DRE + DCF'!$AE$38*(1-(P$18/$I9))*(1+P$18))/($I9-P$18)))+'DRE + DCF'!$S$41)/((1+$I9)^((5-$F$9)*3/12)) -> 87.609874 | Q9: =(NPV($I9,'DRE + DCF'!$U$41:$AC$41,SUM('DRE + DCF'!$AD$41,('DRE + DCF'!$AE$38*(1-(Q$18/$I9))*(1+Q$18))/($I9-Q$18)))+'DRE + DCF'!$S$41)/((1+$I9)^((5-$F$9)*3/12)) -> 87.737434 | ... S9: =(NPV($I9,'DRE + DCF'!$U$41:$AC$41,SUM('DRE + DCF'!$AD$41,('DRE + DCF'!$AE$38*(1-(S$18/$I9))*(1+S$18))/($I9-S$18)))+'DRE + DCF'!$S$41)/((1+$I9)^((5-$F$9)*3/12)) -> 87.992554
A10: DRE + DCF | E10: Ticker | F10: BBAS3 | I10: =I11-0.5% -> 0.14687028 | J10: =(NPV($I10,'DRE + DCF'!$U$41:$AC$41,SUM('DRE + DCF'!$AD$41,('DRE + DCF'!$AE$38*(1-(J$18/$I10))*(1+J$18))/($I10-J$18)))+'DRE + DCF'!$S$41)/((1+$I10)^((5-$F$9)*3/12)) -> 81.833944 | K10: =(NPV($I10,'DRE + DCF'!$U$41:$AC$41,SUM('DRE + DCF'!$AD$41,('DRE + DCF'!$AE$38*(1-(K$18/$I10))*(1+K$18))/($I10-K$18)))+'DRE + DCF'!$S$41)/((1+$I10)^((5-$F$9)*3/12)) -> 81.951636 | L10: =(NPV($I10,'DRE + DCF'!$U$41:$AC$41,SUM('DRE + DCF'!$AD$41,('DRE + DCF'!$AE$38*(1-(L$18/$I10))*(1+L$18))/($I10-L$18)))+'DRE + DCF'!$S$41)/((1+$I10)^((5-$F$9)*3/12)) -> 82.069329 | M10: =(NPV($I10,'DRE + DCF'!$U$41:$AC$41,SUM('DRE + DCF'!$AD$41,('DRE + DCF'!$AE$38*(1-(M$18/$I10))*(1+M$18))/($I10-M$18)))+'DRE + DCF'!$S$41)/((1+$I10)^((5-$F$9)*3/12)) -> 82.187021 | N10: =(NPV($I10,'DRE + DCF'!$U$41:$AC$41,SUM('DRE + DCF'!$AD$41,('DRE + DCF'!$AE$38*(1-(N$18/$I10))*(1+N$18))/($I10-N$18)))+'DRE + DCF'!$S$41)/((1+$I10)^((5-$F$9)*3/12)) -> 82.304713 | O10: =(NPV($I10,'DRE + DCF'!$U$41:$AC$41,SUM('DRE + DCF'!$AD$41,('DRE + DCF'!$AE$38*(1-(O$18/$I10))*(1+O$18))/($I10-O$18)))+'DRE + DCF'!$S$41)/((1+$I10)^((5-$F$9)*3/12)) -> 82.422405 | P10: =(NPV($I10,'DRE + DCF'!$U$41:$AC$41,SUM('DRE + DCF'!$AD$41,('DRE + DCF'!$AE$38*(1-(P$18/$I10))*(1+P$18))/($I10-P$18)))+'DRE + DCF'!$S$41)/((1+$I10)^((5-$F$9)*3/12)) -> 82.540098 | Q10: =(NPV($I10,'DRE + DCF'!$U$41:$AC$41,SUM('DRE + DCF'!$AD$41,('DRE + DCF'!$AE$38*(1-(Q$18/$I10))*(1+Q$18))/($I10-Q$18)))+'DRE + DCF'!$S$41)/((1+$I10)^((5-$F$9)*3/12)) -> 82.65779 | ... S10: =(NPV($I10,'DRE + DCF'!$U$41:$AC$41,SUM('DRE + DCF'!$AD$41,('DRE + DCF'!$AE$38*(1-(S$18/$I10))*(1+S$18))/($I10-S$18)))+'DRE + DCF'!$S$41)/((1+$I10)^((5-$F$9)*3/12)) -> 82.893174
A11: Contas Abertas | E11: Ações Emitidas (Ex-Treasury) | F11: 2853776040 | I11: =I12-0.5% -> 0.15187028 | J11: =(NPV($I11,'DRE + DCF'!$U$41:$AC$41,SUM('DRE + DCF'!$AD$41,('DRE + DCF'!$AE$38*(1-(J$18/$I11))*(1+J$18))/($I11-J$18)))+'DRE + DCF'!$S$41)/((1+$I11)^((5-$F$9)*3/12)) -> 77.243817 | K11: =(NPV($I11,'DRE + DCF'!$U$41:$AC$41,SUM('DRE + DCF'!$AD$41,('DRE + DCF'!$AE$38*(1-(K$18/$I11))*(1+K$18))/($I11-K$18)))+'DRE + DCF'!$S$41)/((1+$I11)^((5-$F$9)*3/12)) -> 77.352553 | L11: =(NPV($I11,'DRE + DCF'!$U$41:$AC$41,SUM('DRE + DCF'!$AD$41,('DRE + DCF'!$AE$38*(1-(L$18/$I11))*(1+L$18))/($I11-L$18)))+'DRE + DCF'!$S$41)/((1+$I11)^((5-$F$9)*3/12)) -> 77.461288 | M11: =(NPV($I11,'DRE + DCF'!$U$41:$AC$41,SUM('DRE + DCF'!$AD$41,('DRE + DCF'!$AE$38*(1-(M$18/$I11))*(1+M$18))/($I11-M$18)))+'DRE + DCF'!$S$41)/((1+$I11)^((5-$F$9)*3/12)) -> 77.570024 | N11: =(NPV($I11,'DRE + DCF'!$U$41:$AC$41,SUM('DRE + DCF'!$AD$41,('DRE + DCF'!$AE$38*(1-(N$18/$I11))*(1+N$18))/($I11-N$18)))+'DRE + DCF'!$S$41)/((1+$I11)^((5-$F$9)*3/12)) -> 77.678759 | O11: =(NPV($I11,'DRE + DCF'!$U$41:$AC$41,SUM('DRE + DCF'!$AD$41,('DRE + DCF'!$AE$38*(1-(O$18/$I11))*(1+O$18))/($I11-O$18)))+'DRE + DCF'!$S$41)/((1+$I11)^((5-$F$9)*3/12)) -> 77.787495 | P11: =(NPV($I11,'DRE + DCF'!$U$41:$AC$41,SUM('DRE + DCF'!$AD$41,('DRE + DCF'!$AE$38*(1-(P$18/$I11))*(1+P$18))/($I11-P$18)))+'DRE + DCF'!$S$41)/((1+$I11)^((5-$F$9)*3/12)) -> 77.89623 | Q11: =(NPV($I11,'DRE + DCF'!$U$41:$AC$41,SUM('DRE + DCF'!$AD$41,('DRE + DCF'!$AE$38*(1-(Q$18/$I11))*(1+Q$18))/($I11-Q$18)))+'DRE + DCF'!$S$41)/((1+$I11)^((5-$F$9)*3/12)) -> 78.004966 | ... S11: =(NPV($I11,'DRE + DCF'!$U$41:$AC$41,SUM('DRE + DCF'!$AD$41,('DRE + DCF'!$AE$38*(1-(S$18/$I11))*(1+S$18))/($I11-S$18)))+'DRE + DCF'!$S$41)/((1+$I11)^((5-$F$9)*3/12)) -> 78.222437
A12: Balanço Patrimonial | E12: Valor da Ação | F12: =SUM('DRE + DCF'!S43,'DRE + DCF'!U43:AE43) -> 71.29825 | I12: =I13-0.5% -> 0.15687028 | J12: =(NPV($I12,'DRE + DCF'!$U$41:$AC$41,SUM('DRE + DCF'!$AD$41,('DRE + DCF'!$AE$38*(1-(J$18/$I12))*(1+J$18))/($I12-J$18)))+'DRE + DCF'!$S$41)/((1+$I12)^((5-$F$9)*3/12)) -> 73.029493 | K12: =(NPV($I12,'DRE + DCF'!$U$41:$AC$41,SUM('DRE + DCF'!$AD$41,('DRE + DCF'!$AE$38*(1-(K$18/$I12))*(1+K$18))/($I12-K$18)))+'DRE + DCF'!$S$41)/((1+$I12)^((5-$F$9)*3/12)) -> 73.130083 | L12: =(NPV($I12,'DRE + DCF'!$U$41:$AC$41,SUM('DRE + DCF'!$AD$41,('DRE + DCF'!$AE$38*(1-(L$18/$I12))*(1+L$18))/($I12-L$18)))+'DRE + DCF'!$S$41)/((1+$I12)^((5-$F$9)*3/12)) -> 73.230672 | M12: =(NPV($I12,'DRE + DCF'!$U$41:$AC$41,SUM('DRE + DCF'!$AD$41,('DRE + DCF'!$AE$38*(1-(M$18/$I12))*(1+M$18))/($I12-M$18)))+'DRE + DCF'!$S$41)/((1+$I12)^((5-$F$9)*3/12)) -> 73.331262 | N12: =(NPV($I12,'DRE + DCF'!$U$41:$AC$41,SUM('DRE + DCF'!$AD$41,('DRE + DCF'!$AE$38*(1-(N$18/$I12))*(1+N$18))/($I12-N$18)))+'DRE + DCF'!$S$41)/((1+$I12)^((5-$F$9)*3/12)) -> 73.431851 | O12: =(NPV($I12,'DRE + DCF'!$U$41:$AC$41,SUM('DRE + DCF'!$AD$41,('DRE + DCF'!$AE$38*(1-(O$18/$I12))*(1+O$18))/($I12-O$18)))+'DRE + DCF'!$S$41)/((1+$I12)^((5-$F$9)*3/12)) -> 73.53244 | P12: =(NPV($I12,'DRE + DCF'!$U$41:$AC$41,SUM('DRE + DCF'!$AD$41,('DRE + DCF'!$AE$38*(1-(P$18/$I12))*(1+P$18))/($I12-P$18)))+'DRE + DCF'!$S$41)/((1+$I12)^((5-$F$9)*3/12)) -> 73.63303 | Q12: =(NPV($I12,'DRE + DCF'!$U$41:$AC$41,SUM('DRE + DCF'!$AD$41,('DRE + DCF'!$AE$38*(1-(Q$18/$I12))*(1+Q$18))/($I12-Q$18)))+'DRE + DCF'!$S$41)/((1+$I12)^((5-$F$9)*3/12)) -> 73.733619 | ... S12: =(NPV($I12,'DRE + DCF'!$U$41:$AC$41,SUM('DRE + DCF'!$AD$41,('DRE + DCF'!$AE$38*(1-(S$18/$I12))*(1+S$18))/($I12-S$18)))+'DRE + DCF'!$S$41)/((1+$I12)^((5-$F$9)*3/12)) -> 73.934798
A13: Projeções - Receita | E13: Cotação | F13: 47.62 | I13: =AVERAGE(Ke!F16:P16) -> 0.16187028 | J13: =(NPV($I13,'DRE + DCF'!$U$41:$AC$41,SUM('DRE + DCF'!$AD$41,('DRE + DCF'!$AE$38*(1-(J$18/$I13))*(1+J$18))/($I13-J$18)))+'DRE + DCF'!$S$41)/((1+$I13)^((5-$F$9)*3/12)) -> 69.152086 | K13: =(NPV($I13,'DRE + DCF'!$U$41:$AC$41,SUM('DRE + DCF'!$AD$41,('DRE + DCF'!$AE$38*(1-(K$18/$I13))*(1+K$18))/($I13-K$18)))+'DRE + DCF'!$S$41)/((1+$I13)^((5-$F$9)*3/12)) -> 69.245253 | L13: =(NPV($I13,'DRE + DCF'!$U$41:$AC$41,SUM('DRE + DCF'!$AD$41,('DRE + DCF'!$AE$38*(1-(L$18/$I13))*(1+L$18))/($I13-L$18)))+'DRE + DCF'!$S$41)/((1+$I13)^((5-$F$9)*3/12)) -> 69.338419 | M13: =(NPV($I13,'DRE + DCF'!$U$41:$AC$41,SUM('DRE + DCF'!$AD$41,('DRE + DCF'!$AE$38*(1-(M$18/$I13))*(1+M$18))/($I13-M$18)))+'DRE + DCF'!$S$41)/((1+$I13)^((5-$F$9)*3/12)) -> 69.431585 | N13: =(NPV($I13,'DRE + DCF'!$U$41:$AC$41,SUM('DRE + DCF'!$AD$41,('DRE + DCF'!$AE$38*(1-(N$18/$I13))*(1+N$18))/($I13-N$18)))+'DRE + DCF'!$S$41)/((1+$I13)^((5-$F$9)*3/12)) -> 69.524752 | O13: =(NPV($I13,'DRE + DCF'!$U$41:$AC$41,SUM('DRE + DCF'!$AD$41,('DRE + DCF'!$AE$38*(1-(O$18/$I13))*(1+O$18))/($I13-O$18)))+'DRE + DCF'!$S$41)/((1+$I13)^((5-$F$9)*3/12)) -> 69.617918 | P13: =(NPV($I13,'DRE + DCF'!$U$41:$AC$41,SUM('DRE + DCF'!$AD$41,('DRE + DCF'!$AE$38*(1-(P$18/$I13))*(1+P$18))/($I13-P$18)))+'DRE + DCF'!$S$41)/((1+$I13)^((5-$F$9)*3/12)) -> 69.711085 | Q13: =(NPV($I13,'DRE + DCF'!$U$41:$AC$41,SUM('DRE + DCF'!$AD$41,('DRE + DCF'!$AE$38*(1-(Q$18/$I13))*(1+Q$18))/($I13-Q$18)))+'DRE + DCF'!$S$41)/((1+$I13)^((5-$F$9)*3/12)) -> 69.804251 | ... S13: =(NPV($I13,'DRE + DCF'!$U$41:$AC$41,SUM('DRE + DCF'!$AD$41,('DRE + DCF'!$AE$38*(1-(S$18/$I13))*(1+S$18))/($I13-S$18)))+'DRE + DCF'!$S$41)/((1+$I13)^((5-$F$9)*3/12)) -> 69.990584
A14: Painel de Índices | E14: Upside | F14: =F12/F13-1 -> 0.49723331 | I14: =I13+0.5% -> 0.16687028 | J14: =(NPV($I14,'DRE + DCF'!$U$41:$AC$41,SUM('DRE + DCF'!$AD$41,('DRE + DCF'!$AE$38*(1-(J$18/$I14))*(1+J$18))/($I14-J$18)))+'DRE + DCF'!$S$41)/((1+$I14)^((5-$F$9)*3/12)) -> 65.577586 | K14: =(NPV($I14,'DRE + DCF'!$U$41:$AC$41,SUM('DRE + DCF'!$AD$41,('DRE + DCF'!$AE$38*(1-(K$18/$I14))*(1+K$18))/($I14-K$18)))+'DRE + DCF'!$S$41)/((1+$I14)^((5-$F$9)*3/12)) -> 65.663977 | L14: =(NPV($I14,'DRE + DCF'!$U$41:$AC$41,SUM('DRE + DCF'!$AD$41,('DRE + DCF'!$AE$38*(1-(L$18/$I14))*(1+L$18))/($I14-L$18)))+'DRE + DCF'!$S$41)/((1+$I14)^((5-$F$9)*3/12)) -> 65.750367 | M14: =(NPV($I14,'DRE + DCF'!$U$41:$AC$41,SUM('DRE + DCF'!$AD$41,('DRE + DCF'!$AE$38*(1-(M$18/$I14))*(1+M$18))/($I14-M$18)))+'DRE + DCF'!$S$41)/((1+$I14)^((5-$F$9)*3/12)) -> 65.836758 | N14: =(NPV($I14,'DRE + DCF'!$U$41:$AC$41,SUM('DRE + DCF'!$AD$41,('DRE + DCF'!$AE$38*(1-(N$18/$I14))*(1+N$18))/($I14-N$18)))+'DRE + DCF'!$S$41)/((1+$I14)^((5-$F$9)*3/12)) -> 65.923148 | O14: =(NPV($I14,'DRE + DCF'!$U$41:$AC$41,SUM('DRE + DCF'!$AD$41,('DRE + DCF'!$AE$38*(1-(O$18/$I14))*(1+O$18))/($I14-O$18)))+'DRE + DCF'!$S$41)/((1+$I14)^((5-$F$9)*3/12)) -> 66.009539 | P14: =(NPV($I14,'DRE + DCF'!$U$41:$AC$41,SUM('DRE + DCF'!$AD$41,('DRE + DCF'!$AE$38*(1-(P$18/$I14))*(1+P$18))/($I14-P$18)))+'DRE + DCF'!$S$41)/((1+$I14)^((5-$F$9)*3/12)) -> 66.095929 | Q14: =(NPV($I14,'DRE + DCF'!$U$41:$AC$41,SUM('DRE + DCF'!$AD$41,('DRE + DCF'!$AE$38*(1-(Q$18/$I14))*(1+Q$18))/($I14-Q$18)))+'DRE + DCF'!$S$41)/((1+$I14)^((5-$F$9)*3/12)) -> 66.18232 | ... S14: =(NPV($I14,'DRE + DCF'!$U$41:$AC$41,SUM('DRE + DCF'!$AD$41,('DRE + DCF'!$AE$38*(1-(S$18/$I14))*(1+S$18))/($I14-S$18)))+'DRE + DCF'!$S$41)/((1+$I14)^((5-$F$9)*3/12)) -> 66.355101
A15: Provisões e Processos | E15: TIR | F15: =VLOOKUP(MIN(TIR!C13:C3382),TIR!C13:D3382,2,0) -> 0.20215217 | I15: =I14+0.5% -> 0.17187028 | J15: =(NPV($I15,'DRE + DCF'!$U$41:$AC$41,SUM('DRE + DCF'!$AD$41,('DRE + DCF'!$AE$38*(1-(J$18/$I15))*(1+J$18))/($I15-J$18)))+'DRE + DCF'!$S$41)/((1+$I15)^((5-$F$9)*3/12)) -> 62.276141 | K15: =(NPV($I15,'DRE + DCF'!$U$41:$AC$41,SUM('DRE + DCF'!$AD$41,('DRE + DCF'!$AE$38*(1-(K$18/$I15))*(1+K$18))/($I15-K$18)))+'DRE + DCF'!$S$41)/((1+$I15)^((5-$F$9)*3/12)) -> 62.356336 | L15: =(NPV($I15,'DRE + DCF'!$U$41:$AC$41,SUM('DRE + DCF'!$AD$41,('DRE + DCF'!$AE$38*(1-(L$18/$I15))*(1+L$18))/($I15-L$18)))+'DRE + DCF'!$S$41)/((1+$I15)^((5-$F$9)*3/12)) -> 62.436531 | M15: =(NPV($I15,'DRE + DCF'!$U$41:$AC$41,SUM('DRE + DCF'!$AD$41,('DRE + DCF'!$AE$38*(1-(M$18/$I15))*(1+M$18))/($I15-M$18)))+'DRE + DCF'!$S$41)/((1+$I15)^((5-$F$9)*3/12)) -> 62.516726 | N15: =(NPV($I15,'DRE + DCF'!$U$41:$AC$41,SUM('DRE + DCF'!$AD$41,('DRE + DCF'!$AE$38*(1-(N$18/$I15))*(1+N$18))/($I15-N$18)))+'DRE + DCF'!$S$41)/((1+$I15)^((5-$F$9)*3/12)) -> 62.59692 | O15: =(NPV($I15,'DRE + DCF'!$U$41:$AC$41,SUM('DRE + DCF'!$AD$41,('DRE + DCF'!$AE$38*(1-(O$18/$I15))*(1+O$18))/($I15-O$18)))+'DRE + DCF'!$S$41)/((1+$I15)^((5-$F$9)*3/12)) -> 62.677115 | P15: =(NPV($I15,'DRE + DCF'!$U$41:$AC$41,SUM('DRE + DCF'!$AD$41,('DRE + DCF'!$AE$38*(1-(P$18/$I15))*(1+P$18))/($I15-P$18)))+'DRE + DCF'!$S$41)/((1+$I15)^((5-$F$9)*3/12)) -> 62.75731 | Q15: =(NPV($I15,'DRE + DCF'!$U$41:$AC$41,SUM('DRE + DCF'!$AD$41,('DRE + DCF'!$AE$38*(1-(Q$18/$I15))*(1+Q$18))/($I15-Q$18)))+'DRE + DCF'!$S$41)/((1+$I15)^((5-$F$9)*3/12)) -> 62.837505 | ... S15: =(NPV($I15,'DRE + DCF'!$U$41:$AC$41,SUM('DRE + DCF'!$AD$41,('DRE + DCF'!$AE$38*(1-(S$18/$I15))*(1+S$18))/($I15-S$18)))+'DRE + DCF'!$S$41)/((1+$I15)^((5-$F$9)*3/12)) -> 62.997894
A16: Projeções Trimestrais | E16: Preço Teto | F16: =TIR!E12 -> 55.401071 | I16: =I15+0.5% -> 0.17687028 | J16: =(NPV($I16,'DRE + DCF'!$U$41:$AC$41,SUM('DRE + DCF'!$AD$41,('DRE + DCF'!$AE$38*(1-(J$18/$I16))*(1+J$18))/($I16-J$18)))+'DRE + DCF'!$S$41)/((1+$I16)^((5-$F$9)*3/12)) -> 59.221454 | K16: =(NPV($I16,'DRE + DCF'!$U$41:$AC$41,SUM('DRE + DCF'!$AD$41,('DRE + DCF'!$AE$38*(1-(K$18/$I16))*(1+K$18))/($I16-K$18)))+'DRE + DCF'!$S$41)/((1+$I16)^((5-$F$9)*3/12)) -> 59.295975 | L16: =(NPV($I16,'DRE + DCF'!$U$41:$AC$41,SUM('DRE + DCF'!$AD$41,('DRE + DCF'!$AE$38*(1-(L$18/$I16))*(1+L$18))/($I16-L$18)))+'DRE + DCF'!$S$41)/((1+$I16)^((5-$F$9)*3/12)) -> 59.370496 | M16: =(NPV($I16,'DRE + DCF'!$U$41:$AC$41,SUM('DRE + DCF'!$AD$41,('DRE + DCF'!$AE$38*(1-(M$18/$I16))*(1+M$18))/($I16-M$18)))+'DRE + DCF'!$S$41)/((1+$I16)^((5-$F$9)*3/12)) -> 59.445016 | N16: =(NPV($I16,'DRE + DCF'!$U$41:$AC$41,SUM('DRE + DCF'!$AD$41,('DRE + DCF'!$AE$38*(1-(N$18/$I16))*(1+N$18))/($I16-N$18)))+'DRE + DCF'!$S$41)/((1+$I16)^((5-$F$9)*3/12)) -> 59.519537 | O16: =(NPV($I16,'DRE + DCF'!$U$41:$AC$41,SUM('DRE + DCF'!$AD$41,('DRE + DCF'!$AE$38*(1-(O$18/$I16))*(1+O$18))/($I16-O$18)))+'DRE + DCF'!$S$41)/((1+$I16)^((5-$F$9)*3/12)) -> 59.594058 | P16: =(NPV($I16,'DRE + DCF'!$U$41:$AC$41,SUM('DRE + DCF'!$AD$41,('DRE + DCF'!$AE$38*(1-(P$18/$I16))*(1+P$18))/($I16-P$18)))+'DRE + DCF'!$S$41)/((1+$I16)^((5-$F$9)*3/12)) -> 59.668578 | Q16: =(NPV($I16,'DRE + DCF'!$U$41:$AC$41,SUM('DRE + DCF'!$AD$41,('DRE + DCF'!$AE$38*(1-(Q$18/$I16))*(1+Q$18))/($I16-Q$18)))+'DRE + DCF'!$S$41)/((1+$I16)^((5-$F$9)*3/12)) -> 59.743099 | ... S16: =(NPV($I16,'DRE + DCF'!$U$41:$AC$41,SUM('DRE + DCF'!$AD$41,('DRE + DCF'!$AE$38*(1-(S$18/$I16))*(1+S$18))/($I16-S$18)))+'DRE + DCF'!$S$41)/((1+$I16)^((5-$F$9)*3/12)) -> 59.89214
I17: =I16+0.5% -> 0.18187028 | J17: =(NPV($I17,'DRE + DCF'!$U$41:$AC$41,SUM('DRE + DCF'!$AD$41,('DRE + DCF'!$AE$38*(1-(J$18/$I17))*(1+J$18))/($I17-J$18)))+'DRE + DCF'!$S$41)/((1+$I17)^((5-$F$9)*3/12)) -> 56.390286 | K17: =(NPV($I17,'DRE + DCF'!$U$41:$AC$41,SUM('DRE + DCF'!$AD$41,('DRE + DCF'!$AE$38*(1-(K$18/$I17))*(1+K$18))/($I17-K$18)))+'DRE + DCF'!$S$41)/((1+$I17)^((5-$F$9)*3/12)) -> 56.459603 | L17: =(NPV($I17,'DRE + DCF'!$U$41:$AC$41,SUM('DRE + DCF'!$AD$41,('DRE + DCF'!$AE$38*(1-(L$18/$I17))*(1+L$18))/($I17-L$18)))+'DRE + DCF'!$S$41)/((1+$I17)^((5-$F$9)*3/12)) -> 56.528919 | M17: =(NPV($I17,'DRE + DCF'!$U$41:$AC$41,SUM('DRE + DCF'!$AD$41,('DRE + DCF'!$AE$38*(1-(M$18/$I17))*(1+M$18))/($I17-M$18)))+'DRE + DCF'!$S$41)/((1+$I17)^((5-$F$9)*3/12)) -> 56.598236 | N17: =(NPV($I17,'DRE + DCF'!$U$41:$AC$41,SUM('DRE + DCF'!$AD$41,('DRE + DCF'!$AE$38*(1-(N$18/$I17))*(1+N$18))/($I17-N$18)))+'DRE + DCF'!$S$41)/((1+$I17)^((5-$F$9)*3/12)) -> 56.667553 | O17: =(NPV($I17,'DRE + DCF'!$U$41:$AC$41,SUM('DRE + DCF'!$AD$41,('DRE + DCF'!$AE$38*(1-(O$18/$I17))*(1+O$18))/($I17-O$18)))+'DRE + DCF'!$S$41)/((1+$I17)^((5-$F$9)*3/12)) -> 56.736869 | P17: =(NPV($I17,'DRE + DCF'!$U$41:$AC$41,SUM('DRE + DCF'!$AD$41,('DRE + DCF'!$AE$38*(1-(P$18/$I17))*(1+P$18))/($I17-P$18)))+'DRE + DCF'!$S$41)/((1+$I17)^((5-$F$9)*3/12)) -> 56.806186 | Q17: =(NPV($I17,'DRE + DCF'!$U$41:$AC$41,SUM('DRE + DCF'!$AD$41,('DRE + DCF'!$AE$38*(1-(Q$18/$I17))*(1+Q$18))/($I17-Q$18)))+'DRE + DCF'!$S$41)/((1+$I17)^((5-$F$9)*3/12)) -> 56.875502 | ... S17: =(NPV($I17,'DRE + DCF'!$U$41:$AC$41,SUM('DRE + DCF'!$AD$41,('DRE + DCF'!$AE$38*(1-(S$18/$I17))*(1+S$18))/($I17-S$18)))+'DRE + DCF'!$S$41)/((1+$I17)^((5-$F$9)*3/12)) -> 57.014135
J18: =K18-0.25% -> 0.083102165 | K18: =L18-0.25% -> 0.085602165 | L18: =M18-0.25% -> 0.088102165 | M18: =N18-0.25% -> 0.090602165 | N18: ='DRE + DCF'!AG38 -> 0.093102165 | O18: =N18+0.25% -> 0.095602165 | P18: =O18+0.25% -> 0.098102165 | Q18: =P18+0.25% -> 0.10060217 | R18: =Q18+0.25% -> 0.10310217 | S18: =R18+0.25% -> 0.10560217
J19: Growth

Sheet Ke
K4: =Dashboard!$I$4 -> Banco do Brasil ($BBAS3)
A7: Páginas
A8: Dashboard
A9: Ke | E9: Atualizado em: 13/04/2023 | F9: 2023 | G9: =F9+1 -> 2024 | H9: =G9+1 -> 2025 | I9: =H9+1 -> 2026 | J9: =I9+1 -> 2027 | K9: =J9+1 -> 2028 | L9: =K9+1 -> 2029 | M9: =L9+1 -> 2030 | N9: =M9+1 -> 2031 | ... P9: =O9+1 -> 2033 | Q9: Descrição
A10: DRE + DCF | E10: DI | F10: 0.1145 | G10: 0.1092 | H10: 0.1033 | I10: 0.1035 | J10: 0.106 | K10: 0.1085 | L10: 0.1104 | M10: 0.1119 | N10: 0.1131 | O10: 0.1139 | P10: 0.1141 | Q10: A taxa livre de risco no Brasil pode partir do DI, que é equivalente ao prêmio de um titulo IPCA+ do governo de mesmo prazo somado à inflação implicita.
A11: Contas Abertas | E11: CDS | F11: 0.0036 | G11: 0.0048 | H11: 0.0075 | I11: 0.0108 | J11: 0.0145 | K11: 0.0185 | L11: 0.0219 | M11: 0.0248 | N11: 0.0261 | O11: 0.0271 | P11: 0.028 | Q11: Credit Default Swap (CDS)
A12: Balanço Patrimonial | E12: Inflação Implícita | F12: 0.0567 | G12: 0.0426 | H12: 0.0472 | I12: 0.0512 | J12: 0.0542 | K12: 0.0563 | L12: 0.0576 | M12: 0.0585 | N12: 0.0591 | O12: 0.0594 | P12: 0.0594
A13: Projeções - Receita | E13: Taxa Livre de Risco | F13: =F10-F11 -> 0.1109 | G13: =G10-G11 -> 0.1044 | H13: =H10-H11 -> 0.0958 | I13: =I10-I11 -> 0.0927 | J13: =J10-J11 -> 0.0915 | K13: =K10-K11 -> 0.09 | L13: =L10-L11 -> 0.0885 | M13: =M10-M11 -> 0.0871 | ... P13: =P10-P11 -> 0.0861
A14: Painel de Índices | E14: Beta | F14: =SLOPE(H23:H763,I23:I763) -> 1.0626196 | G14: =F14 -> 1.0626196 | H14: =G14 -> 1.0626196 | I14: =H14 -> 1.0626196 | J14: =I14 -> 1.0626196 | K14: =J14 -> 1.0626196 | L14: =K14 -> 1.0626196 | M14: =L14 -> 1.0626196 | N14: =M14 -> 1.0626196 | ... P14: =O14 -> 1.0626196 | Q14: Beta Clássico
A15: Provisões e Processos | E15: Prêmio de Risco | F15: 0.065 | G15: 0.065 | H15: 0.065 | I15: 0.065 | J15: 0.065 | K15: 0.065 | L15: 0.065 | M15: 0.065 | N15: 0.065 | O15: 0.065 | P15: 0.065 | Q15: Dados Alternativos FGV: https://goo.gl/bBfwGq
A16: Projeções Trimestrais | E16: Custo de Capital Próprio (Ke) | F16: =F13+F14*F15 -> 0.17997028 | G16: =G13+G14*G15 -> 0.17347028 | H16: =H13+H14*H15 -> 0.16487028 | I16: =I13+I14*I15 -> 0.16177028 | J16: =J13+J14*J15 -> 0.16057028 | K16: =K13+K14*K15 -> 0.15907028 | L16: =L13+L14*L15 -> 0.15757028 | M16: =M13+M14*M15 -> 0.15617028 | ... P16: =P13+P14*P15 -> 0.15517028
E17: Desconto | F17: =(1+F16)^((5-Dashboard!$F$9)*3/12) -> 1.0862644 | G17: =F17*(1+G16) -> 1.2746989 | H17: =G17*(1+H16) -> 1.4848589 | I17: =H17*(1+I16) -> 1.7250649 | J17: =I17*(1+J16) -> 2.0020591 | K17: =J17*(1+K16) -> 2.3205272 | L17: =K17*(1+L16) -> 2.6861733 | M17: =L17*(1+M16) -> 3.1056737 | N17: =M17*(1+N16) -> 3.5903771 | ... P17: =O17*(1+P16) -> 4.7939684
E21: Data | F21: Preço BBAS3 | G21: IBOV | H21: Variação BBAS3 | I21: Variação IBOV
E22: 45086 | F22: 47.740002 | G22: 117019 | H22: - | I22: -
E23: 45084 | F23: 45.52 | G23: 115488 | H23: =F23/F22-1 -> -0.046501925 | I23: =G23/G22-1 -> -0.013083345
E24: 45083 | F24: 45.540001 | G24: 114610 | H24: =F24/F23-1 -> 0.00043938928 | I24: =G24/G23-1 -> -0.0076025215
E25: 45082 | F25: 45.02 | G25: 112696 | H25: =F25/F24-1 -> -0.011418555 | I25: =G25/G24-1 -> -0.016700113
E26: 45079 | F26: 44.740002 | G26: 112558 | H26: =F26/F25-1 -> -0.0062194136 | I26: =G26/G25-1 -> -0.0012245333
E27: 45078 | F27: 44.085583 | G27: 110565 | H27: =F27/F26-1 -> -0.014627156 | I27: =G27/G26-1 -> -0.017706427
E28: 45077 | F28: 43.967335 | G28: 108335 | H28: =F28/F27-1 -> -0.0026822374 | I28: =G28/G27-1 -> -0.020169131
E29: 45076 | F29: 44.046165 | G29: 108967 | H29: =F29/F28-1 -> 0.0017929219 | I29: =G29/G28-1 -> 0.0058337564
E30: 45075 | F30: 43.671722 | G30: 110333 | H30: =F30/F29-1 -> -0.0085011487 | I30: =G30/G29-1 -> 0.012535905
E31: 45072 | F31: 43.750557 | G31: 110906 | H31: =F31/F30-1 -> 0.0018051727 | I31: =G31/G30-1 -> 0.0051933692
E32: 45071 | F32: 44.006752 | G32: 110054 | H32: =F32/F31-1 -> 0.0058558112 | I32: =G32/G31-1 -> -0.0076821813
E33: 45070 | F33: 43.957481 | G33: 108800 | H33: =F33/F32-1 -> -0.0011196236 | I33: =G33/G32-1 -> -0.011394406
E34: 45069 | F34: 43.829384 | G34: 109929 | H34: =F34/F33-1 -> -0.0029141115 | I34: =G34/G33-1 -> 0.010376838
... E764: 43994 | F764: 26.976826 | G764: 92795 | H764: =F764/F763-1 -> 0.0084668849 | I764: =G764/G763-1 -> 0.0045358102

Sheet TIR
L4: =Dashboard!$I$4 -> Banco do Brasil ($BBAS3)
A7: Páginas
A8: Dashboard
A9: Ke
A10: DRE + DCF | C10: Delta | D10: TIR | E10: Preço Justo | F10: Valor da Perpetuidade | G10: Growth | H10: Ke | S10: Taxa de Desconto
A11: Contas Abertas | H11: 2023 | I11: 2024 | J11: 2025 | K11: 2026 | L11: 2027 | M11: 2028 | N11: 2029 | O11: 2030 | P11: 2031 | Q11: 2032 | R11: 2033 | S11: 2023 | T11: 2024 | U11: 2025 | V11: 2026 | W11: 2027 | X11: 2028 | Y11: 2029 | Z11: 2030 | AA11: 2031 | AB11: 2032 | AC11: 2033
A12: Balanço Patrimonial | C12: Preço Teto | D12: =AVERAGE(Ke!$F$16:$P$16) -> 0.16187028 | E12: {=SUM('DRE + DCF'!$S$41/TIR!S12,'DRE + DCF'!U43:AD43/TIR!$T$12:$AC$12,F12)} -> 55.401071 | F12: ='DRE + DCF'!$AE$38*'DRE + DCF'!$AE$39*(1+G12)/(R12-G12)/AC12 -> 40.885989 | G12: =R12*(1-'DRE + DCF'!$AE$39) -> 0.097122165 | H12: =$D12 -> 0.16187028 | I12: =$D12 -> 0.16187028 | J12: =$D12 -> 0.16187028 | K12: =$D12 -> 0.16187028 | L12: =$D12 -> 0.16187028 | M12: =$D12 -> 0.16187028 | N12: =$D12 -> 0.16187028 | O12: =$D12 -> 0.16187028 | ... R12: =$D12 -> 0.16187028 | S12: =(1+H12)^((5-Dashboard!$F$9)*3/12) -> 1.0779009 | T12: =(S12)*(1+I12) -> 1.252381 | U12: =(T12)*(1+J12) -> 1.4551042 | V12: =(U12)*(1+K12) -> 1.6906423 | W12: =(V12)*(1+L12) -> 1.9643071 | X12: =(W12)*(1+M12) -> 2.28227 | Y12: =(X12)*(1+N12) -> 2.6517017 | Z12: =(Y12)*(1+O12) -> 3.0809334 | AA12: =(Z12)*(1+P12) -> 3.5796449 | ... AC12: =(AB12)*(1+R12) -> 4.8323149
A13: Projeções - Receita | C13: =ABS(E13-Dashboard!$F$13) -> 122.43462 | D13: ='DRE + DCF'!AG38+0.00005 -> 0.093152165 | E13: {=SUM('DRE + DCF'!$S$41/TIR!S13,'DRE + DCF'!$U$41:$AD$41/TIR!T13:AC13,TIR!F13)} -> 170.05462 | F13: ='DRE + DCF'!$AE$38*'DRE + DCF'!$AE$39*(1+G13)/(R13-G13)/AC13 -> 129.69451 | G13: =R13*(1-'DRE + DCF'!$AE$39) -> 0.055891299 | H13: =$D13 -> 0.093152165 | I13: =$D13 -> 0.093152165 | J13: =$D13 -> 0.093152165 | K13: =$D13 -> 0.093152165 | L13: =$D13 -> 0.093152165 | M13: =$D13 -> 0.093152165 | N13: =$D13 -> 0.093152165 | O13: =$D13 -> 0.093152165 | ... R13: =$D13 -> 0.093152165 | S13: =(1+H13)^((5-Dashboard!$F$9)*3/12) -> 1.0455392 | T13: =(S13)*(1+I13) -> 1.1429334 | U13: =(T13)*(1+J13) -> 1.2494001 | V13: =(U13)*(1+K13) -> 1.3657845 | W13: =(V13)*(1+L13) -> 1.4930102 | X13: =(W13)*(1+M13) -> 1.6320874 | Y13: =(X13)*(1+N13) -> 1.7841199 | Z13: =(Y13)*(1+O13) -> 1.9503145 | AA13: =(Z13)*(1+P13) -> 2.1319905 | ... AC13: =(AB13)*(1+R13) -> 2.5476895
A14: Painel de Índices | C14: =ABS(E14-Dashboard!$F$13) -> 122.15698 | D14: =D13+0.0001 -> 0.093252165 | E14: {=SUM('DRE + DCF'!$S$41/TIR!S14,'DRE + DCF'!$U$41:$AD$41/TIR!T14:AC14,TIR!F14)} -> 169.77698 | F14: ='DRE + DCF'!$AE$38*'DRE + DCF'!$AE$39*(1+G14)/(R14-G14)/AC14 -> 129.43841 | G14: =R14*(1-'DRE + DCF'!$AE$39) -> 0.055951299 | H14: =$D14 -> 0.093252165 | I14: =$D14 -> 0.093252165 | J14: =$D14 -> 0.093252165 | K14: =$D14 -> 0.093252165 | L14: =$D14 -> 0.093252165 | M14: =$D14 -> 0.093252165 | N14: =$D14 -> 0.093252165 | O14: =$D14 -> 0.093252165 | ... R14: =$D14 -> 0.093252165 | S14: =(1+H14)^((5-Dashboard!$F$9)*3/12) -> 1.045587 | T14: =(S14)*(1+I14) -> 1.1430902 | U14: =(T14)*(1+J14) -> 1.2496859 | V14: =(U14)*(1+K14) -> 1.3662218 | W14: =(V14)*(1+L14) -> 1.4936249 | X14: =(W14)*(1+M14) -> 1.6329087 | Y14: =(X14)*(1+N14) -> 1.785181 | Z14: =(Y14)*(1+O14) -> 1.951653 | AA14: =(Z14)*(1+P14) -> 2.1336488 | ... AC14: =(AB14)*(1+R14) -> 2.5501377
A15: Provisões e Processos | C15: =ABS(E15-Dashboard!$F$13) -> 121.88001 | D15: =D14+0.0001 -> 0.093352165 | E15: {=SUM('DRE + DCF'!$S$41/TIR!S15,'DRE + DCF'!$U$41:$AD$41/TIR!T15:AC15,TIR!F15)} -> 169.50001 | F15: ='DRE + DCF'!$AE$38*'DRE + DCF'!$AE$39*(1+G15)/(R15-G15)/AC15 -> 129.18298 | G15: =R15*(1-'DRE + DCF'!$AE$39) -> 0.056011299 | H15: =$D15 -> 0.093352165 | I15: =$D15 -> 0.093352165 | J15: =$D15 -> 0.093352165 | K15: =$D15 -> 0.093352165 | L15: =$D15 -> 0.093352165 | M15: =$D15 -> 0.093352165 | N15: =$D15 -> 0.093352165 | O15: =$D15 -> 0.093352165 | ... R15: =$D15 -> 0.093352165 | S15: =(1+H15)^((5-Dashboard!$F$9)*3/12) -> 1.0456348 | T15: =(S15)*(1+I15) -> 1.1432471 | U15: =(T15)*(1+J15) -> 1.2499717 | V15: =(U15)*(1+K15) -> 1.3666592 | W15: =(V15)*(1+L15) -> 1.4942398 | X15: =(W15)*(1+M15) -> 1.6337304 | Y15: =(X15)*(1+N15) -> 1.7862426 | Z15: =(Y15)*(1+O15) -> 1.9529922 | AA15: =(Z15)*(1+P15) -> 2.1353083 | ... AC15: =(AB15)*(1+R15) -> 2.552588
A16: Projeções Trimestrais | C16: =ABS(E16-Dashboard!$F$13) -> 121.60373 | D16: =D15+0.0001 -> 0.093452165 | E16: {=SUM('DRE + DCF'!$S$41/TIR!S16,'DRE + DCF'!$U$41:$AD$41/TIR!T16:AC16,TIR!F16)} -> 169.22373 | F16: ='DRE + DCF'!$AE$38*'DRE + DCF'!$AE$39*(1+G16)/(R16-G16)/AC16 -> 128.92821 | G16: =R16*(1-'DRE + DCF'!$AE$39) -> 0.056071299 | H16: =$D16 -> 0.093452165 | I16: =$D16 -> 0.093452165 | J16: =$D16 -> 0.093452165 | K16: =$D16 -> 0.093452165 | L16: =$D16 -> 0.093452165 | M16: =$D16 -> 0.093452165 | N16: =$D16 -> 0.093452165 | O16: =$D16 -> 0.093452165 | ... R16: =$D16 -> 0.093452165 | S16: =(1+H16)^((5-Dashboard!$F$9)*3/12) -> 1.0456826 | T16: =(S16)*(1+I16) -> 1.1434039 | U16: =(T16)*(1+J16) -> 1.2502575 | V16: =(U16)*(1+K16) -> 1.3670968 | W16: =(V16)*(1+L16) -> 1.4948549 | X16: =(W16)*(1+M16) -> 1.6345524 | Y16: =(X16)*(1+N16) -> 1.7873048 | Z16: =(Y16)*(1+O16) -> 1.9543323 | AA16: =(Z16)*(1+P16) -> 2.1369689 | ... AC16: =(AB16)*(1+R16) -> 2.5550405
C17: =ABS(E17-Dashboard!$F$13) -> 121.32812 | D17: =D16+0.0001 -> 0.093552165 | E17: {=SUM('DRE + DCF'!$S$41/TIR!S17,'DRE + DCF'!$U$41:$AD$41/TIR!T17:AC17,TIR!F17)} -> 168.94812 | F17: ='DRE + DCF'!$AE$38*'DRE + DCF'!$AE$39*(1+G17)/(R17-G17)/AC17 -> 128.67409 | G17: =R17*(1-'DRE + DCF'!$AE$39) -> 0.056131299 | H17: =$D17 -> 0.093552165 | I17: =$D17 -> 0.093552165 | J17: =$D17 -> 0.093552165 | K17: =$D17 -> 0.093552165 | L17: =$D17 -> 0.093552165 | M17: =$D17 -> 0.093552165 | N17: =$D17 -> 0.093552165 | O17: =$D17 -> 0.093552165 | ... R17: =$D17 -> 0.093552165 | S17: =(1+H17)^((5-Dashboard!$F$9)*3/12) -> 1.0457304 | T17: =(S17)*(1+I17) -> 1.1435608 | U17: =(T17)*(1+J17) -> 1.2505434 | V17: =(U17)*(1+K17) -> 1.3675344 | W17: =(V17)*(1+L17) -> 1.4954702 | X17: =(W17)*(1+M17) -> 1.6353747 | Y17: =(X17)*(1+N17) -> 1.7883676 | Z17: =(Y17)*(1+O17) -> 1.9556732 | AA17: =(Z17)*(1+P17) -> 2.1386307 | ... AC17: =(AB17)*(1+R17) -> 2.557495
C18: =ABS(E18-Dashboard!$F$13) -> 121.05319 | D18: =D17+0.0001 -> 0.093652165 | E18: {=SUM('DRE + DCF'!$S$41/TIR!S18,'DRE + DCF'!$U$41:$AD$41/TIR!T18:AC18,TIR!F18)} -> 168.67319 | F18: ='DRE + DCF'!$AE$38*'DRE + DCF'!$AE$39*(1+G18)/(R18-G18)/AC18 -> 128.42064 | G18: =R18*(1-'DRE + DCF'!$AE$39) -> 0.056191299 | H18: =$D18 -> 0.093652165 | I18: =$D18 -> 0.093652165 | J18: =$D18 -> 0.093652165 | K18: =$D18 -> 0.093652165 | L18: =$D18 -> 0.093652165 | M18: =$D18 -> 0.093652165 | N18: =$D18 -> 0.093652165 | O18: =$D18 -> 0.093652165 | ... R18: =$D18 -> 0.093652165 | S18: =(1+H18)^((5-Dashboard!$F$9)*3/12) -> 1.0457783 | T18: =(S18)*(1+I18) -> 1.1437177 | U18: =(T18)*(1+J18) -> 1.2508293 | V18: =(U18)*(1+K18) -> 1.3679722 | W18: =(V18)*(1+L18) -> 1.4960857 | X18: =(W18)*(1+M18) -> 1.6361974 | Y18: =(X18)*(1+N18) -> 1.7894308 | Z18: =(Y18)*(1+O18) -> 1.9570149 | AA18: =(Z18)*(1+P18) -> 2.1402936 | ... AC18: =(AB18)*(1+R18) -> 2.5599517
C19: =ABS(E19-Dashboard!$F$13) -> 120.77893 | D19: =D18+0.0001 -> 0.093752165 | E19: {=SUM('DRE + DCF'!$S$41/TIR!S19,'DRE + DCF'!$U$41:$AD$41/TIR!T19:AC19,TIR!F19)} -> 168.39893 | F19: ='DRE + DCF'!$AE$38*'DRE + DCF'!$AE$39*(1+G19)/(R19-G19)/AC19 -> 128.16784 | G19: =R19*(1-'DRE + DCF'!$AE$39) -> 0.056251299 | H19: =$D19 -> 0.093752165 | I19: =$D19 -> 0.093752165 | J19: =$D19 -> 0.093752165 | K19: =$D19 -> 0.093752165 | L19: =$D19 -> 0.093752165 | M19: =$D19 -> 0.093752165 | N19: =$D19 -> 0.093752165 | O19: =$D19 -> 0.093752165 | ... R19: =$D19 -> 0.093752165 | S19: =(1+H19)^((5-Dashboard!$F$9)*3/12) -> 1.0458261 | T19: =(S19)*(1+I19) -> 1.1438745 | U19: =(T19)*(1+J19) -> 1.2511152 | V19: =(U19)*(1+K19) -> 1.36841 | W19: =(V19)*(1+L19) -> 1.4967014 | X19: =(W19)*(1+M19) -> 1.6370204 | Y19: =(X19)*(1+N19) -> 1.7904946 | Z19: =(Y19)*(1+O19) -> 1.9583574 | AA19: =(Z19)*(1+P19) -> 2.1419576 | ... AC19: =(AB19)*(1+R19) -> 2.5624106
C20: =ABS(E20-Dashboard!$F$13) -> 120.50534 | D20: =D19+0.0001 -> 0.093852165 | E20: {=SUM('DRE + DCF'!$S$41/TIR!S20,'DRE + DCF'!$U$41:$AD$41/TIR!T20:AC20,TIR!F20)} -> 168.12534 | F20: ='DRE + DCF'!$AE$38*'DRE + DCF'!$AE$39*(1+G20)/(R20-G20)/AC20 -> 127.9157 | G20: =R20*(1-'DRE + DCF'!$AE$39) -> 0.056311299 | H20: =$D20 -> 0.093852165 | I20: =$D20 -> 0.093852165 | J20: =$D20 -> 0.093852165 | K20: =$D20 -> 0.093852165 | L20: =$D20 -> 0.093852165 | M20: =$D20 -> 0.093852165 | N20: =$D20 -> 0.093852165 | O20: =$D20 -> 0.093852165 | ... R20: =$D20 -> 0.093852165 | S20: =(1+H20)^((5-Dashboard!$F$9)*3/12) -> 1.0458739 | T20: =(S20)*(1+I20) -> 1.1440314 | U20: =(T20)*(1+J20) -> 1.2514012 | V20: =(U20)*(1+K20) -> 1.3688479 | W20: =(V20)*(1+L20) -> 1.4973173 | X20: =(W20)*(1+M20) -> 1.6378438 | Y20: =(X20)*(1+N20) -> 1.7915589 | Z20: =(Y20)*(1+O20) -> 1.9597006 | AA20: =(Z20)*(1+P20) -> 2.1436228 | ... AC20: =(AB20)*(1+R20) -> 2.5648716
C21: =ABS(E21-Dashboard!$F$13) -> 120.23242 | D21: =D20+0.0001 -> 0.093952165 | E21: {=SUM('DRE + DCF'!$S$41/TIR!S21,'DRE + DCF'!$U$41:$AD$41/TIR!T21:AC21,TIR!F21)} -> 167.85242 | F21: ='DRE + DCF'!$AE$38*'DRE + DCF'!$AE$39*(1+G21)/(R21-G21)/AC21 -> 127.66421 | G21: =R21*(1-'DRE + DCF'!$AE$39) -> 0.056371299 | H21: =$D21 -> 0.093952165 | I21: =$D21 -> 0.093952165 | J21: =$D21 -> 0.093952165 | K21: =$D21 -> 0.093952165 | L21: =$D21 -> 0.093952165 | M21: =$D21 -> 0.093952165 | N21: =$D21 -> 0.093952165 | O21: =$D21 -> 0.093952165 | ... R21: =$D21 -> 0.093952165 | S21: =(1+H21)^((5-Dashboard!$F$9)*3/12) -> 1.0459217 | T21: =(S21)*(1+I21) -> 1.1441883 | U21: =(T21)*(1+J21) -> 1.2516873 | V21: =(U21)*(1+K21) -> 1.369286 | W21: =(V21)*(1+L21) -> 1.4979334 | X21: =(W21)*(1+M21) -> 1.6386674 | Y21: =(X21)*(1+N21) -> 1.7926238 | Z21: =(Y21)*(1+O21) -> 1.9610447 | AA21: =(Z21)*(1+P21) -> 2.1452891 | ... AC21: =(AB21)*(1+R21) -> 2.5673347
C22: =ABS(E22-Dashboard!$F$13) -> 119.96017 | D22: =D21+0.0001 -> 0.094052165 | E22: {=SUM('DRE + DCF'!$S$41/TIR!S22,'DRE + DCF'!$U$41:$AD$41/TIR!T22:AC22,TIR!F22)} -> 167.58017 | F22: ='DRE + DCF'!$AE$38*'DRE + DCF'!$AE$39*(1+G22)/(R22-G22)/AC22 -> 127.41337 | G22: =R22*(1-'DRE + DCF'!$AE$39) -> 0.056431299 | H22: =$D22 -> 0.094052165 | I22: =$D22 -> 0.094052165 | J22: =$D22 -> 0.094052165 | K22: =$D22 -> 0.094052165 | L22: =$D22 -> 0.094052165 | M22: =$D22 -> 0.094052165 | N22: =$D22 -> 0.094052165 | O22: =$D22 -> 0.094052165 | ... R22: =$D22 -> 0.094052165 | S22: =(1+H22)^((5-Dashboard!$F$9)*3/12) -> 1.0459695 | T22: =(S22)*(1+I22) -> 1.1443452 | U22: =(T22)*(1+J22) -> 1.2519733 | V22: =(U22)*(1+K22) -> 1.3697241 | W22: =(V22)*(1+L22) -> 1.4985496 | X22: =(W22)*(1+M22) -> 1.6394915 | Y22: =(X22)*(1+N22) -> 1.7936892 | Z22: =(Y22)*(1+O22) -> 1.9623896 | AA22: =(Z22)*(1+P22) -> 2.1469565 | ... AC22: =(AB22)*(1+R22) -> 2.5697999
C23: =ABS(E23-Dashboard!$F$13) -> 119.68858 | D23: =D22+0.0001 -> 0.094152165 | E23: {=SUM('DRE + DCF'!$S$41/TIR!S23,'DRE + DCF'!$U$41:$AD$41/TIR!T23:AC23,TIR!F23)} -> 167.30858 | F23: ='DRE + DCF'!$AE$38*'DRE + DCF'!$AE$39*(1+G23)/(R23-G23)/AC23 -> 127.16317 | G23: =R23*(1-'DRE + DCF'!$AE$39) -> 0.056491299 | H23: =$D23 -> 0.094152165 | I23: =$D23 -> 0.094152165 | J23: =$D23 -> 0.094152165 | K23: =$D23 -> 0.094152165 | L23: =$D23 -> 0.094152165 | M23: =$D23 -> 0.094152165 | N23: =$D23 -> 0.094152165 | O23: =$D23 -> 0.094152165 | ... R23: =$D23 -> 0.094152165 | S23: =(1+H23)^((5-Dashboard!$F$9)*3/12) -> 1.0460173 | T23: =(S23)*(1+I23) -> 1.1445021 | U23: =(T23)*(1+J23) -> 1.2522594 | V23: =(U23)*(1+K23) -> 1.3701624 | W23: =(V23)*(1+L23) -> 1.4991661 | X23: =(W23)*(1+M23) -> 1.6403159 | Y23: =(X23)*(1+N23) -> 1.7947551 | Z23: =(Y23)*(1+O23) -> 1.9637352 | AA23: =(Z23)*(1+P23) -> 2.1486251 | ... AC23: =(AB23)*(1+R23) -> 2.5722673
C24: =ABS(E24-Dashboard!$F$13) -> 119.41765 | D24: =D23+0.0001 -> 0.094252165 | E24: {=SUM('DRE + DCF'!$S$41/TIR!S24,'DRE + DCF'!$U$41:$AD$41/TIR!T24:AC24,TIR!F24)} -> 167.03765 | F24: ='DRE + DCF'!$AE$38*'DRE + DCF'!$AE$39*(1+G24)/(R24-G24)/AC24 -> 126.91363 | G24: =R24*(1-'DRE + DCF'!$AE$39) -> 0.056551299 | H24: =$D24 -> 0.094252165 | I24: =$D24 -> 0.094252165 | J24: =$D24 -> 0.094252165 | K24: =$D24 -> 0.094252165 | L24: =$D24 -> 0.094252165 | M24: =$D24 -> 0.094252165 | N24: =$D24 -> 0.094252165 | O24: =$D24 -> 0.094252165 | ... R24: =$D24 -> 0.094252165 | S24: =(1+H24)^((5-Dashboard!$F$9)*3/12) -> 1.0460651 | T24: =(S24)*(1+I24) -> 1.144659 | U24: =(T24)*(1+J24) -> 1.2525456 | V24: =(U24)*(1+K24) -> 1.3706007 | W24: =(V24)*(1+L24) -> 1.4997828 | X24: =(W24)*(1+M24) -> 1.6411406 | Y24: =(X24)*(1+N24) -> 1.7958216 | Z24: =(Y24)*(1+O24) -> 1.9650817 | AA24: =(Z24)*(1+P24) -> 2.1502949 | ... AC24: =(AB24)*(1+R24) -> 2.5747369
C25: =ABS(E25-Dashboard!$F$13) -> 119.14739 | D25: =D24+0.0001 -> 0.094352165 | E25: {=SUM('DRE + DCF'!$S$41/TIR!S25,'DRE + DCF'!$U$41:$AD$41/TIR!T25:AC25,TIR!F25)} -> 166.76739 | F25: ='DRE + DCF'!$AE$38*'DRE + DCF'!$AE$39*(1+G25)/(R25-G25)/AC25 -> 126.66472 | G25: =R25*(1-'DRE + DCF'!$AE$39) -> 0.056611299 | H25: =$D25 -> 0.094352165 | I25: =$D25 -> 0.094352165 | J25: =$D25 -> 0.094352165 | K25: =$D25 -> 0.094352165 | L25: =$D25 -> 0.094352165 | M25: =$D25 -> 0.094352165 | N25: =$D25 -> 0.094352165 | O25: =$D25 -> 0.094352165 | ... R25: =$D25 -> 0.094352165 | S25: =(1+H25)^((5-Dashboard!$F$9)*3/12) -> 1.0461129 | T25: =(S25)*(1+I25) -> 1.1448159 | U25: =(T25)*(1+J25) -> 1.2528318 | V25: =(U25)*(1+K25) -> 1.3710391 | W25: =(V25)*(1+L25) -> 1.5003997 | X25: =(W25)*(1+M25) -> 1.6419656 | Y25: =(X25)*(1+N25) -> 1.7968886 | Z25: =(Y25)*(1+O25) -> 1.966429 | AA25: =(Z25)*(1+P25) -> 2.1519658 | ... AC25: =(AB25)*(1+R25) -> 2.5772086
C26: =ABS(E26-Dashboard!$F$13) -> 118.87778 | D26: =D25+0.0001 -> 0.094452165 | E26: {=SUM('DRE + DCF'!$S$41/TIR!S26,'DRE + DCF'!$U$41:$AD$41/TIR!T26:AC26,TIR!F26)} -> 166.49778 | F26: ='DRE + DCF'!$AE$38*'DRE + DCF'!$AE$39*(1+G26)/(R26-G26)/AC26 -> 126.41645 | G26: =R26*(1-'DRE + DCF'!$AE$39) -> 0.056671299 | H26: =$D26 -> 0.094452165 | I26: =$D26 -> 0.094452165 | J26: =$D26 -> 0.094452165 | K26: =$D26 -> 0.094452165 | L26: =$D26 -> 0.094452165 | M26: =$D26 -> 0.094452165 | N26: =$D26 -> 0.094452165 | O26: =$D26 -> 0.094452165 | ... R26: =$D26 -> 0.094452165 | S26: =(1+H26)^((5-Dashboard!$F$9)*3/12) -> 1.0461607 | T26: =(S26)*(1+I26) -> 1.1449728 | U26: =(T26)*(1+J26) -> 1.253118 | V26: =(U26)*(1+K26) -> 1.3714777 | W26: =(V26)*(1+L26) -> 1.5010167 | X26: =(W26)*(1+M26) -> 1.642791 | Y26: =(X26)*(1+N26) -> 1.7979562 | Z26: =(Y26)*(1+O26) -> 1.967777 | AA26: =(Z26)*(1+P26) -> 2.1536378 | ... AC26: =(AB26)*(1+R26) -> 2.5796824
C27: =ABS(E27-Dashboard!$F$13) -> 118.60882 | D27: =D26+0.0001 -> 0.094552165 | E27: {=SUM('DRE + DCF'!$S$41/TIR!S27,'DRE + DCF'!$U$41:$AD$41/TIR!T27:AC27,TIR!F27)} -> 166.22882 | F27: ='DRE + DCF'!$AE$38*'DRE + DCF'!$AE$39*(1+G27)/(R27-G27)/AC27 -> 126.16883 | G27: =R27*(1-'DRE + DCF'!$AE$39) -> 0.056731299 | H27: =$D27 -> 0.094552165 | I27: =$D27 -> 0.094552165 | J27: =$D27 -> 0.094552165 | K27: =$D27 -> 0.094552165 | L27: =$D27 -> 0.094552165 | M27: =$D27 -> 0.094552165 | N27: =$D27 -> 0.094552165 | O27: =$D27 -> 0.094552165 | ... R27: =$D27 -> 0.094552165 | S27: =(1+H27)^((5-Dashboard!$F$9)*3/12) -> 1.0462085 | T27: =(S27)*(1+I27) -> 1.1451297 | U27: =(T27)*(1+J27) -> 1.2534042 | V27: =(U27)*(1+K27) -> 1.3719163 | W27: =(V27)*(1+L27) -> 1.501634 | X27: =(W27)*(1+M27) -> 1.6436167 | Y27: =(X27)*(1+N27) -> 1.7990243 | Z27: =(Y27)*(1+O27) -> 1.9691259 | AA27: =(Z27)*(1+P27) -> 2.155311 | ... AC27: =(AB27)*(1+R27) -> 2.5821584
C28: =ABS(E28-Dashboard!$F$13) -> 118.34052 | D28: =D27+0.0001 -> 0.094652165 | E28: {=SUM('DRE + DCF'!$S$41/TIR!S28,'DRE + DCF'!$U$41:$AD$41/TIR!T28:AC28,TIR!F28)} -> 165.96052 | F28: ='DRE + DCF'!$AE$38*'DRE + DCF'!$AE$39*(1+G28)/(R28-G28)/AC28 -> 125.92184 | G28: =R28*(1-'DRE + DCF'!$AE$39) -> 0.056791299 | H28: =$D28 -> 0.094652165 | I28: =$D28 -> 0.094652165 | J28: =$D28 -> 0.094652165 | K28: =$D28 -> 0.094652165 | L28: =$D28 -> 0.094652165 | M28: =$D28 -> 0.094652165 | N28: =$D28 -> 0.094652165 | O28: =$D28 -> 0.094652165 | ... R28: =$D28 -> 0.094652165 | S28: =(1+H28)^((5-Dashboard!$F$9)*3/12) -> 1.0462563 | T28: =(S28)*(1+I28) -> 1.1452867 | U28: =(T28)*(1+J28) -> 1.2536905 | V28: =(U28)*(1+K28) -> 1.3723551 | W28: =(V28)*(1+L28) -> 1.5022514 | X28: =(W28)*(1+M28) -> 1.6444428 | Y28: =(X28)*(1+N28) -> 1.8000929 | Z28: =(Y28)*(1+O28) -> 1.9704756 | AA28: =(Z28)*(1+P28) -> 2.1569853 | ... AC28: =(AB28)*(1+R28) -> 2.5846365
... C3382: =ABS(E3382-Dashboard!$F$13) -> 33.876457 | D3382: =D3381+0.0001 -> 0.43005217 | E3382: {=SUM('DRE + DCF'!$S$41/TIR!S3382,'DRE + DCF'!$U$41:$AD$41/TIR!T3382:AC3382,TIR!F3382)} -> 13.743543 | F3382: ='DRE + DCF'!$AE$38*'DRE + DCF'!$AE$39*(1+G3382)/(R3382-G3382)/AC3382 -> 1.9935054 | G3382: =R3382*(1-'DRE + DCF'!$AE$39) -> 0.2580313 | H3382: =$D3382 -> 0.43005217 | I3382: =$D3382 -> 0.43005217 | J3382: =$D3382 -> 0.43005217 | K3382: =$D3382 -> 0.43005217 | L3382: =$D3382 -> 0.43005217 | M3382: =$D3382 -> 0.43005217 | N3382: =$D3382 -> 0.43005217 | O3382: =$D3382 -> 0.43005217 | ... R3382: =$D3382 -> 0.43005217 | S3382: =(1+H3382)^((5-Dashboard!$F$9)*3/12) -> 1.1958479 | T3382: =(S3382)*(1+I3382) -> 1.7101249 | U3382: =(T3382)*(1+J3382) -> 2.4455678 | V3382: =(U3382)*(1+K3382) -> 3.4972895 | W3382: =(V3382)*(1+L3382) -> 5.0013064 | X3382: =(W3382)*(1+M3382) -> 7.152129 | Y3382: =(X3382)*(1+N3382) -> 10.227918 | Z3382: =(Y3382)*(1+O3382) -> 14.626456 | AA3382: =(Z3382)*(1+P3382) -> 20.916595 | ... AC3382: =(AB3382)*(1+R3382) -> 42.775465

Sheet DRE + DCF
L4: =Dashboard!$I$4 -> Banco do Brasil ($BBAS3)
A7: Páginas
A8: Dashboard
A9: Ke | F9: 2014 | G9: 2015 | H9: 2016 | I9: 2017 | J9: 2018 | K9: 2019 | L9: 2020 | M9: 2021 | N9: 2022 | O9: 1T23 | P9: 2T23 | Q9: 3T23 | R9: 4T23 | S9: YTG23 | T9: 2023 | U9: 2024 | V9: 2025 | W9: 2026 | X9: 2027 | Y9: 2028 | Z9: 2029 | AA9: 2030 | AB9: 2031 | AC9: 2032 | AD9: 2033
A10: DRE + DCF | E10: Margem Financeira Líquida | F10: ='Projeções - Receitas'!F26 -> 2.7953349e+10 | G10: ='Projeções - Receitas'!G26 -> 2.7970373e+10 | H10: ='Projeções - Receitas'!H26 -> 2.647592e+10 | I10: ='Projeções - Receitas'!I26 -> 3.1171212e+10 | J10: ='Projeções - Receitas'!J26 -> 3.4564593e+10 | K10: ='Projeções - Receitas'!K26 -> 3.9015565e+10 | L10: ='Projeções - Receitas'!L26 -> 3.4616132e+10 | M10: ='Projeções - Receitas'!M26 -> 4.6197474e+10 | ... AD10: ='Projeções - Receitas'!AD26 -> 1.5619141e+11
A11: Contas Abertas | E11: Crescimento da Margem Financeira Líquida (YoY)¹ | F11: - | G11: =G10/F10-1 -> 0.00060900094 | H11: =H10/G10-1 -> -0.05342984 | I11: =I10/H10-1 -> 0.17734197 | J11: =J10/I10-1 -> 0.10886264 | K11: =K10/J10-1 -> 0.1287726 | L11: =L10/K10-1 -> -0.11276098 | M11: =M10/L10-1 -> 0.33456488 | N11: =N10/M10-1 -> 0.22626163 | T11: =T10/N10-1 -> 0.12050995 | U11: =U10/T10-1 -> -0.14332781 | V11: =V10/U10-1 -> 0.10648138 | W11: =W10/V10-1 -> 0.10548775 | X11: =X10/W10-1 -> 0.10498077 | Y11: =Y10/X10-1 -> 0.10477662 | Z11: =Z10/Y10-1 -> 0.10465168 | AA11: =AA10/Z10-1 -> 0.10449577 | AB11: =AB10/AA10-1 -> 0.10432174 | ... AD11: =AD10/AC10-1 -> 0.29295034
A12: Balanço Patrimonial | E12: Outras Receitas Operacionais | F12: ='Projeções - Receitas'!F133 -> 2.1778487e+10 | G12: ='Projeções - Receitas'!G133 -> 2.2047848e+10 | H12: ='Projeções - Receitas'!H133 -> 2.3794116e+10 | I12: ='Projeções - Receitas'!I133 -> 2.5941416e+10 | J12: ='Projeções - Receitas'!J133 -> 2.7452372e+10 | K12: ='Projeções - Receitas'!K133 -> 2.9208671e+10 | L12: ='Projeções - Receitas'!L133 -> 2.8701888e+10 | M12: ='Projeções - Receitas'!M133 -> 2.9343336e+10 | ... AD12: ='Projeções - Receitas'!AD133 -> 5.4181929e+10
A13: Projeções - Receita | E13: Crescimento das Outra Receitas Operacionais (YoY)¹ | F13: - | G13: =G12/F12-1 -> 0.012368192 | H13: =H12/G12-1 -> 0.079203561 | I13: =I12/H12-1 -> 0.090245008 | J13: =J12/I12-1 -> 0.058244951 | K13: =K12/J12-1 -> 0.063976216 | L13: =L12/K12-1 -> -0.017350426 | M13: =M12/L12-1 -> 0.02234863 | N13: =N12/M12-1 -> 0.10189156 | T13: =T12/N12-1 -> 0.051905333 | U13: =U12/T12-1 -> 0.038253156 | V13: =V12/U12-1 -> 0.041695745 | W13: =W12/V12-1 -> 0.044742827 | X13: =X12/W12-1 -> 0.047095003 | Y13: =Y12/X12-1 -> 0.048813626 | Z13: =Z12/Y12-1 -> 0.049958046 | AA13: =AA12/Z12-1 -> 0.050816379 | AB13: =AB12/AA12-1 -> 0.051456573 | ... AD13: =AD12/AC12-1 -> 0.052055296
A14: Painel de Índices | E14: Despesas Tributárias sobre Faturamento | F14: ='DRE CMN 4.720 - Contas Abertas'!F51 -> -4.0697476e+09 | G14: ='DRE CMN 4.720 - Contas Abertas'!G51 -> -4.3215667e+09 | H14: ='DRE CMN 4.720 - Contas Abertas'!H51 -> -5.1158347e+09 | I14: ='DRE CMN 4.720 - Contas Abertas'!I51 -> -5.0005496e+09 | J14: ='DRE CMN 4.720 - Contas Abertas'!J51 -> -4.5897923e+09 | K14: ='DRE CMN 4.720 - Contas Abertas'!K51 -> -4.4577427e+09 | L14: ='DRE CMN 4.720 - Contas Abertas'!L51 -> -4.8462431e+09 | M14: ='DRE CMN 4.720 - Contas Abertas'!M51 -> -5.0006834e+09 | ... P14: ='DRE CMN 4.720 - Contas Abertas'!P51 -> -1.7373917e+09 | Q14: ='Projeções Trimestrais'!H77 -> -1.6662303e+09 | R14: ='Projeções Trimestrais'!I77 -> -1.7327327e+09 | S14: =SUM(Q14:R14) -> -3.398963e+09 | T14: =SUM(O14:R14) -> -6.6882739e+09 | U14: =U15*SUM(U10,U12) -> -7.0544894e+09 | V14: =V15*SUM(V10,V12) -> -7.6257239e+09 | W14: =W15*SUM(W10,W12) -> -8.2543952e+09 | X14: =X15*SUM(X10,X12) -> -8.9459776e+09 | Y14: =Y15*SUM(Y10,Y12) -> -9.706182e+09 | Z14: =Z15*SUM(Z10,Z12) -> -1.0540393e+10 | AA14: =AA15*SUM(AA10,AA12) -> -1.1454727e+10 | AB14: =AB15*SUM(AB10,AB12) -> -1.2456086e+10 | ... AD14: =AD15*SUM(AD10,AD12) -> -1.6546447e+10
A15: Provisões e Processos | E15: Despesas Tributárias sobre Fauramento como % Total de Receitas | F15: =F14/SUM(F10,F12) -> -0.081833849 | G15: =G14/SUM(G10,G12) -> -0.086399848 | H15: =H14/SUM(H10,H12) -> -0.10176708 | I15: =I14/SUM(I10,I12) -> -0.087555936 | J15: =J14/SUM(J10,J12) -> -0.074008657 | K15: =K14/SUM(K10,K12) -> -0.065339577 | L15: =L14/SUM(L10,L12) -> -0.076538134 | M15: =M14/SUM(M10,M12) -> -0.066198435 | ... T15: =T14/SUM(T10,T12) -> -0.068605745 | U15: =AVERAGE($F$15:$N$15) -> -0.078652775 | V15: =AVERAGE($F$15:$N$15) -> -0.078652775 | W15: =AVERAGE($F$15:$N$15) -> -0.078652775 | X15: =AVERAGE($F$15:$N$15) -> -0.078652775 | Y15: =AVERAGE($F$15:$N$15) -> -0.078652775 | Z15: =AVERAGE($F$15:$N$15) -> -0.078652775 | AA15: =AVERAGE($F$15:$N$15) -> -0.078652775 | AB15: =AVERAGE($F$15:$N$15) -> -0.078652775 | ... AD15: =AVERAGE($F$15:$N$15) -> -0.078652775
A16: Projeções Trimestrais | E16: Margem de Contribuição | F16: =F10+F12+F14 -> 4.5662089e+10 | G16: =G10+G12+G14 -> 4.5696654e+10 | H16: =H10+H12+H14 -> 4.5154201e+10 | I16: =I10+I12+I14 -> 5.2112079e+10 | J16: =J10+J12+J14 -> 5.7427173e+10 | K16: =K10+K12+K14 -> 6.3766494e+10 | L16: =L10+L12+L14 -> 5.8471777e+10 | M16: =M10+M12+M14 -> 7.0540126e+10 | ... R16: =R10+R12+R14 -> 2.3493632e+10 | S16: =SUM(Q16:R16) -> 4.6526924e+10 | T16: =SUM(O16:R16) -> 9.0672328e+10 | U16: =U10+U12+U14 -> 8.2637061e+10 | V16: =V10+V12+V14 -> 8.9328565e+10 | W16: =W10+W12+W14 -> 9.669289e+10 | X16: =X10+X12+X14 -> 1.0479416e+11 | Y16: =Y10+Y12+Y14 -> 1.1369928e+11 | Z16: =Z10+Z12+Z14 -> 1.2347132e+11 | AA16: =AA10+AA12+AA14 -> 1.3418193e+11 | AB16: =AB10+AB12+AB14 -> 1.4591196e+11 | ... AD16: =AD10+AD12+AD14 -> 1.9382689e+11
E17: Crescimento das Margem de Contribuição (YoY)¹ | F17: - | G17: =G16/F16-1 -> 0.00075697494 | H17: =H16/G16-1 -> -0.011870728 | I17: =I16/H16-1 -> 0.15409146 | J17: =J16/I16-1 -> 0.10199352 | K17: =K16/J16-1 -> 0.11038887 | L17: =L16/K16-1 -> -0.083032897 | M17: =M16/L16-1 -> 0.20639615 | N17: =N16/M16-1 -> 0.17538379 | T17: =T16/N16-1 -> 0.093600839 | U17: =U16/T16-1 -> -0.088618727 | V17: =V16/U16-1 -> 0.08097461 | W17: =W16/V16-1 -> 0.082440871 | X17: =X16/W16-1 -> 0.083783537 | Y17: =Y16/X16-1 -> 0.08497723 | Z17: =Z16/Y16-1 -> 0.085946352 | AA17: =AA16/Z16-1 -> 0.086745714 | AB17: =AB16/AA16-1 -> 0.087418863 | ... AD17: =AD16/AC16-1 -> 0.22094744
E18: Outras Despesas/Receitas Operacionais | F18: =SUM('DRE CMN 4.720 - Contas Abertas'!F53,'DRE CMN 4.720 - Contas Abertas'!F56,'DRE CMN 4.720 - Contas Abertas'!F58,'DRE CMN 4.720 - Contas Abertas'!F61) -> -2.9084322e+10 | G18: =SUM('DRE CMN 4.720 - Contas Abertas'!G53,'DRE CMN 4.720 - Contas Abertas'!G56,'DRE CMN 4.720 - Contas Abertas'!G58,'DRE CMN 4.720 - Contas Abertas'!G61) -> -2.9928889e+10 | H18: =SUM('DRE CMN 4.720 - Contas Abertas'!H53,'DRE CMN 4.720 - Contas Abertas'!H56,'DRE CMN 4.720 - Contas Abertas'!H58,'DRE CMN 4.720 - Contas Abertas'!H61) -> -3.4437793e+10 | I18: =SUM('DRE CMN 4.720 - Contas Abertas'!I53,'DRE CMN 4.720 - Contas Abertas'!I56,'DRE CMN 4.720 - Contas Abertas'!I58,'DRE CMN 4.720 - Contas Abertas'!I61) -> -3.3548637e+10 | J18: =SUM('DRE CMN 4.720 - Contas Abertas'!J53,'DRE CMN 4.720 - Contas Abertas'!J56,'DRE CMN 4.720 - Contas Abertas'!J58,'DRE CMN 4.720 - Contas Abertas'!J61) -> -3.4325727e+10 | K18: =SUM('DRE CMN 4.720 - Contas Abertas'!K53,'DRE CMN 4.720 - Contas Abertas'!K56,'DRE CMN 4.720 - Contas Abertas'!K58,'DRE CMN 4.720 - Contas Abertas'!K61) -> -3.8851252e+10 | L18: =SUM('DRE CMN 4.720 - Contas Abertas'!L53,'DRE CMN 4.720 - Contas Abertas'!L56,'DRE CMN 4.720 - Contas Abertas'!L58,'DRE CMN 4.720 - Contas Abertas'!L61) -> -3.8370837e+10 | M18: =SUM('DRE CMN 4.720 - Contas Abertas'!M53,'DRE CMN 4.720 - Contas Abertas'!M56,'DRE CMN 4.720 - Contas Abertas'!M58,'DRE CMN 4.720 - Contas Abertas'!M61) -> -3.943413e+10 | ... P18: =SUM('DRE CMN 4.720 - Contas Abertas'!P53,'DRE CMN 4.720 - Contas Abertas'!P56,'DRE CMN 4.720 - Contas Abertas'!P58,'DRE CMN 4.720 - Contas Abertas'!P61) -> -9.2200254e+09 | Q18: ='Projeções Trimestrais'!H91 -> -9.4218503e+09 | R18: ='Projeções Trimestrais'!I91 -> -9.5376927e+09 | S18: =SUM(Q18:R18) -> -1.8959543e+10 | T18: =SUM(O18:R18) -> -3.7155337e+10 | U18: =T18*(1+'Projeções - Receitas'!U11) -> -3.8738154e+10 | V18: =U18*(1+'Projeções - Receitas'!V11) -> -4.0566595e+10 | W18: =V18*(1+'Projeções - Receitas'!W11) -> -4.2643605e+10 | X18: =W18*(1+'Projeções - Receitas'!X11) -> -4.4954888e+10 | Y18: =X18*(1+'Projeções - Receitas'!Y11) -> -4.7485848e+10 | Z18: =Y18*(1+'Projeções - Receitas'!Z11) -> -5.0221033e+10 | AA18: =Z18*(1+'Projeções - Receitas'!AA11) -> -5.3158964e+10 | AB18: =AA18*(1+'Projeções - Receitas'!AB11) -> -5.6300658e+10 | ... AD18: =AC18*(1+'Projeções - Receitas'!AD11) -> -6.3187826e+10
E19: Despesas Operacionais como % de Outras Receitas Operacionais | F19: =F18/F12 -> -1.3354611 | G19: =G18/G12 -> -1.3574517 | H19: =H18/H12 -> -1.4473239 | I19: =I18/I12 -> -1.2932462 | J19: =J18/J12 -> -1.2503738 | K19: =K18/K12 -> -1.3301273 | L19: =L18/L12 -> -1.336875 | M19: =M18/M12 -> -1.3438871 | ... AD19: =AD18/AD12 -> -1.1662159
E20: Resultado Operacional | F20: =SUM(F16,F18) -> 1.6577767e+10 | G20: =SUM(G16,G18) -> 1.5767765e+10 | H20: =SUM(H16,H18) -> 1.0716408e+10 | I20: =SUM(I16,I18) -> 1.8563442e+10 | J20: =SUM(J16,J18) -> 2.3101445e+10 | K20: =SUM(K16,K18) -> 2.4915242e+10 | L20: =SUM(L16,L18) -> 2.010094e+10 | M20: =SUM(M16,M18) -> 3.1105996e+10 | ... AD20: =SUM(AD16,AD18) -> 1.3063907e+11
E21: Crescimento do Resultado Operacional (YoY)¹ | F21: - | G21: =G20/F20-1 -> -0.048860714 | H21: =H20/G20-1 -> -0.32035975 | I21: =I20/H20-1 -> 0.73224474 | J21: =J20/I20-1 -> 0.24445918 | K21: =K20/J20-1 -> 0.078514406 | L21: =L20/K20-1 -> -0.19322717 | M21: =M20/L20-1 -> 0.54748963 | N21: =N20/M20-1 -> 0.56108785 | T21: =T20/N20-1 -> 0.10209803 | U21: =U20/T20-1 -> -0.17972019 | V21: =V20/U20-1 -> 0.11077868 | W21: =W20/V20-1 -> 0.10843112 | X21: =X20/W20-1 -> 0.10712425 | Y21: =Y20/X20-1 -> 0.1065213 | Z21: =Z20/Y20-1 -> 0.10627532 | AA21: =AA20/Z20-1 -> 0.10611122 | AB21: =AB20/AA20-1 -> 0.1059988 | ... AD21: =AD20/AC20-1 -> 0.31817116
E22: Resultado Não Operacional | F22: ='DRE CMN 4.720 - Contas Abertas'!F69 -> 1.4382725e+08 | G22: ='DRE CMN 4.720 - Contas Abertas'!G69 -> 1.6606351e+08 | H22: ='DRE CMN 4.720 - Contas Abertas'!H69 -> 2.2713104e+08 | I22: ='DRE CMN 4.720 - Contas Abertas'!I69 -> 1.8627469e+08 | J22: ='DRE CMN 4.720 - Contas Abertas'!J69 -> 2.1793005e+08 | K22: ='DRE CMN 4.720 - Contas Abertas'!K69 -> 1.2321214e+08 | L22: ='DRE CMN 4.720 - Contas Abertas'!L69 -> 1.549019e+08 | M22: ='DRE CMN 4.720 - Contas Abertas'!M69 -> 2.460578e+08 | ... O22: ='DRE CMN 4.720 - Contas Abertas'!O69 -> 1.0686121e+08
E23: Resultado Antes do IR | F23: =F20+F22 -> 1.6721594e+10 | G23: =G20+G22 -> 1.5933829e+10 | H23: =H20+H22 -> 1.0943539e+10 | I23: =I20+I22 -> 1.8749716e+10 | J23: =J20+J22 -> 2.3319375e+10 | K23: =K20+K22 -> 2.5038454e+10 | L23: =L20+L22 -> 2.0255842e+10 | M23: =M20+M22 -> 3.1352054e+10 | ... AD23: =AD20+AD22 -> 1.3063907e+11
E24: Imposto de Renda e Contribuição Social | F24: ='DRE CMN 4.720 - Contas Abertas'!F71 -> -2.4363414e+09 | G24: ='DRE CMN 4.720 - Contas Abertas'!G71 -> -8.2814101e+08 | H24: ='DRE CMN 4.720 - Contas Abertas'!H71 -> -1.1790907e+09 | I24: ='DRE CMN 4.720 - Contas Abertas'!I71 -> -4.6035192e+09 | J24: ='DRE CMN 4.720 - Contas Abertas'!J71 -> -6.6956437e+09 | K24: ='DRE CMN 4.720 - Contas Abertas'!K71 -> -3.1404959e+09 | L24: ='DRE CMN 4.720 - Contas Abertas'!L71 -> -3.0934574e+09 | M24: ='DRE CMN 4.720 - Contas Abertas'!M71 -> -6.0804538e+09 | ... P24: ='DRE CMN 4.720 - Contas Abertas'!P71 -> -2.3347449e+09 | Q24: =Q25*Q20 -> -2.723783e+09 | R24: =R25*R20 -> -2.7927205e+09 | S24: =SUM(Q24:R24) -> -5.5165034e+09 | T24: =SUM(O24:R24) -> -1.0415595e+10 | U24: =U25*U20 -> -8.5838009e+09 | V24: =V25*V20 -> -9.5792433e+09 | W24: =W25*W20 -> -1.0667301e+10 | X24: =X25*X20 -> -1.1864686e+10 | Y24: =Y25*Y20 -> -1.3189009e+10 | Z24: =Z25*Z20 -> -1.4657584e+10 | AA24: =AA25*AA20 -> -1.6286926e+10 | AB24: =AB25*AB20 -> -1.8095174e+10 | ... AD24: =AD25*AD20 -> -2.8740595e+10
E25: Imposto de Renda e Contribuição Social como % do Resultado Operacional | F25: =F24/F20 -> -0.14696439 | G25: =G24/G20 -> -0.05252114 | H25: =H24/H20 -> -0.11002667 | I25: =I24/I20 -> -0.24798846 | J25: =J24/J20 -> -0.28983657 | K25: =K24/K20 -> -0.12604718 | L25: =L24/L20 -> -0.15389616 | M25: =M24/M20 -> -0.1954753 | ... P25: =P24/P20 -> -0.17905271 | Q25: =AVERAGE($I$25:$P$25) -> -0.20010982 | R25: =AVERAGE($I$25:$P$25) -> -0.20010982 | S25: =S24/S20 -> -0.20010982 | T25: =T24/T20 -> -0.19462222 | U25: =T25+(($AD$25-$N$25)/11) -> -0.19553564 | V25: =U25+(($AD$25-$N$25)/11) -> -0.19644906 | W25: =V25+(($AD$25-$N$25)/11) -> -0.19736248 | X25: =W25+(($AD$25-$N$25)/11) -> -0.19827591 | Y25: =X25+(($AD$25-$N$25)/11) -> -0.19918933 | Z25: =Y25+(($AD$25-$N$25)/11) -> -0.20010275 | AA25: =Z25+(($AD$25-$N$25)/11) -> -0.20101618 | AB25: =AA25+(($AD$25-$N$25)/11) -> -0.2019296 | AC25: =AB25+(($AD$25-$N$25)/11) -> -0.20284302 | AD25: -0.22
E26: Resultado Antes de Participações Estatutárias e Minoritárias | F26: =F23+F24 -> 1.4285253e+10 | G26: =G23+G24 -> 1.5105688e+10 | H26: =H23+H24 -> 9.7644484e+09 | I26: =I23+I24 -> 1.4146197e+10 | J26: =J23+J24 -> 1.6623732e+10 | K26: =K23+K24 -> 2.1897958e+10 | L26: =L23+L24 -> 1.7162384e+10 | M26: =M23+M24 -> 2.52716e+10 | ... O26: =O23+O24 -> 1.0452697e+10 | P26: =P20+P24 -> 1.0704683e+10 | Q26: =Q20+Q24 -> 1.0887658e+10 | R26: =R20+R24 -> 1.1163219e+10 | S26: =SUM(Q26:R26) -> 2.2050877e+10 | T26: =SUM(O26:R26) -> 4.3208257e+10 | U26: =U20+U24 -> 3.5315106e+10 | V26: =V20+V24 -> 3.9182727e+10 | W26: =W20+W24 -> 4.3381984e+10 | X26: =X20+X24 -> 4.7974588e+10 | Y26: =Y20+Y24 -> 5.3024423e+10 | Z26: =Z20+Z24 -> 5.8592702e+10 | AA26: =AA20+AA24 -> 6.4736036e+10 | AB26: =AB20+AB24 -> 7.1516125e+10 | ... AD26: =AD20+AD24 -> 1.0189847e+11
E27: Participações Estatutárias no Lucro | F27: ='DRE CMN 4.720 - Contas Abertas'!F72 -> -1.4673351e+09 | G27: ='DRE CMN 4.720 - Contas Abertas'!G72 -> -1.7896844e+09 | H27: ='DRE CMN 4.720 - Contas Abertas'!H72 -> -9.1857229e+08 | I27: ='DRE CMN 4.720 - Contas Abertas'!I72 -> -1.4362506e+09 | J27: ='DRE CMN 4.720 - Contas Abertas'!J72 -> -1.714864e+09 | K27: ='DRE CMN 4.720 - Contas Abertas'!K72 -> -2.3467088e+09 | L27: ='DRE CMN 4.720 - Contas Abertas'!L72 -> -1.7020458e+09 | M27: ='DRE CMN 4.720 - Contas Abertas'!M72 -> -2.6449656e+09 | ... P27: ='DRE CMN 4.720 - Contas Abertas'!P72 -> -1.1195509e+09
E28: Participações Minoritárias | F28: ='DRE CMN 4.720 - Contas Abertas'!F73 -> -1.4751949e+09 | G28: ='DRE CMN 4.720 - Contas Abertas'!G73 -> -1.721658e+09 | H28: ='DRE CMN 4.720 - Contas Abertas'!H73 -> -1.675039e+09 | I28: ='DRE CMN 4.720 - Contas Abertas'!I73 -> -1.6500334e+09 | J28: ='DRE CMN 4.720 - Contas Abertas'!J73 -> -1.395849e+09 | K28: ='DRE CMN 4.720 - Contas Abertas'!K73 -> -1.7037475e+09 | L28: ='DRE CMN 4.720 - Contas Abertas'!L73 -> -1.5765221e+09 | M28: ='DRE CMN 4.720 - Contas Abertas'!M73 -> -1.6055132e+09 | ... P28: ='DRE CMN 4.720 - Contas Abertas'!P73 -> -8.5127961e+08
E29: Lucro dos Acionistas Ajustado dos Acionistas Controladores | F29: =SUM(F26:F28) -> 1.1342723e+10 | G29: =SUM(G26:G28) -> 1.1594346e+10 | H29: =SUM(H26:H28) -> 7.1708371e+09 | I29: =SUM(I26:I28) -> 1.1059913e+10 | J29: =SUM(J26:J28) -> 1.3513019e+10 | K29: =SUM(K26:K28) -> 1.7847502e+10 | L29: =SUM(L26:L28) -> 1.3883817e+10 | M29: =SUM(M26:M28) -> 2.1021121e+10 | ... P29: =SUM(P26:P28) -> 8.7338521e+09 | Q29: =Q31 -> 8.8831402e+09 | R29: =R31 -> 9.1079677e+09 | S29: =SUM(Q29:R29) -> 1.7991108e+10 | T29: =SUM(O29:R29) -> 3.5274495e+10 | U29: =U33*U26 -> 2.883066e+10 | V29: =V33*V26 -> 3.198812e+10 | W29: =W33*W26 -> 3.5416323e+10 | X29: =X33*X26 -> 3.9165648e+10 | Y29: =Y33*Y26 -> 4.3288248e+10 | Z29: =Z33*Z26 -> 4.7834098e+10 | AA29: =AA33*AA26 -> 5.2849413e+10 | AB29: =AB33*AB26 -> 5.8384564e+10 | ... AD29: =AD33*AD26 -> 8.3188202e+10
E30: Itens Extraordinários | F30: ='DRE CMN 4.720 - Contas Abertas'!F75 -> -97174908 | G30: ='DRE CMN 4.720 - Contas Abertas'!G75 -> 2.8052129e+09 | H30: ='DRE CMN 4.720 - Contas Abertas'!H75 -> 8.6271862e+08 | I30: ='DRE CMN 4.720 - Contas Abertas'!I75 -> -49136775 | J30: ='DRE CMN 4.720 - Contas Abertas'!J75 -> -6.5099451e+08 | K30: ='DRE CMN 4.720 - Contas Abertas'!K75 -> 3.1456721e+08 | L30: ='DRE CMN 4.720 - Contas Abertas'!L75 -> -1.1864323e+09 | M30: ='DRE CMN 4.720 - Contas Abertas'!M75 -> -1.3107195e+09 | ... P30: ='DRE CMN 4.720 - Contas Abertas'!P75 -> -4.3080478e+08
E31: Lucro dos Acionistas dos Acionistas Controladores | F31: =F29+F30 -> 1.1245548e+10 | G31: =G29+G30 -> 1.4399558e+10 | H31: =H29+H30 -> 8.0335558e+09 | I31: =I29+I30 -> 1.1010776e+10 | J31: =J29+J30 -> 1.2862024e+10 | K31: =K29+K30 -> 1.8162069e+10 | L31: =L29+L30 -> 1.2697384e+10 | M31: =M29+M30 -> 1.9710402e+10 | ... P31: =P29+P30 -> 8.3030474e+09 | Q31: =Q33*Q26 -> 8.8831402e+09 | R31: =R33*R26 -> 9.1079677e+09 | S31: =SUM(Q31:R31) -> 1.7991108e+10 | T31: =SUM(O31:R31) -> 3.4500749e+10 | U31: =U29 -> 2.883066e+10 | V31: =V29 -> 3.198812e+10 | W31: =W29 -> 3.5416323e+10 | X31: =X29 -> 3.9165648e+10 | Y31: =Y29 -> 4.3288248e+10 | Z31: =Z29 -> 4.7834098e+10 | AA31: =AA29 -> 5.2849413e+10 | AB31: =AB29 -> 5.8384564e+10 | ... AD31: =AD29 -> 8.3188202e+10
E32: Crescimento Lucro Líquido dos Acionistas Controladoresl (YoY)¹ | F32: - | G32: =G31/F31-1 -> 0.28046749 | H32: =H31/G31-1 -> -0.44209708 | I32: =I31/H31-1 -> 0.37059809 | J32: =J31/I31-1 -> 0.16813056 | K32: =K31/J31-1 -> 0.41206924 | L32: =L31/K31-1 -> -0.30088448 | M32: =M31/L31-1 -> 0.55231988 | N32: =N31/M31-1 -> 0.5733564 | T32: =T31/N31-1 -> 0.11251515 | U32: =U31/T31-1 -> -0.16434685 | V32: =V31/U31-1 -> 0.10951745 | W32: =W31/V31-1 -> 0.10717113 | X32: =X31/W31-1 -> 0.10586431 | Y32: =Y31/X31-1 -> 0.10526062 | Z32: =Z31/Y31-1 -> 0.10501348 | AA32: =AA31/Z31-1 -> 0.10484813 | AB32: =AB31/AA31-1 -> 0.10473439 | ... AD32: =AD31/AC31-1 -> 0.28980054
E33: % do Lucro Pertencente aos Acionistas | F33: =F29/F26 -> 0.79401625 | G33: =G29/G26 -> 0.76754833 | H33: =H29/H26 -> 0.7343822 | I33: =I29/I26 -> 0.78182942 | J33: =J29/J26 -> 0.81287517 | K33: =K29/K26 -> 0.81503041 | L33: =L29/L26 -> 0.80896781 | M33: =M29/M26 -> 0.83180809 | ... P33: =P29/P26 -> 0.81589081 | Q33: =P33 -> 0.81589081 | R33: =Q33 -> 0.81589081 | S33: =S29/S26 -> 0.81589081 | T33: =T29/T26 -> 0.81638321 | U33: =T33 -> 0.81638321 | V33: =U33 -> 0.81638321 | W33: =V33 -> 0.81638321 | X33: =W33 -> 0.81638321 | Y33: =X33 -> 0.81638321 | Z33: =Y33 -> 0.81638321 | AA33: =Z33 -> 0.81638321 | AB33: =AA33 -> 0.81638321 | ... AD33: =AC33 -> 0.81638321
E34: 1 - Ano a Ano
F37: 2014 | G37: 2015 | H37: 2016 | I37: 2017 | J37: 2018 | K37: 2019 | L37: 2020 | M37: 2021 | N37: 2022 | O37: 1T23 | P37: 2T23 | Q37: 3T23 | R37: 4T23 | S37: YTG23 | T37: 2023 | U37: 2024 | V37: 2025 | W37: 2026 | X37: 2027 | Y37: 2028 | Z37: 2029 | AA37: 2030 | AB37: 2031 | AC37: 2032 | AD37: 2033 | AE37: Perpetuidade | AF37: ROE Perp. | AG37: Growth
E38: Lucro Líquido por Ação | F38: 4.04 | G38: 5.05 | H38: 2.84 | I38: 3.91 | J38: 4.54 | K38: 6.39 | L38: 4.39 | M38: 3.86 | N38: 10.79 | O38: 2.8640131 | P38: =P31/Dashboard!$F$11 -> 2.9094951 | Q38: =Q31/Dashboard!$F$11 -> 3.1127671 | R38: =R31/Dashboard!$F$11 -> 3.1915496 | S38: =SUM(Q38:R38) -> 6.3043167 | T38: =SUM(O38:R38) -> 12.077825 | U38: =U31/Dashboard!$F$11 -> 10.102636 | V38: =V31/Dashboard!$F$11 -> 11.209051 | W38: =W31/Dashboard!$F$11 -> 12.410337 | X38: =X31/Dashboard!$F$11 -> 13.724149 | Y38: =Y31/Dashboard!$F$11 -> 15.168762 | Z38: =Z31/Dashboard!$F$11 -> 16.761686 | AA38: =AA31/Dashboard!$F$11 -> 18.519117 | AB38: =AB31/Dashboard!$F$11 -> 20.458706 | ... AD38: =AD31/Dashboard!$F$11 -> 29.150221 | AE38: =AD38 -> 29.150221 | AF38: =Ke!P16 -> 0.15517028 | AG38: =AF38*AE40 -> 0.093102165
