Workbook

Sheet Dashboard
H3: SIMPAR (SIMH3)
A7: Páginas
A8: Dashboard
A9: WACC | E9: Ticker | F9: SIMH3 | G9: WACC | H9: =H10-0.5% -> 0.090330137 | I9: =(((NPV($H9,'DRE + DCF'!$V$36,'DRE + DCF'!$X$36:$AA$36)*((1+$H9)^((12-3)/12))+('DRE + DCF'!$AB$36*(1+I$18)/(($H9-I$18)*(1+$H9)^(COUNT('DRE + DCF'!$W$22:$AA$22)-((12-3)/12)))))+SUM($F$12:$F$17)))/$F$10-(((NPV($H9,'DRE + DCF'!$V$36,'DRE + DCF'!$X$36:$AA$36)*((1+$H9)^((12-3)/12))+('DRE + DCF'!$AB$36*(1+I$18)/(($H9-I$18)*(1+$H9)^(COUNT('DRE + DCF'!$W$22:$AA$22)-((12-3)/12)))))*$F$40+$F$42)*(1-$F$39))/$F$10 -> 14.189123 | J9: =(((NPV($H9,'DRE + DCF'!$V$36,'DRE + DCF'!$X$36:$AA$36)*((1+$H9)^((12-3)/12))+('DRE + DCF'!$AB$36*(1+J$18)/(($H9-J$18)*(1+$H9)^(COUNT('DRE + DCF'!$W$22:$AA$22)-((12-3)/12)))))+SUM($F$12:$F$17)))/$F$10-(((NPV($H9,'DRE + DCF'!$V$36,'DRE + DCF'!$X$36:$AA$36)*((1+$H9)^((12-3)/12))+('DRE + DCF'!$AB$36*(1+J$18)/(($H9-J$18)*(1+$H9)^(COUNT('DRE + DCF'!$W$22:$AA$22)-((12-3)/12)))))*$F$40+$F$42)*(1-$F$39))/$F$10 -> 15.347343 | K9: =(((NPV($H9,'DRE + DCF'!$V$36,'DRE + DCF'!$X$36:$AA$36)*((1+$H9)^((12-3)/12))+('DRE + DCF'!$AB$36*(1+K$18)/(($H9-K$18)*(1+$H9)^(COUNT('DRE + DCF'!$W$22:$AA$22)-((12-3)/12)))))+SUM($F$12:$F$17)))/$F$10-(((NPV($H9,'DRE + DCF'!$V$36,'DRE + DCF'!$X$36:$AA$36)*((1+$H9)^((12-3)/12))+('DRE + DCF'!$AB$36*(1+K$18)/(($H9-K$18)*(1+$H9)^(COUNT('DRE + DCF'!$W$22:$AA$22)-((12-3)/12)))))*$F$40+$F$42)*(1-$F$39))/$F$10 -> 16.743585 | L9: =(((NPV($H9,'DRE + DCF'!$V$36,'DRE + DCF'!$X$36:$AA$36)*((1+$H9)^((12-3)/12))+('DRE + DCF'!$AB$36*(1+L$18)/(($H9-L$18)*(1+$H9)^(COUNT('DRE + DCF'!$W$22:$AA$22)-((12-3)/12)))))+SUM($F$12:$F$17)))/$F$10-(((NPV($H9,'DRE + DCF'!$V$36,'DRE + DCF'!$X$36:$AA$36)*((1+$H9)^((12-3)/12))+('DRE + DCF'!$AB$36*(1+L$18)/(($H9-L$18)*(1+$H9)^(COUNT('DRE + DCF'!$W$22:$AA$22)-((12-3)/12)))))*$F$40+$F$42)*(1-$F$39))/$F$10 -> 18.459623 | M9: =(((NPV($H9,'DRE + DCF'!$V$36,'DRE + DCF'!$X$36:$AA$36)*((1+$H9)^((12-3)/12))+('DRE + DCF'!$AB$36*(1+M$18)/(($H9-M$18)*(1+$H9)^(COUNT('DRE + DCF'!$W$22:$AA$22)-((12-3)/12)))))+SUM($F$12:$F$17)))/$F$10-(((NPV($H9,'DRE + DCF'!$V$36,'DRE + DCF'!$X$36:$AA$36)*((1+$H9)^((12-3)/12))+('DRE + DCF'!$AB$36*(1+M$18)/(($H9-M$18)*(1+$H9)^(COUNT('DRE + DCF'!$W$22:$AA$22)-((12-3)/12)))))*$F$40+$F$42)*(1-$F$39))/$F$10 -> 20.619537 | N9: =(((NPV($H9,'DRE + DCF'!$V$36,'DRE + DCF'!$X$36:$AA$36)*((1+$H9)^((12-3)/12))+('DRE + DCF'!$AB$36*(1+N$18)/(($H9-N$18)*(1+$H9)^(COUNT('DRE + DCF'!$W$22:$AA$22)-((12-3)/12)))))+SUM($F$12:$F$17)))/$F$10-(((NPV($H9,'DRE + DCF'!$V$36,'DRE + DCF'!$X$36:$AA$36)*((1+$H9)^((12-3)/12))+('DRE + DCF'!$AB$36*(1+N$18)/(($H9-N$18)*(1+$H9)^(COUNT('DRE + DCF'!$W$22:$AA$22)-((12-3)/12)))))*$F$40+$F$42)*(1-$F$39))/$F$10 -> 23.421132 | O9: =(((NPV($H9,'DRE + DCF'!$V$36,'DRE + DCF'!$X$36:$AA$36)*((1+$H9)^((12-3)/12))+('DRE + DCF'!$AB$36*(1+O$18)/(($H9-O$18)*(1+$H9)^(COUNT('DRE + DCF'!$W$22:$AA$22)-((12-3)/12)))))+SUM($F$12:$F$17)))/$F$10-(((NPV($H9,'DRE + DCF'!$V$36,'DRE + DCF'!$X$36:$AA$36)*((1+$H9)^((12-3)/12))+('DRE + DCF'!$AB$36*(1+O$18)/(($H9-O$18)*(1+$H9)^(COUNT('DRE + DCF'!$W$22:$AA$22)-((12-3)/12)))))*$F$40+$F$42)*(1-$F$39))/$F$10 -> 27.200246 | P9: =(((NPV($H9,'DRE + DCF'!$V$36,'DRE + DCF'!$X$36:$AA$36)*((1+$H9)^((12-3)/12))+('DRE + DCF'!$AB$36*(1+P$18)/(($H9-P$18)*(1+$H9)^(COUNT('DRE + DCF'!$W$22:$AA$22)-((12-3)/12)))))+SUM($F$12:$F$17)))/$F$10-(((NPV($H9,'DRE + DCF'!$V$36,'DRE + DCF'!$X$36:$AA$36)*((1+$H9)^((12-3)/12))+('DRE + DCF'!$AB$36*(1+P$18)/(($H9-P$18)*(1+$H9)^(COUNT('DRE + DCF'!$W$22:$AA$22)-((12-3)/12)))))*$F$40+$F$42)*(1-$F$39))/$F$10 -> 32.576599 | ... R9: =(((NPV($H9,'DRE + DCF'!$V$36,'DRE + DCF'!$X$36:$AA$36)*((1+$H9)^((12-3)/12))+('DRE + DCF'!$AB$36*(1+R$18)/(($H9-R$18)*(1+$H9)^(COUNT('DRE + DCF'!$W$22:$AA$22)-((12-3)/12)))))+SUM($F$12:$F$17)))/$F$10-(((NPV($H9,'DRE + DCF'!$V$36,'DRE + DCF'!$X$36:$AA$36)*((1+$H9)^((12-3)/12))+('DRE + DCF'!$AB$36*(1+R$18)/(($H9-R$18)*(1+$H9)^(COUNT('DRE + DCF'!$W$22:$AA$22)-((12-3)/12)))))*$F$40+$F$42)*(1-$F$39))/$F$10 -> 55.136581
A10: DRE Consolidado | E10: Ações Emitidas (mil) | F10: 873040.53 | H10: =H11-0.5% -> 0.095330137 | I10: =(((NPV($H10,'DRE + DCF'!$V$36,'DRE + DCF'!$X$36:$AA$36)*((1+$H10)^((12-3)/12))+('DRE + DCF'!$AB$36*(1+I$18)/(($H10-I$18)*(1+$H10)^(COUNT('DRE + DCF'!$W$22:$AA$22)-((12-3)/12)))))+SUM($F$12:$F$17)))/$F$10-(((NPV($H10,'DRE + DCF'!$V$36,'DRE + DCF'!$X$36:$AA$36)*((1+$H10)^((12-3)/12))+('DRE + DCF'!$AB$36*(1+I$18)/(($H10-I$18)*(1+$H10)^(COUNT('DRE + DCF'!$W$22:$AA$22)-((12-3)/12)))))*$F$40+$F$42)*(1-$F$39))/$F$10 -> 12.188699 | J10: =(((NPV($H10,'DRE + DCF'!$V$36,'DRE + DCF'!$X$36:$AA$36)*((1+$H10)^((12-3)/12))+('DRE + DCF'!$AB$36*(1+J$18)/(($H10-J$18)*(1+$H10)^(COUNT('DRE + DCF'!$W$22:$AA$22)-((12-3)/12)))))+SUM($F$12:$F$17)))/$F$10-(((NPV($H10,'DRE + DCF'!$V$36,'DRE + DCF'!$X$36:$AA$36)*((1+$H10)^((12-3)/12))+('DRE + DCF'!$AB$36*(1+J$18)/(($H10-J$18)*(1+$H10)^(COUNT('DRE + DCF'!$W$22:$AA$22)-((12-3)/12)))))*$F$40+$F$42)*(1-$F$39))/$F$10 -> 13.01048 | K10: =(((NPV($H10,'DRE + DCF'!$V$36,'DRE + DCF'!$X$36:$AA$36)*((1+$H10)^((12-3)/12))+('DRE + DCF'!$AB$36*(1+K$18)/(($H10-K$18)*(1+$H10)^(COUNT('DRE + DCF'!$W$22:$AA$22)-((12-3)/12)))))+SUM($F$12:$F$17)))/$F$10-(((NPV($H10,'DRE + DCF'!$V$36,'DRE + DCF'!$X$36:$AA$36)*((1+$H10)^((12-3)/12))+('DRE + DCF'!$AB$36*(1+K$18)/(($H10-K$18)*(1+$H10)^(COUNT('DRE + DCF'!$W$22:$AA$22)-((12-3)/12)))))*$F$40+$F$42)*(1-$F$39))/$F$10 -> 13.972353 | L10: =(((NPV($H10,'DRE + DCF'!$V$36,'DRE + DCF'!$X$36:$AA$36)*((1+$H10)^((12-3)/12))+('DRE + DCF'!$AB$36*(1+L$18)/(($H10-L$18)*(1+$H10)^(COUNT('DRE + DCF'!$W$22:$AA$22)-((12-3)/12)))))+SUM($F$12:$F$17)))/$F$10-(((NPV($H10,'DRE + DCF'!$V$36,'DRE + DCF'!$X$36:$AA$36)*((1+$H10)^((12-3)/12))+('DRE + DCF'!$AB$36*(1+L$18)/(($H10-L$18)*(1+$H10)^(COUNT('DRE + DCF'!$W$22:$AA$22)-((12-3)/12)))))*$F$40+$F$42)*(1-$F$39))/$F$10 -> 15.113478 | M10: =(((NPV($H10,'DRE + DCF'!$V$36,'DRE + DCF'!$X$36:$AA$36)*((1+$H10)^((12-3)/12))+('DRE + DCF'!$AB$36*(1+M$18)/(($H10-M$18)*(1+$H10)^(COUNT('DRE + DCF'!$W$22:$AA$22)-((12-3)/12)))))+SUM($F$12:$F$17)))/$F$10-(((NPV($H10,'DRE + DCF'!$V$36,'DRE + DCF'!$X$36:$AA$36)*((1+$H10)^((12-3)/12))+('DRE + DCF'!$AB$36*(1+M$18)/(($H10-M$18)*(1+$H10)^(COUNT('DRE + DCF'!$W$22:$AA$22)-((12-3)/12)))))*$F$40+$F$42)*(1-$F$39))/$F$10 -> 16.489111 | N10: =(((NPV($H10,'DRE + DCF'!$V$36,'DRE + DCF'!$X$36:$AA$36)*((1+$H10)^((12-3)/12))+('DRE + DCF'!$AB$36*(1+N$18)/(($H10-N$18)*(1+$H10)^(COUNT('DRE + DCF'!$W$22:$AA$22)-((12-3)/12)))))+SUM($F$12:$F$17)))/$F$10-(((NPV($H10,'DRE + DCF'!$V$36,'DRE + DCF'!$X$36:$AA$36)*((1+$H10)^((12-3)/12))+('DRE + DCF'!$AB$36*(1+N$18)/(($H10-N$18)*(1+$H10)^(COUNT('DRE + DCF'!$W$22:$AA$22)-((12-3)/12)))))*$F$40+$F$42)*(1-$F$39))/$F$10 -> 18.179821 | O10: =(((NPV($H10,'DRE + DCF'!$V$36,'DRE + DCF'!$X$36:$AA$36)*((1+$H10)^((12-3)/12))+('DRE + DCF'!$AB$36*(1+O$18)/(($H10-O$18)*(1+$H10)^(COUNT('DRE + DCF'!$W$22:$AA$22)-((12-3)/12)))))+SUM($F$12:$F$17)))/$F$10-(((NPV($H10,'DRE + DCF'!$V$36,'DRE + DCF'!$X$36:$AA$36)*((1+$H10)^((12-3)/12))+('DRE + DCF'!$AB$36*(1+O$18)/(($H10-O$18)*(1+$H10)^(COUNT('DRE + DCF'!$W$22:$AA$22)-((12-3)/12)))))*$F$40+$F$42)*(1-$F$39))/$F$10 -> 20.307856 | P10: =(((NPV($H10,'DRE + DCF'!$V$36,'DRE + DCF'!$X$36:$AA$36)*((1+$H10)^((12-3)/12))+('DRE + DCF'!$AB$36*(1+P$18)/(($H10-P$18)*(1+$H10)^(COUNT('DRE + DCF'!$W$22:$AA$22)-((12-3)/12)))))+SUM($F$12:$F$17)))/$F$10-(((NPV($H10,'DRE + DCF'!$V$36,'DRE + DCF'!$X$36:$AA$36)*((1+$H10)^((12-3)/12))+('DRE + DCF'!$AB$36*(1+P$18)/(($H10-P$18)*(1+$H10)^(COUNT('DRE + DCF'!$W$22:$AA$22)-((12-3)/12)))))*$F$40+$F$42)*(1-$F$39))/$F$10 -> 23.0681 | ... R10: =(((NPV($H10,'DRE + DCF'!$V$36,'DRE + DCF'!$X$36:$AA$36)*((1+$H10)^((12-3)/12))+('DRE + DCF'!$AB$36*(1+R$18)/(($H10-R$18)*(1+$H10)^(COUNT('DRE + DCF'!$W$22:$AA$22)-((12-3)/12)))))+SUM($F$12:$F$17)))/$F$10-(((NPV($H10,'DRE + DCF'!$V$36,'DRE + DCF'!$X$36:$AA$36)*((1+$H10)^((12-3)/12))+('DRE + DCF'!$AB$36*(1+R$18)/(($H10-R$18)*(1+$H10)^(COUNT('DRE + DCF'!$W$22:$AA$22)-((12-3)/12)))))*$F$40+$F$42)*(1-$F$39))/$F$10 -> 32.088436
A11: DRE + DCF | E11: Valor da Empresa (mil) | F11: =SUM('DRE + DCF'!V38:AB38) -> 10729800 | H11: =H12-0.5% -> 0.10033014 | I11: =(((NPV($H11,'DRE + DCF'!$V$36,'DRE + DCF'!$X$36:$AA$36)*((1+$H11)^((12-3)/12))+('DRE + DCF'!$AB$36*(1+I$18)/(($H11-I$18)*(1+$H11)^(COUNT('DRE + DCF'!$W$22:$AA$22)-((12-3)/12)))))+SUM($F$12:$F$17)))/$F$10-(((NPV($H11,'DRE + DCF'!$V$36,'DRE + DCF'!$X$36:$AA$36)*((1+$H11)^((12-3)/12))+('DRE + DCF'!$AB$36*(1+I$18)/(($H11-I$18)*(1+$H11)^(COUNT('DRE + DCF'!$W$22:$AA$22)-((12-3)/12)))))*$F$40+$F$42)*(1-$F$39))/$F$10 -> 10.691676 | J11: =(((NPV($H11,'DRE + DCF'!$V$36,'DRE + DCF'!$X$36:$AA$36)*((1+$H11)^((12-3)/12))+('DRE + DCF'!$AB$36*(1+J$18)/(($H11-J$18)*(1+$H11)^(COUNT('DRE + DCF'!$W$22:$AA$22)-((12-3)/12)))))+SUM($F$12:$F$17)))/$F$10-(((NPV($H11,'DRE + DCF'!$V$36,'DRE + DCF'!$X$36:$AA$36)*((1+$H11)^((12-3)/12))+('DRE + DCF'!$AB$36*(1+J$18)/(($H11-J$18)*(1+$H11)^(COUNT('DRE + DCF'!$W$22:$AA$22)-((12-3)/12)))))*$F$40+$F$42)*(1-$F$39))/$F$10 -> 11.302495 | K11: =(((NPV($H11,'DRE + DCF'!$V$36,'DRE + DCF'!$X$36:$AA$36)*((1+$H11)^((12-3)/12))+('DRE + DCF'!$AB$36*(1+K$18)/(($H11-K$18)*(1+$H11)^(COUNT('DRE + DCF'!$W$22:$AA$22)-((12-3)/12)))))+SUM($F$12:$F$17)))/$F$10-(((NPV($H11,'DRE + DCF'!$V$36,'DRE + DCF'!$X$36:$AA$36)*((1+$H11)^((12-3)/12))+('DRE + DCF'!$AB$36*(1+K$18)/(($H11-K$18)*(1+$H11)^(COUNT('DRE + DCF'!$W$22:$AA$22)-((12-3)/12)))))*$F$40+$F$42)*(1-$F$39))/$F$10 -> 12.002278 | L11: =(((NPV($H11,'DRE + DCF'!$V$36,'DRE + DCF'!$X$36:$AA$36)*((1+$H11)^((12-3)/12))+('DRE + DCF'!$AB$36*(1+L$18)/(($H11-L$18)*(1+$H11)^(COUNT('DRE + DCF'!$W$22:$AA$22)-((12-3)/12)))))+SUM($F$12:$F$17)))/$F$10-(((NPV($H11,'DRE + DCF'!$V$36,'DRE + DCF'!$X$36:$AA$36)*((1+$H11)^((12-3)/12))+('DRE + DCF'!$AB$36*(1+L$18)/(($H11-L$18)*(1+$H11)^(COUNT('DRE + DCF'!$W$22:$AA$22)-((12-3)/12)))))*$F$40+$F$42)*(1-$F$39))/$F$10 -> 12.811984 | M11: =(((NPV($H11,'DRE + DCF'!$V$36,'DRE + DCF'!$X$36:$AA$36)*((1+$H11)^((12-3)/12))+('DRE + DCF'!$AB$36*(1+M$18)/(($H11-M$18)*(1+$H11)^(COUNT('DRE + DCF'!$W$22:$AA$22)-((12-3)/12)))))+SUM($F$12:$F$17)))/$F$10-(((NPV($H11,'DRE + DCF'!$V$36,'DRE + DCF'!$X$36:$AA$36)*((1+$H11)^((12-3)/12))+('DRE + DCF'!$AB$36*(1+M$18)/(($H11-M$18)*(1+$H11)^(COUNT('DRE + DCF'!$W$22:$AA$22)-((12-3)/12)))))*$F$40+$F$42)*(1-$F$39))/$F$10 -> 13.759724 | N11: =(((NPV($H11,'DRE + DCF'!$V$36,'DRE + DCF'!$X$36:$AA$36)*((1+$H11)^((12-3)/12))+('DRE + DCF'!$AB$36*(1+N$18)/(($H11-N$18)*(1+$H11)^(COUNT('DRE + DCF'!$W$22:$AA$22)-((12-3)/12)))))+SUM($F$12:$F$17)))/$F$10-(((NPV($H11,'DRE + DCF'!$V$36,'DRE + DCF'!$X$36:$AA$36)*((1+$H11)^((12-3)/12))+('DRE + DCF'!$AB$36*(1+N$18)/(($H11-N$18)*(1+$H11)^(COUNT('DRE + DCF'!$W$22:$AA$22)-((12-3)/12)))))*$F$40+$F$42)*(1-$F$39))/$F$10 -> 14.884082 | O11: =(((NPV($H11,'DRE + DCF'!$V$36,'DRE + DCF'!$X$36:$AA$36)*((1+$H11)^((12-3)/12))+('DRE + DCF'!$AB$36*(1+O$18)/(($H11-O$18)*(1+$H11)^(COUNT('DRE + DCF'!$W$22:$AA$22)-((12-3)/12)))))+SUM($F$12:$F$17)))/$F$10-(((NPV($H11,'DRE + DCF'!$V$36,'DRE + DCF'!$X$36:$AA$36)*((1+$H11)^((12-3)/12))+('DRE + DCF'!$AB$36*(1+O$18)/(($H11-O$18)*(1+$H11)^(COUNT('DRE + DCF'!$W$22:$AA$22)-((12-3)/12)))))*$F$40+$F$42)*(1-$F$39))/$F$10 -> 16.239504 | P11: =(((NPV($H11,'DRE + DCF'!$V$36,'DRE + DCF'!$X$36:$AA$36)*((1+$H11)^((12-3)/12))+('DRE + DCF'!$AB$36*(1+P$18)/(($H11-P$18)*(1+$H11)^(COUNT('DRE + DCF'!$W$22:$AA$22)-((12-3)/12)))))+SUM($F$12:$F$17)))/$F$10-(((NPV($H11,'DRE + DCF'!$V$36,'DRE + DCF'!$X$36:$AA$36)*((1+$H11)^((12-3)/12))+('DRE + DCF'!$AB$36*(1+P$18)/(($H11-P$18)*(1+$H11)^(COUNT('DRE + DCF'!$W$22:$AA$22)-((12-3)/12)))))*$F$40+$F$42)*(1-$F$39))/$F$10 -> 17.905372 | ... R11: =(((NPV($H11,'DRE + DCF'!$V$36,'DRE + DCF'!$X$36:$AA$36)*((1+$H11)^((12-3)/12))+('DRE + DCF'!$AB$36*(1+R$18)/(($H11-R$18)*(1+$H11)^(COUNT('DRE + DCF'!$W$22:$AA$22)-((12-3)/12)))))+SUM($F$12:$F$17)))/$F$10-(((NPV($H11,'DRE + DCF'!$V$36,'DRE + DCF'!$X$36:$AA$36)*((1+$H11)^((12-3)/12))+('DRE + DCF'!$AB$36*(1+R$18)/(($H11-R$18)*(1+$H11)^(COUNT('DRE + DCF'!$W$22:$AA$22)-((12-3)/12)))))*$F$40+$F$42)*(1-$F$39))/$F$10 -> 22.721828
A12: DRE - Contas Abertas | E12: Dívida (mil) | F12: =-F36 -> -13637481 | H12: =H13-0.5% -> 0.10533014 | I12: =(((NPV($H12,'DRE + DCF'!$V$36,'DRE + DCF'!$X$36:$AA$36)*((1+$H12)^((12-3)/12))+('DRE + DCF'!$AB$36*(1+I$18)/(($H12-I$18)*(1+$H12)^(COUNT('DRE + DCF'!$W$22:$AA$22)-((12-3)/12)))))+SUM($F$12:$F$17)))/$F$10-(((NPV($H12,'DRE + DCF'!$V$36,'DRE + DCF'!$X$36:$AA$36)*((1+$H12)^((12-3)/12))+('DRE + DCF'!$AB$36*(1+I$18)/(($H12-I$18)*(1+$H12)^(COUNT('DRE + DCF'!$W$22:$AA$22)-((12-3)/12)))))*$F$40+$F$42)*(1-$F$39))/$F$10 -> 9.5278566 | J12: =(((NPV($H12,'DRE + DCF'!$V$36,'DRE + DCF'!$X$36:$AA$36)*((1+$H12)^((12-3)/12))+('DRE + DCF'!$AB$36*(1+J$18)/(($H12-J$18)*(1+$H12)^(COUNT('DRE + DCF'!$W$22:$AA$22)-((12-3)/12)))))+SUM($F$12:$F$17)))/$F$10-(((NPV($H12,'DRE + DCF'!$V$36,'DRE + DCF'!$X$36:$AA$36)*((1+$H12)^((12-3)/12))+('DRE + DCF'!$AB$36*(1+J$18)/(($H12-J$18)*(1+$H12)^(COUNT('DRE + DCF'!$W$22:$AA$22)-((12-3)/12)))))*$F$40+$F$42)*(1-$F$39))/$F$10 -> 9.9980257 | K12: =(((NPV($H12,'DRE + DCF'!$V$36,'DRE + DCF'!$X$36:$AA$36)*((1+$H12)^((12-3)/12))+('DRE + DCF'!$AB$36*(1+K$18)/(($H12-K$18)*(1+$H12)^(COUNT('DRE + DCF'!$W$22:$AA$22)-((12-3)/12)))))+SUM($F$12:$F$17)))/$F$10-(((NPV($H12,'DRE + DCF'!$V$36,'DRE + DCF'!$X$36:$AA$36)*((1+$H12)^((12-3)/12))+('DRE + DCF'!$AB$36*(1+K$18)/(($H12-K$18)*(1+$H12)^(COUNT('DRE + DCF'!$W$22:$AA$22)-((12-3)/12)))))*$F$40+$F$42)*(1-$F$39))/$F$10 -> 10.527967 | L12: =(((NPV($H12,'DRE + DCF'!$V$36,'DRE + DCF'!$X$36:$AA$36)*((1+$H12)^((12-3)/12))+('DRE + DCF'!$AB$36*(1+L$18)/(($H12-L$18)*(1+$H12)^(COUNT('DRE + DCF'!$W$22:$AA$22)-((12-3)/12)))))+SUM($F$12:$F$17)))/$F$10-(((NPV($H12,'DRE + DCF'!$V$36,'DRE + DCF'!$X$36:$AA$36)*((1+$H12)^((12-3)/12))+('DRE + DCF'!$AB$36*(1+L$18)/(($H12-L$18)*(1+$H12)^(COUNT('DRE + DCF'!$W$22:$AA$22)-((12-3)/12)))))*$F$40+$F$42)*(1-$F$39))/$F$10 -> 11.129852 | M12: =(((NPV($H12,'DRE + DCF'!$V$36,'DRE + DCF'!$X$36:$AA$36)*((1+$H12)^((12-3)/12))+('DRE + DCF'!$AB$36*(1+M$18)/(($H12-M$18)*(1+$H12)^(COUNT('DRE + DCF'!$W$22:$AA$22)-((12-3)/12)))))+SUM($F$12:$F$17)))/$F$10-(((NPV($H12,'DRE + DCF'!$V$36,'DRE + DCF'!$X$36:$AA$36)*((1+$H12)^((12-3)/12))+('DRE + DCF'!$AB$36*(1+M$18)/(($H12-M$18)*(1+$H12)^(COUNT('DRE + DCF'!$W$22:$AA$22)-((12-3)/12)))))*$F$40+$F$42)*(1-$F$39))/$F$10 -> 11.819399 | N12: =(((NPV($H12,'DRE + DCF'!$V$36,'DRE + DCF'!$X$36:$AA$36)*((1+$H12)^((12-3)/12))+('DRE + DCF'!$AB$36*(1+N$18)/(($H12-N$18)*(1+$H12)^(COUNT('DRE + DCF'!$W$22:$AA$22)-((12-3)/12)))))+SUM($F$12:$F$17)))/$F$10-(((NPV($H12,'DRE + DCF'!$V$36,'DRE + DCF'!$X$36:$AA$36)*((1+$H12)^((12-3)/12))+('DRE + DCF'!$AB$36*(1+N$18)/(($H12-N$18)*(1+$H12)^(COUNT('DRE + DCF'!$W$22:$AA$22)-((12-3)/12)))))*$F$40+$F$42)*(1-$F$39))/$F$10 -> 12.617262 | O12: =(((NPV($H12,'DRE + DCF'!$V$36,'DRE + DCF'!$X$36:$AA$36)*((1+$H12)^((12-3)/12))+('DRE + DCF'!$AB$36*(1+O$18)/(($H12-O$18)*(1+$H12)^(COUNT('DRE + DCF'!$W$22:$AA$22)-((12-3)/12)))))+SUM($F$12:$F$17)))/$F$10-(((NPV($H12,'DRE + DCF'!$V$36,'DRE + DCF'!$X$36:$AA$36)*((1+$H12)^((12-3)/12))+('DRE + DCF'!$AB$36*(1+O$18)/(($H12-O$18)*(1+$H12)^(COUNT('DRE + DCF'!$W$22:$AA$22)-((12-3)/12)))))*$F$40+$F$42)*(1-$F$39))/$F$10 -> 13.551139 | P12: =(((NPV($H12,'DRE + DCF'!$V$36,'DRE + DCF'!$X$36:$AA$36)*((1+$H12)^((12-3)/12))+('DRE + DCF'!$AB$36*(1+P$18)/(($H12-P$18)*(1+$H12)^(COUNT('DRE + DCF'!$W$22:$AA$22)-((12-3)/12)))))+SUM($F$12:$F$17)))/$F$10-(((NPV($H12,'DRE + DCF'!$V$36,'DRE + DCF'!$X$36:$AA$36)*((1+$H12)^((12-3)/12))+('DRE + DCF'!$AB$36*(1+P$18)/(($H12-P$18)*(1+$H12)^(COUNT('DRE + DCF'!$W$22:$AA$22)-((12-3)/12)))))*$F$40+$F$42)*(1-$F$39))/$F$10 -> 14.659052 | ... R12: =(((NPV($H12,'DRE + DCF'!$V$36,'DRE + DCF'!$X$36:$AA$36)*((1+$H12)^((12-3)/12))+('DRE + DCF'!$AB$36*(1+R$18)/(($H12-R$18)*(1+$H12)^(COUNT('DRE + DCF'!$W$22:$AA$22)-((12-3)/12)))))+SUM($F$12:$F$17)))/$F$10-(((NPV($H12,'DRE + DCF'!$V$36,'DRE + DCF'!$X$36:$AA$36)*((1+$H12)^((12-3)/12))+('DRE + DCF'!$AB$36*(1+R$18)/(($H12-R$18)*(1+$H12)^(COUNT('DRE + DCF'!$W$22:$AA$22)-((12-3)/12)))))*$F$40+$F$42)*(1-$F$39))/$F$10 -> 17.63615
A13: Balanço Patrimonial | E13: Ativos/Passivos Não-Operacionais | F13: =F29 -> 3676632.3 | H13: =WACC!P20 -> 0.11033014 | I13: =(((NPV($H13,'DRE + DCF'!$V$36,'DRE + DCF'!$X$36:$AA$36)*((1+$H13)^((12-3)/12))+('DRE + DCF'!$AB$36*(1+I$18)/(($H13-I$18)*(1+$H13)^(COUNT('DRE + DCF'!$W$22:$AA$22)-((12-3)/12)))))+SUM($F$12:$F$17)))/$F$10-(((NPV($H13,'DRE + DCF'!$V$36,'DRE + DCF'!$X$36:$AA$36)*((1+$H13)^((12-3)/12))+('DRE + DCF'!$AB$36*(1+I$18)/(($H13-I$18)*(1+$H13)^(COUNT('DRE + DCF'!$W$22:$AA$22)-((12-3)/12)))))*$F$40+$F$42)*(1-$F$39))/$F$10 -> 8.5960433 | J13: =(((NPV($H13,'DRE + DCF'!$V$36,'DRE + DCF'!$X$36:$AA$36)*((1+$H13)^((12-3)/12))+('DRE + DCF'!$AB$36*(1+J$18)/(($H13-J$18)*(1+$H13)^(COUNT('DRE + DCF'!$W$22:$AA$22)-((12-3)/12)))))+SUM($F$12:$F$17)))/$F$10-(((NPV($H13,'DRE + DCF'!$V$36,'DRE + DCF'!$X$36:$AA$36)*((1+$H13)^((12-3)/12))+('DRE + DCF'!$AB$36*(1+J$18)/(($H13-J$18)*(1+$H13)^(COUNT('DRE + DCF'!$W$22:$AA$22)-((12-3)/12)))))*$F$40+$F$42)*(1-$F$39))/$F$10 -> 8.9679503 | K13: =(((NPV($H13,'DRE + DCF'!$V$36,'DRE + DCF'!$X$36:$AA$36)*((1+$H13)^((12-3)/12))+('DRE + DCF'!$AB$36*(1+K$18)/(($H13-K$18)*(1+$H13)^(COUNT('DRE + DCF'!$W$22:$AA$22)-((12-3)/12)))))+SUM($F$12:$F$17)))/$F$10-(((NPV($H13,'DRE + DCF'!$V$36,'DRE + DCF'!$X$36:$AA$36)*((1+$H13)^((12-3)/12))+('DRE + DCF'!$AB$36*(1+K$18)/(($H13-K$18)*(1+$H13)^(COUNT('DRE + DCF'!$W$22:$AA$22)-((12-3)/12)))))*$F$40+$F$42)*(1-$F$39))/$F$10 -> 9.3818047 | L13: =(((NPV($H13,'DRE + DCF'!$V$36,'DRE + DCF'!$X$36:$AA$36)*((1+$H13)^((12-3)/12))+('DRE + DCF'!$AB$36*(1+L$18)/(($H13-L$18)*(1+$H13)^(COUNT('DRE + DCF'!$W$22:$AA$22)-((12-3)/12)))))+SUM($F$12:$F$17)))/$F$10-(((NPV($H13,'DRE + DCF'!$V$36,'DRE + DCF'!$X$36:$AA$36)*((1+$H13)^((12-3)/12))+('DRE + DCF'!$AB$36*(1+L$18)/(($H13-L$18)*(1+$H13)^(COUNT('DRE + DCF'!$W$22:$AA$22)-((12-3)/12)))))*$F$40+$F$42)*(1-$F$39))/$F$10 -> 9.8451275 | M13: =(((NPV($H13,'DRE + DCF'!$V$36,'DRE + DCF'!$X$36:$AA$36)*((1+$H13)^((12-3)/12))+('DRE + DCF'!$AB$36*(1+M$18)/(($H13-M$18)*(1+$H13)^(COUNT('DRE + DCF'!$W$22:$AA$22)-((12-3)/12)))))+SUM($F$12:$F$17)))/$F$10-(((NPV($H13,'DRE + DCF'!$V$36,'DRE + DCF'!$X$36:$AA$36)*((1+$H13)^((12-3)/12))+('DRE + DCF'!$AB$36*(1+M$18)/(($H13-M$18)*(1+$H13)^(COUNT('DRE + DCF'!$W$22:$AA$22)-((12-3)/12)))))*$F$40+$F$42)*(1-$F$39))/$F$10 -> 10.367352 | N13: =(((NPV($H13,'DRE + DCF'!$V$36,'DRE + DCF'!$X$36:$AA$36)*((1+$H13)^((12-3)/12))+('DRE + DCF'!$AB$36*(1+N$18)/(($H13-N$18)*(1+$H13)^(COUNT('DRE + DCF'!$W$22:$AA$22)-((12-3)/12)))))+SUM($F$12:$F$17)))/$F$10-(((NPV($H13,'DRE + DCF'!$V$36,'DRE + DCF'!$X$36:$AA$36)*((1+$H13)^((12-3)/12))+('DRE + DCF'!$AB$36*(1+N$18)/(($H13-N$18)*(1+$H13)^(COUNT('DRE + DCF'!$W$22:$AA$22)-((12-3)/12)))))*$F$40+$F$42)*(1-$F$39))/$F$10 -> 10.960473 | O13: =(((NPV($H13,'DRE + DCF'!$V$36,'DRE + DCF'!$X$36:$AA$36)*((1+$H13)^((12-3)/12))+('DRE + DCF'!$AB$36*(1+O$18)/(($H13-O$18)*(1+$H13)^(COUNT('DRE + DCF'!$W$22:$AA$22)-((12-3)/12)))))+SUM($F$12:$F$17)))/$F$10-(((NPV($H13,'DRE + DCF'!$V$36,'DRE + DCF'!$X$36:$AA$36)*((1+$H13)^((12-3)/12))+('DRE + DCF'!$AB$36*(1+O$18)/(($H13-O$18)*(1+$H13)^(COUNT('DRE + DCF'!$W$22:$AA$22)-((12-3)/12)))))*$F$40+$F$42)*(1-$F$39))/$F$10 -> 11.639979 | P13: =(((NPV($H13,'DRE + DCF'!$V$36,'DRE + DCF'!$X$36:$AA$36)*((1+$H13)^((12-3)/12))+('DRE + DCF'!$AB$36*(1+P$18)/(($H13-P$18)*(1+$H13)^(COUNT('DRE + DCF'!$W$22:$AA$22)-((12-3)/12)))))+SUM($F$12:$F$17)))/$F$10-(((NPV($H13,'DRE + DCF'!$V$36,'DRE + DCF'!$X$36:$AA$36)*((1+$H13)^((12-3)/12))+('DRE + DCF'!$AB$36*(1+P$18)/(($H13-P$18)*(1+$H13)^(COUNT('DRE + DCF'!$W$22:$AA$22)-((12-3)/12)))))*$F$40+$F$42)*(1-$F$39))/$F$10 -> 12.426224 | ... R13: =(((NPV($H13,'DRE + DCF'!$V$36,'DRE + DCF'!$X$36:$AA$36)*((1+$H13)^((12-3)/12))+('DRE + DCF'!$AB$36*(1+R$18)/(($H13-R$18)*(1+$H13)^(COUNT('DRE + DCF'!$W$22:$AA$22)-((12-3)/12)))))+SUM($F$12:$F$17)))/$F$10-(((NPV($H13,'DRE + DCF'!$V$36,'DRE + DCF'!$X$36:$AA$36)*((1+$H13)^((12-3)/12))+('DRE + DCF'!$AB$36*(1+R$18)/(($H13-R$18)*(1+$H13)^(COUNT('DRE + DCF'!$W$22:$AA$22)-((12-3)/12)))))*$F$40+$F$42)*(1-$F$39))/$F$10 -> 14.438283
A14: Painel de Índices | E14: Empresas de Capital Aberto | F14: =K29 -> 12494156 | H14: =H13+0.5% -> 0.11533014 | I14: =(((NPV($H14,'DRE + DCF'!$V$36,'DRE + DCF'!$X$36:$AA$36)*((1+$H14)^((12-3)/12))+('DRE + DCF'!$AB$36*(1+I$18)/(($H14-I$18)*(1+$H14)^(COUNT('DRE + DCF'!$W$22:$AA$22)-((12-3)/12)))))+SUM($F$12:$F$17)))/$F$10-(((NPV($H14,'DRE + DCF'!$V$36,'DRE + DCF'!$X$36:$AA$36)*((1+$H14)^((12-3)/12))+('DRE + DCF'!$AB$36*(1+I$18)/(($H14-I$18)*(1+$H14)^(COUNT('DRE + DCF'!$W$22:$AA$22)-((12-3)/12)))))*$F$40+$F$42)*(1-$F$39))/$F$10 -> 7.8322874 | J14: =(((NPV($H14,'DRE + DCF'!$V$36,'DRE + DCF'!$X$36:$AA$36)*((1+$H14)^((12-3)/12))+('DRE + DCF'!$AB$36*(1+J$18)/(($H14-J$18)*(1+$H14)^(COUNT('DRE + DCF'!$W$22:$AA$22)-((12-3)/12)))))+SUM($F$12:$F$17)))/$F$10-(((NPV($H14,'DRE + DCF'!$V$36,'DRE + DCF'!$X$36:$AA$36)*((1+$H14)^((12-3)/12))+('DRE + DCF'!$AB$36*(1+J$18)/(($H14-J$18)*(1+$H14)^(COUNT('DRE + DCF'!$W$22:$AA$22)-((12-3)/12)))))*$F$40+$F$42)*(1-$F$39))/$F$10 -> 8.1329693 | K14: =(((NPV($H14,'DRE + DCF'!$V$36,'DRE + DCF'!$X$36:$AA$36)*((1+$H14)^((12-3)/12))+('DRE + DCF'!$AB$36*(1+K$18)/(($H14-K$18)*(1+$H14)^(COUNT('DRE + DCF'!$W$22:$AA$22)-((12-3)/12)))))+SUM($F$12:$F$17)))/$F$10-(((NPV($H14,'DRE + DCF'!$V$36,'DRE + DCF'!$X$36:$AA$36)*((1+$H14)^((12-3)/12))+('DRE + DCF'!$AB$36*(1+K$18)/(($H14-K$18)*(1+$H14)^(COUNT('DRE + DCF'!$W$22:$AA$22)-((12-3)/12)))))*$F$40+$F$42)*(1-$F$39))/$F$10 -> 8.4641276 | L14: =(((NPV($H14,'DRE + DCF'!$V$36,'DRE + DCF'!$X$36:$AA$36)*((1+$H14)^((12-3)/12))+('DRE + DCF'!$AB$36*(1+L$18)/(($H14-L$18)*(1+$H14)^(COUNT('DRE + DCF'!$W$22:$AA$22)-((12-3)/12)))))+SUM($F$12:$F$17)))/$F$10-(((NPV($H14,'DRE + DCF'!$V$36,'DRE + DCF'!$X$36:$AA$36)*((1+$H14)^((12-3)/12))+('DRE + DCF'!$AB$36*(1+L$18)/(($H14-L$18)*(1+$H14)^(COUNT('DRE + DCF'!$W$22:$AA$22)-((12-3)/12)))))*$F$40+$F$42)*(1-$F$39))/$F$10 -> 8.8306433 | M14: =(((NPV($H14,'DRE + DCF'!$V$36,'DRE + DCF'!$X$36:$AA$36)*((1+$H14)^((12-3)/12))+('DRE + DCF'!$AB$36*(1+M$18)/(($H14-M$18)*(1+$H14)^(COUNT('DRE + DCF'!$W$22:$AA$22)-((12-3)/12)))))+SUM($F$12:$F$17)))/$F$10-(((NPV($H14,'DRE + DCF'!$V$36,'DRE + DCF'!$X$36:$AA$36)*((1+$H14)^((12-3)/12))+('DRE + DCF'!$AB$36*(1+M$18)/(($H14-M$18)*(1+$H14)^(COUNT('DRE + DCF'!$W$22:$AA$22)-((12-3)/12)))))*$F$40+$F$42)*(1-$F$39))/$F$10 -> 9.2384983 | N14: =(((NPV($H14,'DRE + DCF'!$V$36,'DRE + DCF'!$X$36:$AA$36)*((1+$H14)^((12-3)/12))+('DRE + DCF'!$AB$36*(1+N$18)/(($H14-N$18)*(1+$H14)^(COUNT('DRE + DCF'!$W$22:$AA$22)-((12-3)/12)))))+SUM($F$12:$F$17)))/$F$10-(((NPV($H14,'DRE + DCF'!$V$36,'DRE + DCF'!$X$36:$AA$36)*((1+$H14)^((12-3)/12))+('DRE + DCF'!$AB$36*(1+N$18)/(($H14-N$18)*(1+$H14)^(COUNT('DRE + DCF'!$W$22:$AA$22)-((12-3)/12)))))*$F$40+$F$42)*(1-$F$39))/$F$10 -> 9.6951047 | O14: =(((NPV($H14,'DRE + DCF'!$V$36,'DRE + DCF'!$X$36:$AA$36)*((1+$H14)^((12-3)/12))+('DRE + DCF'!$AB$36*(1+O$18)/(($H14-O$18)*(1+$H14)^(COUNT('DRE + DCF'!$W$22:$AA$22)-((12-3)/12)))))+SUM($F$12:$F$17)))/$F$10-(((NPV($H14,'DRE + DCF'!$V$36,'DRE + DCF'!$X$36:$AA$36)*((1+$H14)^((12-3)/12))+('DRE + DCF'!$AB$36*(1+O$18)/(($H14-O$18)*(1+$H14)^(COUNT('DRE + DCF'!$W$22:$AA$22)-((12-3)/12)))))*$F$40+$F$42)*(1-$F$39))/$F$10 -> 10.209759 | P14: =(((NPV($H14,'DRE + DCF'!$V$36,'DRE + DCF'!$X$36:$AA$36)*((1+$H14)^((12-3)/12))+('DRE + DCF'!$AB$36*(1+P$18)/(($H14-P$18)*(1+$H14)^(COUNT('DRE + DCF'!$W$22:$AA$22)-((12-3)/12)))))+SUM($F$12:$F$17)))/$F$10-(((NPV($H14,'DRE + DCF'!$V$36,'DRE + DCF'!$X$36:$AA$36)*((1+$H14)^((12-3)/12))+('DRE + DCF'!$AB$36*(1+P$18)/(($H14-P$18)*(1+$H14)^(COUNT('DRE + DCF'!$W$22:$AA$22)-((12-3)/12)))))*$F$40+$F$42)*(1-$F$39))/$F$10 -> 10.794282 | ... R14: =(((NPV($H14,'DRE + DCF'!$V$36,'DRE + DCF'!$X$36:$AA$36)*((1+$H14)^((12-3)/12))+('DRE + DCF'!$AB$36*(1+R$18)/(($H14-R$18)*(1+$H14)^(COUNT('DRE + DCF'!$W$22:$AA$22)-((12-3)/12)))))+SUM($F$12:$F$17)))/$F$10-(((NPV($H14,'DRE + DCF'!$V$36,'DRE + DCF'!$X$36:$AA$36)*((1+$H14)^((12-3)/12))+('DRE + DCF'!$AB$36*(1+R$18)/(($H14-R$18)*(1+$H14)^(COUNT('DRE + DCF'!$W$22:$AA$22)-((12-3)/12)))))*$F$40+$F$42)*(1-$F$39))/$F$10 -> 12.238785
A15: Projeções - Receita e EBIT | E15: Valor do Equity da Automob que não pertence à Simpar | F15: =-F44 -> -1461068.2 | H15: =H14+0.5% -> 0.12033014 | I15: =(((NPV($H15,'DRE + DCF'!$V$36,'DRE + DCF'!$X$36:$AA$36)*((1+$H15)^((12-3)/12))+('DRE + DCF'!$AB$36*(1+I$18)/(($H15-I$18)*(1+$H15)^(COUNT('DRE + DCF'!$W$22:$AA$22)-((12-3)/12)))))+SUM($F$12:$F$17)))/$F$10-(((NPV($H15,'DRE + DCF'!$V$36,'DRE + DCF'!$X$36:$AA$36)*((1+$H15)^((12-3)/12))+('DRE + DCF'!$AB$36*(1+I$18)/(($H15-I$18)*(1+$H15)^(COUNT('DRE + DCF'!$W$22:$AA$22)-((12-3)/12)))))*$F$40+$F$42)*(1-$F$39))/$F$10 -> 7.1941941 | J15: =(((NPV($H15,'DRE + DCF'!$V$36,'DRE + DCF'!$X$36:$AA$36)*((1+$H15)^((12-3)/12))+('DRE + DCF'!$AB$36*(1+J$18)/(($H15-J$18)*(1+$H15)^(COUNT('DRE + DCF'!$W$22:$AA$22)-((12-3)/12)))))+SUM($F$12:$F$17)))/$F$10-(((NPV($H15,'DRE + DCF'!$V$36,'DRE + DCF'!$X$36:$AA$36)*((1+$H15)^((12-3)/12))+('DRE + DCF'!$AB$36*(1+J$18)/(($H15-J$18)*(1+$H15)^(COUNT('DRE + DCF'!$W$22:$AA$22)-((12-3)/12)))))*$F$40+$F$42)*(1-$F$39))/$F$10 -> 7.4416871 | K15: =(((NPV($H15,'DRE + DCF'!$V$36,'DRE + DCF'!$X$36:$AA$36)*((1+$H15)^((12-3)/12))+('DRE + DCF'!$AB$36*(1+K$18)/(($H15-K$18)*(1+$H15)^(COUNT('DRE + DCF'!$W$22:$AA$22)-((12-3)/12)))))+SUM($F$12:$F$17)))/$F$10-(((NPV($H15,'DRE + DCF'!$V$36,'DRE + DCF'!$X$36:$AA$36)*((1+$H15)^((12-3)/12))+('DRE + DCF'!$AB$36*(1+K$18)/(($H15-K$18)*(1+$H15)^(COUNT('DRE + DCF'!$W$22:$AA$22)-((12-3)/12)))))*$F$40+$F$42)*(1-$F$39))/$F$10 -> 7.7119569 | L15: =(((NPV($H15,'DRE + DCF'!$V$36,'DRE + DCF'!$X$36:$AA$36)*((1+$H15)^((12-3)/12))+('DRE + DCF'!$AB$36*(1+L$18)/(($H15-L$18)*(1+$H15)^(COUNT('DRE + DCF'!$W$22:$AA$22)-((12-3)/12)))))+SUM($F$12:$F$17)))/$F$10-(((NPV($H15,'DRE + DCF'!$V$36,'DRE + DCF'!$X$36:$AA$36)*((1+$H15)^((12-3)/12))+('DRE + DCF'!$AB$36*(1+L$18)/(($H15-L$18)*(1+$H15)^(COUNT('DRE + DCF'!$W$22:$AA$22)-((12-3)/12)))))*$F$40+$F$42)*(1-$F$39))/$F$10 -> 8.0082992 | M15: =(((NPV($H15,'DRE + DCF'!$V$36,'DRE + DCF'!$X$36:$AA$36)*((1+$H15)^((12-3)/12))+('DRE + DCF'!$AB$36*(1+M$18)/(($H15-M$18)*(1+$H15)^(COUNT('DRE + DCF'!$W$22:$AA$22)-((12-3)/12)))))+SUM($F$12:$F$17)))/$F$10-(((NPV($H15,'DRE + DCF'!$V$36,'DRE + DCF'!$X$36:$AA$36)*((1+$H15)^((12-3)/12))+('DRE + DCF'!$AB$36*(1+M$18)/(($H15-M$18)*(1+$H15)^(COUNT('DRE + DCF'!$W$22:$AA$22)-((12-3)/12)))))*$F$40+$F$42)*(1-$F$39))/$F$10 -> 8.3346783 | N15: =(((NPV($H15,'DRE + DCF'!$V$36,'DRE + DCF'!$X$36:$AA$36)*((1+$H15)^((12-3)/12))+('DRE + DCF'!$AB$36*(1+N$18)/(($H15-N$18)*(1+$H15)^(COUNT('DRE + DCF'!$W$22:$AA$22)-((12-3)/12)))))+SUM($F$12:$F$17)))/$F$10-(((NPV($H15,'DRE + DCF'!$V$36,'DRE + DCF'!$X$36:$AA$36)*((1+$H15)^((12-3)/12))+('DRE + DCF'!$AB$36*(1+N$18)/(($H15-N$18)*(1+$H15)^(COUNT('DRE + DCF'!$W$22:$AA$22)-((12-3)/12)))))*$F$40+$F$42)*(1-$F$39))/$F$10 -> 8.6959044 | O15: =(((NPV($H15,'DRE + DCF'!$V$36,'DRE + DCF'!$X$36:$AA$36)*((1+$H15)^((12-3)/12))+('DRE + DCF'!$AB$36*(1+O$18)/(($H15-O$18)*(1+$H15)^(COUNT('DRE + DCF'!$W$22:$AA$22)-((12-3)/12)))))+SUM($F$12:$F$17)))/$F$10-(((NPV($H15,'DRE + DCF'!$V$36,'DRE + DCF'!$X$36:$AA$36)*((1+$H15)^((12-3)/12))+('DRE + DCF'!$AB$36*(1+O$18)/(($H15-O$18)*(1+$H15)^(COUNT('DRE + DCF'!$W$22:$AA$22)-((12-3)/12)))))*$F$40+$F$42)*(1-$F$39))/$F$10 -> 9.0978733 | P15: =(((NPV($H15,'DRE + DCF'!$V$36,'DRE + DCF'!$X$36:$AA$36)*((1+$H15)^((12-3)/12))+('DRE + DCF'!$AB$36*(1+P$18)/(($H15-P$18)*(1+$H15)^(COUNT('DRE + DCF'!$W$22:$AA$22)-((12-3)/12)))))+SUM($F$12:$F$17)))/$F$10-(((NPV($H15,'DRE + DCF'!$V$36,'DRE + DCF'!$X$36:$AA$36)*((1+$H15)^((12-3)/12))+('DRE + DCF'!$AB$36*(1+P$18)/(($H15-P$18)*(1+$H15)^(COUNT('DRE + DCF'!$W$22:$AA$22)-((12-3)/12)))))*$F$40+$F$42)*(1-$F$39))/$F$10 -> 9.54789 | ... R15: =(((NPV($H15,'DRE + DCF'!$V$36,'DRE + DCF'!$X$36:$AA$36)*((1+$H15)^((12-3)/12))+('DRE + DCF'!$AB$36*(1+R$18)/(($H15-R$18)*(1+$H15)^(COUNT('DRE + DCF'!$W$22:$AA$22)-((12-3)/12)))))+SUM($F$12:$F$17)))/$F$10-(((NPV($H15,'DRE + DCF'!$V$36,'DRE + DCF'!$X$36:$AA$36)*((1+$H15)^((12-3)/12))+('DRE + DCF'!$AB$36*(1+R$18)/(($H15-R$18)*(1+$H15)^(COUNT('DRE + DCF'!$W$22:$AA$22)-((12-3)/12)))))*$F$40+$F$42)*(1-$F$39))/$F$10 -> 10.631204
A16: Projeções - CG + Capex | E16: Desconto de Holding | F16: =('Projeções - Receita e EBIT'!V133)/((WACC!P20)-3.5%)/'DRE + DCF'!AA37 -> -1549244.3 | H16: =H15+0.5% -> 0.12533014 | I16: =(((NPV($H16,'DRE + DCF'!$V$36,'DRE + DCF'!$X$36:$AA$36)*((1+$H16)^((12-3)/12))+('DRE + DCF'!$AB$36*(1+I$18)/(($H16-I$18)*(1+$H16)^(COUNT('DRE + DCF'!$W$22:$AA$22)-((12-3)/12)))))+SUM($F$12:$F$17)))/$F$10-(((NPV($H16,'DRE + DCF'!$V$36,'DRE + DCF'!$X$36:$AA$36)*((1+$H16)^((12-3)/12))+('DRE + DCF'!$AB$36*(1+I$18)/(($H16-I$18)*(1+$H16)^(COUNT('DRE + DCF'!$W$22:$AA$22)-((12-3)/12)))))*$F$40+$F$42)*(1-$F$39))/$F$10 -> 6.652546 | J16: =(((NPV($H16,'DRE + DCF'!$V$36,'DRE + DCF'!$X$36:$AA$36)*((1+$H16)^((12-3)/12))+('DRE + DCF'!$AB$36*(1+J$18)/(($H16-J$18)*(1+$H16)^(COUNT('DRE + DCF'!$W$22:$AA$22)-((12-3)/12)))))+SUM($F$12:$F$17)))/$F$10-(((NPV($H16,'DRE + DCF'!$V$36,'DRE + DCF'!$X$36:$AA$36)*((1+$H16)^((12-3)/12))+('DRE + DCF'!$AB$36*(1+J$18)/(($H16-J$18)*(1+$H16)^(COUNT('DRE + DCF'!$W$22:$AA$22)-((12-3)/12)))))*$F$40+$F$42)*(1-$F$39))/$F$10 -> 6.85933 | K16: =(((NPV($H16,'DRE + DCF'!$V$36,'DRE + DCF'!$X$36:$AA$36)*((1+$H16)^((12-3)/12))+('DRE + DCF'!$AB$36*(1+K$18)/(($H16-K$18)*(1+$H16)^(COUNT('DRE + DCF'!$W$22:$AA$22)-((12-3)/12)))))+SUM($F$12:$F$17)))/$F$10-(((NPV($H16,'DRE + DCF'!$V$36,'DRE + DCF'!$X$36:$AA$36)*((1+$H16)^((12-3)/12))+('DRE + DCF'!$AB$36*(1+K$18)/(($H16-K$18)*(1+$H16)^(COUNT('DRE + DCF'!$W$22:$AA$22)-((12-3)/12)))))*$F$40+$F$42)*(1-$F$39))/$F$10 -> 7.0835406 | L16: =(((NPV($H16,'DRE + DCF'!$V$36,'DRE + DCF'!$X$36:$AA$36)*((1+$H16)^((12-3)/12))+('DRE + DCF'!$AB$36*(1+L$18)/(($H16-L$18)*(1+$H16)^(COUNT('DRE + DCF'!$W$22:$AA$22)-((12-3)/12)))))+SUM($F$12:$F$17)))/$F$10-(((NPV($H16,'DRE + DCF'!$V$36,'DRE + DCF'!$X$36:$AA$36)*((1+$H16)^((12-3)/12))+('DRE + DCF'!$AB$36*(1+L$18)/(($H16-L$18)*(1+$H16)^(COUNT('DRE + DCF'!$W$22:$AA$22)-((12-3)/12)))))*$F$40+$F$42)*(1-$F$39))/$F$10 -> 7.3274775 | M16: =(((NPV($H16,'DRE + DCF'!$V$36,'DRE + DCF'!$X$36:$AA$36)*((1+$H16)^((12-3)/12))+('DRE + DCF'!$AB$36*(1+M$18)/(($H16-M$18)*(1+$H16)^(COUNT('DRE + DCF'!$W$22:$AA$22)-((12-3)/12)))))+SUM($F$12:$F$17)))/$F$10-(((NPV($H16,'DRE + DCF'!$V$36,'DRE + DCF'!$X$36:$AA$36)*((1+$H16)^((12-3)/12))+('DRE + DCF'!$AB$36*(1+M$18)/(($H16-M$18)*(1+$H16)^(COUNT('DRE + DCF'!$W$22:$AA$22)-((12-3)/12)))))*$F$40+$F$42)*(1-$F$39))/$F$10 -> 7.593864 | N16: =(((NPV($H16,'DRE + DCF'!$V$36,'DRE + DCF'!$X$36:$AA$36)*((1+$H16)^((12-3)/12))+('DRE + DCF'!$AB$36*(1+N$18)/(($H16-N$18)*(1+$H16)^(COUNT('DRE + DCF'!$W$22:$AA$22)-((12-3)/12)))))+SUM($F$12:$F$17)))/$F$10-(((NPV($H16,'DRE + DCF'!$V$36,'DRE + DCF'!$X$36:$AA$36)*((1+$H16)^((12-3)/12))+('DRE + DCF'!$AB$36*(1+N$18)/(($H16-N$18)*(1+$H16)^(COUNT('DRE + DCF'!$W$22:$AA$22)-((12-3)/12)))))*$F$40+$F$42)*(1-$F$39))/$F$10 -> 7.8859485 | O16: =(((NPV($H16,'DRE + DCF'!$V$36,'DRE + DCF'!$X$36:$AA$36)*((1+$H16)^((12-3)/12))+('DRE + DCF'!$AB$36*(1+O$18)/(($H16-O$18)*(1+$H16)^(COUNT('DRE + DCF'!$W$22:$AA$22)-((12-3)/12)))))+SUM($F$12:$F$17)))/$F$10-(((NPV($H16,'DRE + DCF'!$V$36,'DRE + DCF'!$X$36:$AA$36)*((1+$H16)^((12-3)/12))+('DRE + DCF'!$AB$36*(1+O$18)/(($H16-O$18)*(1+$H16)^(COUNT('DRE + DCF'!$W$22:$AA$22)-((12-3)/12)))))*$F$40+$F$42)*(1-$F$39))/$F$10 -> 8.2076381 | P16: =(((NPV($H16,'DRE + DCF'!$V$36,'DRE + DCF'!$X$36:$AA$36)*((1+$H16)^((12-3)/12))+('DRE + DCF'!$AB$36*(1+P$18)/(($H16-P$18)*(1+$H16)^(COUNT('DRE + DCF'!$W$22:$AA$22)-((12-3)/12)))))+SUM($F$12:$F$17)))/$F$10-(((NPV($H16,'DRE + DCF'!$V$36,'DRE + DCF'!$X$36:$AA$36)*((1+$H16)^((12-3)/12))+('DRE + DCF'!$AB$36*(1+P$18)/(($H16-P$18)*(1+$H16)^(COUNT('DRE + DCF'!$W$22:$AA$22)-((12-3)/12)))))*$F$40+$F$42)*(1-$F$39))/$F$10 -> 8.5636741 | ... R16: =(((NPV($H16,'DRE + DCF'!$V$36,'DRE + DCF'!$X$36:$AA$36)*((1+$H16)^((12-3)/12))+('DRE + DCF'!$AB$36*(1+R$18)/(($H16-R$18)*(1+$H16)^(COUNT('DRE + DCF'!$W$22:$AA$22)-((12-3)/12)))))+SUM($F$12:$F$17)))/$F$10-(((NPV($H16,'DRE + DCF'!$V$36,'DRE + DCF'!$X$36:$AA$36)*((1+$H16)^((12-3)/12))+('DRE + DCF'!$AB$36*(1+R$18)/(($H16-R$18)*(1+$H16)^(COUNT('DRE + DCF'!$W$22:$AA$22)-((12-3)/12)))))*$F$40+$F$42)*(1-$F$39))/$F$10 -> 9.4034181
A17: Projeções 2023 | E17: Passivo Judicial Capital Fechado | F17: =IF(F54>=0,0,F54) -> 0 | H17: =H16+0.5% -> 0.13033014 | I17: =(((NPV($H17,'DRE + DCF'!$V$36,'DRE + DCF'!$X$36:$AA$36)*((1+$H17)^((12-3)/12))+('DRE + DCF'!$AB$36*(1+I$18)/(($H17-I$18)*(1+$H17)^(COUNT('DRE + DCF'!$W$22:$AA$22)-((12-3)/12)))))+SUM($F$12:$F$17)))/$F$10-(((NPV($H17,'DRE + DCF'!$V$36,'DRE + DCF'!$X$36:$AA$36)*((1+$H17)^((12-3)/12))+('DRE + DCF'!$AB$36*(1+I$18)/(($H17-I$18)*(1+$H17)^(COUNT('DRE + DCF'!$W$22:$AA$22)-((12-3)/12)))))*$F$40+$F$42)*(1-$F$39))/$F$10 -> 6.1865515 | J17: =(((NPV($H17,'DRE + DCF'!$V$36,'DRE + DCF'!$X$36:$AA$36)*((1+$H17)^((12-3)/12))+('DRE + DCF'!$AB$36*(1+J$18)/(($H17-J$18)*(1+$H17)^(COUNT('DRE + DCF'!$W$22:$AA$22)-((12-3)/12)))))+SUM($F$12:$F$17)))/$F$10-(((NPV($H17,'DRE + DCF'!$V$36,'DRE + DCF'!$X$36:$AA$36)*((1+$H17)^((12-3)/12))+('DRE + DCF'!$AB$36*(1+J$18)/(($H17-J$18)*(1+$H17)^(COUNT('DRE + DCF'!$W$22:$AA$22)-((12-3)/12)))))*$F$40+$F$42)*(1-$F$39))/$F$10 -> 6.361528 | K17: =(((NPV($H17,'DRE + DCF'!$V$36,'DRE + DCF'!$X$36:$AA$36)*((1+$H17)^((12-3)/12))+('DRE + DCF'!$AB$36*(1+K$18)/(($H17-K$18)*(1+$H17)^(COUNT('DRE + DCF'!$W$22:$AA$22)-((12-3)/12)))))+SUM($F$12:$F$17)))/$F$10-(((NPV($H17,'DRE + DCF'!$V$36,'DRE + DCF'!$X$36:$AA$36)*((1+$H17)^((12-3)/12))+('DRE + DCF'!$AB$36*(1+K$18)/(($H17-K$18)*(1+$H17)^(COUNT('DRE + DCF'!$W$22:$AA$22)-((12-3)/12)))))*$F$40+$F$42)*(1-$F$39))/$F$10 -> 6.5501045 | L17: =(((NPV($H17,'DRE + DCF'!$V$36,'DRE + DCF'!$X$36:$AA$36)*((1+$H17)^((12-3)/12))+('DRE + DCF'!$AB$36*(1+L$18)/(($H17-L$18)*(1+$H17)^(COUNT('DRE + DCF'!$W$22:$AA$22)-((12-3)/12)))))+SUM($F$12:$F$17)))/$F$10-(((NPV($H17,'DRE + DCF'!$V$36,'DRE + DCF'!$X$36:$AA$36)*((1+$H17)^((12-3)/12))+('DRE + DCF'!$AB$36*(1+L$18)/(($H17-L$18)*(1+$H17)^(COUNT('DRE + DCF'!$W$22:$AA$22)-((12-3)/12)))))*$F$40+$F$42)*(1-$F$39))/$F$10 -> 6.7539305 | M17: =(((NPV($H17,'DRE + DCF'!$V$36,'DRE + DCF'!$X$36:$AA$36)*((1+$H17)^((12-3)/12))+('DRE + DCF'!$AB$36*(1+M$18)/(($H17-M$18)*(1+$H17)^(COUNT('DRE + DCF'!$W$22:$AA$22)-((12-3)/12)))))+SUM($F$12:$F$17)))/$F$10-(((NPV($H17,'DRE + DCF'!$V$36,'DRE + DCF'!$X$36:$AA$36)*((1+$H17)^((12-3)/12))+('DRE + DCF'!$AB$36*(1+M$18)/(($H17-M$18)*(1+$H17)^(COUNT('DRE + DCF'!$W$22:$AA$22)-((12-3)/12)))))*$F$40+$F$42)*(1-$F$39))/$F$10 -> 6.9749337 | N17: =(((NPV($H17,'DRE + DCF'!$V$36,'DRE + DCF'!$X$36:$AA$36)*((1+$H17)^((12-3)/12))+('DRE + DCF'!$AB$36*(1+N$18)/(($H17-N$18)*(1+$H17)^(COUNT('DRE + DCF'!$W$22:$AA$22)-((12-3)/12)))))+SUM($F$12:$F$17)))/$F$10-(((NPV($H17,'DRE + DCF'!$V$36,'DRE + DCF'!$X$36:$AA$36)*((1+$H17)^((12-3)/12))+('DRE + DCF'!$AB$36*(1+N$18)/(($H17-N$18)*(1+$H17)^(COUNT('DRE + DCF'!$W$22:$AA$22)-((12-3)/12)))))*$F$40+$F$42)*(1-$F$39))/$F$10 -> 7.2153812 | O17: =(((NPV($H17,'DRE + DCF'!$V$36,'DRE + DCF'!$X$36:$AA$36)*((1+$H17)^((12-3)/12))+('DRE + DCF'!$AB$36*(1+O$18)/(($H17-O$18)*(1+$H17)^(COUNT('DRE + DCF'!$W$22:$AA$22)-((12-3)/12)))))+SUM($F$12:$F$17)))/$F$10-(((NPV($H17,'DRE + DCF'!$V$36,'DRE + DCF'!$X$36:$AA$36)*((1+$H17)^((12-3)/12))+('DRE + DCF'!$AB$36*(1+O$18)/(($H17-O$18)*(1+$H17)^(COUNT('DRE + DCF'!$W$22:$AA$22)-((12-3)/12)))))*$F$40+$F$42)*(1-$F$39))/$F$10 -> 7.477957 | P17: =(((NPV($H17,'DRE + DCF'!$V$36,'DRE + DCF'!$X$36:$AA$36)*((1+$H17)^((12-3)/12))+('DRE + DCF'!$AB$36*(1+P$18)/(($H17-P$18)*(1+$H17)^(COUNT('DRE + DCF'!$W$22:$AA$22)-((12-3)/12)))))+SUM($F$12:$F$17)))/$F$10-(((NPV($H17,'DRE + DCF'!$V$36,'DRE + DCF'!$X$36:$AA$36)*((1+$H17)^((12-3)/12))+('DRE + DCF'!$AB$36*(1+P$18)/(($H17-P$18)*(1+$H17)^(COUNT('DRE + DCF'!$W$22:$AA$22)-((12-3)/12)))))*$F$40+$F$42)*(1-$F$39))/$F$10 -> 7.7658633 | ... R17: =(((NPV($H17,'DRE + DCF'!$V$36,'DRE + DCF'!$X$36:$AA$36)*((1+$H17)^((12-3)/12))+('DRE + DCF'!$AB$36*(1+R$18)/(($H17-R$18)*(1+$H17)^(COUNT('DRE + DCF'!$W$22:$AA$22)-((12-3)/12)))))+SUM($F$12:$F$17)))/$F$10-(((NPV($H17,'DRE + DCF'!$V$36,'DRE + DCF'!$X$36:$AA$36)*((1+$H17)^((12-3)/12))+('DRE + DCF'!$AB$36*(1+R$18)/(($H17-R$18)*(1+$H17)^(COUNT('DRE + DCF'!$W$22:$AA$22)-((12-3)/12)))))*$F$40+$F$42)*(1-$F$39))/$F$10 -> 8.433894
A18: Processos | E18: Valor da Ação | F18: =SUM($F$11:$F$17)/$F$10 -> 11.743778 | I18: =J18-0.25% -> 0.061 | J18: =K18-0.25% -> 0.0635 | K18: =L18-0.25% -> 0.066 | L18: =M18-0.25% -> 0.0685 | M18: ='DRE + DCF'!AD23 -> 0.071 | N18: =M18+0.25% -> 0.0735 | O18: =N18+0.25% -> 0.076 | P18: =O18+0.25% -> 0.0785 | Q18: =P18+0.25% -> 0.081 | R18: =Q18+0.25% -> 0.0835
E19: Cotação | F19: 6.16 | I19: Growth
E20: =IF(F20=0,"",IF(F20>0,"Upside","Downside")) -> Upside | F20: =IF(F18<0,"-",F18/F19-1) -> 0.90645746
E21: TIR | F21: 0.258
N24: Preço Teto | O24: 12.93 | P24: 11.31 | Q24: =O24/P24-1 -> 0.14323607
E25: Total Holding | F25: =SUM('Balanço Patrimonial'!P21,'Balanço Patrimonial'!P24+'Balanço Patrimonial'!P36+'Balanço Patrimonial'!P37) -> 12521834 | H25: Empresa | I25: Valor do Equity | J25: Participação Simpar | K25: Valor da Participação da Simpar | O25: =F18*(1-Q24) -> 10.061645
E26: JSL | F26: 3528272.2 | H26: JSL | I26: =SUM([1]Dashboard!$F$12:$F$16) -> 4067739.9 | J26: 0.7242 | K26: =I26*J26 -> 2945857.2
E27: Movida | F27: 2901197.7 | H27: Movida | I27: =SUM([2]Dashboard!$F$12:$F$15) -> 5221771.3 | J27: 0.6519 | K27: =I27*J27 -> 3404072.7
E28: Vamos | F28: 2415732.2 | H28: Vamos | I28: =SUM([3]Dashboard!$F$12:$F$15) -> 8896938.8 | J28: 0.6906 | K28: =I28*J28 -> 6144225.9
E29: Holding excluindo empresas de capital aberto | F29: =F25-SUM(F26:F28) -> 3676632.3 | H29: Total | K29: =SUM(K26:K28) -> 12494156
E32: Total Holding | F32: =WACC!F19 -> 55498129 | H32: Empresa | I32: Market Cap | J32: Participação Simpar | K32: Valor de mercado da Participação
E33: JSL | F33: -9650368 | H33: JSL | I33: =[1]Dashboard!$F$18*[1]Dashboard!$F$11 -> 3388479.7 | J33: =J26 -> 0.7242 | K33: =I33*J33 -> 2453937
E34: Movida | F34: -17964301 | H34: Movida | I34: =[2]Dashboard!$F$17*[2]Dashboard!$F$11 -> 2623067.1 | J34: =J27 -> 0.6519 | K34: =I34*J34 -> 1709977.4
E35: Vamos | F35: -14245979 | H35: Vamos | I35: =[3]Dashboard!$F$17*[3]Dashboard!$F$11 -> 9088591.2 | J35: =J28 -> 0.6906 | K35: =I35*J35 -> 6276581.1
E36: Holding excluindo empresas de capital aberto | F36: =SUM(F32:F35) -> 13637481 | H36: Simpar | I36: =F19*F10 -> 5377929.7 | J36: 1 | K36: =J36*I36 -> 5377929.7
H37: Empresas de Capital Fechado | K37: =K36-SUM(K33:K35) -> -5062565.8
E39: Participação da Simpar na Automob | F39: 0.794
E40: % médio do EBIT projetado que vem da Automob | F40: =AVERAGE('Projeções - Receita e EBIT'!$R$57:$V$57) -> 0.59655019
E41: Valor da Empresa da Automob baseado no EBIT | F41: =F11*F40 -> 6400863.9
E42: Dívida Líquida Automob | F42: 691700
E43: Valor do Equity Automob | F43: =F41+F42 -> 7092563.9
E44: Valor do Equity da Automob que não pertence à Simpar | F44: =F43*(1-$F$39) -> 1461068.2
E48: Total Holding | F48: =WACC!F35 -> 0
E49: JSL | F49: -528483
E50: Movida | F50: =[4]Dashboard!$F$15 -> 0
E51: Vamos | F51: -108010
E52: Holding excluindo empresas de capital aberto | F52: =SUM(F48:F51) -> -636493
E53: Holding | F53: =('Balanço Patrimonial'!P80-'Balanço Patrimonial'!P41)*-1 -> -631328
...

Sheet WACC
F3: =Dashboard!$H$3 -> SIMPAR (SIMH3)
A7: Páginas
A8: Dashboard
A9: WACC | E9: Atualizado em: 10/05/2024 | F9: 2024 | G9: =F9+1 -> 2025 | H9: =G9+1 -> 2026 | I9: =H9+1 -> 2027 | J9: =I9+1 -> 2028 | K9: =J9+1 -> 2029 | L9: =K9+1 -> 2030 | M9: =L9+1 -> 2031 | N9: =M9+1 -> 2032 | ... P9: =O9+1 -> 2034
A10: DRE Consolidado | E10: DI | F10: 0.1021 | G10: 0.1045 | H10: 0.10785 | I10: 0.1108 | J10: 0.11282 | K10: 0.1141 | L10: 0.11493 | M10: 0.1154 | N10: 0.11554 | O10: 0.1154 | P10: 0.1184
A11: DRE + DCF | E11: CDS | F11: 0.005192376 | G11: 0.007529595 | H11: 0.009825664 | I11: 0.012549005 | J11: 0.015362527 | K11: 0.017833094 | L11: 0.019839556 | M11: 0.021316616 | N11: 0.022198978 | O11: 0.022423308 | P11: 0.023871661
A12: DRE - Contas Abertas | E12: Inflação Implícita | F12: 0.04033 | G12: 0.03754 | H12: 0.04248 | I12: 0.04517 | J12: 0.0472 | K12: 0.04849 | L12: 0.05011 | M12: 0.05077 | N12: 0.05097 | O12: 0.05121 | P12: 0.05
A13: Balanço Patrimonial | E13: Taxa Livre de Risco | F13: =F10-F11 -> 0.096907624 | G13: =G10-G11 -> 0.096970405 | H13: =H10-H11 -> 0.098024336 | I13: =I10-I11 -> 0.098250995 | J13: =J10-J11 -> 0.097457473 | K13: =K10-K11 -> 0.096266906 | L13: =L10-L11 -> 0.095090444 | M13: =M10-M11 -> 0.094083384 | ... P13: =P10-P11 -> 0.094528339
A14: Painel de Índices | E14: Beta | F14: 2 | G14: =F14 -> 2 | H14: =G14 -> 2 | I14: =H14 -> 2 | J14: =I14 -> 2 | K14: =J14 -> 2 | L14: =K14 -> 2 | M14: =L14 -> 2 | N14: =M14 -> 2 | ... P14: =O14 -> 2
A15: Projeções - Receita e EBIT | E15: Prêmio de Risco | F15: 0.065 | G15: 0.065 | H15: 0.065 | I15: 0.065 | J15: 0.065 | K15: 0.065 | L15: 0.065 | M15: 0.065 | N15: 0.065 | O15: 0.065 | P15: 0.065
A16: Projeções - CG + Capex | E16: Custo de Capital Próprio (Ke) | F16: =F13+(F14*F15) -> 0.22690762 | G16: =G13+(G14*G15) -> 0.2269704 | H16: =H13+(H14*H15) -> 0.22802434 | I16: =I13+(I14*I15) -> 0.228251 | J16: =J13+(J14*J15) -> 0.22745747 | K16: =K13+(K14*K15) -> 0.22626691 | L16: =L13+(L14*L15) -> 0.22509044 | M16: =M13+(M14*M15) -> 0.22408338 | ... P16: =P13+(P14*P15) -> 0.22452834
A17: Projeções 2023 | E17: Valor Justo do Equity (R$ Mil) | F17: =Dashboard!F19*Dashboard!F10 -> 5377929.7 | G17: =F17 -> 5377929.7 | H17: =G17 -> 5377929.7 | I17: =H17 -> 5377929.7 | J17: =I17 -> 5377929.7 | K17: =J17 -> 5377929.7 | L17: =K17 -> 5377929.7 | M17: =L17 -> 5377929.7 | N17: =M17 -> 5377929.7 | ... P17: =O17 -> 5377929.7
A18: Processos | E18: Custo de Capital de Terceiros (Kd) | F18: =F10+3.2% -> 0.1341 | G18: =G10+3.2% -> 0.1365 | H18: =H10+3.2% -> 0.13985 | I18: =I10+3.2% -> 0.1428 | J18: =J10+3.2% -> 0.14482 | K18: =K10+3.2% -> 0.1461 | L18: =L10+3.2% -> 0.14693 | M18: =M10+3.2% -> 0.1474 | ... P18: =P10+3.2% -> 0.1504
E19: Dívida Bruta (R$ Mil) | F19: =SUM('Balanço Patrimonial'!P54:P60,'Balanço Patrimonial'!P63,'Balanço Patrimonial'!P72:P76,'Balanço Patrimonial'!P78,'Balanço Patrimonial'!P85) -> 55498129 | G19: =SUM('Balanço Patrimonial'!P54:P60,'Balanço Patrimonial'!P63,'Balanço Patrimonial'!P72:P76,'Balanço Patrimonial'!P78,'Balanço Patrimonial'!P85) -> 55498129 | H19: =G19 -> 55498129 | I19: =H19 -> 55498129 | J19: =I19 -> 55498129 | K19: =J19 -> 55498129 | L19: =K19 -> 55498129 | M19: =L19 -> 55498129 | N19: =M19 -> 55498129 | O19: =N19 -> 55498129 | P19: =O19 -> 55498129
E20: WACC | F20: =((F16*F17)+(F18*F19*(1-'DRE + DCF'!W23)))/(F17+F19) -> 0.10073271 | G20: =((G16*G17)+(G18*G19*(1-'DRE + DCF'!X23)))/(G17+G19) -> 0.10218233 | H20: =((H16*H17)+(H18*H19*(1-'DRE + DCF'!Y23)))/(H17+H19) -> 0.10429111 | I20: =((I16*I17)+(I18*I19*(1-'DRE + DCF'!Z23)))/(I17+I19) -> 0.10608613 | J20: =((J16*J17)+(J18*J19*(1-'DRE + DCF'!$AA$23)))/(J17+J19) -> 0.10723145 | K20: =((K16*K17)+(K18*K19*(1-'DRE + DCF'!$AA$23)))/(K17+K19) -> 0.10789644 | L20: =((L16*L17)+(L18*L19*(1-'DRE + DCF'!$AA$23)))/(L17+L19) -> 0.10829192 | M20: =((M16*M17)+(M18*M19*(1-'DRE + DCF'!$AA$23)))/(M17+M19) -> 0.10848575 | N20: =((N16*N17)+(N18*N19*(1-'DRE + DCF'!$AA$23)))/(N17+N19) -> 0.1085044 | O20: =((O16*O17)+(O18*O19*(1-'DRE + DCF'!$AA$23)))/(O17+O19) -> 0.10838798 | P20: =((P16*P17)+(P18*P19*(1-'DRE + DCF'!$AA$23)))/(P17+P19) -> 0.11033014
E21: Desconto | F21: =1*(1+F20)^((9)/12) -> 1.0746361 | G21: =F21*(1+G20) -> 1.1844449 | H21: =G21*(1+H20) -> 1.3079719 | I21: =H21*(1+I20) -> 1.4467296 | J21: =I21*(1+J20) -> 1.6018645 | K21: =J21*(1+K20) -> 1.7747 | L21: =K21*(1+L20) -> 1.9668857 | M21: =L21*(1+M20) -> 2.1802647 | N21: =M21*(1+N20) -> 2.4168331 | ... P21: =O21*(1+P20) -> 2.9743398

Sheet DRE Consolidado
K2: =Dashboard!H3 -> SIMPAR (SIMH3)
A7: Páginas
A8: Dashboard
A9: WACC
A10: DRE Consolidado
A11: DRE + DCF
A12: DRE - Contas Abertas | E12: Data do Último Resultado: | K12: 2014 | L12: 2015 | M12: 2016 | N12: 2017 | O12: 2018 | P12: 2019 | Q12: 2020 | R12: 2021 | S12: 2022 | T12: 2023 | U12: YTD 2024 | V12: YTG 2024E | W12: 2024 | X12: =W12+1 -> 2025 | Y12: =X12+1 -> 2026 | Z12: =Y12+1 -> 2027 | AA12: =Z12+1 -> 2028
A13: Balanço Patrimonial | E13: Receita Bruta | K13: 6079086.1 | L13: 6561486.7 | M13: 7403983 | N13: 8199829 | O13: 9203466 | P13: 10734355 | Q13: 10874860 | R13: 15453380 | S13: 26844012 | T13: 35513417
A14: Painel de Índices | E14: Deduções | K14: =-(K13-K16) -> -539892.08 | L14: =-(L13-L16) -> -571574.68 | M14: =-(M13-M16) -> -880867 | N14: =-(N13-N16) -> -944025 | O14: =-(O13-O16) -> -1128077 | P14: =-(P13-P16) -> -1048146.5 | Q14: =-(Q13-Q16) -> -1067803 | R14: =-(R13-R16) -> -1587161 | S14: -2462220.7 | T14: -2462220.7
A15: Projeções - Receita e EBIT | E15: % da Receita Bruta | K15: =-K14/K13 -> 0.088811389 | L15: =-L14/L13 -> 0.087110545 | M15: =-M14/M13 -> 0.11897205 | N15: =-N14/N13 -> 0.1151274 | O15: =-O14/O13 -> 0.12257089 | P15: =-P14/P13 -> 0.097644102 | Q15: =-Q14/Q13 -> 0.098190046 | R15: =-R14/R13 -> 0.1027064 | ... T15: =-T14/T13 -> 0.069332126
A16: Projeções - CG + Capex | E16: Receita Líquida | K16: 5539194 | L16: 5989912 | M16: 6523116 | N16: 7255804 | O16: 8075389 | P16: 9686209 | Q16: 9807057 | R16: 13866219 | S16: 24381791 | T16: 31843613 | U16: 9146986 | V16: =W16-SUM(U16:U16) -> 28759355 | W16: ='Projeções - Receita e EBIT'!R10 -> 37906341 | X16: ='Projeções - Receita e EBIT'!S10 -> 43423210 | Y16: ='Projeções - Receita e EBIT'!T10 -> 50252034 | Z16: ='Projeções - Receita e EBIT'!U10 -> 55355892 | AA16: ='Projeções - Receita e EBIT'!V10 -> 60832681
A17: Projeções 2023 | E17: Crescimento da Receita (YoY)¹ | K17: 0 | L17: =L16/K16-1 -> 0.081368878 | M17: =M16/L16-1 -> 0.089017001 | N17: =N16/M16-1 -> 0.11232178 | O17: =O16/N16-1 -> 0.11295578 | P17: =P16/O16-1 -> 0.19947274 | Q17: =Q16/P16-1 -> 0.012476295 | R17: =R16/Q16-1 -> 0.41390215 | S17: =S16/R16-1 -> 0.758359 | T17: =T16/S16-1 -> 0.30604077 | W17: =W16/T16-1 -> 0.19039071 | X17: =X16/W16-1 -> 0.14553946 | Y17: =Y16/X16-1 -> 0.15726208 | Z17: =Z16/Y16-1 -> 0.10156521 | AA17: =AA16/Z16-1 -> 0.098937782
A18: Processos | E18: Custos das Vendas e Serviços | K18: -3865141 | L18: -3974936 | M18: -3936687 | N18: -4032052 | O18: -4699220 | P18: -5102646 | Q18: -5168883 | R18: -7304534 | S18: -12624428 | T18: -23669760 | U18: -6677400
E19: Custo de Construção | F19: Custo de Construção | U19: 0
A20: Gráficos | E20: Custo de Venda de Ativos Desmobilizados | K20: -681231 | L20: -877618 | M20: -1289069 | N20: -1737637 | O20: -1609867 | P20: -2524180 | Q20: -2618101 | R20: -2077780 | S20: -4166192 | U20: 0
E21: Lucro Bruto | K21: =K16+K18+K20 -> 992822 | L21: =L16+L18+L20 -> 1137358 | M21: =M16+M18+M20 -> 1297360 | N21: =N16+N18+N20 -> 1486115 | O21: =O16+O18+O20 -> 1766302 | P21: =P16+P18+P20 -> 2059383 | Q21: =Q16+Q18+Q20 -> 2020073 | R21: =R16+R18+R20 -> 4483905 | ... T21: =T16+T18+T20 -> 8173853 | U21: =U16+U18+U19+U20 -> 2469586
E22: Margem Bruta | K22: =K21/K16 -> 0.17923582 | L22: =L21/L16 -> 0.18987892 | M22: =M21/M16 -> 0.19888654 | N22: =N21/N16 -> 0.20481741 | O22: =O21/O16 -> 0.21872655 | P22: =P21/P16 -> 0.2126098 | Q22: =Q21/Q16 -> 0.20598157 | R22: =R21/R16 -> 0.32336897 | ... U22: =U21/U16 -> 0.26998904
E23: Despesas/ Receitas Operacionais | K23: =SUM(K24,K26,K28,K29,K32) -> -532720 | L23: =SUM(L24,L26,L28,L29,L32) -> -553903 | M23: =SUM(M24,M26,M28,M29,M32) -> -798577 | N23: =SUM(N24,N26,N28,N29,N32) -> -781645 | O23: =SUM(O24,O26,O28,O29,O32) -> -805585 | P23: =SUM(P24,P26,P28,P29,P32) -> -860218 | Q23: =SUM(Q24,Q26,Q28,Q29,Q32) -> -990091 | R23: =SUM(R24,R26,R28,R29,R32) -> -1353354 | ... U23: =SUM(U24,U26,U28,U29,U32) -> -891623
E24: Despesas Tributárias | K24: -8093 | L24: -9584 | M24: 0 | N24: 0 | O24: 0 | P24: 0 | Q24: 0 | R24: 0 | S24: 0 | U24: 0
E25: (%) da Receita Líquida | K25: =-K24/K16 -> 0.0014610429 | L25: =-L24/L16 -> 0.0016000235 | M25: =-M24/M16 -> 0 | N25: =-N24/N16 -> 0 | O25: =-O24/O16 -> 0 | P25: =-P24/P16 -> 0 | Q25: =-Q24/Q16 -> 0 | R25: =-R24/R16 -> 0 | ... U25: =-U24/U16 -> 0
E26: Despesas Comerciais Gerais e Administrativas | K26: -491535 | L26: -510134 | M26: -684175 | N26: -746102 | O26: -794421 | P26: =-571098-293107 -> -864205 | Q26: -896692 | R26: -1398455 | S26: =-884377-1397532 -> -2281909 | T26: =-1217597-2064530 -> -3282127 | U26: =-349090-452112 -> -801202
E27: (%) da Receita Líquida | K27: =-K26/K16 -> 0.088737639 | L27: =-L26/L16 -> 0.085165525 | M27: =-M26/M16 -> 0.10488469 | N27: =-N26/N16 -> 0.1028283 | O27: =-O26/O16 -> 0.098375571 | P27: =-P26/P16 -> 0.089220148 | Q27: =-Q26/Q16 -> 0.091433342 | R27: =-R26/R16 -> 0.10085338 | ... U27: =-U26/U16 -> 0.087591913
E28: Perdas pela Não Recuperabilidade de Ativos | K28: 0 | L28: 0 | M28: 0 | N28: 0 | O28: -9146 | P28: -32527 | Q28: -78667 | R28: -56164 | S28: -127315 | T28: -184393 | U28: -53232
E29: Resultado Operacional Outros | K29: =SUM(K30:K31) -> -33186 | L29: =SUM(L30:L31) -> -34256 | M29: =SUM(M30:M31) -> -114402 | N29: =SUM(N30:N31) -> -35543 | O29: =SUM(O30:O31) -> -1058 | P29: =SUM(P30:P31) -> 37715 | Q29: =SUM(Q30:Q31) -> -14217 | R29: =SUM(R30:R31) -> 102799 | ... U29: =SUM(U30:U31) -> -36142
E30: Outras Receitas Operacionais | K30: -33186 | L30: -34256 | M30: -114402 | N30: -35543 | O30: -1058 | P30: 37715 | Q30: -14217 | R30: 102799 | S30: 0 | T30: 182011 | U30: 0
E31: Outras Despesas Operacionais | K31: 0 | L31: 0 | M31: 0 | N31: 0 | O31: 0 | P31: 0 | Q31: 0 | R31: 0 | S31: -67941 | U31: -36142
E32: Resultado de Equivalência Patrimonial | K32: 94 | L32: 71 | M32: 0 | N32: 0 | O32: -960 | P32: -1201 | Q32: -515 | R32: -1534 | S32: 2810 | T32: 5327 | U32: -1047
E33: EBITDA | K33: =K35+K56+'Projeções - CG + Capex'!K57 -> 868967 | L33: =L35+L56+'Projeções - CG + Capex'!L57 -> 1092081 | M33: =M35+M56+'Projeções - CG + Capex'!M57 -> 1045970 | N33: =N35+N56+'Projeções - CG + Capex'!N57 -> 1230201 | O33: =O35+O56+'Projeções - CG + Capex'!O57 -> 1597534 | P33: =P35+P56+'Projeções - CG + Capex'!P57 -> 2115909 | Q33: =Q35+Q56+'Projeções - CG + Capex'!Q57 -> 2141935 | R33: =R35+R56+'Projeções - CG + Capex'!R57 -> 4189665 | ... U33: =U35+U56+'Projeções - CG + Capex'!U57 -> 2391544 | W33: ='DRE Consolidado'!W76 -> 10673112 | X33: ='DRE Consolidado'!X76 -> 12207507 | Y33: ='DRE Consolidado'!Y76 -> 13530227 | Z33: ='DRE Consolidado'!Z76 -> 14681135 | AA33: ='DRE Consolidado'!AA76 -> 15843161
E34: Margem EBITDA | K34: =K33/K16 -> 0.15687607 | L34: =L33/L16 -> 0.18232004 | M34: =M33/M16 -> 0.16034821 | N34: =N33/N16 -> 0.16954717 | O34: =O33/O16 -> 0.1978275 | P34: =P33/P16 -> 0.21844552 | Q34: =Q33/Q16 -> 0.21840752 | R34: =R33/R16 -> 0.30214906 | ... U34: =U33/U16 -> 0.26145705 | V34: =U34 -> 0.26145705
E35: EBIT | K35: =K21+K23 -> 460102 | L35: =L21+L23 -> 583455 | M35: =M21+M23 -> 498783 | N35: =N21+N23 -> 704470 | O35: =O21+O23 -> 960717 | P35: =P21+P23 -> 1199165 | Q35: =Q21+Q23 -> 1029982 | R35: =R21+R23 -> 3130551 | ... U35: =U21+U23 -> 1577963 | V35: =V16*V38 -> 4983198.7
E36: Eventos não Recorrentes | K36: ='DRE - Contas Abertas'!F56 -> -24516 | L36: ='DRE - Contas Abertas'!I56 -> 34204 | M36: ='DRE - Contas Abertas'!J56 -> 30444 | N36: ='DRE - Contas Abertas'!I56 -> 34204 | O36: ='DRE - Contas Abertas'!J56 -> 30444 | P36: ='DRE - Contas Abertas'!K56 -> -929 | Q36: ='DRE - Contas Abertas'!L56 -> -141683 | R36: ='DRE - Contas Abertas'!M56 -> 107566 | S36: ='DRE - Contas Abertas'!N56 -> 12526 | T36: ='DRE - Contas Abertas'!O56 -> -16503 | U36: ='DRE - Contas Abertas'!P56 -> -6956
E37: EBIT Recorrente | K37: =SUM(K35-K36) -> 484618 | L37: =SUM(L35-L36) -> 549251 | M37: =SUM(M35-M36) -> 468339 | N37: =SUM(N35-N36) -> 670266 | O37: =SUM(O35-O36) -> 930273 | P37: =SUM(P35-P36) -> 1200094 | Q37: =SUM(Q35-Q36) -> 1171665 | R37: =SUM(R35-R36) -> 3022985 | ... U37: =SUM(U35-U36) -> 1584919 | V37: =V35 -> 4983198.7
E38: Margem EBIT | K38: =K37/K16 -> 0.087488902 | L38: =L37/L16 -> 0.091696005 | M38: =M37/M16 -> 0.071796822 | N38: =N37/N16 -> 0.092376531 | O38: =O37/O16 -> 0.11519854 | P38: =P37/P16 -> 0.12389718 | Q38: =Q37/Q16 -> 0.11947162 | R38: =R37/R16 -> 0.21801076 | ... U38: =U37/U16 -> 0.17327227 | V38: =U38 -> 0.17327227
E39: Resultado Financeiro | K39: =SUM(K40:K41) -> -348965 | L39: =SUM(L40:L41) -> -516233 | M39: =SUM(M40:M41) -> -748253 | N39: =SUM(N40:N41) -> -670541 | O39: =SUM(O40:O41) -> -681219 | P39: =SUM(P40:P41) -> -768039 | Q39: =SUM(Q40:Q41) -> -374776 | R39: =SUM(R40:R41) -> -1217593 | ... U39: =SUM(U40:U41) -> -1476938
E40: Receitas Financeiras | K40: 109484 | L40: 198480 | M40: 201723 | N40: 209555 | O40: 317809 | P40: 365336 | Q40: 679426 | R40: 736362 | S40: 1229042 | T40: 1137502 | U40: 356775
E41: Despesas Financeiras | K41: -458449 | L41: -714713 | M41: -949976 | N41: -880096 | O41: -999028 | P41: -1133375 | Q41: -1054202 | R41: -1953955 | S41: -5358473 | T41: -7031228 | U41: -1833713
E42: Resultado Antes dos Tributos Sobre o Lucro | K42: =K35+K39 -> 111137 | L42: =L35+L39 -> 67222 | M42: =M35+M39 -> -249470 | N42: =N35+N39 -> 33929 | O42: =O35+O39 -> 279498 | P42: =P35+P39 -> 431126 | Q42: =Q35+Q39 -> 655206 | R42: =R35+R39 -> 1912958 | ... U42: =U35+U39 -> 101025
E43: Imposto de Renda e CSLL | K43: =K44+K45 -> -38697 | L43: =L44+L45 -> -20461 | M43: =M44+M45 -> 66296 | N43: =N44+N45 -> -17211 | O43: =O44+O45 -> -90328 | P43: =P44+P45 -> -112501 | Q43: =Q44+Q45 -> -229167 | R43: =R44+R45 -> -584008 | ... U43: =U44+U45 -> -10923
E44: Corrente | K44: -19885 | L44: -13925 | M44: -21844 | N44: -30178 | O44: -72495 | P44: -68869 | Q44: -177605 | R44: -126774 | S44: -117262 | T44: -85675 | U44: -70729
E45: Diferido | K45: -18812 | L45: -6536 | M45: 88140 | N45: 12967 | O45: -17833 | P45: -43632 | Q45: -51562 | R45: -457234 | S45: 70584 | T45: 462880 | U45: 59806
...

Sheet DRE + DCF
K2: =Dashboard!H3 -> SIMPAR (SIMH3)
A7: Páginas
A8: Dashboard
A9: WACC
A10: DRE Consolidado
A11: DRE + DCF
A12: DRE - Contas Abertas | K12: 2014 | L12: 2015 | M12: 2016 | N12: 2017 | O12: 2018 | P12: 2019 | Q12: 2020 | R12: 2021 | S12: 2022 | T12: 2023 | U12: YTD 2024 | V12: YTG 2024E | W12: 2024 | X12: =W12+1 -> 2025 | Y12: =X12+1 -> 2026 | Z12: =Y12+1 -> 2027 | AA12: =Z12+1 -> 2028
A13: Balanço Patrimonial | E13: Receita Líquida Ex empresas de capital aberto | O13: =SUM('Projeções - Receita e EBIT'!J16:J22) -> 1415123 | P13: =SUM('Projeções - Receita e EBIT'!K16:K22) -> 1536679 | Q13: =SUM('Projeções - Receita e EBIT'!L16:L22) -> 1381814 | R13: =SUM('Projeções - Receita e EBIT'!M16:M22) -> 1414123 | S13: =SUM('Projeções - Receita e EBIT'!N16:N22) -> 3845902 | T13: =SUM('Projeções - Receita e EBIT'!O16:O22) -> 7841471 | U13: =SUM('Projeções - Receita e EBIT'!P16:P22) -> 2328887 | V13: =W13-U13 -> 7248647.8 | W13: =SUM('Projeções - Receita e EBIT'!R16:R22) -> 9577534.8 | X13: =SUM('Projeções - Receita e EBIT'!S16:S22) -> 10339893 | Y13: =SUM('Projeções - Receita e EBIT'!T16:T22) -> 10898010 | Z13: =SUM('Projeções - Receita e EBIT'!U16:U22) -> 11565348 | AA13: =SUM('Projeções - Receita e EBIT'!V16:V22) -> 12301821
E14: EBITDA Excluindo Empresas de Capital Aberto | O14: =O15+O24+O32 -> 278146 | P14: =P15+P24+P32 -> 339526 | Q14: =Q15+Q24+Q32 -> 354594 | R14: =R15+R24+R32 -> 298861 | S14: =S15+S24+S32 -> 590052 | T14: =T15+T24+T32 -> 477484.88 | U14: =U15+U24+U32 -> 99646 | V14: =V15+V24+V32 -> 1463550.7 | ... AA14: =AA15+AA24+AA32 -> 2187898.9
A15: Painel de Índices | E15: EBIT Recorrente Excluindo Empresas de Capital Aberto | O15: =SUM('Projeções - Receita e EBIT'!J37+'Projeções - Receita e EBIT'!J56+'Projeções - Receita e EBIT'!J75+'Projeções - Receita e EBIT'!J98+'Projeções - Receita e EBIT'!J133+'Projeções - Receita e EBIT'!J151) -> 127598 | P15: =SUM('Projeções - Receita e EBIT'!K37+'Projeções - Receita e EBIT'!K56+'Projeções - Receita e EBIT'!K75+'Projeções - Receita e EBIT'!K98+'Projeções - Receita e EBIT'!K133+'Projeções - Receita e EBIT'!K151) -> 164843 | Q15: =SUM('Projeções - Receita e EBIT'!L37+'Projeções - Receita e EBIT'!L56+'Projeções - Receita e EBIT'!L75+'Projeções - Receita e EBIT'!L98+'Projeções - Receita e EBIT'!L133+'Projeções - Receita e EBIT'!L151) -> 160737 | R15: =SUM('Projeções - Receita e EBIT'!M37+'Projeções - Receita e EBIT'!M56+'Projeções - Receita e EBIT'!M75+'Projeções - Receita e EBIT'!M98+'Projeções - Receita e EBIT'!M133+'Projeções - Receita e EBIT'!M151) -> 186246 | S15: =SUM('Projeções - Receita e EBIT'!N37+'Projeções - Receita e EBIT'!N56+'Projeções - Receita e EBIT'!N75+'Projeções - Receita e EBIT'!N98+'Projeções - Receita e EBIT'!N133+'Projeções - Receita e EBIT'!N151) -> 320049 | T15: =SUM('Projeções - Receita e EBIT'!O37+'Projeções - Receita e EBIT'!O56+'Projeções - Receita e EBIT'!O75+'Projeções - Receita e EBIT'!O98+'Projeções - Receita e EBIT'!O133+'Projeções - Receita e EBIT'!O151) -> 237755.88 | U15: =SUM('Projeções - Receita e EBIT'!P37+'Projeções - Receita e EBIT'!P56+'Projeções - Receita e EBIT'!P75+'Projeções - Receita e EBIT'!P98+'Projeções - Receita e EBIT'!P133+'Projeções - Receita e EBIT'!P151) -> 64614 | V15: =W15-U15 -> 515623.67 | W15: =SUM('Projeções - Receita e EBIT'!R37,'Projeções - Receita e EBIT'!R56,'Projeções - Receita e EBIT'!R75,'Projeções - Receita e EBIT'!R98) -> 580237.67 | X15: =SUM('Projeções - Receita e EBIT'!S37,'Projeções - Receita e EBIT'!S56,'Projeções - Receita e EBIT'!S75,'Projeções - Receita e EBIT'!S98) -> 746967.05 | Y15: =SUM('Projeções - Receita e EBIT'!T37,'Projeções - Receita e EBIT'!T56,'Projeções - Receita e EBIT'!T75,'Projeções - Receita e EBIT'!T98) -> 800701 | Z15: =SUM('Projeções - Receita e EBIT'!U37,'Projeções - Receita e EBIT'!U56,'Projeções - Receita e EBIT'!U75,'Projeções - Receita e EBIT'!U98) -> 860120.97 | AA15: =SUM('Projeções - Receita e EBIT'!V37,'Projeções - Receita e EBIT'!V56,'Projeções - Receita e EBIT'!V75,'Projeções - Receita e EBIT'!V98) -> 925341.58
A16: Projeções - Receita e EBIT | E16: Margem EBIT Excluindo Empresas de Capital Aberto | O16: =O15/O13 -> 0.090167427 | P16: =P15/P13 -> 0.10727224 | Q16: =Q15/Q13 -> 0.11632318 | R16: =R15/R13 -> 0.13170424 | S16: =S15/S13 -> 0.083218189 | T16: =T15/T13 -> 0.030320317 | U16: =U15/U13 -> 0.027744584 | W16: =W15/W13 -> 0.060583197 | X16: =X15/X13 -> 0.072241273 | Y16: =Y15/Y13 -> 0.073472221 | Z16: =Z15/Z13 -> 0.074370522 | AA16: =AA15/AA13 -> 0.075219888
A17: Projeções - CG + Capex | E17: Imposto de Renda e CSLL Ex empresas de capital aberto | M17: ='DRE Consolidado'!M43-SUM('DRE - Contas Abertas'!H145:H147) -> 125739 | N17: ='DRE Consolidado'!N43-SUM('DRE - Contas Abertas'!I145:I147) -> -9835 | O17: ='DRE Consolidado'!O43-SUM('DRE - Contas Abertas'!J145:J147) -> -8702 | P17: ='DRE Consolidado'!P43-SUM('DRE - Contas Abertas'!K145:K147) -> -14799 | Q17: ='DRE Consolidado'!Q43-SUM('DRE - Contas Abertas'!L145:L147) -> -151261 | R17: ='DRE Consolidado'!R43-SUM('DRE - Contas Abertas'!M145:M147) -> 5761 | S17: ='DRE Consolidado'!S43-SUM('DRE - Contas Abertas'!N145:N147) -> 196898 | T17: ='DRE Consolidado'!T43-SUM('DRE - Contas Abertas'!O145:O147) -> 139608 | U17: 0 | V17: =W17-U17 -> -197280.81 | W17: =-W23*W15 -> -197280.81 | X17: =-X23*X15 -> -253968.8 | Y17: =-Y23*Y15 -> -272238.34 | Z17: =-Z23*Z15 -> -292441.13 | AA17: =-AA23*AA15 -> -314616.14
A18: Projeções 2023
A19: Processos
A20: Gráficos
K22: 2014 | L22: 2015 | M22: 2016 | N22: 2017 | O22: 2018 | P22: 2019 | Q22: 2020 | R22: 2021 | S22: 2022 | T22: 2023 | U22: YTD 2024 | V22: YTG 2024E | W22: 2024 | X22: =W22+1 -> 2025 | Y22: =X22+1 -> 2026 | Z22: =Y22+1 -> 2027 | AA22: =Z22+1 -> 2028 | AB22: Perpetuidade | AC22: ROIC Perp. | AD22: Growth
