Workbook

Sheet Dashboard
H3: SIMPAR (SIMH3)
A7: Páginas
A8: Dashboard
A9: WACC | E9: Ticker | F9: SIMH3 | G9: WACC | H9: =H10-0.5% -> 0.14112663 | I9: =(((NPV($H9,'DRE + DCF'!$U$36,'DRE + DCF'!$W$36:$Z$36)*((1+$H9)^((12-3)/12))+('DRE + DCF'!$AA$36*(1+I$18)/(($H9-I$18)*(1+$H9)^(COUNT('DRE + DCF'!$V$22:$Z$22)-((12-3)/12)))))+SUM($F$12:$F$17)))/$F$10-(((NPV($H9,'DRE + DCF'!$U$36,'DRE + DCF'!$W$36:$Z$36)*((1+$H9)^((12-3)/12))+('DRE + DCF'!$AA$36*(1+I$18)/(($H9-I$18)*(1+$H9)^(COUNT('DRE + DCF'!$V$22:$Z$22)-((12-3)/12)))))*$F$40+$F$42)*(1-$F$39))/$F$10 -> 13.507825 | J9: =(((NPV($H9,'DRE + DCF'!$U$36,'DRE + DCF'!$W$36:$Z$36)*((1+$H9)^((12-3)/12))+('DRE + DCF'!$AA$36*(1+J$18)/(($H9-J$18)*(1+$H9)^(COUNT('DRE + DCF'!$V$22:$Z$22)-((12-3)/12)))))+SUM($F$12:$F$17)))/$F$10-(((NPV($H9,'DRE + DCF'!$U$36,'DRE + DCF'!$W$36:$Z$36)*((1+$H9)^((12-3)/12))+('DRE + DCF'!$AA$36*(1+J$18)/(($H9-J$18)*(1+$H9)^(COUNT('DRE + DCF'!$V$22:$Z$22)-((12-3)/12)))))*$F$40+$F$42)*(1-$F$39))/$F$10 -> 13.783559 | K9: =(((NPV($H9,'DRE + DCF'!$U$36,'DRE + DCF'!$W$36:$Z$36)*((1+$H9)^((12-3)/12))+('DRE + DCF'!$AA$36*(1+K$18)/(($H9-K$18)*(1+$H9)^(COUNT('DRE + DCF'!$V$22:$Z$22)-((12-3)/12)))))+SUM($F$12:$F$17)))/$F$10-(((NPV($H9,'DRE + DCF'!$U$36,'DRE + DCF'!$W$36:$Z$36)*((1+$H9)^((12-3)/12))+('DRE + DCF'!$AA$36*(1+K$18)/(($H9-K$18)*(1+$H9)^(COUNT('DRE + DCF'!$V$22:$Z$22)-((12-3)/12)))))*$F$40+$F$42)*(1-$F$39))/$F$10 -> 14.079224 | L9: =(((NPV($H9,'DRE + DCF'!$U$36,'DRE + DCF'!$W$36:$Z$36)*((1+$H9)^((12-3)/12))+('DRE + DCF'!$AA$36*(1+L$18)/(($H9-L$18)*(1+$H9)^(COUNT('DRE + DCF'!$V$22:$Z$22)-((12-3)/12)))))+SUM($F$12:$F$17)))/$F$10-(((NPV($H9,'DRE + DCF'!$U$36,'DRE + DCF'!$W$36:$Z$36)*((1+$H9)^((12-3)/12))+('DRE + DCF'!$AA$36*(1+L$18)/(($H9-L$18)*(1+$H9)^(COUNT('DRE + DCF'!$V$22:$Z$22)-((12-3)/12)))))*$F$40+$F$42)*(1-$F$39))/$F$10 -> 14.397063 | M9: =(((NPV($H9,'DRE + DCF'!$U$36,'DRE + DCF'!$W$36:$Z$36)*((1+$H9)^((12-3)/12))+('DRE + DCF'!$AA$36*(1+M$18)/(($H9-M$18)*(1+$H9)^(COUNT('DRE + DCF'!$V$22:$Z$22)-((12-3)/12)))))+SUM($F$12:$F$17)))/$F$10-(((NPV($H9,'DRE + DCF'!$U$36,'DRE + DCF'!$W$36:$Z$36)*((1+$H9)^((12-3)/12))+('DRE + DCF'!$AA$36*(1+M$18)/(($H9-M$18)*(1+$H9)^(COUNT('DRE + DCF'!$V$22:$Z$22)-((12-3)/12)))))*$F$40+$F$42)*(1-$F$39))/$F$10 -> 14.739668 | N9: =(((NPV($H9,'DRE + DCF'!$U$36,'DRE + DCF'!$W$36:$Z$36)*((1+$H9)^((12-3)/12))+('DRE + DCF'!$AA$36*(1+N$18)/(($H9-N$18)*(1+$H9)^(COUNT('DRE + DCF'!$V$22:$Z$22)-((12-3)/12)))))+SUM($F$12:$F$17)))/$F$10-(((NPV($H9,'DRE + DCF'!$U$36,'DRE + DCF'!$W$36:$Z$36)*((1+$H9)^((12-3)/12))+('DRE + DCF'!$AA$36*(1+N$18)/(($H9-N$18)*(1+$H9)^(COUNT('DRE + DCF'!$V$22:$Z$22)-((12-3)/12)))))*$F$40+$F$42)*(1-$F$39))/$F$10 -> 15.110049 | O9: =(((NPV($H9,'DRE + DCF'!$U$36,'DRE + DCF'!$W$36:$Z$36)*((1+$H9)^((12-3)/12))+('DRE + DCF'!$AA$36*(1+O$18)/(($H9-O$18)*(1+$H9)^(COUNT('DRE + DCF'!$V$22:$Z$22)-((12-3)/12)))))+SUM($F$12:$F$17)))/$F$10-(((NPV($H9,'DRE + DCF'!$U$36,'DRE + DCF'!$W$36:$Z$36)*((1+$H9)^((12-3)/12))+('DRE + DCF'!$AA$36*(1+O$18)/(($H9-O$18)*(1+$H9)^(COUNT('DRE + DCF'!$V$22:$Z$22)-((12-3)/12)))))*$F$40+$F$42)*(1-$F$39))/$F$10 -> 15.51173 | P9: =(((NPV($H9,'DRE + DCF'!$U$36,'DRE + DCF'!$W$36:$Z$36)*((1+$H9)^((12-3)/12))+('DRE + DCF'!$AA$36*(1+P$18)/(($H9-P$18)*(1+$H9)^(COUNT('DRE + DCF'!$V$22:$Z$22)-((12-3)/12)))))+SUM($F$12:$F$17)))/$F$10-(((NPV($H9,'DRE + DCF'!$U$36,'DRE + DCF'!$W$36:$Z$36)*((1+$H9)^((12-3)/12))+('DRE + DCF'!$AA$36*(1+P$18)/(($H9-P$18)*(1+$H9)^(COUNT('DRE + DCF'!$V$22:$Z$22)-((12-3)/12)))))*$F$40+$F$42)*(1-$F$39))/$F$10 -> 15.94885 | ... R9: =(((NPV($H9,'DRE + DCF'!$U$36,'DRE + DCF'!$W$36:$Z$36)*((1+$H9)^((12-3)/12))+('DRE + DCF'!$AA$36*(1+R$18)/(($H9-R$18)*(1+$H9)^(COUNT('DRE + DCF'!$V$22:$Z$22)-((12-3)/12)))))+SUM($F$12:$F$17)))/$F$10-(((NPV($H9,'DRE + DCF'!$U$36,'DRE + DCF'!$W$36:$Z$36)*((1+$H9)^((12-3)/12))+('DRE + DCF'!$AA$36*(1+R$18)/(($H9-R$18)*(1+$H9)^(COUNT('DRE + DCF'!$V$22:$Z$22)-((12-3)/12)))))*$F$40+$F$42)*(1-$F$39))/$F$10 -> 16.949989
A10: DRE Consolidado | E10: Ações Emitidas (mil) | F10: 838407.91 | H10: =H11-0.5% -> 0.14612663 | I10: =(((NPV($H10,'DRE + DCF'!$U$36,'DRE + DCF'!$W$36:$Z$36)*((1+$H10)^((12-3)/12))+('DRE + DCF'!$AA$36*(1+I$18)/(($H10-I$18)*(1+$H10)^(COUNT('DRE + DCF'!$V$22:$Z$22)-((12-3)/12)))))+SUM($F$12:$F$17)))/$F$10-(((NPV($H10,'DRE + DCF'!$U$36,'DRE + DCF'!$W$36:$Z$36)*((1+$H10)^((12-3)/12))+('DRE + DCF'!$AA$36*(1+I$18)/(($H10-I$18)*(1+$H10)^(COUNT('DRE + DCF'!$V$22:$Z$22)-((12-3)/12)))))*$F$40+$F$42)*(1-$F$39))/$F$10 -> 12.877401 | J10: =(((NPV($H10,'DRE + DCF'!$U$36,'DRE + DCF'!$W$36:$Z$36)*((1+$H10)^((12-3)/12))+('DRE + DCF'!$AA$36*(1+J$18)/(($H10-J$18)*(1+$H10)^(COUNT('DRE + DCF'!$V$22:$Z$22)-((12-3)/12)))))+SUM($F$12:$F$17)))/$F$10-(((NPV($H10,'DRE + DCF'!$U$36,'DRE + DCF'!$W$36:$Z$36)*((1+$H10)^((12-3)/12))+('DRE + DCF'!$AA$36*(1+J$18)/(($H10-J$18)*(1+$H10)^(COUNT('DRE + DCF'!$V$22:$Z$22)-((12-3)/12)))))*$F$40+$F$42)*(1-$F$39))/$F$10 -> 13.115468 | K10: =(((NPV($H10,'DRE + DCF'!$U$36,'DRE + DCF'!$W$36:$Z$36)*((1+$H10)^((12-3)/12))+('DRE + DCF'!$AA$36*(1+K$18)/(($H10-K$18)*(1+$H10)^(COUNT('DRE + DCF'!$V$22:$Z$22)-((12-3)/12)))))+SUM($F$12:$F$17)))/$F$10-(((NPV($H10,'DRE + DCF'!$U$36,'DRE + DCF'!$W$36:$Z$36)*((1+$H10)^((12-3)/12))+('DRE + DCF'!$AA$36*(1+K$18)/(($H10-K$18)*(1+$H10)^(COUNT('DRE + DCF'!$V$22:$Z$22)-((12-3)/12)))))*$F$40+$F$42)*(1-$F$39))/$F$10 -> 13.369583 | L10: =(((NPV($H10,'DRE + DCF'!$U$36,'DRE + DCF'!$W$36:$Z$36)*((1+$H10)^((12-3)/12))+('DRE + DCF'!$AA$36*(1+L$18)/(($H10-L$18)*(1+$H10)^(COUNT('DRE + DCF'!$V$22:$Z$22)-((12-3)/12)))))+SUM($F$12:$F$17)))/$F$10-(((NPV($H10,'DRE + DCF'!$U$36,'DRE + DCF'!$W$36:$Z$36)*((1+$H10)^((12-3)/12))+('DRE + DCF'!$AA$36*(1+L$18)/(($H10-L$18)*(1+$H10)^(COUNT('DRE + DCF'!$V$22:$Z$22)-((12-3)/12)))))*$F$40+$F$42)*(1-$F$39))/$F$10 -> 13.641426 | M10: =(((NPV($H10,'DRE + DCF'!$U$36,'DRE + DCF'!$W$36:$Z$36)*((1+$H10)^((12-3)/12))+('DRE + DCF'!$AA$36*(1+M$18)/(($H10-M$18)*(1+$H10)^(COUNT('DRE + DCF'!$V$22:$Z$22)-((12-3)/12)))))+SUM($F$12:$F$17)))/$F$10-(((NPV($H10,'DRE + DCF'!$U$36,'DRE + DCF'!$W$36:$Z$36)*((1+$H10)^((12-3)/12))+('DRE + DCF'!$AA$36*(1+M$18)/(($H10-M$18)*(1+$H10)^(COUNT('DRE + DCF'!$V$22:$Z$22)-((12-3)/12)))))*$F$40+$F$42)*(1-$F$39))/$F$10 -> 13.93292 | N10: =(((NPV($H10,'DRE + DCF'!$U$36,'DRE + DCF'!$W$36:$Z$36)*((1+$H10)^((12-3)/12))+('DRE + DCF'!$AA$36*(1+N$18)/(($H10-N$18)*(1+$H10)^(COUNT('DRE + DCF'!$V$22:$Z$22)-((12-3)/12)))))+SUM($F$12:$F$17)))/$F$10-(((NPV($H10,'DRE + DCF'!$U$36,'DRE + DCF'!$W$36:$Z$36)*((1+$H10)^((12-3)/12))+('DRE + DCF'!$AA$36*(1+N$18)/(($H10-N$18)*(1+$H10)^(COUNT('DRE + DCF'!$V$22:$Z$22)-((12-3)/12)))))*$F$40+$F$42)*(1-$F$39))/$F$10 -> 14.246275 | O10: =(((NPV($H10,'DRE + DCF'!$U$36,'DRE + DCF'!$W$36:$Z$36)*((1+$H10)^((12-3)/12))+('DRE + DCF'!$AA$36*(1+O$18)/(($H10-O$18)*(1+$H10)^(COUNT('DRE + DCF'!$V$22:$Z$22)-((12-3)/12)))))+SUM($F$12:$F$17)))/$F$10-(((NPV($H10,'DRE + DCF'!$U$36,'DRE + DCF'!$W$36:$Z$36)*((1+$H10)^((12-3)/12))+('DRE + DCF'!$AA$36*(1+O$18)/(($H10-O$18)*(1+$H10)^(COUNT('DRE + DCF'!$V$22:$Z$22)-((12-3)/12)))))*$F$40+$F$42)*(1-$F$39))/$F$10 -> 14.584046 | P10: =(((NPV($H10,'DRE + DCF'!$U$36,'DRE + DCF'!$W$36:$Z$36)*((1+$H10)^((12-3)/12))+('DRE + DCF'!$AA$36*(1+P$18)/(($H10-P$18)*(1+$H10)^(COUNT('DRE + DCF'!$V$22:$Z$22)-((12-3)/12)))))+SUM($F$12:$F$17)))/$F$10-(((NPV($H10,'DRE + DCF'!$U$36,'DRE + DCF'!$W$36:$Z$36)*((1+$H10)^((12-3)/12))+('DRE + DCF'!$AA$36*(1+P$18)/(($H10-P$18)*(1+$H10)^(COUNT('DRE + DCF'!$V$22:$Z$22)-((12-3)/12)))))*$F$40+$F$42)*(1-$F$39))/$F$10 -> 14.949202 | ... R10: =(((NPV($H10,'DRE + DCF'!$U$36,'DRE + DCF'!$W$36:$Z$36)*((1+$H10)^((12-3)/12))+('DRE + DCF'!$AA$36*(1+R$18)/(($H10-R$18)*(1+$H10)^(COUNT('DRE + DCF'!$V$22:$Z$22)-((12-3)/12)))))+SUM($F$12:$F$17)))/$F$10-(((NPV($H10,'DRE + DCF'!$U$36,'DRE + DCF'!$W$36:$Z$36)*((1+$H10)^((12-3)/12))+('DRE + DCF'!$AA$36*(1+R$18)/(($H10-R$18)*(1+$H10)^(COUNT('DRE + DCF'!$V$22:$Z$22)-((12-3)/12)))))*$F$40+$F$42)*(1-$F$39))/$F$10 -> 15.776168
A11: DRE + DCF | E11: Valor da Empresa (mil) | F11: =SUM('DRE + DCF'!U38:AA38) -> 8157123.4 | H11: =H12-0.5% -> 0.15112663 | I11: =(((NPV($H11,'DRE + DCF'!$U$36,'DRE + DCF'!$W$36:$Z$36)*((1+$H11)^((12-3)/12))+('DRE + DCF'!$AA$36*(1+I$18)/(($H11-I$18)*(1+$H11)^(COUNT('DRE + DCF'!$V$22:$Z$22)-((12-3)/12)))))+SUM($F$12:$F$17)))/$F$10-(((NPV($H11,'DRE + DCF'!$U$36,'DRE + DCF'!$W$36:$Z$36)*((1+$H11)^((12-3)/12))+('DRE + DCF'!$AA$36*(1+I$18)/(($H11-I$18)*(1+$H11)^(COUNT('DRE + DCF'!$V$22:$Z$22)-((12-3)/12)))))*$F$40+$F$42)*(1-$F$39))/$F$10 -> 12.320962 | J11: =(((NPV($H11,'DRE + DCF'!$U$36,'DRE + DCF'!$W$36:$Z$36)*((1+$H11)^((12-3)/12))+('DRE + DCF'!$AA$36*(1+J$18)/(($H11-J$18)*(1+$H11)^(COUNT('DRE + DCF'!$V$22:$Z$22)-((12-3)/12)))))+SUM($F$12:$F$17)))/$F$10-(((NPV($H11,'DRE + DCF'!$U$36,'DRE + DCF'!$W$36:$Z$36)*((1+$H11)^((12-3)/12))+('DRE + DCF'!$AA$36*(1+J$18)/(($H11-J$18)*(1+$H11)^(COUNT('DRE + DCF'!$V$22:$Z$22)-((12-3)/12)))))*$F$40+$F$42)*(1-$F$39))/$F$10 -> 12.528224 | K11: =(((NPV($H11,'DRE + DCF'!$U$36,'DRE + DCF'!$W$36:$Z$36)*((1+$H11)^((12-3)/12))+('DRE + DCF'!$AA$36*(1+K$18)/(($H11-K$18)*(1+$H11)^(COUNT('DRE + DCF'!$V$22:$Z$22)-((12-3)/12)))))+SUM($F$12:$F$17)))/$F$10-(((NPV($H11,'DRE + DCF'!$U$36,'DRE + DCF'!$W$36:$Z$36)*((1+$H11)^((12-3)/12))+('DRE + DCF'!$AA$36*(1+K$18)/(($H11-K$18)*(1+$H11)^(COUNT('DRE + DCF'!$V$22:$Z$22)-((12-3)/12)))))*$F$40+$F$42)*(1-$F$39))/$F$10 -> 12.748576 | L11: =(((NPV($H11,'DRE + DCF'!$U$36,'DRE + DCF'!$W$36:$Z$36)*((1+$H11)^((12-3)/12))+('DRE + DCF'!$AA$36*(1+L$18)/(($H11-L$18)*(1+$H11)^(COUNT('DRE + DCF'!$V$22:$Z$22)-((12-3)/12)))))+SUM($F$12:$F$17)))/$F$10-(((NPV($H11,'DRE + DCF'!$U$36,'DRE + DCF'!$W$36:$Z$36)*((1+$H11)^((12-3)/12))+('DRE + DCF'!$AA$36*(1+L$18)/(($H11-L$18)*(1+$H11)^(COUNT('DRE + DCF'!$V$22:$Z$22)-((12-3)/12)))))*$F$40+$F$42)*(1-$F$39))/$F$10 -> 12.983298 | M11: =(((NPV($H11,'DRE + DCF'!$U$36,'DRE + DCF'!$W$36:$Z$36)*((1+$H11)^((12-3)/12))+('DRE + DCF'!$AA$36*(1+M$18)/(($H11-M$18)*(1+$H11)^(COUNT('DRE + DCF'!$V$22:$Z$22)-((12-3)/12)))))+SUM($F$12:$F$17)))/$F$10-(((NPV($H11,'DRE + DCF'!$U$36,'DRE + DCF'!$W$36:$Z$36)*((1+$H11)^((12-3)/12))+('DRE + DCF'!$AA$36*(1+M$18)/(($H11-M$18)*(1+$H11)^(COUNT('DRE + DCF'!$V$22:$Z$22)-((12-3)/12)))))*$F$40+$F$42)*(1-$F$39))/$F$10 -> 13.233844 | N11: =(((NPV($H11,'DRE + DCF'!$U$36,'DRE + DCF'!$W$36:$Z$36)*((1+$H11)^((12-3)/12))+('DRE + DCF'!$AA$36*(1+N$18)/(($H11-N$18)*(1+$H11)^(COUNT('DRE + DCF'!$V$22:$Z$22)-((12-3)/12)))))+SUM($F$12:$F$17)))/$F$10-(((NPV($H11,'DRE + DCF'!$U$36,'DRE + DCF'!$W$36:$Z$36)*((1+$H11)^((12-3)/12))+('DRE + DCF'!$AA$36*(1+N$18)/(($H11-N$18)*(1+$H11)^(COUNT('DRE + DCF'!$V$22:$Z$22)-((12-3)/12)))))*$F$40+$F$42)*(1-$F$39))/$F$10 -> 13.501868 | O11: =(((NPV($H11,'DRE + DCF'!$U$36,'DRE + DCF'!$W$36:$Z$36)*((1+$H11)^((12-3)/12))+('DRE + DCF'!$AA$36*(1+O$18)/(($H11-O$18)*(1+$H11)^(COUNT('DRE + DCF'!$V$22:$Z$22)-((12-3)/12)))))+SUM($F$12:$F$17)))/$F$10-(((NPV($H11,'DRE + DCF'!$U$36,'DRE + DCF'!$W$36:$Z$36)*((1+$H11)^((12-3)/12))+('DRE + DCF'!$AA$36*(1+O$18)/(($H11-O$18)*(1+$H11)^(COUNT('DRE + DCF'!$V$22:$Z$22)-((12-3)/12)))))*$F$40+$F$42)*(1-$F$39))/$F$10 -> 13.789267 | P11: =(((NPV($H11,'DRE + DCF'!$U$36,'DRE + DCF'!$W$36:$Z$36)*((1+$H11)^((12-3)/12))+('DRE + DCF'!$AA$36*(1+P$18)/(($H11-P$18)*(1+$H11)^(COUNT('DRE + DCF'!$V$22:$Z$22)-((12-3)/12)))))+SUM($F$12:$F$17)))/$F$10-(((NPV($H11,'DRE + DCF'!$U$36,'DRE + DCF'!$W$36:$Z$36)*((1+$H11)^((12-3)/12))+('DRE + DCF'!$AA$36*(1+P$18)/(($H11-P$18)*(1+$H11)^(COUNT('DRE + DCF'!$V$22:$Z$22)-((12-3)/12)))))*$F$40+$F$42)*(1-$F$39))/$F$10 -> 14.09822 | ... R11: =(((NPV($H11,'DRE + DCF'!$U$36,'DRE + DCF'!$W$36:$Z$36)*((1+$H11)^((12-3)/12))+('DRE + DCF'!$AA$36*(1+R$18)/(($H11-R$18)*(1+$H11)^(COUNT('DRE + DCF'!$V$22:$Z$22)-((12-3)/12)))))+SUM($F$12:$F$17)))/$F$10-(((NPV($H11,'DRE + DCF'!$U$36,'DRE + DCF'!$W$36:$Z$36)*((1+$H11)^((12-3)/12))+('DRE + DCF'!$AA$36*(1+R$18)/(($H11-R$18)*(1+$H11)^(COUNT('DRE + DCF'!$V$22:$Z$22)-((12-3)/12)))))*$F$40+$F$42)*(1-$F$39))/$F$10 -> 14.791273
A12: DRE - Contas Abertas | E12: Dívida (mil) | F12: =-F36 -> -9232802 | H12: =H13-0.5% -> 0.15612663 | I12: =(((NPV($H12,'DRE + DCF'!$U$36,'DRE + DCF'!$W$36:$Z$36)*((1+$H12)^((12-3)/12))+('DRE + DCF'!$AA$36*(1+I$18)/(($H12-I$18)*(1+$H12)^(COUNT('DRE + DCF'!$V$22:$Z$22)-((12-3)/12)))))+SUM($F$12:$F$17)))/$F$10-(((NPV($H12,'DRE + DCF'!$U$36,'DRE + DCF'!$W$36:$Z$36)*((1+$H12)^((12-3)/12))+('DRE + DCF'!$AA$36*(1+I$18)/(($H12-I$18)*(1+$H12)^(COUNT('DRE + DCF'!$V$22:$Z$22)-((12-3)/12)))))*$F$40+$F$42)*(1-$F$39))/$F$10 -> 11.82609 | J12: =(((NPV($H12,'DRE + DCF'!$U$36,'DRE + DCF'!$W$36:$Z$36)*((1+$H12)^((12-3)/12))+('DRE + DCF'!$AA$36*(1+J$18)/(($H12-J$18)*(1+$H12)^(COUNT('DRE + DCF'!$V$22:$Z$22)-((12-3)/12)))))+SUM($F$12:$F$17)))/$F$10-(((NPV($H12,'DRE + DCF'!$U$36,'DRE + DCF'!$W$36:$Z$36)*((1+$H12)^((12-3)/12))+('DRE + DCF'!$AA$36*(1+J$18)/(($H12-J$18)*(1+$H12)^(COUNT('DRE + DCF'!$V$22:$Z$22)-((12-3)/12)))))*$F$40+$F$42)*(1-$F$39))/$F$10 -> 12.007866 | K12: =(((NPV($H12,'DRE + DCF'!$U$36,'DRE + DCF'!$W$36:$Z$36)*((1+$H12)^((12-3)/12))+('DRE + DCF'!$AA$36*(1+K$18)/(($H12-K$18)*(1+$H12)^(COUNT('DRE + DCF'!$V$22:$Z$22)-((12-3)/12)))))+SUM($F$12:$F$17)))/$F$10-(((NPV($H12,'DRE + DCF'!$U$36,'DRE + DCF'!$W$36:$Z$36)*((1+$H12)^((12-3)/12))+('DRE + DCF'!$AA$36*(1+K$18)/(($H12-K$18)*(1+$H12)^(COUNT('DRE + DCF'!$V$22:$Z$22)-((12-3)/12)))))*$F$40+$F$42)*(1-$F$39))/$F$10 -> 12.200439 | L12: =(((NPV($H12,'DRE + DCF'!$U$36,'DRE + DCF'!$W$36:$Z$36)*((1+$H12)^((12-3)/12))+('DRE + DCF'!$AA$36*(1+L$18)/(($H12-L$18)*(1+$H12)^(COUNT('DRE + DCF'!$V$22:$Z$22)-((12-3)/12)))))+SUM($F$12:$F$17)))/$F$10-(((NPV($H12,'DRE + DCF'!$U$36,'DRE + DCF'!$W$36:$Z$36)*((1+$H12)^((12-3)/12))+('DRE + DCF'!$AA$36*(1+L$18)/(($H12-L$18)*(1+$H12)^(COUNT('DRE + DCF'!$V$22:$Z$22)-((12-3)/12)))))*$F$40+$F$42)*(1-$F$39))/$F$10 -> 12.404802 | M12: =(((NPV($H12,'DRE + DCF'!$U$36,'DRE + DCF'!$W$36:$Z$36)*((1+$H12)^((12-3)/12))+('DRE + DCF'!$AA$36*(1+M$18)/(($H12-M$18)*(1+$H12)^(COUNT('DRE + DCF'!$V$22:$Z$22)-((12-3)/12)))))+SUM($F$12:$F$17)))/$F$10-(((NPV($H12,'DRE + DCF'!$U$36,'DRE + DCF'!$W$36:$Z$36)*((1+$H12)^((12-3)/12))+('DRE + DCF'!$AA$36*(1+M$18)/(($H12-M$18)*(1+$H12)^(COUNT('DRE + DCF'!$V$22:$Z$22)-((12-3)/12)))))*$F$40+$F$42)*(1-$F$39))/$F$10 -> 12.622072 | N12: =(((NPV($H12,'DRE + DCF'!$U$36,'DRE + DCF'!$W$36:$Z$36)*((1+$H12)^((12-3)/12))+('DRE + DCF'!$AA$36*(1+N$18)/(($H12-N$18)*(1+$H12)^(COUNT('DRE + DCF'!$V$22:$Z$22)-((12-3)/12)))))+SUM($F$12:$F$17)))/$F$10-(((NPV($H12,'DRE + DCF'!$U$36,'DRE + DCF'!$W$36:$Z$36)*((1+$H12)^((12-3)/12))+('DRE + DCF'!$AA$36*(1+N$18)/(($H12-N$18)*(1+$H12)^(COUNT('DRE + DCF'!$V$22:$Z$22)-((12-3)/12)))))*$F$40+$F$42)*(1-$F$39))/$F$10 -> 12.853511 | O12: =(((NPV($H12,'DRE + DCF'!$U$36,'DRE + DCF'!$W$36:$Z$36)*((1+$H12)^((12-3)/12))+('DRE + DCF'!$AA$36*(1+O$18)/(($H12-O$18)*(1+$H12)^(COUNT('DRE + DCF'!$V$22:$Z$22)-((12-3)/12)))))+SUM($F$12:$F$17)))/$F$10-(((NPV($H12,'DRE + DCF'!$U$36,'DRE + DCF'!$W$36:$Z$36)*((1+$H12)^((12-3)/12))+('DRE + DCF'!$AA$36*(1+O$18)/(($H12-O$18)*(1+$H12)^(COUNT('DRE + DCF'!$V$22:$Z$22)-((12-3)/12)))))*$F$40+$F$42)*(1-$F$39))/$F$10 -> 13.100552 | P12: =(((NPV($H12,'DRE + DCF'!$U$36,'DRE + DCF'!$W$36:$Z$36)*((1+$H12)^((12-3)/12))+('DRE + DCF'!$AA$36*(1+P$18)/(($H12-P$18)*(1+$H12)^(COUNT('DRE + DCF'!$V$22:$Z$22)-((12-3)/12)))))+SUM($F$12:$F$17)))/$F$10-(((NPV($H12,'DRE + DCF'!$U$36,'DRE + DCF'!$W$36:$Z$36)*((1+$H12)^((12-3)/12))+('DRE + DCF'!$AA$36*(1+P$18)/(($H12-P$18)*(1+$H12)^(COUNT('DRE + DCF'!$V$22:$Z$22)-((12-3)/12)))))*$F$40+$F$42)*(1-$F$39))/$F$10 -> 13.364828 | ... R12: =(((NPV($H12,'DRE + DCF'!$U$36,'DRE + DCF'!$W$36:$Z$36)*((1+$H12)^((12-3)/12))+('DRE + DCF'!$AA$36*(1+R$18)/(($H12-R$18)*(1+$H12)^(COUNT('DRE + DCF'!$V$22:$Z$22)-((12-3)/12)))))+SUM($F$12:$F$17)))/$F$10-(((NPV($H12,'DRE + DCF'!$U$36,'DRE + DCF'!$W$36:$Z$36)*((1+$H12)^((12-3)/12))+('DRE + DCF'!$AA$36*(1+R$18)/(($H12-R$18)*(1+$H12)^(COUNT('DRE + DCF'!$V$22:$Z$22)-((12-3)/12)))))*$F$40+$F$42)*(1-$F$39))/$F$10 -> 13.952838
A13: Balanço Patrimonial | E13: Ativos/Passivos Não-Operacionais | F13: =F29 -> 1773707.9 | H13: =WACC!P20 -> 0.16112663 | I13: =(((NPV($H13,'DRE + DCF'!$U$36,'DRE + DCF'!$W$36:$Z$36)*((1+$H13)^((12-3)/12))+('DRE + DCF'!$AA$36*(1+I$18)/(($H13-I$18)*(1+$H13)^(COUNT('DRE + DCF'!$V$22:$Z$22)-((12-3)/12)))))+SUM($F$12:$F$17)))/$F$10-(((NPV($H13,'DRE + DCF'!$U$36,'DRE + DCF'!$W$36:$Z$36)*((1+$H13)^((12-3)/12))+('DRE + DCF'!$AA$36*(1+I$18)/(($H13-I$18)*(1+$H13)^(COUNT('DRE + DCF'!$V$22:$Z$22)-((12-3)/12)))))*$F$40+$F$42)*(1-$F$39))/$F$10 -> 11.383005 | J13: =(((NPV($H13,'DRE + DCF'!$U$36,'DRE + DCF'!$W$36:$Z$36)*((1+$H13)^((12-3)/12))+('DRE + DCF'!$AA$36*(1+J$18)/(($H13-J$18)*(1+$H13)^(COUNT('DRE + DCF'!$V$22:$Z$22)-((12-3)/12)))))+SUM($F$12:$F$17)))/$F$10-(((NPV($H13,'DRE + DCF'!$U$36,'DRE + DCF'!$W$36:$Z$36)*((1+$H13)^((12-3)/12))+('DRE + DCF'!$AA$36*(1+J$18)/(($H13-J$18)*(1+$H13)^(COUNT('DRE + DCF'!$V$22:$Z$22)-((12-3)/12)))))*$F$40+$F$42)*(1-$F$39))/$F$10 -> 11.543474 | K13: =(((NPV($H13,'DRE + DCF'!$U$36,'DRE + DCF'!$W$36:$Z$36)*((1+$H13)^((12-3)/12))+('DRE + DCF'!$AA$36*(1+K$18)/(($H13-K$18)*(1+$H13)^(COUNT('DRE + DCF'!$V$22:$Z$22)-((12-3)/12)))))+SUM($F$12:$F$17)))/$F$10-(((NPV($H13,'DRE + DCF'!$U$36,'DRE + DCF'!$W$36:$Z$36)*((1+$H13)^((12-3)/12))+('DRE + DCF'!$AA$36*(1+K$18)/(($H13-K$18)*(1+$H13)^(COUNT('DRE + DCF'!$V$22:$Z$22)-((12-3)/12)))))*$F$40+$F$42)*(1-$F$39))/$F$10 -> 11.712941 | L13: =(((NPV($H13,'DRE + DCF'!$U$36,'DRE + DCF'!$W$36:$Z$36)*((1+$H13)^((12-3)/12))+('DRE + DCF'!$AA$36*(1+L$18)/(($H13-L$18)*(1+$H13)^(COUNT('DRE + DCF'!$V$22:$Z$22)-((12-3)/12)))))+SUM($F$12:$F$17)))/$F$10-(((NPV($H13,'DRE + DCF'!$U$36,'DRE + DCF'!$W$36:$Z$36)*((1+$H13)^((12-3)/12))+('DRE + DCF'!$AA$36*(1+L$18)/(($H13-L$18)*(1+$H13)^(COUNT('DRE + DCF'!$V$22:$Z$22)-((12-3)/12)))))*$F$40+$F$42)*(1-$F$39))/$F$10 -> 11.892185 | M13: =(((NPV($H13,'DRE + DCF'!$U$36,'DRE + DCF'!$W$36:$Z$36)*((1+$H13)^((12-3)/12))+('DRE + DCF'!$AA$36*(1+M$18)/(($H13-M$18)*(1+$H13)^(COUNT('DRE + DCF'!$V$22:$Z$22)-((12-3)/12)))))+SUM($F$12:$F$17)))/$F$10-(((NPV($H13,'DRE + DCF'!$U$36,'DRE + DCF'!$W$36:$Z$36)*((1+$H13)^((12-3)/12))+('DRE + DCF'!$AA$36*(1+M$18)/(($H13-M$18)*(1+$H13)^(COUNT('DRE + DCF'!$V$22:$Z$22)-((12-3)/12)))))*$F$40+$F$42)*(1-$F$39))/$F$10 -> 12.082076 | N13: =(((NPV($H13,'DRE + DCF'!$U$36,'DRE + DCF'!$W$36:$Z$36)*((1+$H13)^((12-3)/12))+('DRE + DCF'!$AA$36*(1+N$18)/(($H13-N$18)*(1+$H13)^(COUNT('DRE + DCF'!$V$22:$Z$22)-((12-3)/12)))))+SUM($F$12:$F$17)))/$F$10-(((NPV($H13,'DRE + DCF'!$U$36,'DRE + DCF'!$W$36:$Z$36)*((1+$H13)^((12-3)/12))+('DRE + DCF'!$AA$36*(1+N$18)/(($H13-N$18)*(1+$H13)^(COUNT('DRE + DCF'!$V$22:$Z$22)-((12-3)/12)))))*$F$40+$F$42)*(1-$F$39))/$F$10 -> 12.283593 | O13: =(((NPV($H13,'DRE + DCF'!$U$36,'DRE + DCF'!$W$36:$Z$36)*((1+$H13)^((12-3)/12))+('DRE + DCF'!$AA$36*(1+O$18)/(($H13-O$18)*(1+$H13)^(COUNT('DRE + DCF'!$V$22:$Z$22)-((12-3)/12)))))+SUM($F$12:$F$17)))/$F$10-(((NPV($H13,'DRE + DCF'!$U$36,'DRE + DCF'!$W$36:$Z$36)*((1+$H13)^((12-3)/12))+('DRE + DCF'!$AA$36*(1+O$18)/(($H13-O$18)*(1+$H13)^(COUNT('DRE + DCF'!$V$22:$Z$22)-((12-3)/12)))))*$F$40+$F$42)*(1-$F$39))/$F$10 -> 12.497837 | P13: =(((NPV($H13,'DRE + DCF'!$U$36,'DRE + DCF'!$W$36:$Z$36)*((1+$H13)^((12-3)/12))+('DRE + DCF'!$AA$36*(1+P$18)/(($H13-P$18)*(1+$H13)^(COUNT('DRE + DCF'!$V$22:$Z$22)-((12-3)/12)))))+SUM($F$12:$F$17)))/$F$10-(((NPV($H13,'DRE + DCF'!$U$36,'DRE + DCF'!$W$36:$Z$36)*((1+$H13)^((12-3)/12))+('DRE + DCF'!$AA$36*(1+P$18)/(($H13-P$18)*(1+$H13)^(COUNT('DRE + DCF'!$V$22:$Z$22)-((12-3)/12)))))*$F$40+$F$42)*(1-$F$39))/$F$10 -> 12.726052 | ... R13: =(((NPV($H13,'DRE + DCF'!$U$36,'DRE + DCF'!$W$36:$Z$36)*((1+$H13)^((12-3)/12))+('DRE + DCF'!$AA$36*(1+R$18)/(($H13-R$18)*(1+$H13)^(COUNT('DRE + DCF'!$V$22:$Z$22)-((12-3)/12)))))+SUM($F$12:$F$17)))/$F$10-(((NPV($H13,'DRE + DCF'!$U$36,'DRE + DCF'!$W$36:$Z$36)*((1+$H13)^((12-3)/12))+('DRE + DCF'!$AA$36*(1+R$18)/(($H13-R$18)*(1+$H13)^(COUNT('DRE + DCF'!$V$22:$Z$22)-((12-3)/12)))))*$F$40+$F$42)*(1-$F$39))/$F$10 -> 13.230248
A14: Painel de Índices | E14: Empresas de Capital Aberto | F14: =K29 -> 12801997 | H14: =H13+0.5% -> 0.16612663 | I14: =(((NPV($H14,'DRE + DCF'!$U$36,'DRE + DCF'!$W$36:$Z$36)*((1+$H14)^((12-3)/12))+('DRE + DCF'!$AA$36*(1+I$18)/(($H14-I$18)*(1+$H14)^(COUNT('DRE + DCF'!$V$22:$Z$22)-((12-3)/12)))))+SUM($F$12:$F$17)))/$F$10-(((NPV($H14,'DRE + DCF'!$U$36,'DRE + DCF'!$W$36:$Z$36)*((1+$H14)^((12-3)/12))+('DRE + DCF'!$AA$36*(1+I$18)/(($H14-I$18)*(1+$H14)^(COUNT('DRE + DCF'!$V$22:$Z$22)-((12-3)/12)))))*$F$40+$F$42)*(1-$F$39))/$F$10 -> 10.983895 | J14: =(((NPV($H14,'DRE + DCF'!$U$36,'DRE + DCF'!$W$36:$Z$36)*((1+$H14)^((12-3)/12))+('DRE + DCF'!$AA$36*(1+J$18)/(($H14-J$18)*(1+$H14)^(COUNT('DRE + DCF'!$V$22:$Z$22)-((12-3)/12)))))+SUM($F$12:$F$17)))/$F$10-(((NPV($H14,'DRE + DCF'!$U$36,'DRE + DCF'!$W$36:$Z$36)*((1+$H14)^((12-3)/12))+('DRE + DCF'!$AA$36*(1+J$18)/(($H14-J$18)*(1+$H14)^(COUNT('DRE + DCF'!$V$22:$Z$22)-((12-3)/12)))))*$F$40+$F$42)*(1-$F$39))/$F$10 -> 11.126389 | K14: =(((NPV($H14,'DRE + DCF'!$U$36,'DRE + DCF'!$W$36:$Z$36)*((1+$H14)^((12-3)/12))+('DRE + DCF'!$AA$36*(1+K$18)/(($H14-K$18)*(1+$H14)^(COUNT('DRE + DCF'!$V$22:$Z$22)-((12-3)/12)))))+SUM($F$12:$F$17)))/$F$10-(((NPV($H14,'DRE + DCF'!$U$36,'DRE + DCF'!$W$36:$Z$36)*((1+$H14)^((12-3)/12))+('DRE + DCF'!$AA$36*(1+K$18)/(($H14-K$18)*(1+$H14)^(COUNT('DRE + DCF'!$V$22:$Z$22)-((12-3)/12)))))*$F$40+$F$42)*(1-$F$39))/$F$10 -> 11.276448 | L14: =(((NPV($H14,'DRE + DCF'!$U$36,'DRE + DCF'!$W$36:$Z$36)*((1+$H14)^((12-3)/12))+('DRE + DCF'!$AA$36*(1+L$18)/(($H14-L$18)*(1+$H14)^(COUNT('DRE + DCF'!$V$22:$Z$22)-((12-3)/12)))))+SUM($F$12:$F$17)))/$F$10-(((NPV($H14,'DRE + DCF'!$U$36,'DRE + DCF'!$W$36:$Z$36)*((1+$H14)^((12-3)/12))+('DRE + DCF'!$AA$36*(1+L$18)/(($H14-L$18)*(1+$H14)^(COUNT('DRE + DCF'!$V$22:$Z$22)-((12-3)/12)))))*$F$40+$F$42)*(1-$F$39))/$F$10 -> 11.434691 | M14: =(((NPV($H14,'DRE + DCF'!$U$36,'DRE + DCF'!$W$36:$Z$36)*((1+$H14)^((12-3)/12))+('DRE + DCF'!$AA$36*(1+M$18)/(($H14-M$18)*(1+$H14)^(COUNT('DRE + DCF'!$V$22:$Z$22)-((12-3)/12)))))+SUM($F$12:$F$17)))/$F$10-(((NPV($H14,'DRE + DCF'!$U$36,'DRE + DCF'!$W$36:$Z$36)*((1+$H14)^((12-3)/12))+('DRE + DCF'!$AA$36*(1+M$18)/(($H14-M$18)*(1+$H14)^(COUNT('DRE + DCF'!$V$22:$Z$22)-((12-3)/12)))))*$F$40+$F$42)*(1-$F$39))/$F$10 -> 11.601808 | N14: =(((NPV($H14,'DRE + DCF'!$U$36,'DRE + DCF'!$W$36:$Z$36)*((1+$H14)^((12-3)/12))+('DRE + DCF'!$AA$36*(1+N$18)/(($H14-N$18)*(1+$H14)^(COUNT('DRE + DCF'!$V$22:$Z$22)-((12-3)/12)))))+SUM($F$12:$F$17)))/$F$10-(((NPV($H14,'DRE + DCF'!$U$36,'DRE + DCF'!$W$36:$Z$36)*((1+$H14)^((12-3)/12))+('DRE + DCF'!$AA$36*(1+N$18)/(($H14-N$18)*(1+$H14)^(COUNT('DRE + DCF'!$V$22:$Z$22)-((12-3)/12)))))*$F$40+$F$42)*(1-$F$39))/$F$10 -> 11.778566 | O14: =(((NPV($H14,'DRE + DCF'!$U$36,'DRE + DCF'!$W$36:$Z$36)*((1+$H14)^((12-3)/12))+('DRE + DCF'!$AA$36*(1+O$18)/(($H14-O$18)*(1+$H14)^(COUNT('DRE + DCF'!$V$22:$Z$22)-((12-3)/12)))))+SUM($F$12:$F$17)))/$F$10-(((NPV($H14,'DRE + DCF'!$U$36,'DRE + DCF'!$W$36:$Z$36)*((1+$H14)^((12-3)/12))+('DRE + DCF'!$AA$36*(1+O$18)/(($H14-O$18)*(1+$H14)^(COUNT('DRE + DCF'!$V$22:$Z$22)-((12-3)/12)))))*$F$40+$F$42)*(1-$F$39))/$F$10 -> 11.965824 | P14: =(((NPV($H14,'DRE + DCF'!$U$36,'DRE + DCF'!$W$36:$Z$36)*((1+$H14)^((12-3)/12))+('DRE + DCF'!$AA$36*(1+P$18)/(($H14-P$18)*(1+$H14)^(COUNT('DRE + DCF'!$V$22:$Z$22)-((12-3)/12)))))+SUM($F$12:$F$17)))/$F$10-(((NPV($H14,'DRE + DCF'!$U$36,'DRE + DCF'!$W$36:$Z$36)*((1+$H14)^((12-3)/12))+('DRE + DCF'!$AA$36*(1+P$18)/(($H14-P$18)*(1+$H14)^(COUNT('DRE + DCF'!$V$22:$Z$22)-((12-3)/12)))))*$F$40+$F$42)*(1-$F$39))/$F$10 -> 12.164547 | ... R14: =(((NPV($H14,'DRE + DCF'!$U$36,'DRE + DCF'!$W$36:$Z$36)*((1+$H14)^((12-3)/12))+('DRE + DCF'!$AA$36*(1+R$18)/(($H14-R$18)*(1+$H14)^(COUNT('DRE + DCF'!$V$22:$Z$22)-((12-3)/12)))))+SUM($F$12:$F$17)))/$F$10-(((NPV($H14,'DRE + DCF'!$U$36,'DRE + DCF'!$W$36:$Z$36)*((1+$H14)^((12-3)/12))+('DRE + DCF'!$AA$36*(1+R$18)/(($H14-R$18)*(1+$H14)^(COUNT('DRE + DCF'!$V$22:$Z$22)-((12-3)/12)))))*$F$40+$F$42)*(1-$F$39))/$F$10 -> 12.60087
A15: Projeções - Receita e EBIT | E15: Valor do Equity da Automob que não pertence à Simpar | F15: =-F44 -> -1145069.8 | H15: =H14+0.5% -> 0.17112663 | I15: =(((NPV($H15,'DRE + DCF'!$U$36,'DRE + DCF'!$W$36:$Z$36)*((1+$H15)^((12-3)/12))+('DRE + DCF'!$AA$36*(1+I$18)/(($H15-I$18)*(1+$H15)^(COUNT('DRE + DCF'!$V$22:$Z$22)-((12-3)/12)))))+SUM($F$12:$F$17)))/$F$10-(((NPV($H15,'DRE + DCF'!$U$36,'DRE + DCF'!$W$36:$Z$36)*((1+$H15)^((12-3)/12))+('DRE + DCF'!$AA$36*(1+I$18)/(($H15-I$18)*(1+$H15)^(COUNT('DRE + DCF'!$V$22:$Z$22)-((12-3)/12)))))*$F$40+$F$42)*(1-$F$39))/$F$10 -> 10.622452 | J15: =(((NPV($H15,'DRE + DCF'!$U$36,'DRE + DCF'!$W$36:$Z$36)*((1+$H15)^((12-3)/12))+('DRE + DCF'!$AA$36*(1+J$18)/(($H15-J$18)*(1+$H15)^(COUNT('DRE + DCF'!$V$22:$Z$22)-((12-3)/12)))))+SUM($F$12:$F$17)))/$F$10-(((NPV($H15,'DRE + DCF'!$U$36,'DRE + DCF'!$W$36:$Z$36)*((1+$H15)^((12-3)/12))+('DRE + DCF'!$AA$36*(1+J$18)/(($H15-J$18)*(1+$H15)^(COUNT('DRE + DCF'!$V$22:$Z$22)-((12-3)/12)))))*$F$40+$F$42)*(1-$F$39))/$F$10 -> 10.749653 | K15: =(((NPV($H15,'DRE + DCF'!$U$36,'DRE + DCF'!$W$36:$Z$36)*((1+$H15)^((12-3)/12))+('DRE + DCF'!$AA$36*(1+K$18)/(($H15-K$18)*(1+$H15)^(COUNT('DRE + DCF'!$V$22:$Z$22)-((12-3)/12)))))+SUM($F$12:$F$17)))/$F$10-(((NPV($H15,'DRE + DCF'!$U$36,'DRE + DCF'!$W$36:$Z$36)*((1+$H15)^((12-3)/12))+('DRE + DCF'!$AA$36*(1+K$18)/(($H15-K$18)*(1+$H15)^(COUNT('DRE + DCF'!$V$22:$Z$22)-((12-3)/12)))))*$F$40+$F$42)*(1-$F$39))/$F$10 -> 10.883268 | L15: =(((NPV($H15,'DRE + DCF'!$U$36,'DRE + DCF'!$W$36:$Z$36)*((1+$H15)^((12-3)/12))+('DRE + DCF'!$AA$36*(1+L$18)/(($H15-L$18)*(1+$H15)^(COUNT('DRE + DCF'!$V$22:$Z$22)-((12-3)/12)))))+SUM($F$12:$F$17)))/$F$10-(((NPV($H15,'DRE + DCF'!$U$36,'DRE + DCF'!$W$36:$Z$36)*((1+$H15)^((12-3)/12))+('DRE + DCF'!$AA$36*(1+L$18)/(($H15-L$18)*(1+$H15)^(COUNT('DRE + DCF'!$V$22:$Z$22)-((12-3)/12)))))*$F$40+$F$42)*(1-$F$39))/$F$10 -> 11.023794 | M15: =(((NPV($H15,'DRE + DCF'!$U$36,'DRE + DCF'!$W$36:$Z$36)*((1+$H15)^((12-3)/12))+('DRE + DCF'!$AA$36*(1+M$18)/(($H15-M$18)*(1+$H15)^(COUNT('DRE + DCF'!$V$22:$Z$22)-((12-3)/12)))))+SUM($F$12:$F$17)))/$F$10-(((NPV($H15,'DRE + DCF'!$U$36,'DRE + DCF'!$W$36:$Z$36)*((1+$H15)^((12-3)/12))+('DRE + DCF'!$AA$36*(1+M$18)/(($H15-M$18)*(1+$H15)^(COUNT('DRE + DCF'!$V$22:$Z$22)-((12-3)/12)))))*$F$40+$F$42)*(1-$F$39))/$F$10 -> 11.171781 | N15: =(((NPV($H15,'DRE + DCF'!$U$36,'DRE + DCF'!$W$36:$Z$36)*((1+$H15)^((12-3)/12))+('DRE + DCF'!$AA$36*(1+N$18)/(($H15-N$18)*(1+$H15)^(COUNT('DRE + DCF'!$V$22:$Z$22)-((12-3)/12)))))+SUM($F$12:$F$17)))/$F$10-(((NPV($H15,'DRE + DCF'!$U$36,'DRE + DCF'!$W$36:$Z$36)*((1+$H15)^((12-3)/12))+('DRE + DCF'!$AA$36*(1+N$18)/(($H15-N$18)*(1+$H15)^(COUNT('DRE + DCF'!$V$22:$Z$22)-((12-3)/12)))))*$F$40+$F$42)*(1-$F$39))/$F$10 -> 11.327839 | O15: =(((NPV($H15,'DRE + DCF'!$U$36,'DRE + DCF'!$W$36:$Z$36)*((1+$H15)^((12-3)/12))+('DRE + DCF'!$AA$36*(1+O$18)/(($H15-O$18)*(1+$H15)^(COUNT('DRE + DCF'!$V$22:$Z$22)-((12-3)/12)))))+SUM($F$12:$F$17)))/$F$10-(((NPV($H15,'DRE + DCF'!$U$36,'DRE + DCF'!$W$36:$Z$36)*((1+$H15)^((12-3)/12))+('DRE + DCF'!$AA$36*(1+O$18)/(($H15-O$18)*(1+$H15)^(COUNT('DRE + DCF'!$V$22:$Z$22)-((12-3)/12)))))*$F$40+$F$42)*(1-$F$39))/$F$10 -> 11.492648 | P15: =(((NPV($H15,'DRE + DCF'!$U$36,'DRE + DCF'!$W$36:$Z$36)*((1+$H15)^((12-3)/12))+('DRE + DCF'!$AA$36*(1+P$18)/(($H15-P$18)*(1+$H15)^(COUNT('DRE + DCF'!$V$22:$Z$22)-((12-3)/12)))))+SUM($F$12:$F$17)))/$F$10-(((NPV($H15,'DRE + DCF'!$U$36,'DRE + DCF'!$W$36:$Z$36)*((1+$H15)^((12-3)/12))+('DRE + DCF'!$AA$36*(1+P$18)/(($H15-P$18)*(1+$H15)^(COUNT('DRE + DCF'!$V$22:$Z$22)-((12-3)/12)))))*$F$40+$F$42)*(1-$F$39))/$F$10 -> 11.666965 | ... R15: =(((NPV($H15,'DRE + DCF'!$U$36,'DRE + DCF'!$W$36:$Z$36)*((1+$H15)^((12-3)/12))+('DRE + DCF'!$AA$36*(1+R$18)/(($H15-R$18)*(1+$H15)^(COUNT('DRE + DCF'!$V$22:$Z$22)-((12-3)/12)))))+SUM($F$12:$F$17)))/$F$10-(((NPV($H15,'DRE + DCF'!$U$36,'DRE + DCF'!$W$36:$Z$36)*((1+$H15)^((12-3)/12))+('DRE + DCF'!$AA$36*(1+R$18)/(($H15-R$18)*(1+$H15)^(COUNT('DRE + DCF'!$V$22:$Z$22)-((12-3)/12)))))*$F$40+$F$42)*(1-$F$39))/$F$10 -> 12.047616
A16: Projeções - CG + Capex | E16: Desconto de Holding | F16: =('Projeções - Receita e EBIT'!U115)/((WACC!P20)-3.5%)/'DRE + DCF'!Z37 -> -1046115.4 | H16: =H15+0.5% -> 0.17612663 | I16: =(((NPV($H16,'DRE + DCF'!$U$36,'DRE + DCF'!$W$36:$Z$36)*((1+$H16)^((12-3)/12))+('DRE + DCF'!$AA$36*(1+I$18)/(($H16-I$18)*(1+$H16)^(COUNT('DRE + DCF'!$V$22:$Z$22)-((12-3)/12)))))+SUM($F$12:$F$17)))/$F$10-(((NPV($H16,'DRE + DCF'!$U$36,'DRE + DCF'!$W$36:$Z$36)*((1+$H16)^((12-3)/12))+('DRE + DCF'!$AA$36*(1+I$18)/(($H16-I$18)*(1+$H16)^(COUNT('DRE + DCF'!$V$22:$Z$22)-((12-3)/12)))))*$F$40+$F$42)*(1-$F$39))/$F$10 -> 10.293519 | J16: =(((NPV($H16,'DRE + DCF'!$U$36,'DRE + DCF'!$W$36:$Z$36)*((1+$H16)^((12-3)/12))+('DRE + DCF'!$AA$36*(1+J$18)/(($H16-J$18)*(1+$H16)^(COUNT('DRE + DCF'!$V$22:$Z$22)-((12-3)/12)))))+SUM($F$12:$F$17)))/$F$10-(((NPV($H16,'DRE + DCF'!$U$36,'DRE + DCF'!$W$36:$Z$36)*((1+$H16)^((12-3)/12))+('DRE + DCF'!$AA$36*(1+J$18)/(($H16-J$18)*(1+$H16)^(COUNT('DRE + DCF'!$V$22:$Z$22)-((12-3)/12)))))*$F$40+$F$42)*(1-$F$39))/$F$10 -> 10.407615 | K16: =(((NPV($H16,'DRE + DCF'!$U$36,'DRE + DCF'!$W$36:$Z$36)*((1+$H16)^((12-3)/12))+('DRE + DCF'!$AA$36*(1+K$18)/(($H16-K$18)*(1+$H16)^(COUNT('DRE + DCF'!$V$22:$Z$22)-((12-3)/12)))))+SUM($F$12:$F$17)))/$F$10-(((NPV($H16,'DRE + DCF'!$U$36,'DRE + DCF'!$W$36:$Z$36)*((1+$H16)^((12-3)/12))+('DRE + DCF'!$AA$36*(1+K$18)/(($H16-K$18)*(1+$H16)^(COUNT('DRE + DCF'!$V$22:$Z$22)-((12-3)/12)))))*$F$40+$F$42)*(1-$F$39))/$F$10 -> 10.527186 | L16: =(((NPV($H16,'DRE + DCF'!$U$36,'DRE + DCF'!$W$36:$Z$36)*((1+$H16)^((12-3)/12))+('DRE + DCF'!$AA$36*(1+L$18)/(($H16-L$18)*(1+$H16)^(COUNT('DRE + DCF'!$V$22:$Z$22)-((12-3)/12)))))+SUM($F$12:$F$17)))/$F$10-(((NPV($H16,'DRE + DCF'!$U$36,'DRE + DCF'!$W$36:$Z$36)*((1+$H16)^((12-3)/12))+('DRE + DCF'!$AA$36*(1+L$18)/(($H16-L$18)*(1+$H16)^(COUNT('DRE + DCF'!$V$22:$Z$22)-((12-3)/12)))))*$F$40+$F$42)*(1-$F$39))/$F$10 -> 10.652639 | M16: =(((NPV($H16,'DRE + DCF'!$U$36,'DRE + DCF'!$W$36:$Z$36)*((1+$H16)^((12-3)/12))+('DRE + DCF'!$AA$36*(1+M$18)/(($H16-M$18)*(1+$H16)^(COUNT('DRE + DCF'!$V$22:$Z$22)-((12-3)/12)))))+SUM($F$12:$F$17)))/$F$10-(((NPV($H16,'DRE + DCF'!$U$36,'DRE + DCF'!$W$36:$Z$36)*((1+$H16)^((12-3)/12))+('DRE + DCF'!$AA$36*(1+M$18)/(($H16-M$18)*(1+$H16)^(COUNT('DRE + DCF'!$V$22:$Z$22)-((12-3)/12)))))*$F$40+$F$42)*(1-$F$39))/$F$10 -> 10.784416 | N16: =(((NPV($H16,'DRE + DCF'!$U$36,'DRE + DCF'!$W$36:$Z$36)*((1+$H16)^((12-3)/12))+('DRE + DCF'!$AA$36*(1+N$18)/(($H16-N$18)*(1+$H16)^(COUNT('DRE + DCF'!$V$22:$Z$22)-((12-3)/12)))))+SUM($F$12:$F$17)))/$F$10-(((NPV($H16,'DRE + DCF'!$U$36,'DRE + DCF'!$W$36:$Z$36)*((1+$H16)^((12-3)/12))+('DRE + DCF'!$AA$36*(1+N$18)/(($H16-N$18)*(1+$H16)^(COUNT('DRE + DCF'!$V$22:$Z$22)-((12-3)/12)))))*$F$40+$F$42)*(1-$F$39))/$F$10 -> 10.923009 | O16: =(((NPV($H16,'DRE + DCF'!$U$36,'DRE + DCF'!$W$36:$Z$36)*((1+$H16)^((12-3)/12))+('DRE + DCF'!$AA$36*(1+O$18)/(($H16-O$18)*(1+$H16)^(COUNT('DRE + DCF'!$V$22:$Z$22)-((12-3)/12)))))+SUM($F$12:$F$17)))/$F$10-(((NPV($H16,'DRE + DCF'!$U$36,'DRE + DCF'!$W$36:$Z$36)*((1+$H16)^((12-3)/12))+('DRE + DCF'!$AA$36*(1+O$18)/(($H16-O$18)*(1+$H16)^(COUNT('DRE + DCF'!$V$22:$Z$22)-((12-3)/12)))))*$F$40+$F$42)*(1-$F$39))/$F$10 -> 11.068961 | P16: =(((NPV($H16,'DRE + DCF'!$U$36,'DRE + DCF'!$W$36:$Z$36)*((1+$H16)^((12-3)/12))+('DRE + DCF'!$AA$36*(1+P$18)/(($H16-P$18)*(1+$H16)^(COUNT('DRE + DCF'!$V$22:$Z$22)-((12-3)/12)))))+SUM($F$12:$F$17)))/$F$10-(((NPV($H16,'DRE + DCF'!$U$36,'DRE + DCF'!$W$36:$Z$36)*((1+$H16)^((12-3)/12))+('DRE + DCF'!$AA$36*(1+P$18)/(($H16-P$18)*(1+$H16)^(COUNT('DRE + DCF'!$V$22:$Z$22)-((12-3)/12)))))*$F$40+$F$42)*(1-$F$39))/$F$10 -> 11.222874 | ... R16: =(((NPV($H16,'DRE + DCF'!$U$36,'DRE + DCF'!$W$36:$Z$36)*((1+$H16)^((12-3)/12))+('DRE + DCF'!$AA$36*(1+R$18)/(($H16-R$18)*(1+$H16)^(COUNT('DRE + DCF'!$V$22:$Z$22)-((12-3)/12)))))+SUM($F$12:$F$17)))/$F$10-(((NPV($H16,'DRE + DCF'!$U$36,'DRE + DCF'!$W$36:$Z$36)*((1+$H16)^((12-3)/12))+('DRE + DCF'!$AA$36*(1+R$18)/(($H16-R$18)*(1+$H16)^(COUNT('DRE + DCF'!$V$22:$Z$22)-((12-3)/12)))))*$F$40+$F$42)*(1-$F$39))/$F$10 -> 11.557337
A17: Projeções 2023 | E17: Passivo Judicial Capital Fechado | F17: =IF(F54>=0,0,F54) -> 0 | H17: =H16+0.5% -> 0.18112663 | I17: =(((NPV($H17,'DRE + DCF'!$U$36,'DRE + DCF'!$W$36:$Z$36)*((1+$H17)^((12-3)/12))+('DRE + DCF'!$AA$36*(1+I$18)/(($H17-I$18)*(1+$H17)^(COUNT('DRE + DCF'!$V$22:$Z$22)-((12-3)/12)))))+SUM($F$12:$F$17)))/$F$10-(((NPV($H17,'DRE + DCF'!$U$36,'DRE + DCF'!$W$36:$Z$36)*((1+$H17)^((12-3)/12))+('DRE + DCF'!$AA$36*(1+I$18)/(($H17-I$18)*(1+$H17)^(COUNT('DRE + DCF'!$V$22:$Z$22)-((12-3)/12)))))*$F$40+$F$42)*(1-$F$39))/$F$10 -> 9.9928438 | J17: =(((NPV($H17,'DRE + DCF'!$U$36,'DRE + DCF'!$W$36:$Z$36)*((1+$H17)^((12-3)/12))+('DRE + DCF'!$AA$36*(1+J$18)/(($H17-J$18)*(1+$H17)^(COUNT('DRE + DCF'!$V$22:$Z$22)-((12-3)/12)))))+SUM($F$12:$F$17)))/$F$10-(((NPV($H17,'DRE + DCF'!$U$36,'DRE + DCF'!$W$36:$Z$36)*((1+$H17)^((12-3)/12))+('DRE + DCF'!$AA$36*(1+J$18)/(($H17-J$18)*(1+$H17)^(COUNT('DRE + DCF'!$V$22:$Z$22)-((12-3)/12)))))*$F$40+$F$42)*(1-$F$39))/$F$10 -> 10.095631 | K17: =(((NPV($H17,'DRE + DCF'!$U$36,'DRE + DCF'!$W$36:$Z$36)*((1+$H17)^((12-3)/12))+('DRE + DCF'!$AA$36*(1+K$18)/(($H17-K$18)*(1+$H17)^(COUNT('DRE + DCF'!$V$22:$Z$22)-((12-3)/12)))))+SUM($F$12:$F$17)))/$F$10-(((NPV($H17,'DRE + DCF'!$U$36,'DRE + DCF'!$W$36:$Z$36)*((1+$H17)^((12-3)/12))+('DRE + DCF'!$AA$36*(1+K$18)/(($H17-K$18)*(1+$H17)^(COUNT('DRE + DCF'!$V$22:$Z$22)-((12-3)/12)))))*$F$40+$F$42)*(1-$F$39))/$F$10 -> 10.203125 | L17: =(((NPV($H17,'DRE + DCF'!$U$36,'DRE + DCF'!$W$36:$Z$36)*((1+$H17)^((12-3)/12))+('DRE + DCF'!$AA$36*(1+L$18)/(($H17-L$18)*(1+$H17)^(COUNT('DRE + DCF'!$V$22:$Z$22)-((12-3)/12)))))+SUM($F$12:$F$17)))/$F$10-(((NPV($H17,'DRE + DCF'!$U$36,'DRE + DCF'!$W$36:$Z$36)*((1+$H17)^((12-3)/12))+('DRE + DCF'!$AA$36*(1+L$18)/(($H17-L$18)*(1+$H17)^(COUNT('DRE + DCF'!$V$22:$Z$22)-((12-3)/12)))))*$F$40+$F$42)*(1-$F$39))/$F$10 -> 10.315658 | M17: =(((NPV($H17,'DRE + DCF'!$U$36,'DRE + DCF'!$W$36:$Z$36)*((1+$H17)^((12-3)/12))+('DRE + DCF'!$AA$36*(1+M$18)/(($H17-M$18)*(1+$H17)^(COUNT('DRE + DCF'!$V$22:$Z$22)-((12-3)/12)))))+SUM($F$12:$F$17)))/$F$10-(((NPV($H17,'DRE + DCF'!$U$36,'DRE + DCF'!$W$36:$Z$36)*((1+$H17)^((12-3)/12))+('DRE + DCF'!$AA$36*(1+M$18)/(($H17-M$18)*(1+$H17)^(COUNT('DRE + DCF'!$V$22:$Z$22)-((12-3)/12)))))*$F$40+$F$42)*(1-$F$39))/$F$10 -> 10.433593 | N17: =(((NPV($H17,'DRE + DCF'!$U$36,'DRE + DCF'!$W$36:$Z$36)*((1+$H17)^((12-3)/12))+('DRE + DCF'!$AA$36*(1+N$18)/(($H17-N$18)*(1+$H17)^(COUNT('DRE + DCF'!$V$22:$Z$22)-((12-3)/12)))))+SUM($F$12:$F$17)))/$F$10-(((NPV($H17,'DRE + DCF'!$U$36,'DRE + DCF'!$W$36:$Z$36)*((1+$H17)^((12-3)/12))+('DRE + DCF'!$AA$36*(1+N$18)/(($H17-N$18)*(1+$H17)^(COUNT('DRE + DCF'!$V$22:$Z$22)-((12-3)/12)))))*$F$40+$F$42)*(1-$F$39))/$F$10 -> 10.557327 | O17: =(((NPV($H17,'DRE + DCF'!$U$36,'DRE + DCF'!$W$36:$Z$36)*((1+$H17)^((12-3)/12))+('DRE + DCF'!$AA$36*(1+O$18)/(($H17-O$18)*(1+$H17)^(COUNT('DRE + DCF'!$V$22:$Z$22)-((12-3)/12)))))+SUM($F$12:$F$17)))/$F$10-(((NPV($H17,'DRE + DCF'!$U$36,'DRE + DCF'!$W$36:$Z$36)*((1+$H17)^((12-3)/12))+('DRE + DCF'!$AA$36*(1+O$18)/(($H17-O$18)*(1+$H17)^(COUNT('DRE + DCF'!$V$22:$Z$22)-((12-3)/12)))))*$F$40+$F$42)*(1-$F$39))/$F$10 -> 10.6873 | P17: =(((NPV($H17,'DRE + DCF'!$U$36,'DRE + DCF'!$W$36:$Z$36)*((1+$H17)^((12-3)/12))+('DRE + DCF'!$AA$36*(1+P$18)/(($H17-P$18)*(1+$H17)^(COUNT('DRE + DCF'!$V$22:$Z$22)-((12-3)/12)))))+SUM($F$12:$F$17)))/$F$10-(((NPV($H17,'DRE + DCF'!$U$36,'DRE + DCF'!$W$36:$Z$36)*((1+$H17)^((12-3)/12))+('DRE + DCF'!$AA$36*(1+P$18)/(($H17-P$18)*(1+$H17)^(COUNT('DRE + DCF'!$V$22:$Z$22)-((12-3)/12)))))*$F$40+$F$42)*(1-$F$39))/$F$10 -> 10.823996 | ... R17: =(((NPV($H17,'DRE + DCF'!$U$36,'DRE + DCF'!$W$36:$Z$36)*((1+$H17)^((12-3)/12))+('DRE + DCF'!$AA$36*(1+R$18)/(($H17-R$18)*(1+$H17)^(COUNT('DRE + DCF'!$V$22:$Z$22)-((12-3)/12)))))+SUM($F$12:$F$17)))/$F$10-(((NPV($H17,'DRE + DCF'!$U$36,'DRE + DCF'!$W$36:$Z$36)*((1+$H17)^((12-3)/12))+('DRE + DCF'!$AA$36*(1+R$18)/(($H17-R$18)*(1+$H17)^(COUNT('DRE + DCF'!$V$22:$Z$22)-((12-3)/12)))))*$F$40+$F$42)*(1-$F$39))/$F$10 -> 11.119755
A18: Processos | E18: Valor da Ação | F18: =SUM($F$11:$F$17)/$F$10 -> 13.488472 | I18: =J18-0.25% -> 0.0669568 | J18: =K18-0.25% -> 0.0694568 | K18: =L18-0.25% -> 0.0719568 | L18: =M18-0.25% -> 0.0744568 | M18: ='DRE + DCF'!AC23 -> 0.0769568 | N18: =M18+0.25% -> 0.0794568 | O18: =N18+0.25% -> 0.0819568 | P18: =O18+0.25% -> 0.0844568 | Q18: =P18+0.25% -> 0.0869568 | R18: =Q18+0.25% -> 0.0894568
E19: Cotação | F19: 7.46 | I19: Growth
E20: =IF(F20=0,"",IF(F20>0,"Upside","Downside")) -> Upside | F20: =IF(F18<0,"-",F18/F19-1) -> 0.80810614
E21: TIR | F21: 0.2395
N24: Preço Teto | O24: 12.93 | P24: 11.31 | Q24: =O24/P24-1 -> 0.14323607
E25: Total Holding | F25: =SUM('Balanço Patrimonial'!O21,'Balanço Patrimonial'!O37) -> 7079945.4 | H25: Empresa | I25: Valor do Equity | J25: Participação Simpar | K25: Valor da Participação da Simpar | O25: =F18*(1-Q24) -> 11.556436
E26: JSL | F26: 1178080 | H26: JSL | I26: 4192902 | J26: 0.7242 | K26: =I26*J26 -> 3036499.6
E27: Movida | F27: 1771126.3 | H27: Movida | I27: 4765369 | J27: 0.6519 | K27: =I27*J27 -> 3106544
E28: Vamos | F28: 2357031.2 | H28: Vamos | I28: 9642272.9 | J28: 0.6906 | K28: =I28*J28 -> 6658953.7
E29: Holding excluindo empresas de capital aberto | F29: =F25-SUM(F26:F28) -> 1773707.9 | H29: Total | K29: =SUM(K26:K28) -> 12801997
E32: Total Holding | F32: =WACC!F19 -> 41596826 | H32: Empresa | I32: Market Cap | J32: Participação Simpar | K32: Valor de mercado da Participação
E33: JSL | F33: -6324340 | H33: JSL | I33: 2497679 | J33: =J26 -> 0.7242 | K33: =I33*J33 -> 1808819.1
E34: Movida | F34: -13731980 | H34: Movida | I34: 3623020.9 | J34: =J27 -> 0.6519 | K34: =I34*J34 -> 2361847.3
E35: Vamos | F35: -12307704 | H35: Vamos | I35: 9850575.2 | J35: =J28 -> 0.6906 | K35: =I35*J35 -> 6802807.2
E36: Holding excluindo empresas de capital aberto | F36: =SUM(F32:F35) -> 9232802 | H36: Holding + Empresas de Capital Fechado | K36: =K37-SUM(K33:K35) -> -4718950.6
H37: Simpar | I37: =F19*F10 -> 6254523 | J37: 1 | K37: =J37*I37 -> 6254523
E39: Participação da Simpar na Automob | F39: 0.794
E40: % médio do EBIT projetado que vem da Automob | F40: =AVERAGE('Projeções - Receita e EBIT'!$Q$57:$U$57) -> 0.55262022
E41: Valor da Empresa da Automob baseado no EBIT | F41: =F11*F40 -> 4507791.3
E42: Dívida Líquida Automob | F42: 1050800
E43: Valor do Equity Automob | F43: =F41+F42 -> 5558591.3
E44: Valor do Equity da Automob que não pertence à Simpar | F44: =F43*(1-$F$39) -> 1145069.8
E48: Total Holding | F48: =WACC!F35 -> 0
E49: JSL | F49: -596787
E50: Movida | F50: 0
E51: Vamos | F51: -86952
E52: Holding excluindo empresas de capital aberto | F52: =SUM(F48:F51) -> -683739
E53: Holding Total | F53: =('Balanço Patrimonial'!O82-'Balanço Patrimonial'!O42)*-1 -> -679970
...

Sheet WACC
F3: =Dashboard!$H$3 -> SIMPAR (SIMH3)
A7: Páginas
A8: Dashboard
A9: WACC | E9: Atualizado em: 08/11/2023 | F9: 2023 | G9: =F9+1 -> 2024 | H9: =G9+1 -> 2025 | I9: =H9+1 -> 2026 | J9: =I9+1 -> 2027 | K9: =J9+1 -> 2028 | L9: =K9+1 -> 2029 | M9: =L9+1 -> 2030 | N9: =M9+1 -> 2031 | ... P9: =O9+1 -> 2033
A10: DRE Consolidado | E10: DI | F10: 0.12008 | G10: 0.1082 | H10: 0.1062 | I10: 0.10765 | J10: 0.10959 | K10: 0.1113 | L10: 0.11248 | M10: 0.1132 | N10: 0.11362 | O10: 0.1139 | P10: 0.1139
A11: DRE + DCF | E11: CDS | F11: 0.0039 | G11: 0.003834174 | H11: 0.006638106 | I11: 0.009806918 | J11: 0.013433968 | K11: 0.017234112 | L11: 0.0206891 | M11: 0.023531264 | N11: 0.025541019 | O11: 0.02649878 | P11: 0.026184965
A12: DRE - Contas Abertas | E12: Inflação Implícita | F12: 0.0418 | G12: 0.04217 | H12: 0.04334 | I12: 0.04552 | J12: 0.04854 | K12: 0.05087 | L12: 0.05238 | M12: 0.0543 | N12: 0.05521 | O12: 0.05562 | P12: 0.05584
A13: Balanço Patrimonial | E13: Taxa Livre de Risco | F13: =F10-F11 -> 0.11618 | G13: =G10-G11 -> 0.10436583 | H13: =H10-H11 -> 0.099561894 | I13: =I10-I11 -> 0.097843082 | J13: =J10-J11 -> 0.096156032 | K13: =K10-K11 -> 0.094065888 | L13: =L10-L11 -> 0.0917909 | M13: =M10-M11 -> 0.089668736 | ... P13: =P10-P11 -> 0.087715035
A14: Painel de Índices | E14: Beta | F14: 2 | G14: =F14 -> 2 | H14: =G14 -> 2 | I14: =H14 -> 2 | J14: =I14 -> 2 | K14: =J14 -> 2 | L14: =K14 -> 2 | M14: =L14 -> 2 | N14: =M14 -> 2 | ... P14: =O14 -> 2
A15: Projeções - Receita e EBIT | E15: Prêmio de Risco | F15: 0.065 | G15: 0.065 | H15: 0.065 | I15: 0.065 | J15: 0.065 | K15: 0.065 | L15: 0.065 | M15: 0.065 | N15: 0.065 | O15: 0.065 | P15: 0.065
A16: Projeções - CG + Capex | E16: Custo de Capital Próprio (Ke) | F16: =F13+(F14*F15) -> 0.24618 | G16: =G13+(G14*G15) -> 0.23436583 | H16: =H13+(H14*H15) -> 0.22956189 | I16: =I13+(I14*I15) -> 0.22784308 | J16: =J13+(J14*J15) -> 0.22615603 | K16: =K13+(K14*K15) -> 0.22406589 | L16: =L13+(L14*L15) -> 0.2217909 | M16: =M13+(M14*M15) -> 0.21966874 | ... P16: =P13+(P14*P15) -> 0.21771504
A17: Projeções 2023 | E17: Valor Justo do Equity (R$ Mil) | F17: 11192746 | G17: =F17 -> 11192746 | H17: =G17 -> 11192746 | I17: =H17 -> 11192746 | J17: =I17 -> 11192746 | K17: =J17 -> 11192746 | L17: =K17 -> 11192746 | M17: =L17 -> 11192746 | N17: =M17 -> 11192746 | ... P17: =O17 -> 11192746
A18: Processos | E18: Custo de Capital de Terceiros (Kd) | F18: =F10+3.2% -> 0.15208 | G18: =G10+3.2% -> 0.1402 | H18: =H10+3.2% -> 0.1382 | I18: =I10+3.2% -> 0.13965 | J18: =J10+3.2% -> 0.14159 | K18: =K10+3.2% -> 0.1433 | L18: =L10+3.2% -> 0.14448 | M18: =M10+3.2% -> 0.1452 | ... P18: =P10+3.2% -> 0.1459
E19: Dívida Bruta (R$ Mil) | F19: =SUM('Balanço Patrimonial'!O55:O60,'Balanço Patrimonial'!O74:O77) -> 41596826 | G19: =F19 -> 41596826 | H19: =G19 -> 41596826 | I19: =H19 -> 41596826 | J19: =I19 -> 41596826 | K19: =J19 -> 41596826 | L19: =K19 -> 41596826 | M19: =L19 -> 41596826 | N19: =M19 -> 41596826 | ... P19: =O19 -> 41596826
E20: WACC | F20: =((F16*F17)+(F18*F19))/(F17+F19) -> 0.17203162 | G20: =((G16*G17)+(G18*G19))/(G17+G19) -> 0.16016557 | H20: =((H16*H17)+(H18*H19))/(H17+H19) -> 0.15757107 | I20: =((I16*I17)+(I18*I19))/(I17+I19) -> 0.1583492 | J20: =((J16*J17)+(J18*J19))/(J17+J19) -> 0.15952017 | K20: =((K16*K17)+(K18*K19))/(K17+K19) -> 0.16042444 | L20: =((L16*L17)+(L18*L19))/(L17+L19) -> 0.1608719 | M20: =((M16*M17)+(M18*M19))/(M17+M19) -> 0.16098929 | ... P20: =((P16*P17)+(P18*P19))/(P17+P19) -> 0.16112663
E21: Desconto | F21: =1*(1+F20)^((12-9)/12) -> 1.0404826 | G21: =F21*(1+G20) -> 1.2071321 | H21: =G21*(1+H20) -> 1.3973412 | I21: =H21*(1+I20) -> 1.6186091 | J21: =I21*(1+J20) -> 1.8768099 | K21: =J21*(1+K20) -> 2.1778961 | L21: =K21*(1+L20) -> 2.5282583 | M21: =L21*(1+M20) -> 2.9352808 | N21: =M21*(1+N20) -> 3.4078116 | ... P21: =O21*(1+P20) -> 4.5941997

Sheet DRE Consolidado
K2: =Dashboard!H3 -> SIMPAR (SIMH3)
A7: Páginas
A8: Dashboard
A9: WACC
A10: DRE Consolidado
A11: DRE + DCF
A12: DRE - Contas Abertas | E12: Data do Último Resultado: | K12: 2014 | L12: 2015 | M12: 2016 | N12: 2017 | O12: 2018 | P12: 2019 | Q12: 2020 | R12: 2021 | S12: 2022 | T12: YTD 2023 | U12: YTG 2023E | V12: 2023 | W12: 2024 | X12: 2025 | Y12: 2026 | Z12: 2027
A13: Balanço Patrimonial | E13: Receita Bruta | K13: 6079086.1 | L13: 6561486.7 | M13: 7403983 | N13: 8199829 | O13: 9203466 | P13: 10734355 | Q13: 10874860 | R13: 15453380 | S13: 26844012
A14: Painel de Índices | E14: Deduções | K14: =-(K13-K16) -> -539892.08 | L14: =-(L13-L16) -> -571574.68 | M14: =-(M13-M16) -> -880867 | N14: =-(N13-N16) -> -944025 | O14: =-(O13-O16) -> -1128077 | P14: =-(P13-P16) -> -1048146.5 | Q14: =-(Q13-Q16) -> -1067803 | R14: =-(R13-R16) -> -1587161 | S14: -2462220.7
A15: Projeções - Receita e EBIT | E15: % da Receita Bruta | K15: =-K14/K13 -> 0.088811389 | L15: =-L14/L13 -> 0.087110545 | M15: =-M14/M13 -> 0.11897205 | N15: =-N14/N13 -> 0.1151274 | O15: =-O14/O13 -> 0.12257089 | P15: =-P14/P13 -> 0.097644102 | Q15: =-Q14/Q13 -> 0.098190046 | R15: =-R14/R13 -> 0.1027064 | S15: =-S14/S13 -> 0.091723277
A16: Projeções - CG + Capex | E16: Receita Líquida | K16: 5539194 | L16: 5989912 | M16: 6523116 | N16: 7255804 | O16: 8075389 | P16: 9686209 | Q16: 9807057 | R16: 13866219 | S16: 24381791 | T16: 23321789 | U16: =V16-SUM(T16:T16) -> 8336165.1 | V16: ='Projeções - Receita e EBIT'!Q10 -> 31657954 | W16: ='Projeções - Receita e EBIT'!R10 -> 39929183 | X16: ='Projeções - Receita e EBIT'!S10 -> 47076707 | Y16: ='Projeções - Receita e EBIT'!T10 -> 52864437 | Z16: ='Projeções - Receita e EBIT'!U10 -> 58805341
A17: Projeções 2023 | E17: Crescimento da Receita (YoY)¹ | K17: 0 | L17: =L16/K16-1 -> 0.081368878 | M17: =M16/L16-1 -> 0.089017001 | N17: =N16/M16-1 -> 0.11232178 | O17: =O16/N16-1 -> 0.11295578 | P17: =P16/O16-1 -> 0.19947274 | Q17: =Q16/P16-1 -> 0.012476295 | R17: =R16/Q16-1 -> 0.41390215 | S17: =S16/R16-1 -> 0.758359 | V17: =V16/S16-1 -> 0.29842611 | W17: =W16/V16-1 -> 0.26126858 | X17: =X16/W16-1 -> 0.17900502 | Y17: =Y16/X16-1 -> 0.12294253 | Z17: =Z16/Y16-1 -> 0.11237998
A18: Processos | E18: Custos das Vendas e Serviços | K18: -3865141 | L18: -3974936 | M18: -3936687 | N18: -4032052 | O18: -4699220 | P18: -5102646 | Q18: -5168883 | R18: -7304534 | S18: -12624428 | T18: -12628498
E19: Custo de Construção | F19: Custo de Construção | T19: -82622
A20: Gráficos | E20: Custo de Venda de Ativos Desmobilizados | K20: -681231 | L20: -877618 | M20: -1289069 | N20: -1737637 | O20: -1609867 | P20: -2524180 | Q20: -2618101 | R20: -2077780 | S20: -4166192 | T20: -4104310
E21: Lucro Bruto | K21: =K16+K18+K20 -> 992822 | L21: =L16+L18+L20 -> 1137358 | M21: =M16+M18+M20 -> 1297360 | N21: =N16+N18+N20 -> 1486115 | O21: =O16+O18+O20 -> 1766302 | P21: =P16+P18+P20 -> 2059383 | Q21: =Q16+Q18+Q20 -> 2020073 | R21: =R16+R18+R20 -> 4483905 | S21: =S16+S18+S20 -> 7591171 | T21: =T16+T18+T19+T20 -> 6506359
E22: Margem Bruta | K22: =K21/K16 -> 0.17923582 | L22: =L21/L16 -> 0.18987892 | M22: =M21/M16 -> 0.19888654 | N22: =N21/N16 -> 0.20481741 | O22: =O21/O16 -> 0.21872655 | P22: =P21/P16 -> 0.2126098 | Q22: =Q21/Q16 -> 0.20598157 | R22: =R21/R16 -> 0.32336897 | ... T22: =T21/T16 -> 0.27898199
E23: Despesas/ Receitas Operacionais | K23: =SUM(K24,K26,K28,K29,K32) -> -532720 | L23: =SUM(L24,L26,L28,L29,L32) -> -553903 | M23: =SUM(M24,M26,M28,M29,M32) -> -798577 | N23: =SUM(N24,N26,N28,N29,N32) -> -781645 | O23: =SUM(O24,O26,O28,O29,O32) -> -805585 | P23: =SUM(P24,P26,P28,P29,P32) -> -860218 | Q23: =SUM(Q24,Q26,Q28,Q29,Q32) -> -990091 | R23: =SUM(R24,R26,R28,R29,R32) -> -1353354 | ... T23: =SUM(T24,T26,T28,T29,T32) -> -2233284
E24: Despesas Tributárias | K24: -8093 | L24: -9584 | M24: 0 | N24: 0 | O24: 0 | P24: 0 | Q24: 0 | R24: 0 | S24: 0 | T24: 0
E25: (%) da Receita Líquida | K25: =-K24/K16 -> 0.0014610429 | L25: =-L24/L16 -> 0.0016000235 | M25: =-M24/M16 -> 0 | N25: =-N24/N16 -> 0 | O25: =-O24/O16 -> 0 | P25: =-P24/P16 -> 0 | Q25: =-Q24/Q16 -> 0 | R25: =-R24/R16 -> 0 | ... T25: =-T24/T16 -> 0
E26: Despesas Comerciais Gerais e Administrativas | K26: -491535 | L26: -510134 | M26: -684175 | N26: -746102 | O26: -794421 | P26: =-571098-293107 -> -864205 | Q26: -896692 | R26: -1398455 | S26: =-884377-1397532 -> -2281909 | T26: =-880719-1344926 -> -2225645
E27: (%) da Receita Líquida | K27: =-K26/K16 -> 0.088737639 | L27: =-L26/L16 -> 0.085165525 | M27: =-M26/M16 -> 0.10488469 | N27: =-N26/N16 -> 0.1028283 | O27: =-O26/O16 -> 0.098375571 | P27: =-P26/P16 -> 0.089220148 | Q27: =-Q26/Q16 -> 0.091433342 | R27: =-R26/R16 -> 0.10085338 | ... T27: =-T26/T16 -> 0.095432001
E28: Perdas pela Não Recuperabilidade de Ativos | K28: 0 | L28: 0 | M28: 0 | N28: 0 | O28: -9146 | P28: -32527 | Q28: -78667 | R28: -56164 | S28: -127315 | T28: -153092
E29: Resultado Operacional Outros | K29: =SUM(K30:K31) -> -33186 | L29: =SUM(L30:L31) -> -34256 | M29: =SUM(M30:M31) -> -114402 | N29: =SUM(N30:N31) -> -35543 | O29: =SUM(O30:O31) -> -1058 | P29: =SUM(P30:P31) -> 37715 | Q29: =SUM(Q30:Q31) -> -14217 | R29: =SUM(R30:R31) -> 102799 | ... T29: =SUM(T30:T31) -> 142529
E30: Outras Receitas Operacionais | K30: -33186 | L30: -34256 | M30: -114402 | N30: -35543 | O30: -1058 | P30: 37715 | Q30: -14217 | R30: 102799 | S30: 0 | T30: 142529
E31: Outras Despesas Operacionais | K31: 0 | L31: 0 | M31: 0 | N31: 0 | O31: 0 | P31: 0 | Q31: 0 | R31: 0 | S31: -67941 | T31: 0
E32: Resultado de Equivalência Patrimonial | K32: 94 | L32: 71 | M32: 0 | N32: 0 | O32: -960 | P32: -1201 | Q32: -515 | R32: -1534 | S32: 2810 | T32: 2924
E33: EBITDA | K33: =K34+K55+'Projeções - CG + Capex'!K57 -> 868967 | L33: =L34+L55+'Projeções - CG + Capex'!L57 -> 1092081 | M33: =M34+M55+'Projeções - CG + Capex'!M57 -> 1045970 | N33: =N34+N55+'Projeções - CG + Capex'!N57 -> 1230201 | O33: =O34+O55+'Projeções - CG + Capex'!O57 -> 1597534 | P33: =P34+P55+'Projeções - CG + Capex'!P57 -> 2115909 | Q33: =Q34+Q55+'Projeções - CG + Capex'!Q57 -> 2141935 | R33: =R34+R55+'Projeções - CG + Capex'!R57 -> 4189665 | ... T33: =T34+T55+'Projeções - CG + Capex'!T57 -> 6316302
E34: EBIT | K34: =K21+K23 -> 460102 | L34: =L21+L23 -> 583455 | M34: =M21+M23 -> 498783 | N34: =N21+N23 -> 704470 | O34: =O21+O23 -> 960717 | P34: =P21+P23 -> 1199165 | Q34: =Q21+Q23 -> 1029982 | R34: =R21+R23 -> 3130551 | ... T34: =T21+T23 -> 4273075 | U34: =U16*U37 -> 1444175.9
E35: Eventos não Recorrentes | K35: ='DRE - Contas Abertas'!F56 -> -24516 | L35: ='DRE - Contas Abertas'!I56 -> 34204 | M35: ='DRE - Contas Abertas'!J56 -> 30444 | N35: ='DRE - Contas Abertas'!I56 -> 34204 | O35: ='DRE - Contas Abertas'!J56 -> 30444 | P35: ='DRE - Contas Abertas'!K56 -> -929 | Q35: ='DRE - Contas Abertas'!L56 -> -141683 | R35: ='DRE - Contas Abertas'!M56 -> 107566 | S35: ='DRE - Contas Abertas'!N56 -> 12526 | T35: ='DRE - Contas Abertas'!O56+254800 -> 232756
E36: EBIT Recorrente | K36: =SUM(K34-K35) -> 484618 | L36: =SUM(L34-L35) -> 549251 | M36: =SUM(M34-M35) -> 468339 | N36: =SUM(N34-N35) -> 670266 | O36: =SUM(O34-O35) -> 930273 | P36: =SUM(P34-P35) -> 1200094 | Q36: =SUM(Q34-Q35) -> 1171665 | R36: =SUM(R34-R35) -> 3022985 | ... T36: =SUM(T34-T35) -> 4040319 | U36: =U34 -> 1444175.9
E37: Margem EBIT | K37: =K36/K16 -> 0.087488902 | L37: =L36/L16 -> 0.091696005 | M37: =M36/M16 -> 0.071796822 | N37: =N36/N16 -> 0.092376531 | O37: =O36/O16 -> 0.11519854 | P37: =P36/P16 -> 0.12389718 | Q37: =Q36/Q16 -> 0.11947162 | R37: =R36/R16 -> 0.21801076 | ... T37: =T36/T16 -> 0.17324224 | U37: =T37 -> 0.17324224
E38: Resultado Financeiro | K38: =SUM(K39:K40) -> -348965 | L38: =SUM(L39:L40) -> -516233 | M38: =SUM(M39:M40) -> -748253 | N38: =SUM(N39:N40) -> -670541 | O38: =SUM(O39:O40) -> -681219 | P38: =SUM(P39:P40) -> -768039 | Q38: =SUM(Q39:Q40) -> -374776 | R38: =SUM(R39:R40) -> -1217593 | ... T38: =SUM(T39:T40) -> -4352447
E39: Receitas Financeiras | K39: 109484 | L39: 198480 | M39: 201723 | N39: 209555 | O39: 317809 | P39: 365336 | Q39: 679426 | R39: 736362 | S39: 1229042 | T39: 837998
E40: Despesas Financeiras | K40: -458449 | L40: -714713 | M40: -949976 | N40: -880096 | O40: -999028 | P40: -1133375 | Q40: -1054202 | R40: -1953955 | S40: -5358473 | T40: -5190445
E41: Resultado Antes dos Tributos Sobre o Lucro | K41: =K34+K38 -> 111137 | L41: =L34+L38 -> 67222 | M41: =M34+M38 -> -249470 | N41: =N34+N38 -> 33929 | O41: =O34+O38 -> 279498 | P41: =P34+P38 -> 431126 | Q41: =Q34+Q38 -> 655206 | R41: =R34+R38 -> 1912958 | ... T41: =T34+T38 -> -79372
E42: Imposto de Renda e CSLL | K42: =K43+K44 -> -38697 | L42: =L43+L44 -> -20461 | M42: =M43+M44 -> 66296 | N42: =N43+N44 -> -17211 | O42: =O43+O44 -> -90328 | P42: =P43+P44 -> -112501 | Q42: =Q43+Q44 -> -229167 | R42: =R43+R44 -> -584008 | ... T42: =T43+T44 -> 145549
E43: Corrente | K43: -19885 | L43: -13925 | M43: -21844 | N43: -30178 | O43: -72495 | P43: -68869 | Q43: -177605 | R43: -126774 | S43: -117262 | T43: -86034
E44: Diferido | K44: -18812 | L44: -6536 | M44: 88140 | N44: 12967 | O44: -17833 | P44: -43632 | Q44: -51562 | R44: -457234 | S44: 70584 | T44: 231583
E45: Resultado Líquido de Operações Continuadas | K45: =K41+K42 -> 72440 | L45: =L41+L42 -> 46761 | M45: =M41+M42 -> -183174 | N45: =N41+N42 -> 16718 | O45: =O41+O42 -> 189170 | P45: =P41+P42 -> 318625 | Q45: =Q41+Q42 -> 426039 | R45: =R41+R42 -> 1328950 | ... T45: =T41+T42 -> 66177
...

Sheet DRE + DCF
K2: =Dashboard!H3 -> SIMPAR (SIMH3)
A7: Páginas
A8: Dashboard
A9: WACC
A10: DRE Consolidado
A11: DRE + DCF
A12: DRE - Contas Abertas | K12: 2014 | L12: 2015 | M12: 2016 | N12: 2017 | O12: 2018 | P12: 2019 | Q12: 2020 | R12: 2021 | S12: 2022 | T12: YTD 2023 | U12: YTG 2023E | V12: 2023 | W12: 2024 | X12: 2025 | Y12: 2026 | Z12: 2027E
A13: Balanço Patrimonial | E13: Receita Líquida Ex empresas de capital aberto | O13: =SUM('Projeções - Receita e EBIT'!J16:J21) -> 1415123 | P13: =SUM('Projeções - Receita e EBIT'!K16:K21) -> 1536679 | Q13: =SUM('Projeções - Receita e EBIT'!L16:L21) -> 1381814 | R13: =SUM('Projeções - Receita e EBIT'!M16:M21) -> 1414123 | S13: =SUM('Projeções - Receita e EBIT'!N16:N21) -> 3845902 | T13: =SUM('Projeções - Receita e EBIT'!O16:O21) -> 5427196 | U13: =V13-T13 -> 1810933.6 | V13: =SUM('Projeções - Receita e EBIT'!Q16:Q21) -> 7238129.6 | W13: =SUM('Projeções - Receita e EBIT'!R16:R21) -> 9847123 | X13: =SUM('Projeções - Receita e EBIT'!S16:S21) -> 10473362 | Y13: =SUM('Projeções - Receita e EBIT'!T16:T21) -> 11109057 | Z13: =SUM('Projeções - Receita e EBIT'!U16:U21) -> 11828495
E14: EBITDA Excluindo Empresas de Capital Aberto | O14: =O15+O24+O32 -> 278146 | P14: =P15+P24+P32 -> 339526 | Q14: =Q15+Q24+Q32 -> 354594 | R14: =R15+R24+R32 -> 298861 | S14: =S15+S24+S32 -> 590052 | T14: =T15+T24+T32 -> 363582 | U14: =U15+U24+U32 -> 348859.95 | V14: =V15+V24+V32 -> 712441.95 | ... Z14: =Z15+Z24+Z32 -> 1725128
A15: Painel de Índices | E15: EBIT Recorrente Excluindo Empresas de Capital Aberto | O15: =SUM('Projeções - Receita e EBIT'!J37+'Projeções - Receita e EBIT'!J56+'Projeções - Receita e EBIT'!J75+'Projeções - Receita e EBIT'!J98+'Projeções - Receita e EBIT'!J115+'Projeções - Receita e EBIT'!J133) -> 127598 | P15: =SUM('Projeções - Receita e EBIT'!K37+'Projeções - Receita e EBIT'!K56+'Projeções - Receita e EBIT'!K75+'Projeções - Receita e EBIT'!K98+'Projeções - Receita e EBIT'!K115+'Projeções - Receita e EBIT'!K133) -> 164843 | Q15: =SUM('Projeções - Receita e EBIT'!L37+'Projeções - Receita e EBIT'!L56+'Projeções - Receita e EBIT'!L75+'Projeções - Receita e EBIT'!L98+'Projeções - Receita e EBIT'!L115+'Projeções - Receita e EBIT'!L133) -> 160737 | R15: =SUM('Projeções - Receita e EBIT'!M37+'Projeções - Receita e EBIT'!M56+'Projeções - Receita e EBIT'!M75+'Projeções - Receita e EBIT'!M98+'Projeções - Receita e EBIT'!M115+'Projeções - Receita e EBIT'!M133) -> 186246 | S15: =SUM('Projeções - Receita e EBIT'!N37+'Projeções - Receita e EBIT'!N56+'Projeções - Receita e EBIT'!N75+'Projeções - Receita e EBIT'!N98+'Projeções - Receita e EBIT'!N115+'Projeções - Receita e EBIT'!N133) -> 320049 | T15: =SUM('Projeções - Receita e EBIT'!O37+'Projeções - Receita e EBIT'!O56+'Projeções - Receita e EBIT'!O75+'Projeções - Receita e EBIT'!O98+'Projeções - Receita e EBIT'!O115+'Projeções - Receita e EBIT'!O133) -> 236261 | U15: =V15-T15 -> 306375.79 | V15: =SUM('Projeções - Receita e EBIT'!Q37,'Projeções - Receita e EBIT'!Q56,'Projeções - Receita e EBIT'!Q75,'Projeções - Receita e EBIT'!Q98) -> 542636.79 | W15: =SUM('Projeções - Receita e EBIT'!R37,'Projeções - Receita e EBIT'!R56,'Projeções - Receita e EBIT'!R75,'Projeções - Receita e EBIT'!R98) -> 792913.18 | X15: =SUM('Projeções - Receita e EBIT'!S37,'Projeções - Receita e EBIT'!S56,'Projeções - Receita e EBIT'!S75,'Projeções - Receita e EBIT'!S98) -> 862708.77 | Y15: =SUM('Projeções - Receita e EBIT'!T37,'Projeções - Receita e EBIT'!T56,'Projeções - Receita e EBIT'!T75,'Projeções - Receita e EBIT'!T98) -> 915996.11 | Z15: =SUM('Projeções - Receita e EBIT'!U37,'Projeções - Receita e EBIT'!U56,'Projeções - Receita e EBIT'!U75,'Projeções - Receita e EBIT'!U98) -> 975272.8
A16: Projeções - Receita e EBIT | E16: Margem EBIT Excluindo Empresas de Capital Aberto | O16: =O15/O13 -> 0.090167427 | P16: =P15/P13 -> 0.10727224 | Q16: =Q15/Q13 -> 0.11632318 | R16: =R15/R13 -> 0.13170424 | S16: =S15/S13 -> 0.083218189 | T16: =T15/T13 -> 0.043532793 | V16: =V15/V13 -> 0.074969201 | W16: =W15/W13 -> 0.080522319 | X16: =X15/X13 -> 0.082371715 | Y16: =Y15/Y13 -> 0.082454896 | Z16: =Z15/Z13 -> 0.082451133
A17: Projeções - CG + Capex | E17: Imposto de Renda e CSLL Ex empresas de capital aberto | M17: ='DRE Consolidado'!M42-SUM('DRE - Contas Abertas'!H146:H148) -> 125739 | N17: ='DRE Consolidado'!N42-SUM('DRE - Contas Abertas'!I146:I148) -> -9835 | O17: ='DRE Consolidado'!O42-SUM('DRE - Contas Abertas'!J146:J148) -> -8702 | P17: ='DRE Consolidado'!P42-SUM('DRE - Contas Abertas'!K146:K148) -> -14799 | Q17: ='DRE Consolidado'!Q42-SUM('DRE - Contas Abertas'!L146:L148) -> -151261 | R17: ='DRE Consolidado'!R42-SUM('DRE - Contas Abertas'!M146:M148) -> 5761 | S17: ='DRE Consolidado'!S42-SUM('DRE - Contas Abertas'!N146:N148) -> 196898 | T17: ='DRE Consolidado'!T42-SUM('DRE - Contas Abertas'!O146:O148) -> 191113 | U17: =V17-T17 -> -191113 | V17: =-V23*V15 -> 0 | W17: =-W23*W15 -> -62630.188 | X17: =-X23*X15 -> -68143.163 | Y17: =-Y23*Y15 -> -72352.194 | Z17: =-Z23*Z15 -> -77034.308
A18: Projeções 2023
A19: Processos
A20: Gráficos
K22: 2014 | L22: 2015 | M22: 2016 | N22: 2017 | O22: 2018 | P22: 2019 | Q22: 2020 | R22: 2021 | S22: 2022 | T22: YTD 2023 | U22: YTG 2023E | V22: 2023 | W22: 2024 | X22: 2025 | Y22: 2026 | Z22: 2027 | AA22: Perpetuidade | AB22: ROIC Perp. | AC22: Growth
E23: Alíquota Efetiva Ex Empresas de Capital Aberto | F23: 0.030034188 | G23: -0.02092541 | H23: -0.043315116 | I23: 0.13811998 | J23: -0.59211219 | K23: =IFERROR(IF(K15>0,-K17/K15,"-"),"-") -> - | L23: =IFERROR(IF(L15>0,-L17/L15,"-"),"-") -> - | M23: =IFERROR(IF(M15>0,-M17/M15,"-"),"-") -> - | N23: =IFERROR(IF(N15>0,-N17/N15,"-"),"-") -> - | O23: =IFERROR(IF('DRE Consolidado'!O36>0,-O17/O15,"-"),"-") -> 0.068198561 | P23: =IFERROR(IF('DRE Consolidado'!P36>0,-P17/P15,"-"),"-") -> 0.089776333 | Q23: =IFERROR(IF('DRE Consolidado'!Q36>0,-Q17/Q15,"-"),"-") -> 0.94104655 | R23: =IFERROR(IF('DRE Consolidado'!R36>0,-R17/R15,"-"),"-") -> -0.030932208 | S23: =IFERROR(IF('DRE Consolidado'!S36>0,-S17/S15,"-"),"-") -> -0.61521205 | T23: =IFERROR(IF('DRE Consolidado'!T36>0,-T17/T15,"-"),"-") -> -0.80890625 | U23: =IFERROR(IF(#REF!>0,-#REF!/#REF!,"-"),"-") -> - | V23: 0 | W23: =AVERAGE($O$23:$P$23) -> 0.078987447 | X23: =AVERAGE($O$23:$P$23) -> 0.078987447 | Y23: =AVERAGE($O$23:$P$23) -> 0.078987447 | Z23: =AVERAGE($O$23:$P$23) -> 0.078987447 | AB23: =WACC!P20 -> 0.16112663 | AC23: =(1+'Projeções - CG + Capex'!U37)*(1+'Projeções - CG + Capex'!U38)-1 -> 0.0769568
E24: D&A do Arrendamento Ex empresas de capital aberto | P24: ='Projeções - CG + Capex'!P48-SUM('Projeções - CG + Capex'!P45:P47) -> 17522 | Q24: ='Projeções - CG + Capex'!Q48-SUM('Projeções - CG + Capex'!Q45:Q47) -> -29457 | R24: ='Projeções - CG + Capex'!R48-SUM('Projeções - CG + Capex'!R45:R47) -> 18427 | S24: ='Projeções - CG + Capex'!S48-SUM('Projeções - CG + Capex'!S45:S47) -> -87846 | T24: ='Projeções - CG + Capex'!T48-SUM('Projeções - CG + Capex'!T45:T47) -> 97812 | U24: =V24-SUM(T24:T24) -> 32637.671 | V24: =V25*V13 -> 130449.67 | W24: =W25*W13 -> 139355.73 | X24: =X25*X13 -> 148218.21 | Y24: =Y25*Y13 -> 157214.51 | Z24: =Z25*Z13 -> 167395.95
E25: D&A do Arrendamento como (%) da Receita das empresas de Capital Fechado | P25: =P24/P13 -> 0.011402512 | Q25: =Q24/Q13 -> -0.02131763 | R25: =R24/R13 -> 0.013030691 | S25: =S24/S13 -> -0.022841456 | T25: =T24/T13 -> 0.018022566 | U25: =U24/U13 -> 0.018022566 | V25: =T25 -> 0.018022566 | W25: =AVERAGE($P$25,$R$25,$T$25) -> 0.014151923 | X25: =AVERAGE($P$25,$R$25,$T$25) -> 0.014151923 | Y25: =AVERAGE($P$25,$R$25,$T$25) -> 0.014151923 | Z25: =AVERAGE($P$25,$R$25,$T$25) -> 0.014151923
