Workbook
Name InfImp22: '[1]Dados Complementares'!$F$11
Name InfImp23: '[1]Dados Complementares'!$G$11
Name InfImp24: '[1]Dados Complementares'!$H$11
Name InfImp25: '[1]Dados Complementares'!$I$11
Name InfImp26: '[1]Dados Complementares'!$J$11
Name InfImp27: '[1]Dados Complementares'!$K$11
Name InfImp28: '[1]Dados Complementares'!$L$11
Name InfImp29: '[1]Dados Complementares'!$M$11
Name InfImp30: '[1]Dados Complementares'!$N$11
Name InfImp32: '[1]Dados Complementares'!$P$11
Name PIB26_BRASIL: '[1]Dados Complementares'!$J$14
Name PIB26_CHINA: '[1]Dados Complementares'!$J$15
Name PIB26_INDIA: '[1]Dados Complementares'!$J$16
Name PIB26_MUNDO: '[1]Dados Complementares'!$J$20
Name PIB27_BRASIL: '[1]Dados Complementares'!$K$14
Name PIB27_INDIA: '[1]Dados Complementares'!$K$16

Sheet Dashboard
I3: Raia Drogasil ($RADL3)
A7: Páginas
A8: Dashboard
A9: WACC | E9: Trimestre | F9: 1 | H9: WACC | I9: =I10-0.5% -> 0.11847175 | J9: =((SUM('DRE + DCF'!$P$54,NPV($I9,'DRE + DCF'!$Q$54:$AZ$54,SUM('DRE + DCF'!$BA$54,('DRE + DCF'!$BB$46*(1-((J$18-'Projeções - Receita'!$BA$58)/('DRE + DCF'!$BC$43-'Projeções - Receita'!$BA$58)))*(1+J$18))/($I9-J$18))))/((1+$I9)^((5-$F$9)*3/12)))+SUM($F$13:$F$14))/$F$11 -> 41.506622 | K9: =((SUM('DRE + DCF'!$P$54,NPV($I9,'DRE + DCF'!$Q$54:$AZ$54,SUM('DRE + DCF'!$BA$54,('DRE + DCF'!$BB$46*(1-((K$18-'Projeções - Receita'!$BA$58)/('DRE + DCF'!$BC$43-'Projeções - Receita'!$BA$58)))*(1+K$18))/($I9-K$18))))/((1+$I9)^((5-$F$9)*3/12)))+SUM($F$13:$F$14))/$F$11 -> 42.026797 | L9: =((SUM('DRE + DCF'!$P$54,NPV($I9,'DRE + DCF'!$Q$54:$AZ$54,SUM('DRE + DCF'!$BA$54,('DRE + DCF'!$BB$46*(1-((L$18-'Projeções - Receita'!$BA$58)/('DRE + DCF'!$BC$43-'Projeções - Receita'!$BA$58)))*(1+L$18))/($I9-L$18))))/((1+$I9)^((5-$F$9)*3/12)))+SUM($F$13:$F$14))/$F$11 -> 42.609525 | M9: =((SUM('DRE + DCF'!$P$54,NPV($I9,'DRE + DCF'!$Q$54:$AZ$54,SUM('DRE + DCF'!$BA$54,('DRE + DCF'!$BB$46*(1-((M$18-'Projeções - Receita'!$BA$58)/('DRE + DCF'!$BC$43-'Projeções - Receita'!$BA$58)))*(1+M$18))/($I9-M$18))))/((1+$I9)^((5-$F$9)*3/12)))+SUM($F$13:$F$14))/$F$11 -> 43.267183 | N9: =((SUM('DRE + DCF'!$P$54,NPV($I9,'DRE + DCF'!$Q$54:$AZ$54,SUM('DRE + DCF'!$BA$54,('DRE + DCF'!$BB$46*(1-((N$18-'Projeções - Receita'!$BA$58)/('DRE + DCF'!$BC$43-'Projeções - Receita'!$BA$58)))*(1+N$18))/($I9-N$18))))/((1+$I9)^((5-$F$9)*3/12)))+SUM($F$13:$F$14))/$F$11 -> 44.015641 | O9: =((SUM('DRE + DCF'!$P$54,NPV($I9,'DRE + DCF'!$Q$54:$AZ$54,SUM('DRE + DCF'!$BA$54,('DRE + DCF'!$BB$46*(1-((O$18-'Projeções - Receita'!$BA$58)/('DRE + DCF'!$BC$43-'Projeções - Receita'!$BA$58)))*(1+O$18))/($I9-O$18))))/((1+$I9)^((5-$F$9)*3/12)))+SUM($F$13:$F$14))/$F$11 -> 44.875596 | P9: =((SUM('DRE + DCF'!$P$54,NPV($I9,'DRE + DCF'!$Q$54:$AZ$54,SUM('DRE + DCF'!$BA$54,('DRE + DCF'!$BB$46*(1-((P$18-'Projeções - Receita'!$BA$58)/('DRE + DCF'!$BC$43-'Projeções - Receita'!$BA$58)))*(1+P$18))/($I9-P$18))))/((1+$I9)^((5-$F$9)*3/12)))+SUM($F$13:$F$14))/$F$11 -> 45.87455 | Q9: =((SUM('DRE + DCF'!$P$54,NPV($I9,'DRE + DCF'!$Q$54:$AZ$54,SUM('DRE + DCF'!$BA$54,('DRE + DCF'!$BB$46*(1-((Q$18-'Projeções - Receita'!$BA$58)/('DRE + DCF'!$BC$43-'Projeções - Receita'!$BA$58)))*(1+Q$18))/($I9-Q$18))))/((1+$I9)^((5-$F$9)*3/12)))+SUM($F$13:$F$14))/$F$11 -> 47.049859 | ... S9: =((SUM('DRE + DCF'!$P$54,NPV($I9,'DRE + DCF'!$Q$54:$AZ$54,SUM('DRE + DCF'!$BA$54,('DRE + DCF'!$BB$46*(1-((S$18-'Projeções - Receita'!$BA$58)/('DRE + DCF'!$BC$43-'Projeções - Receita'!$BA$58)))*(1+S$18))/($I9-S$18))))/((1+$I9)^((5-$F$9)*3/12)))+SUM($F$13:$F$14))/$F$11 -> 50.160515
A10: DRE + DCF | E10: Ticker | F10: RADL3 | I10: =I11-0.5% -> 0.12347175 | J10: =((SUM('DRE + DCF'!$P$54,NPV($I10,'DRE + DCF'!$Q$54:$AZ$54,SUM('DRE + DCF'!$BA$54,('DRE + DCF'!$BB$46*(1-((J$18-'Projeções - Receita'!$BA$58)/('DRE + DCF'!$BC$43-'Projeções - Receita'!$BA$58)))*(1+J$18))/($I10-J$18))))/((1+$I10)^((5-$F$9)*3/12)))+SUM($F$13:$F$14))/$F$11 -> 35.777812 | K10: =((SUM('DRE + DCF'!$P$54,NPV($I10,'DRE + DCF'!$Q$54:$AZ$54,SUM('DRE + DCF'!$BA$54,('DRE + DCF'!$BB$46*(1-((K$18-'Projeções - Receita'!$BA$58)/('DRE + DCF'!$BC$43-'Projeções - Receita'!$BA$58)))*(1+K$18))/($I10-K$18))))/((1+$I10)^((5-$F$9)*3/12)))+SUM($F$13:$F$14))/$F$11 -> 36.107173 | L10: =((SUM('DRE + DCF'!$P$54,NPV($I10,'DRE + DCF'!$Q$54:$AZ$54,SUM('DRE + DCF'!$BA$54,('DRE + DCF'!$BB$46*(1-((L$18-'Projeções - Receita'!$BA$58)/('DRE + DCF'!$BC$43-'Projeções - Receita'!$BA$58)))*(1+L$18))/($I10-L$18))))/((1+$I10)^((5-$F$9)*3/12)))+SUM($F$13:$F$14))/$F$11 -> 36.471437 | M10: =((SUM('DRE + DCF'!$P$54,NPV($I10,'DRE + DCF'!$Q$54:$AZ$54,SUM('DRE + DCF'!$BA$54,('DRE + DCF'!$BB$46*(1-((M$18-'Projeções - Receita'!$BA$58)/('DRE + DCF'!$BC$43-'Projeções - Receita'!$BA$58)))*(1+M$18))/($I10-M$18))))/((1+$I10)^((5-$F$9)*3/12)))+SUM($F$13:$F$14))/$F$11 -> 36.876708 | N10: =((SUM('DRE + DCF'!$P$54,NPV($I10,'DRE + DCF'!$Q$54:$AZ$54,SUM('DRE + DCF'!$BA$54,('DRE + DCF'!$BB$46*(1-((N$18-'Projeções - Receita'!$BA$58)/('DRE + DCF'!$BC$43-'Projeções - Receita'!$BA$58)))*(1+N$18))/($I10-N$18))))/((1+$I10)^((5-$F$9)*3/12)))+SUM($F$13:$F$14))/$F$11 -> 37.330595 | O10: =((SUM('DRE + DCF'!$P$54,NPV($I10,'DRE + DCF'!$Q$54:$AZ$54,SUM('DRE + DCF'!$BA$54,('DRE + DCF'!$BB$46*(1-((O$18-'Projeções - Receita'!$BA$58)/('DRE + DCF'!$BC$43-'Projeções - Receita'!$BA$58)))*(1+O$18))/($I10-O$18))))/((1+$I10)^((5-$F$9)*3/12)))+SUM($F$13:$F$14))/$F$11 -> 37.842719 | P10: =((SUM('DRE + DCF'!$P$54,NPV($I10,'DRE + DCF'!$Q$54:$AZ$54,SUM('DRE + DCF'!$BA$54,('DRE + DCF'!$BB$46*(1-((P$18-'Projeções - Receita'!$BA$58)/('DRE + DCF'!$BC$43-'Projeções - Receita'!$BA$58)))*(1+P$18))/($I10-P$18))))/((1+$I10)^((5-$F$9)*3/12)))+SUM($F$13:$F$14))/$F$11 -> 38.425415 | Q10: =((SUM('DRE + DCF'!$P$54,NPV($I10,'DRE + DCF'!$Q$54:$AZ$54,SUM('DRE + DCF'!$BA$54,('DRE + DCF'!$BB$46*(1-((Q$18-'Projeções - Receita'!$BA$58)/('DRE + DCF'!$BC$43-'Projeções - Receita'!$BA$58)))*(1+Q$18))/($I10-Q$18))))/((1+$I10)^((5-$F$9)*3/12)))+SUM($F$13:$F$14))/$F$11 -> 39.094767 | ... S10: =((SUM('DRE + DCF'!$P$54,NPV($I10,'DRE + DCF'!$Q$54:$AZ$54,SUM('DRE + DCF'!$BA$54,('DRE + DCF'!$BB$46*(1-((S$18-'Projeções - Receita'!$BA$58)/('DRE + DCF'!$BC$43-'Projeções - Receita'!$BA$58)))*(1+S$18))/($I10-S$18))))/((1+$I10)^((5-$F$9)*3/12)))+SUM($F$13:$F$14))/$F$11 -> 40.786603
A11: DRE - Contas Abertas | E11: Ações Emitidas (mil) | F11: 1647747.4 | I11: =I12-0.5% -> 0.12847175 | J11: =((SUM('DRE + DCF'!$P$54,NPV($I11,'DRE + DCF'!$Q$54:$AZ$54,SUM('DRE + DCF'!$BA$54,('DRE + DCF'!$BB$46*(1-((J$18-'Projeções - Receita'!$BA$58)/('DRE + DCF'!$BC$43-'Projeções - Receita'!$BA$58)))*(1+J$18))/($I11-J$18))))/((1+$I11)^((5-$F$9)*3/12)))+SUM($F$13:$F$14))/$F$11 -> 31.208886 | K11: =((SUM('DRE + DCF'!$P$54,NPV($I11,'DRE + DCF'!$Q$54:$AZ$54,SUM('DRE + DCF'!$BA$54,('DRE + DCF'!$BB$46*(1-((K$18-'Projeções - Receita'!$BA$58)/('DRE + DCF'!$BC$43-'Projeções - Receita'!$BA$58)))*(1+K$18))/($I11-K$18))))/((1+$I11)^((5-$F$9)*3/12)))+SUM($F$13:$F$14))/$F$11 -> 31.420764 | L11: =((SUM('DRE + DCF'!$P$54,NPV($I11,'DRE + DCF'!$Q$54:$AZ$54,SUM('DRE + DCF'!$BA$54,('DRE + DCF'!$BB$46*(1-((L$18-'Projeções - Receita'!$BA$58)/('DRE + DCF'!$BC$43-'Projeções - Receita'!$BA$58)))*(1+L$18))/($I11-L$18))))/((1+$I11)^((5-$F$9)*3/12)))+SUM($F$13:$F$14))/$F$11 -> 31.652621 | M11: =((SUM('DRE + DCF'!$P$54,NPV($I11,'DRE + DCF'!$Q$54:$AZ$54,SUM('DRE + DCF'!$BA$54,('DRE + DCF'!$BB$46*(1-((M$18-'Projeções - Receita'!$BA$58)/('DRE + DCF'!$BC$43-'Projeções - Receita'!$BA$58)))*(1+M$18))/($I11-M$18))))/((1+$I11)^((5-$F$9)*3/12)))+SUM($F$13:$F$14))/$F$11 -> 31.907585 | N11: =((SUM('DRE + DCF'!$P$54,NPV($I11,'DRE + DCF'!$Q$54:$AZ$54,SUM('DRE + DCF'!$BA$54,('DRE + DCF'!$BB$46*(1-((N$18-'Projeções - Receita'!$BA$58)/('DRE + DCF'!$BC$43-'Projeções - Receita'!$BA$58)))*(1+N$18))/($I11-N$18))))/((1+$I11)^((5-$F$9)*3/12)))+SUM($F$13:$F$14))/$F$11 -> 32.189473 | O11: =((SUM('DRE + DCF'!$P$54,NPV($I11,'DRE + DCF'!$Q$54:$AZ$54,SUM('DRE + DCF'!$BA$54,('DRE + DCF'!$BB$46*(1-((O$18-'Projeções - Receita'!$BA$58)/('DRE + DCF'!$BC$43-'Projeções - Receita'!$BA$58)))*(1+O$18))/($I11-O$18))))/((1+$I11)^((5-$F$9)*3/12)))+SUM($F$13:$F$14))/$F$11 -> 32.502992 | P11: =((SUM('DRE + DCF'!$P$54,NPV($I11,'DRE + DCF'!$Q$54:$AZ$54,SUM('DRE + DCF'!$BA$54,('DRE + DCF'!$BB$46*(1-((P$18-'Projeções - Receita'!$BA$58)/('DRE + DCF'!$BC$43-'Projeções - Receita'!$BA$58)))*(1+P$18))/($I11-P$18))))/((1+$I11)^((5-$F$9)*3/12)))+SUM($F$13:$F$14))/$F$11 -> 32.854011 | Q11: =((SUM('DRE + DCF'!$P$54,NPV($I11,'DRE + DCF'!$Q$54:$AZ$54,SUM('DRE + DCF'!$BA$54,('DRE + DCF'!$BB$46*(1-((Q$18-'Projeções - Receita'!$BA$58)/('DRE + DCF'!$BC$43-'Projeções - Receita'!$BA$58)))*(1+Q$18))/($I11-Q$18))))/((1+$I11)^((5-$F$9)*3/12)))+SUM($F$13:$F$14))/$F$11 -> 33.249951 | ... S11: =((SUM('DRE + DCF'!$P$54,NPV($I11,'DRE + DCF'!$Q$54:$AZ$54,SUM('DRE + DCF'!$BA$54,('DRE + DCF'!$BB$46*(1-((S$18-'Projeções - Receita'!$BA$58)/('DRE + DCF'!$BC$43-'Projeções - Receita'!$BA$58)))*(1+S$18))/($I11-S$18))))/((1+$I11)^((5-$F$9)*3/12)))+SUM($F$13:$F$14))/$F$11 -> 34.217549
A12: Balanço Patrimonial | E12: Valor da Empresa (mil) | F12: =SUM('DRE + DCF'!P56:BB56) -> 42241218 | I12: =I13-0.5% -> 0.13347175 | J12: =((SUM('DRE + DCF'!$P$54,NPV($I12,'DRE + DCF'!$Q$54:$AZ$54,SUM('DRE + DCF'!$BA$54,('DRE + DCF'!$BB$46*(1-((J$18-'Projeções - Receita'!$BA$58)/('DRE + DCF'!$BC$43-'Projeções - Receita'!$BA$58)))*(1+J$18))/($I12-J$18))))/((1+$I12)^((5-$F$9)*3/12)))+SUM($F$13:$F$14))/$F$11 -> 27.496603 | K12: =((SUM('DRE + DCF'!$P$54,NPV($I12,'DRE + DCF'!$Q$54:$AZ$54,SUM('DRE + DCF'!$BA$54,('DRE + DCF'!$BB$46*(1-((K$18-'Projeções - Receita'!$BA$58)/('DRE + DCF'!$BC$43-'Projeções - Receita'!$BA$58)))*(1+K$18))/($I12-K$18))))/((1+$I12)^((5-$F$9)*3/12)))+SUM($F$13:$F$14))/$F$11 -> 27.634439 | L12: =((SUM('DRE + DCF'!$P$54,NPV($I12,'DRE + DCF'!$Q$54:$AZ$54,SUM('DRE + DCF'!$BA$54,('DRE + DCF'!$BB$46*(1-((L$18-'Projeções - Receita'!$BA$58)/('DRE + DCF'!$BC$43-'Projeções - Receita'!$BA$58)))*(1+L$18))/($I12-L$18))))/((1+$I12)^((5-$F$9)*3/12)))+SUM($F$13:$F$14))/$F$11 -> 27.783915 | M12: =((SUM('DRE + DCF'!$P$54,NPV($I12,'DRE + DCF'!$Q$54:$AZ$54,SUM('DRE + DCF'!$BA$54,('DRE + DCF'!$BB$46*(1-((M$18-'Projeções - Receita'!$BA$58)/('DRE + DCF'!$BC$43-'Projeções - Receita'!$BA$58)))*(1+M$18))/($I12-M$18))))/((1+$I12)^((5-$F$9)*3/12)))+SUM($F$13:$F$14))/$F$11 -> 27.946682 | N12: =((SUM('DRE + DCF'!$P$54,NPV($I12,'DRE + DCF'!$Q$54:$AZ$54,SUM('DRE + DCF'!$BA$54,('DRE + DCF'!$BB$46*(1-((N$18-'Projeções - Receita'!$BA$58)/('DRE + DCF'!$BC$43-'Projeções - Receita'!$BA$58)))*(1+N$18))/($I12-N$18))))/((1+$I12)^((5-$F$9)*3/12)))+SUM($F$13:$F$14))/$F$11 -> 28.124717 | O12: =((SUM('DRE + DCF'!$P$54,NPV($I12,'DRE + DCF'!$Q$54:$AZ$54,SUM('DRE + DCF'!$BA$54,('DRE + DCF'!$BB$46*(1-((O$18-'Projeções - Receita'!$BA$58)/('DRE + DCF'!$BC$43-'Projeções - Receita'!$BA$58)))*(1+O$18))/($I12-O$18))))/((1+$I12)^((5-$F$9)*3/12)))+SUM($F$13:$F$14))/$F$11 -> 28.320411 | P12: =((SUM('DRE + DCF'!$P$54,NPV($I12,'DRE + DCF'!$Q$54:$AZ$54,SUM('DRE + DCF'!$BA$54,('DRE + DCF'!$BB$46*(1-((P$18-'Projeções - Receita'!$BA$58)/('DRE + DCF'!$BC$43-'Projeções - Receita'!$BA$58)))*(1+P$18))/($I12-P$18))))/((1+$I12)^((5-$F$9)*3/12)))+SUM($F$13:$F$14))/$F$11 -> 28.53668 | Q12: =((SUM('DRE + DCF'!$P$54,NPV($I12,'DRE + DCF'!$Q$54:$AZ$54,SUM('DRE + DCF'!$BA$54,('DRE + DCF'!$BB$46*(1-((Q$18-'Projeções - Receita'!$BA$58)/('DRE + DCF'!$BC$43-'Projeções - Receita'!$BA$58)))*(1+Q$18))/($I12-Q$18))))/((1+$I12)^((5-$F$9)*3/12)))+SUM($F$13:$F$14))/$F$11 -> 28.77712 | ... S12: =((SUM('DRE + DCF'!$P$54,NPV($I12,'DRE + DCF'!$Q$54:$AZ$54,SUM('DRE + DCF'!$BA$54,('DRE + DCF'!$BB$46*(1-((S$18-'Projeções - Receita'!$BA$58)/('DRE + DCF'!$BC$43-'Projeções - Receita'!$BA$58)))*(1+S$18))/($I12-S$18))))/((1+$I12)^((5-$F$9)*3/12)))+SUM($F$13:$F$14))/$F$11 -> 29.349648
A13: Painel de Índices | E13: Dívida (mil) | F13: =-WACC!F19 -> -6057912 | I13: =WACC!P20 -> 0.13847175 | J13: =((SUM('DRE + DCF'!$P$54,NPV($I13,'DRE + DCF'!$Q$54:$AZ$54,SUM('DRE + DCF'!$BA$54,('DRE + DCF'!$BB$46*(1-((J$18-'Projeções - Receita'!$BA$58)/('DRE + DCF'!$BC$43-'Projeções - Receita'!$BA$58)))*(1+J$18))/($I13-J$18))))/((1+$I13)^((5-$F$9)*3/12)))+SUM($F$13:$F$14))/$F$11 -> 24.432465 | K13: =((SUM('DRE + DCF'!$P$54,NPV($I13,'DRE + DCF'!$Q$54:$AZ$54,SUM('DRE + DCF'!$BA$54,('DRE + DCF'!$BB$46*(1-((K$18-'Projeções - Receita'!$BA$58)/('DRE + DCF'!$BC$43-'Projeções - Receita'!$BA$58)))*(1+K$18))/($I13-K$18))))/((1+$I13)^((5-$F$9)*3/12)))+SUM($F$13:$F$14))/$F$11 -> 24.522777 | L13: =((SUM('DRE + DCF'!$P$54,NPV($I13,'DRE + DCF'!$Q$54:$AZ$54,SUM('DRE + DCF'!$BA$54,('DRE + DCF'!$BB$46*(1-((L$18-'Projeções - Receita'!$BA$58)/('DRE + DCF'!$BC$43-'Projeções - Receita'!$BA$58)))*(1+L$18))/($I13-L$18))))/((1+$I13)^((5-$F$9)*3/12)))+SUM($F$13:$F$14))/$F$11 -> 24.619944 | M13: =((SUM('DRE + DCF'!$P$54,NPV($I13,'DRE + DCF'!$Q$54:$AZ$54,SUM('DRE + DCF'!$BA$54,('DRE + DCF'!$BB$46*(1-((M$18-'Projeções - Receita'!$BA$58)/('DRE + DCF'!$BC$43-'Projeções - Receita'!$BA$58)))*(1+M$18))/($I13-M$18))))/((1+$I13)^((5-$F$9)*3/12)))+SUM($F$13:$F$14))/$F$11 -> 24.724855 | N13: =((SUM('DRE + DCF'!$P$54,NPV($I13,'DRE + DCF'!$Q$54:$AZ$54,SUM('DRE + DCF'!$BA$54,('DRE + DCF'!$BB$46*(1-((N$18-'Projeções - Receita'!$BA$58)/('DRE + DCF'!$BC$43-'Projeções - Receita'!$BA$58)))*(1+N$18))/($I13-N$18))))/((1+$I13)^((5-$F$9)*3/12)))+SUM($F$13:$F$14))/$F$11 -> 24.838559 | O13: =((SUM('DRE + DCF'!$P$54,NPV($I13,'DRE + DCF'!$Q$54:$AZ$54,SUM('DRE + DCF'!$BA$54,('DRE + DCF'!$BB$46*(1-((O$18-'Projeções - Receita'!$BA$58)/('DRE + DCF'!$BC$43-'Projeções - Receita'!$BA$58)))*(1+O$18))/($I13-O$18))))/((1+$I13)^((5-$F$9)*3/12)))+SUM($F$13:$F$14))/$F$11 -> 24.962301 | P13: =((SUM('DRE + DCF'!$P$54,NPV($I13,'DRE + DCF'!$Q$54:$AZ$54,SUM('DRE + DCF'!$BA$54,('DRE + DCF'!$BB$46*(1-((P$18-'Projeções - Receita'!$BA$58)/('DRE + DCF'!$BC$43-'Projeções - Receita'!$BA$58)))*(1+P$18))/($I13-P$18))))/((1+$I13)^((5-$F$9)*3/12)))+SUM($F$13:$F$14))/$F$11 -> 25.097576 | Q13: =((SUM('DRE + DCF'!$P$54,NPV($I13,'DRE + DCF'!$Q$54:$AZ$54,SUM('DRE + DCF'!$BA$54,('DRE + DCF'!$BB$46*(1-((Q$18-'Projeções - Receita'!$BA$58)/('DRE + DCF'!$BC$43-'Projeções - Receita'!$BA$58)))*(1+Q$18))/($I13-Q$18))))/((1+$I13)^((5-$F$9)*3/12)))+SUM($F$13:$F$14))/$F$11 -> 25.246188 | ... S13: =((SUM('DRE + DCF'!$P$54,NPV($I13,'DRE + DCF'!$Q$54:$AZ$54,SUM('DRE + DCF'!$BA$54,('DRE + DCF'!$BB$46*(1-((S$18-'Projeções - Receita'!$BA$58)/('DRE + DCF'!$BC$43-'Projeções - Receita'!$BA$58)))*(1+S$18))/($I13-S$18))))/((1+$I13)^((5-$F$9)*3/12)))+SUM($F$13:$F$14))/$F$11 -> 25.592752
A14: Provisões e Processos | E14: Ativos Não-Operacionais | F14: ='Balanço Patrimonial'!O17+'Balanço Patrimonial'!O18 -> 100884.59 | I14: =I13+0.5% -> 0.14347175 | J14: =((SUM('DRE + DCF'!$P$54,NPV($I14,'DRE + DCF'!$Q$54:$AZ$54,SUM('DRE + DCF'!$BA$54,('DRE + DCF'!$BB$46*(1-((J$18-'Projeções - Receita'!$BA$58)/('DRE + DCF'!$BC$43-'Projeções - Receita'!$BA$58)))*(1+J$18))/($I14-J$18))))/((1+$I14)^((5-$F$9)*3/12)))+SUM($F$13:$F$14))/$F$11 -> 21.868792 | K14: =((SUM('DRE + DCF'!$P$54,NPV($I14,'DRE + DCF'!$Q$54:$AZ$54,SUM('DRE + DCF'!$BA$54,('DRE + DCF'!$BB$46*(1-((K$18-'Projeções - Receita'!$BA$58)/('DRE + DCF'!$BC$43-'Projeções - Receita'!$BA$58)))*(1+K$18))/($I14-K$18))))/((1+$I14)^((5-$F$9)*3/12)))+SUM($F$13:$F$14))/$F$11 -> 21.928163 | L14: =((SUM('DRE + DCF'!$P$54,NPV($I14,'DRE + DCF'!$Q$54:$AZ$54,SUM('DRE + DCF'!$BA$54,('DRE + DCF'!$BB$46*(1-((L$18-'Projeções - Receita'!$BA$58)/('DRE + DCF'!$BC$43-'Projeções - Receita'!$BA$58)))*(1+L$18))/($I14-L$18))))/((1+$I14)^((5-$F$9)*3/12)))+SUM($F$13:$F$14))/$F$11 -> 21.991588 | M14: =((SUM('DRE + DCF'!$P$54,NPV($I14,'DRE + DCF'!$Q$54:$AZ$54,SUM('DRE + DCF'!$BA$54,('DRE + DCF'!$BB$46*(1-((M$18-'Projeções - Receita'!$BA$58)/('DRE + DCF'!$BC$43-'Projeções - Receita'!$BA$58)))*(1+M$18))/($I14-M$18))))/((1+$I14)^((5-$F$9)*3/12)))+SUM($F$13:$F$14))/$F$11 -> 22.059552 | N14: =((SUM('DRE + DCF'!$P$54,NPV($I14,'DRE + DCF'!$Q$54:$AZ$54,SUM('DRE + DCF'!$BA$54,('DRE + DCF'!$BB$46*(1-((N$18-'Projeções - Receita'!$BA$58)/('DRE + DCF'!$BC$43-'Projeções - Receita'!$BA$58)))*(1+N$18))/($I14-N$18))))/((1+$I14)^((5-$F$9)*3/12)))+SUM($F$13:$F$14))/$F$11 -> 22.132616 | O14: =((SUM('DRE + DCF'!$P$54,NPV($I14,'DRE + DCF'!$Q$54:$AZ$54,SUM('DRE + DCF'!$BA$54,('DRE + DCF'!$BB$46*(1-((O$18-'Projeções - Receita'!$BA$58)/('DRE + DCF'!$BC$43-'Projeções - Receita'!$BA$58)))*(1+O$18))/($I14-O$18))))/((1+$I14)^((5-$F$9)*3/12)))+SUM($F$13:$F$14))/$F$11 -> 22.211443 | P14: =((SUM('DRE + DCF'!$P$54,NPV($I14,'DRE + DCF'!$Q$54:$AZ$54,SUM('DRE + DCF'!$BA$54,('DRE + DCF'!$BB$46*(1-((P$18-'Projeções - Receita'!$BA$58)/('DRE + DCF'!$BC$43-'Projeções - Receita'!$BA$58)))*(1+P$18))/($I14-P$18))))/((1+$I14)^((5-$F$9)*3/12)))+SUM($F$13:$F$14))/$F$11 -> 22.296811 | Q14: =((SUM('DRE + DCF'!$P$54,NPV($I14,'DRE + DCF'!$Q$54:$AZ$54,SUM('DRE + DCF'!$BA$54,('DRE + DCF'!$BB$46*(1-((Q$18-'Projeções - Receita'!$BA$58)/('DRE + DCF'!$BC$43-'Projeções - Receita'!$BA$58)))*(1+Q$18))/($I14-Q$18))))/((1+$I14)^((5-$F$9)*3/12)))+SUM($F$13:$F$14))/$F$11 -> 22.389649 | ... S14: =((SUM('DRE + DCF'!$P$54,NPV($I14,'DRE + DCF'!$Q$54:$AZ$54,SUM('DRE + DCF'!$BA$54,('DRE + DCF'!$BB$46*(1-((S$18-'Projeções - Receita'!$BA$58)/('DRE + DCF'!$BC$43-'Projeções - Receita'!$BA$58)))*(1+S$18))/($I14-S$18))))/((1+$I14)^((5-$F$9)*3/12)))+SUM($F$13:$F$14))/$F$11 -> 22.602409
A15: Projeções - Receita | E15: Valor da Ação | F15: =SUM(F12:F14)/F11 -> 22.020481 | I15: =I14+0.5% -> 0.14847175 | J15: =((SUM('DRE + DCF'!$P$54,NPV($I15,'DRE + DCF'!$Q$54:$AZ$54,SUM('DRE + DCF'!$BA$54,('DRE + DCF'!$BB$46*(1-((J$18-'Projeções - Receita'!$BA$58)/('DRE + DCF'!$BC$43-'Projeções - Receita'!$BA$58)))*(1+J$18))/($I15-J$18))))/((1+$I15)^((5-$F$9)*3/12)))+SUM($F$13:$F$14))/$F$11 -> 19.698331 | K15: =((SUM('DRE + DCF'!$P$54,NPV($I15,'DRE + DCF'!$Q$54:$AZ$54,SUM('DRE + DCF'!$BA$54,('DRE + DCF'!$BB$46*(1-((K$18-'Projeções - Receita'!$BA$58)/('DRE + DCF'!$BC$43-'Projeções - Receita'!$BA$58)))*(1+K$18))/($I15-K$18))))/((1+$I15)^((5-$F$9)*3/12)))+SUM($F$13:$F$14))/$F$11 -> 19.73734 | L15: =((SUM('DRE + DCF'!$P$54,NPV($I15,'DRE + DCF'!$Q$54:$AZ$54,SUM('DRE + DCF'!$BA$54,('DRE + DCF'!$BB$46*(1-((L$18-'Projeções - Receita'!$BA$58)/('DRE + DCF'!$BC$43-'Projeções - Receita'!$BA$58)))*(1+L$18))/($I15-L$18))))/((1+$I15)^((5-$F$9)*3/12)))+SUM($F$13:$F$14))/$F$11 -> 19.778738 | M15: =((SUM('DRE + DCF'!$P$54,NPV($I15,'DRE + DCF'!$Q$54:$AZ$54,SUM('DRE + DCF'!$BA$54,('DRE + DCF'!$BB$46*(1-((M$18-'Projeções - Receita'!$BA$58)/('DRE + DCF'!$BC$43-'Projeções - Receita'!$BA$58)))*(1+M$18))/($I15-M$18))))/((1+$I15)^((5-$F$9)*3/12)))+SUM($F$13:$F$14))/$F$11 -> 19.822789 | N15: =((SUM('DRE + DCF'!$P$54,NPV($I15,'DRE + DCF'!$Q$54:$AZ$54,SUM('DRE + DCF'!$BA$54,('DRE + DCF'!$BB$46*(1-((N$18-'Projeções - Receita'!$BA$58)/('DRE + DCF'!$BC$43-'Projeções - Receita'!$BA$58)))*(1+N$18))/($I15-N$18))))/((1+$I15)^((5-$F$9)*3/12)))+SUM($F$13:$F$14))/$F$11 -> 19.869797 | O15: =((SUM('DRE + DCF'!$P$54,NPV($I15,'DRE + DCF'!$Q$54:$AZ$54,SUM('DRE + DCF'!$BA$54,('DRE + DCF'!$BB$46*(1-((O$18-'Projeções - Receita'!$BA$58)/('DRE + DCF'!$BC$43-'Projeções - Receita'!$BA$58)))*(1+O$18))/($I15-O$18))))/((1+$I15)^((5-$F$9)*3/12)))+SUM($F$13:$F$14))/$F$11 -> 19.920115 | P15: =((SUM('DRE + DCF'!$P$54,NPV($I15,'DRE + DCF'!$Q$54:$AZ$54,SUM('DRE + DCF'!$BA$54,('DRE + DCF'!$BB$46*(1-((P$18-'Projeções - Receita'!$BA$58)/('DRE + DCF'!$BC$43-'Projeções - Receita'!$BA$58)))*(1+P$18))/($I15-P$18))))/((1+$I15)^((5-$F$9)*3/12)))+SUM($F$13:$F$14))/$F$11 -> 19.974153 | Q15: =((SUM('DRE + DCF'!$P$54,NPV($I15,'DRE + DCF'!$Q$54:$AZ$54,SUM('DRE + DCF'!$BA$54,('DRE + DCF'!$BB$46*(1-((Q$18-'Projeções - Receita'!$BA$58)/('DRE + DCF'!$BC$43-'Projeções - Receita'!$BA$58)))*(1+Q$18))/($I15-Q$18))))/((1+$I15)^((5-$F$9)*3/12)))+SUM($F$13:$F$14))/$F$11 -> 20.032395 | ... S15: =((SUM('DRE + DCF'!$P$54,NPV($I15,'DRE + DCF'!$Q$54:$AZ$54,SUM('DRE + DCF'!$BA$54,('DRE + DCF'!$BB$46*(1-((S$18-'Projeções - Receita'!$BA$58)/('DRE + DCF'!$BC$43-'Projeções - Receita'!$BA$58)))*(1+S$18))/($I15-S$18))))/((1+$I15)^((5-$F$9)*3/12)))+SUM($F$13:$F$14))/$F$11 -> 20.163869
A16: Projeções - Capex | E16: Cotação | F16: 25.35 | I16: =I15+0.5% -> 0.15347175 | J16: =((SUM('DRE + DCF'!$P$54,NPV($I16,'DRE + DCF'!$Q$54:$AZ$54,SUM('DRE + DCF'!$BA$54,('DRE + DCF'!$BB$46*(1-((J$18-'Projeções - Receita'!$BA$58)/('DRE + DCF'!$BC$43-'Projeções - Receita'!$BA$58)))*(1+J$18))/($I16-J$18))))/((1+$I16)^((5-$F$9)*3/12)))+SUM($F$13:$F$14))/$F$11 -> 17.841514 | K16: =((SUM('DRE + DCF'!$P$54,NPV($I16,'DRE + DCF'!$Q$54:$AZ$54,SUM('DRE + DCF'!$BA$54,('DRE + DCF'!$BB$46*(1-((K$18-'Projeções - Receita'!$BA$58)/('DRE + DCF'!$BC$43-'Projeções - Receita'!$BA$58)))*(1+K$18))/($I16-K$18))))/((1+$I16)^((5-$F$9)*3/12)))+SUM($F$13:$F$14))/$F$11 -> 17.867017 | L16: =((SUM('DRE + DCF'!$P$54,NPV($I16,'DRE + DCF'!$Q$54:$AZ$54,SUM('DRE + DCF'!$BA$54,('DRE + DCF'!$BB$46*(1-((L$18-'Projeções - Receita'!$BA$58)/('DRE + DCF'!$BC$43-'Projeções - Receita'!$BA$58)))*(1+L$18))/($I16-L$18))))/((1+$I16)^((5-$F$9)*3/12)))+SUM($F$13:$F$14))/$F$11 -> 17.893908 | M16: =((SUM('DRE + DCF'!$P$54,NPV($I16,'DRE + DCF'!$Q$54:$AZ$54,SUM('DRE + DCF'!$BA$54,('DRE + DCF'!$BB$46*(1-((M$18-'Projeções - Receita'!$BA$58)/('DRE + DCF'!$BC$43-'Projeções - Receita'!$BA$58)))*(1+M$18))/($I16-M$18))))/((1+$I16)^((5-$F$9)*3/12)))+SUM($F$13:$F$14))/$F$11 -> 17.922331 | N16: =((SUM('DRE + DCF'!$P$54,NPV($I16,'DRE + DCF'!$Q$54:$AZ$54,SUM('DRE + DCF'!$BA$54,('DRE + DCF'!$BB$46*(1-((N$18-'Projeções - Receita'!$BA$58)/('DRE + DCF'!$BC$43-'Projeções - Receita'!$BA$58)))*(1+N$18))/($I16-N$18))))/((1+$I16)^((5-$F$9)*3/12)))+SUM($F$13:$F$14))/$F$11 -> 17.95245 | O16: =((SUM('DRE + DCF'!$P$54,NPV($I16,'DRE + DCF'!$Q$54:$AZ$54,SUM('DRE + DCF'!$BA$54,('DRE + DCF'!$BB$46*(1-((O$18-'Projeções - Receita'!$BA$58)/('DRE + DCF'!$BC$43-'Projeções - Receita'!$BA$58)))*(1+O$18))/($I16-O$18))))/((1+$I16)^((5-$F$9)*3/12)))+SUM($F$13:$F$14))/$F$11 -> 17.984452 | P16: =((SUM('DRE + DCF'!$P$54,NPV($I16,'DRE + DCF'!$Q$54:$AZ$54,SUM('DRE + DCF'!$BA$54,('DRE + DCF'!$BB$46*(1-((P$18-'Projeções - Receita'!$BA$58)/('DRE + DCF'!$BC$43-'Projeções - Receita'!$BA$58)))*(1+P$18))/($I16-P$18))))/((1+$I16)^((5-$F$9)*3/12)))+SUM($F$13:$F$14))/$F$11 -> 18.018552 | Q16: =((SUM('DRE + DCF'!$P$54,NPV($I16,'DRE + DCF'!$Q$54:$AZ$54,SUM('DRE + DCF'!$BA$54,('DRE + DCF'!$BB$46*(1-((Q$18-'Projeções - Receita'!$BA$58)/('DRE + DCF'!$BC$43-'Projeções - Receita'!$BA$58)))*(1+Q$18))/($I16-Q$18))))/((1+$I16)^((5-$F$9)*3/12)))+SUM($F$13:$F$14))/$F$11 -> 18.055001 | ... S16: =((SUM('DRE + DCF'!$P$54,NPV($I16,'DRE + DCF'!$Q$54:$AZ$54,SUM('DRE + DCF'!$BA$54,('DRE + DCF'!$BB$46*(1-((S$18-'Projeções - Receita'!$BA$58)/('DRE + DCF'!$BC$43-'Projeções - Receita'!$BA$58)))*(1+S$18))/($I16-S$18))))/((1+$I16)^((5-$F$9)*3/12)))+SUM($F$13:$F$14))/$F$11 -> 18.136162
A17: Projeções 2022 | E17: =IF(F17=0,"",IF(F17>0,"Upside","Downside")) -> Downside | F17: =F15/F16-1 -> -0.13134198 | I17: =I16+0.5% -> 0.15847175 | J17: =((SUM('DRE + DCF'!$P$54,NPV($I17,'DRE + DCF'!$Q$54:$AZ$54,SUM('DRE + DCF'!$BA$54,('DRE + DCF'!$BB$46*(1-((J$18-'Projeções - Receita'!$BA$58)/('DRE + DCF'!$BC$43-'Projeções - Receita'!$BA$58)))*(1+J$18))/($I17-J$18))))/((1+$I17)^((5-$F$9)*3/12)))+SUM($F$13:$F$14))/$F$11 -> 16.238212 | K17: =((SUM('DRE + DCF'!$P$54,NPV($I17,'DRE + DCF'!$Q$54:$AZ$54,SUM('DRE + DCF'!$BA$54,('DRE + DCF'!$BB$46*(1-((K$18-'Projeções - Receita'!$BA$58)/('DRE + DCF'!$BC$43-'Projeções - Receita'!$BA$58)))*(1+K$18))/($I17-K$18))))/((1+$I17)^((5-$F$9)*3/12)))+SUM($F$13:$F$14))/$F$11 -> 16.254709 | L17: =((SUM('DRE + DCF'!$P$54,NPV($I17,'DRE + DCF'!$Q$54:$AZ$54,SUM('DRE + DCF'!$BA$54,('DRE + DCF'!$BB$46*(1-((L$18-'Projeções - Receita'!$BA$58)/('DRE + DCF'!$BC$43-'Projeções - Receita'!$BA$58)))*(1+L$18))/($I17-L$18))))/((1+$I17)^((5-$F$9)*3/12)))+SUM($F$13:$F$14))/$F$11 -> 16.271992 | M17: =((SUM('DRE + DCF'!$P$54,NPV($I17,'DRE + DCF'!$Q$54:$AZ$54,SUM('DRE + DCF'!$BA$54,('DRE + DCF'!$BB$46*(1-((M$18-'Projeções - Receita'!$BA$58)/('DRE + DCF'!$BC$43-'Projeções - Receita'!$BA$58)))*(1+M$18))/($I17-M$18))))/((1+$I17)^((5-$F$9)*3/12)))+SUM($F$13:$F$14))/$F$11 -> 16.290136 | N17: =((SUM('DRE + DCF'!$P$54,NPV($I17,'DRE + DCF'!$Q$54:$AZ$54,SUM('DRE + DCF'!$BA$54,('DRE + DCF'!$BB$46*(1-((N$18-'Projeções - Receita'!$BA$58)/('DRE + DCF'!$BC$43-'Projeções - Receita'!$BA$58)))*(1+N$18))/($I17-N$18))))/((1+$I17)^((5-$F$9)*3/12)))+SUM($F$13:$F$14))/$F$11 -> 16.309228 | O17: =((SUM('DRE + DCF'!$P$54,NPV($I17,'DRE + DCF'!$Q$54:$AZ$54,SUM('DRE + DCF'!$BA$54,('DRE + DCF'!$BB$46*(1-((O$18-'Projeções - Receita'!$BA$58)/('DRE + DCF'!$BC$43-'Projeções - Receita'!$BA$58)))*(1+O$18))/($I17-O$18))))/((1+$I17)^((5-$F$9)*3/12)))+SUM($F$13:$F$14))/$F$11 -> 16.329364 | P17: =((SUM('DRE + DCF'!$P$54,NPV($I17,'DRE + DCF'!$Q$54:$AZ$54,SUM('DRE + DCF'!$BA$54,('DRE + DCF'!$BB$46*(1-((P$18-'Projeções - Receita'!$BA$58)/('DRE + DCF'!$BC$43-'Projeções - Receita'!$BA$58)))*(1+P$18))/($I17-P$18))))/((1+$I17)^((5-$F$9)*3/12)))+SUM($F$13:$F$14))/$F$11 -> 16.350655 | Q17: =((SUM('DRE + DCF'!$P$54,NPV($I17,'DRE + DCF'!$Q$54:$AZ$54,SUM('DRE + DCF'!$BA$54,('DRE + DCF'!$BB$46*(1-((Q$18-'Projeções - Receita'!$BA$58)/('DRE + DCF'!$BC$43-'Projeções - Receita'!$BA$58)))*(1+Q$18))/($I17-Q$18))))/((1+$I17)^((5-$F$9)*3/12)))+SUM($F$13:$F$14))/$F$11 -> 16.37323 | ... S17: =((SUM('DRE + DCF'!$P$54,NPV($I17,'DRE + DCF'!$Q$54:$AZ$54,SUM('DRE + DCF'!$BA$54,('DRE + DCF'!$BB$46*(1-((S$18-'Projeções - Receita'!$BA$58)/('DRE + DCF'!$BC$43-'Projeções - Receita'!$BA$58)))*(1+S$18))/($I17-S$18))))/((1+$I17)^((5-$F$9)*3/12)))+SUM($F$13:$F$14))/$F$11 -> 16.422843
E18: TIR | F18: 0.1383656 | J18: =K18-0.25% -> 0.0730656 | K18: =L18-0.25% -> 0.0755656 | L18: =M18-0.25% -> 0.0780656 | M18: =N18-0.25% -> 0.0805656 | N18: =O18-0.25% -> 0.0830656 | O18: ='DRE + DCF'!BD43 -> 0.0855656 | P18: =O18+0.25% -> 0.0880656 | Q18: =P18+0.25% -> 0.0905656 | R18: =Q18+0.25% -> 0.0930656 | S18: =R18+0.25% -> 0.0955656
J19: Growth
F22: =VLOOKUP(MIN(#REF!),#REF!,2,FALSE) -> #REF!

Sheet WACC
S3: =Dashboard!$I$3 -> Raia Drogasil ($RADL3)
A7: Páginas
A8: Dashboard
A9: WACC | E9: Atualizado em: 10/04/2023 | F9: 2023 | G9: =F9+1 -> 2024 | H9: =G9+1 -> 2025 | I9: =H9+1 -> 2026 | J9: =I9+1 -> 2027 | K9: =J9+1 -> 2028 | L9: =K9+1 -> 2029 | M9: =L9+1 -> 2030 | N9: =M9+1 -> 2031 | ... AQ9: =AP9+1 -> 2060 | AR9: Descrição
A10: DRE + DCF | E10: DI | F10: 0.1367155 | G10: 0.1296456 | H10: 0.1183783 | I10: 0.1169052 | J10: 0.1166546 | K10: 0.1170971 | L10: 0.117698 | M10: 0.1183976 | N10: 0.1184996 | O10: 0.1185 | P10: 0.1185 | Q10: =P10 -> 0.1185 | R10: =Q10 -> 0.1185 | S10: =R10 -> 0.1185 | T10: =S10 -> 0.1185 | U10: =T10 -> 0.1185 | V10: =U10 -> 0.1185 | W10: =V10 -> 0.1185 | X10: =W10 -> 0.1185 | ... AQ10: =AP10 -> 0.1185 | AR10: A taxa livre de risco no Brasil pode partir do DI, que é equivalente ao prêmio de um titulo IPCA+ do governo de mesmo prazo somado à inflação implicita.
A11: DRE - Contas Abertas | E11: CDS | F11: 0.008755413 | G11: 0.009904279 | H11: 0.01464963 | I11: 0.01941573 | J11: 0.024180477 | K11: 0.028611426 | L11: 0.031305624 | M11: 0.032702755 | N11: 0.033554629 | O11: 0.034613059 | P11: 0.036629856 | Q11: =P11 -> 0.036629856 | R11: =Q11 -> 0.036629856 | S11: =R11 -> 0.036629856 | T11: =S11 -> 0.036629856 | U11: =T11 -> 0.036629856 | V11: =U11 -> 0.036629856 | W11: =V11 -> 0.036629856 | X11: =W11 -> 0.036629856 | ... AQ11: =AP11 -> 0.036629856 | AR11: Credit Default Swap (CDS) - Fonte: investing.com
A12: Balanço Patrimonial | E12: Inflação Implícita | F12: 0.06688 | G12: 0.05303 | H12: 0.06963 | I12: 0.06656 | J12: 0.07113 | K12: 0.06915 | L12: 0.07392 | M12: 0.07356 | N12: 0.06627 | O12: 0.06154 | P12: 0.06428 | Q12: =P12 -> 0.06428 | R12: =Q12 -> 0.06428 | S12: =R12 -> 0.06428 | T12: =S12 -> 0.06428 | U12: =T12 -> 0.06428 | V12: =U12 -> 0.06428 | W12: =V12 -> 0.06428 | X12: =W12 -> 0.06428 | ... AQ12: =AP12 -> 0.06428
A13: Painel de Índices | E13: Taxa Livre de Risco | F13: =F10-F11 -> 0.12796009 | G13: =G10-G11 -> 0.11974132 | H13: =H10-H11 -> 0.10372867 | I13: =I10-I11 -> 0.09748947 | J13: =J10-J11 -> 0.092474123 | K13: =K10-K11 -> 0.088485674 | L13: =L10-L11 -> 0.086392376 | M13: =M10-M11 -> 0.085694845 | ... AQ13: =AQ10-AQ11 -> 0.081870144
A14: Provisões e Processos | E14: Bottom-up Beta | F14: 0.88382 | G14: =F14 -> 0.88382 | H14: =G14 -> 0.88382 | I14: =H14 -> 0.88382 | J14: =I14 -> 0.88382 | K14: =J14 -> 0.88382 | L14: =K14 -> 0.88382 | M14: =L14 -> 0.88382 | N14: =M14 -> 0.88382 | ... AQ14: =AP14 -> 0.88382 | AR14: Bottom-Up Beta levando em consideração o beta de empresas do mesmo setor e a alavancagem da empresa.
A15: Projeções - Receita | E15: Prêmio de Risco | F15: 0.065 | G15: 0.065 | H15: 0.065 | I15: 0.065 | J15: 0.065 | K15: 0.065 | L15: 0.065 | M15: 0.065 | N15: 0.065 | O15: 0.065 | P15: 0.065 | Q15: 0.065 | R15: 0.065 | S15: 0.065 | T15: 0.065 | U15: 0.065 | V15: 0.065 | W15: 0.065 | X15: 0.065 | Y15: 0.065 | Z15: 0.065 | AA15: 0.065 | AB15: 0.065 | AC15: 0.065 | AD15: 0.065 | AE15: 0.065 | AF15: 0.065 | AG15: 0.065 | AH15: 0.065 | AI15: 0.065 | AJ15: 0.065 | AK15: 0.065 | AL15: 0.065 | AM15: 0.065 | AN15: 0.065 | AO15: 0.065 | AP15: 0.065 | AQ15: 0.065 | AR15: Dados Alternativos FGV: https://goo.gl/bBfwGq
A16: Projeções - Capex | E16: Custo de Capital Próprio (Ke) | F16: =F13+(F14*F15) -> 0.18540839 | G16: =G13+(G14*G15) -> 0.17718962 | H16: =H13+(H14*H15) -> 0.16117697 | I16: =I13+(I14*I15) -> 0.15493777 | J16: =J13+(J14*J15) -> 0.14992242 | K16: =K13+(K14*K15) -> 0.14593397 | L16: =L13+(L14*L15) -> 0.14384068 | M16: =M13+(M14*M15) -> 0.14314315 | ... AQ16: =AQ13+(AQ14*AQ15) -> 0.13931844
A17: Projeções 2022 | E17: Valor do Equity (R$ Mil) | F17: 36287500 | G17: 36287500 | H17: 36287500 | I17: 36287500 | J17: 36287500 | K17: 36287500 | L17: 36287500 | M17: 36287500 | N17: 36287500 | O17: 36287500 | P17: 36287500 | Q17: 36287500 | R17: 36287500 | S17: 36287500 | T17: 36287500 | U17: 36287500 | V17: 36287500 | W17: 36287500 | X17: 36287500 | Y17: 36287500 | Z17: 36287500 | AA17: 36287500 | AB17: 36287500 | AC17: 36287500 | AD17: 36287500 | AE17: 36287500 | AF17: 36287500 | AG17: 36287500 | AH17: 36287500 | AI17: 36287500 | AJ17: 36287500 | AK17: 36287500 | AL17: 36287500 | AM17: 36287500 | AN17: 36287500 | AO17: 36287500 | AP17: 36287500 | AQ17: 36287500 | AR17: Valor Justo do Equity
E18: Custo de Capital de Terceiros (Kd) | F18: =F10+1.49% -> 0.1516155 | G18: =G10+1.49% -> 0.1445456 | H18: =H10+1.49% -> 0.1332783 | I18: =I10+1.49% -> 0.1318052 | J18: =J10+1.49% -> 0.1315546 | K18: =K10+1.49% -> 0.1319971 | L18: =L10+1.49% -> 0.132598 | M18: =M10+1.49% -> 0.1332976 | ... AQ18: =AQ10+1.49% -> 0.1334 | AR18: Custo da Dívida baseado na debênture de prazo mais longo emitida nos últimos doze meses (DI + 1,49%)
E19: Dívida Bruta (R$ Mil) | F19: =('Balanço Patrimonial'!$O$43+'Balanço Patrimonial'!$O$47+'Balanço Patrimonial'!$O$49+'Balanço Patrimonial'!$O$55) -> 6057912 | G19: =F19 -> 6057912 | H19: =G19 -> 6057912 | I19: =H19 -> 6057912 | J19: =I19 -> 6057912 | K19: =J19 -> 6057912 | L19: =K19 -> 6057912 | M19: =L19 -> 6057912 | N19: =M19 -> 6057912 | ... AQ19: =AP19 -> 6057912 | AR19: Valor contábil dos empréstimos, financiamentos e passivo de arrendamento no último balanço patrimonial divulgado.
E20: WACC | F20: =((F16*F17)+(F18*F19))/(F17+F19) -> 0.18057399 | G20: =((G16*G17)+(G18*G19))/(G17+G19) -> 0.17251958 | H20: =((H16*H17)+(H18*H19))/(H17+H19) -> 0.1571858 | I20: =((I16*I17)+(I18*I19))/(I17+I19) -> 0.15162844 | J20: =((J16*J17)+(J18*J19))/(J17+J19) -> 0.14729473 | K20: =((K16*K17)+(K18*K19))/(K17+K19) -> 0.14394017 | L20: =((L16*L17)+(L18*L19))/(L17+L19) -> 0.1422323 | M20: =((M16*M17)+(M18*M19))/(M17+M19) -> 0.14173465 | ... AQ20: =((AQ16*AQ17)+(AQ18*AQ19))/(AQ17+AQ19) -> 0.13847175
E21: Desconto | F21: =(1+F20)^((5-Dashboard!$F$9)*3/12) -> 1.180574 | G21: =F21*(1+G20) -> 1.3842461 | H21: =G21*(1+H20) -> 1.60183 | I21: =H21*(1+I20) -> 1.8447129 | J21: =I21*(1+J20) -> 2.1164294 | K21: =J21*(1+K20) -> 2.4210687 | L21: =K21*(1+L20) -> 2.7654228 | M21: =L21*(1+M20) -> 3.1573791 | N21: =M21*(1+N20) -> 3.6029062 | ... AQ21: =AP21*(1+AQ20) -> 155.11625

Sheet DRE + DCF
J2: Raia Drogasil ($RADL3)
A7: Páginas
A8: Dashboard
A9: WACC | E9: Data do Último Resultado: | F9: 2013 | G9: =F9+1 -> 2014 | H9: =G9+1 -> 2015 | I9: =H9+1 -> 2016 | J9: =I9+1 -> 2017 | K9: =J9+1 -> 2018 | L9: =K9+1 -> 2019 | M9: =L9+1 -> 2020 | N9: 2021 | O9: 2022 | P9: 2023 | Q9: 2024 | R9: 2025 | S9: 2026 | T9: 2027 | U9: 2028 | V9: 2029 | W9: 2030 | X9: 2031 | Y9: =X9+1 -> 2032 | Z9: =Y9+1 -> 2033 | AA9: =Z9+1 -> 2034 | AB9: =AA9+1 -> 2035 | AC9: =AB9+1 -> 2036 | AD9: =AC9+1 -> 2037 | AE9: =AD9+1 -> 2038 | AF9: =AE9+1 -> 2039 | ... BA9: =AZ9+1 -> 2060
A10: DRE + DCF | E10: Receita Bruta | F10: 6464103 | G10: 7658890 | H10: 9295978 | I10: 11827566 | J10: 13852469 | K10: 15519133 | L10: 18468183 | M10: 21180476 | N10: 25605684 | O10: 30950564
A11: DRE - Contas Abertas | E11: Impostos Incidentes sobre vendas | F11: -197812 | G11: -221733 | H11: -278605 | I11: -425384 | J11: -500288 | K11: -585676 | L11: -747690 | M11: -940608 | N11: -1218499 | O11: -1373403
A12: Balanço Patrimonial | E12: (%) da Receita Bruta | F12: =F11/F10 -> -0.030601616 | G12: =G11/G10 -> -0.028951062 | H12: =H11/H10 -> -0.029970488 | I12: =I11/I10 -> -0.035965473 | J12: =J11/J10 -> -0.036115439 | K12: =K11/K10 -> -0.037738964 | L12: =L11/L10 -> -0.040485304 | M12: =M11/M10 -> -0.0444092 | ... O12: =O11/O10 -> -0.044374086
A13: Painel de Índices | E13: Devoluções, Abatimentos e Outros | F13: -33372 | G13: -45588 | H13: -119524 | I13: -145617 | J13: -139676 | K13: -132012 | L13: -154893 | M13: -173028 | N13: -260183 | O13: -509781
A14: Provisões e Processos | E14: (%) da Receita Bruta | F14: =F13/F10 -> -0.0051626653 | G14: =G13/G10 -> -0.0059522986 | H14: =H13/H10 -> -0.012857604 | I14: =I13/I10 -> -0.012311662 | J14: =J13/J10 -> -0.010083112 | K14: =K13/K10 -> -0.008506403 | L14: =L13/L10 -> -0.0083870189 | M14: =M13/M10 -> -0.0081692215 | ... O14: =O13/O10 -> -0.016470815
A15: Projeções - Receita | E15: Receita Líquida | F15: 6232919 | G15: 7391569 | H15: 8897849 | I15: 11256565 | J15: 13212505 | K15: 14801445 | L15: 17565600 | M15: 20066840 | N15: 24127002 | O15: 29067380 | P15: ='Projeções - Receita'!P22 -> 33449541 | Q15: ='Projeções - Receita'!Q22 -> 37882634 | R15: ='Projeções - Receita'!R22 -> 43302702 | S15: ='Projeções - Receita'!S22 -> 49095679 | T15: ='Projeções - Receita'!T22 -> 55616250 | U15: ='Projeções - Receita'!U22 -> 62622077 | V15: ='Projeções - Receita'!V22 -> 70543239 | W15: ='Projeções - Receita'!W22 -> 79175286 | ... BA15: ='Projeções - Receita'!BA22 -> 1.1232524e+09
A16: Projeções - Capex | E16: Crescimento da Receita (YoY)¹ | G16: =G15/F15-1 -> 0.18589204 | H16: =H15/G15-1 -> 0.20378353 | I16: =I15/H15-1 -> 0.26508834 | J16: =J15/I15-1 -> 0.17375993 | K16: =K15/J15-1 -> 0.12026031 | L16: =L15/K15-1 -> 0.186749 | M16: =M15/L15-1 -> 0.14239423 | N16: =N15/M15-1 -> 0.20233191 | ... BA16: =BA15/AZ15-1 -> 0.085499962
A17: Projeções 2022 | E17: Custos das Vendas e Serviços | F17: -4512743 | G17: -5281377 | H17: -6183289 | I17: -7752422 | J17: -9224505 | K17: -10355923 | L17: -12367239 | M17: -14175708 | N17: -16920834 | O17: -20257912
E18: Lucro Bruto | F18: =F15+F17 -> 1720176 | G18: =G15+G17 -> 2110192 | H18: =H15+H17 -> 2714560 | I18: =I15+I17 -> 3504143 | J18: =J15+J17 -> 3988000 | K18: =K15+K17 -> 4445522 | L18: =L15+L17 -> 5198361 | M18: =M15+M17 -> 5891132 | N18: =N15+N17 -> 7206168 | O18: 8809468
E19: Margem Bruta | F19: =F18/F15 -> 0.27598241 | G19: =G18/G15 -> 0.28548634 | H19: =H18/H15 -> 0.30508048 | I19: =I18/I15 -> 0.31129772 | J19: =J18/J15 -> 0.30183527 | K19: =K18/K15 -> 0.30034378 | L19: =L18/L15 -> 0.29593985 | M19: =M18/M15 -> 0.29357547 | ... O19: =O18/O15 -> 0.30307059
E20: Despesas/ Receitas Operacionais | F20: =F21+F23+F25 -> -1570342 | G20: =G21+G23+G25 -> -1801066 | H20: =H21+H23+H25 -> -2213697 | I20: =I21+I23+I25 -> -2798605 | J20: =J21+J23+J25 -> -3195416 | K20: =K21+K23+K25 -> -3724012 | L20: =L21+L23+L25 -> -4079892 | M20: =M21+M23+M25 -> -4967281 | ... O20: =O21+O23+O25 -> -6969323
E21: Despesas com Vendas | F21: -1188077 | G21: -1409067 | H21: -1742093 | I21: -2218765 | J21: -2825959 | K21: -3261896 | L21: -3754770 | M21: -4256422 | N21: -4966819 | O21: -5805992
E22: (%) da Receita Líquida | F22: =F21/F15 -> -0.19061326 | G22: =G21/G15 -> -0.19063165 | H22: =H21/H15 -> -0.19578811 | I22: =I21/I15 -> -0.19710853 | J22: =J21/J15 -> -0.21388518 | K22: =K21/K15 -> -0.22037686 | L22: =L21/L15 -> -0.213757 | M22: =M21/M15 -> -0.21211222 | ... O22: =O21/O15 -> -0.19974253
E23: Despesas Gerais e Administrativas | F23: -335199 | G23: -382526 | H23: -462786 | I23: -572163 | J23: -369669 | K23: -402568 | L23: -533393 | M23: -679320 | N23: -912404 | O23: -1249847
E24: (%) da Receita Líquida | F24: =F23/F15 -> -0.053778815 | G24: =G23/G15 -> -0.051751665 | H24: =H23/H15 -> -0.052010997 | I24: =I23/I15 -> -0.050829272 | J24: =J23/J15 -> -0.027978722 | K24: =K23/K15 -> -0.027197885 | L24: =L23/L15 -> -0.030365772 | M24: =M23/M15 -> -0.033852864 | ... O24: =O23/O15 -> -0.042998268
E25: Resultado Operacional Outros | F25: -47066 | G25: -9473 | H25: -8818 | I25: -7677 | J25: 212 | K25: -59548 | L25: =355263-146992 -> 208271 | M25: =37911-69450 -> -31539 | N25: =78083-37429 -> 40654 | O25: =50097+36419 -> 86516
E26: (%) da Receita Líquida | F26: =F25/F15 -> -0.0075511971 | G26: =G25/G15 -> -0.0012815953 | H26: =H25/H15 -> -0.00099102603 | I26: =I25/I15 -> -0.00068200201 | J26: =J25/J15 -> 1.6045405e-05 | K26: =K25/K15 -> -0.0040231207 | L26: =L25/L15 -> 0.011856754 | M26: =M25/M15 -> -0.0015716974 | ... O26: =O25/O15 -> 0.0029763948
E27: Equivalência Patrimonial | F27: 0 | G27: 0 | H27: 0 | I27: 0 | J27: 0 | K27: 0 | L27: 0 | M27: =-7867 -> -7867 | N27: -1127 | O27: -821
E28: EBIT | F28: =F18+F20+F27 -> 149834 | G28: =G18+G20+G27 -> 309126 | H28: =H18+H20+H27 -> 500863 | I28: =I18+I20+I27 -> 705538 | J28: =J18+J20+J27 -> 792584 | K28: =K18+K20+K27 -> 721510 | L28: =L18+L20+L27 -> 1118469 | M28: =M18+M20+M27 -> 915984 | ... O28: =O18+O20+O27 -> 1839324
E29: Margem EBIT | F29: =F28/F$15 -> 0.024039138 | G29: =G28/G$15 -> 0.041821432 | H29: =H28/H$15 -> 0.056290346 | I29: =I28/I$15 -> 0.062677913 | J29: =J28/J$15 -> 0.059987413 | K29: =K28/K$15 -> 0.048745916 | L29: =L28/L$15 -> 0.063673828 | M29: =M28/M$15 -> 0.045646649 | ... O29: =O28/O$15 -> 0.063277942
E30: Não-Recorrente | F30: ='DRE - Contas Abertas'!F50 -> 0 | G30: ='DRE - Contas Abertas'!G50 -> 0 | H30: ='DRE - Contas Abertas'!H50 -> 0 | I30: ='DRE - Contas Abertas'!I50 -> 0 | J30: ='DRE - Contas Abertas'!J50 -> 0 | K30: ='DRE - Contas Abertas'!K50 -> -54803 | L30: ='DRE - Contas Abertas'!L50 -> 232320 | M30: ='DRE - Contas Abertas'!M50 -> 28317 | ... O30: ='DRE - Contas Abertas'!O50 -> 91387
E31: EBIT Recorrente | F31: =F28-F30 -> 149834 | G31: =G28-G30 -> 309126 | H31: =H28-H30 -> 500863 | I31: =I28-I30 -> 705538 | J31: =J28-J30 -> 792584 | K31: =K28-K30 -> 776313 | L31: =L28-L30 -> 886149 | M31: =M28-M30 -> 887667 | ... O31: =O28-O30 -> 1747937 | P31: =P32*P15 -> 1778702.2 | Q31: =Q32*Q15 -> 2014434.9 | R31: =R32*R15 -> 2302650.7 | S31: =S32*S15 -> 2610696.2 | T31: =T32*T15 -> 2957432.1 | U31: =U32*U15 -> 3329971.7 | V31: =V32*V15 -> 3751184.9 | W31: =W32*W15 -> 4210199.9 | ... BA31: =BA32*BA15 -> 54962151
E32: Margem EBIT Recorrente | F32: =F31/F$15 -> 0.024039138 | G32: =G31/G$15 -> 0.041821432 | H32: =H31/H$15 -> 0.056290346 | I32: =I31/I$15 -> 0.062677913 | J32: =J31/J$15 -> 0.059987413 | K32: =K31/K$15 -> 0.05244846 | L32: =L31/L$15 -> 0.050447978 | M32: =M31/M$15 -> 0.044235515 | ... O32: =O31/O$15 -> 0.060133971 | P32: =AVERAGE($O$32,$N$32)+('Projeções - Receita'!P66-'Projeções - Receita'!$O$66) -> 0.053175683 | Q32: =AVERAGE($O$32,$N$32)+('Projeções - Receita'!Q66-'Projeções - Receita'!$O$66) -> 0.053175683 | R32: =AVERAGE($O$32,$N$32)+('Projeções - Receita'!R66-'Projeções - Receita'!$O$66) -> 0.053175683 | S32: =AVERAGE($O$32,$N$32)+('Projeções - Receita'!S66-'Projeções - Receita'!$O$66) -> 0.053175683 | T32: =AVERAGE($O$32,$N$32)+('Projeções - Receita'!T66-'Projeções - Receita'!$O$66) -> 0.053175683 | U32: =AVERAGE($O$32,$N$32)+('Projeções - Receita'!U66-'Projeções - Receita'!$O$66) -> 0.053175683 | V32: =AVERAGE($O$32,$N$32)+('Projeções - Receita'!V66-'Projeções - Receita'!$O$66) -> 0.053175683 | W32: =AVERAGE($O$32,$N$32)+('Projeções - Receita'!W66-'Projeções - Receita'!$O$66) -> 0.053175683 | ... BA32: =AVERAGE($O$32,$N$32)+('Projeções - Receita'!BA66-'Projeções - Receita'!$O$66) -> 0.048931258
E33: Resultado Financeiro | F33: =SUM(F34:F35) -> -10447 | G33: =SUM(G34:G35) -> -6902 | H33: =SUM(H34:H35) -> -64961 | I33: =SUM(I34:I35) -> -110322 | J33: =SUM(J34:J35) -> -106040 | K33: =SUM(K34:K35) -> -82654 | L33: =SUM(L34:L35) -> -334301 | M33: =SUM(M34:M35) -> -299616 | ... O33: =SUM(O34:O35) -> -646115
E34: Receitas Financeiras | F34: 9863 | G34: 18347 | H34: 88786 | I34: 109433 | J34: 106883 | K34: 71783 | L34: 76945 | M34: 54182 | N34: 80016 | O34: 293586
E35: Despesas Financeiras | F35: -20310 | G35: -25249 | H35: -153747 | I35: -219755 | J35: -212923 | K35: -154437 | L35: -411246 | M35: -353798 | N35: -459226 | O35: -939701
E36: Resultado Antes dos Tributos Sobre o Lucro | F36: =F28+F33 -> 139387 | G36: =G28+G33 -> 302224 | H36: =H28+H33 -> 435902 | I36: =I28+I33 -> 595216 | J36: =J28+J33 -> 686544 | K36: =K28+K33 -> 638856 | L36: =L28+L33 -> 784168 | M36: =M28+M33 -> 616368 | ... O36: =O28+O33 -> 1193209
E37: Imposto de Renda e CSLL | F37: -38402 | G37: -80838 | H37: -96117 | I37: -143964 | J37: -173891 | K37: -129543 | L37: -106205 | M37: -120835 | N37: -223129 | O37: -178241 | P37: =-P43*P31 -> -284475.13 | Q37: =-Q43*Q31 -> -322176.84 | R37: =-R43*R31 -> -368272.38 | S37: =-S43*S31 -> -417539.36 | T37: =-T43*T31 -> -472994.24 | U37: =-U43*U31 -> -532576.03 | V37: =-V43*V31 -> -599942.39 | W37: =-W43*W31 -> -673354.54 | ... BA37: =-BA43*BA31 -> -10323617
E38: Lucro Líquido | F38: =F36+F37 -> 100985 | G38: =G36+G37 -> 221386 | H38: =H36+H37 -> 339785 | I38: =I36+I37 -> 451252 | J38: =J36+J37 -> 512653 | K38: =K36+K37 -> 509313 | L38: =L36+L37 -> 677963 | M38: =M36+M37 -> 495533 | ... O38: =O36+O37 -> 1014968
E39: Margem Líquida | F39: =F38/F15 -> 0.016201879 | G39: =G38/G15 -> 0.029951151 | H39: =H38/H15 -> 0.038187319 | I39: =I38/I15 -> 0.040087895 | J39: =J38/J15 -> 0.038800591 | K39: =K38/K15 -> 0.034409681 | L39: =L38/L15 -> 0.038596063 | M39: =M38/M15 -> 0.024694122 | ... O39: =O38/O15 -> 0.034917767
F42: =F9 -> 2013 | G42: =G9 -> 2014 | H42: =H9 -> 2015 | I42: =I9 -> 2016 | J42: =J9 -> 2017 | K42: =K9 -> 2018 | L42: =L9 -> 2019 | M42: =M9 -> 2020 | ... BA42: =BA9 -> 2060 | BB42: Perpetuidade | BC42: ROIC Perp. | BD42: Growth
E43: Alíquota Efetiva | F43: =IFERROR(IF(F28>0,-F37/F28,"-"),"-") -> 0.25629697 | G43: =IFERROR(IF(G28>0,-G37/G28,"-"),"-") -> 0.26150502 | H43: =IFERROR(IF(H28>0,-H37/H28,"-"),"-") -> 0.19190278 | I43: =IFERROR(IF(I28>0,-I37/I28,"-"),"-") -> 0.20404854 | J43: =IFERROR(IF(J28>0,-J37/J28,"-"),"-") -> 0.21939757 | K43: =IFERROR(IF(K28>0,-K37/K28,"-"),"-") -> 0.17954429 | L43: =IFERROR(IF(L28>0,-L37/L28,"-"),"-") -> 0.094955694 | M43: =IFERROR(IF(M28>0,-M37/M28,"-"),"-") -> 0.13191824 | ... O43: =IFERROR(IF(O28>0,-O37/O28,"-"),"-") -> 0.096905711 | P43: =(-AVERAGE('DRE - Contas Abertas'!$K$114:$N$114)*2-AVERAGE('DRE - Contas Abertas'!$H$116:$N$116))/3 -> 0.1599341 | Q43: =(-AVERAGE('DRE - Contas Abertas'!$K$114:$N$114)*2-AVERAGE('DRE - Contas Abertas'!$H$116:$N$116))/3 -> 0.1599341 | R43: =(-AVERAGE('DRE - Contas Abertas'!$K$114:$N$114)*2-AVERAGE('DRE - Contas Abertas'!$H$116:$N$116))/3 -> 0.1599341 | S43: =(-AVERAGE('DRE - Contas Abertas'!$K$114:$N$114)*2-AVERAGE('DRE - Contas Abertas'!$H$116:$N$116))/3 -> 0.1599341 | T43: =(-AVERAGE('DRE - Contas Abertas'!$K$114:$N$114)*2-AVERAGE('DRE - Contas Abertas'!$H$116:$N$116))/3 -> 0.1599341 | U43: =(-AVERAGE('DRE - Contas Abertas'!$K$114:$N$114)*2-AVERAGE('DRE - Contas Abertas'!$H$116:$N$116))/3 -> 0.1599341 | V43: =(-AVERAGE('DRE - Contas Abertas'!$K$114:$N$114)*2-AVERAGE('DRE - Contas Abertas'!$H$116:$N$116))/3 -> 0.1599341 | W43: =(-AVERAGE('DRE - Contas Abertas'!$K$114:$N$114)*2-AVERAGE('DRE - Contas Abertas'!$H$116:$N$116))/3 -> 0.1599341 | ... Y43: =(-AVERAGE('DRE - Contas Abertas'!$K$114:$N$114)*2-AVERAGE('DRE - Contas Abertas'!$H$116:$N$116))/3 -> 0.1599341 | Z43: =-AVERAGE('DRE - Contas Abertas'!$H$116:$N$116) -> 0.18783138 | AA43: =-AVERAGE('DRE - Contas Abertas'!$H$116:$N$116) -> 0.18783138 | AB43: =-AVERAGE('DRE - Contas Abertas'!$H$116:$N$116) -> 0.18783138 | AC43: =-AVERAGE('DRE - Contas Abertas'!$H$116:$N$116) -> 0.18783138 | AD43: =-AVERAGE('DRE - Contas Abertas'!$H$116:$N$116) -> 0.18783138 | AE43: =-AVERAGE('DRE - Contas Abertas'!$H$116:$N$116) -> 0.18783138 | AF43: =-AVERAGE('DRE - Contas Abertas'!$H$116:$N$116) -> 0.18783138 | AG43: =-AVERAGE('DRE - Contas Abertas'!$H$116:$N$116) -> 0.18783138 | ... BA43: =-AVERAGE('DRE - Contas Abertas'!$H$116:$N$116) -> 0.18783138 | BC43: =AVERAGE(H57:N58) -> 0.17847899 | BD43: =(1+'Projeções - Capex'!$Z$26)*(1+'Projeções - Receita'!$BA$60)-1 -> 0.0855656
E44: Depreciação de Arrendamento | F44: 0 | G44: 0 | H44: 0 | I44: 0 | J44: 0 | K44: 0 | L44: 533806 | M44: 613434 | N44: 700296 | O44: 815372 | P44: =P45*P15 -> 987056.86 | Q44: =Q45*Q15 -> 1117872.3 | R44: =R45*R15 -> 1277812.1 | S44: =S45*S15 -> 1448756.1 | T44: =T45*T15 -> 1641170.5 | U44: =U45*U15 -> 1847904.3 | V44: =V45*V15 -> 2081648.6 | W44: =W45*W15 -> 2336370.2 | ... BA44: =BA45*BA15 -> 33145865
E45: (%) da Receita Líquida | F45: =F44/F15 -> 0 | G45: =G44/G15 -> 0 | H45: =H44/H15 -> 0 | I45: =I44/I15 -> 0 | J45: =J44/J15 -> 0 | K45: =K44/K15 -> 0 | L45: =L44/L15 -> 0.030389284 | M45: =M44/M15 -> 0.030569537 | ... O45: =O44/O15 -> 0.028051101 | P45: =AVERAGE($L$45:$N$45,$O$45) -> 0.029508831 | Q45: =AVERAGE($L$45:$N$45,$O$45) -> 0.029508831 | R45: =AVERAGE($L$45:$N$45,$O$45) -> 0.029508831 | S45: =AVERAGE($L$45:$N$45,$O$45) -> 0.029508831 | T45: =AVERAGE($L$45:$N$45,$O$45) -> 0.029508831 | U45: =AVERAGE($L$45:$N$45,$O$45) -> 0.029508831 | V45: =AVERAGE($L$45:$N$45,$O$45) -> 0.029508831 | W45: =AVERAGE($L$45:$N$45,$O$45) -> 0.029508831 | ... BA45: =AVERAGE($L$45:$N$45,$O$45) -> 0.029508831
E46: NOPAT Recorrente | F46: =F31+F37+F44 -> 111432 | G46: =G31+G37+G44 -> 228288 | H46: =H31+H37+H44 -> 404746 | I46: =I31+I37+I44 -> 561574 | J46: =J31+J37+J44 -> 618693 | K46: =K31+K37+K44 -> 646770 | L46: =L31+L37+L44 -> 1313750 | M46: =M31+M37+M44 -> 1380266 | ... BA46: =BA31+BA37+BA44 -> 77784399 | BB46: =BA46 -> 77784399
E47: Margem NOPAT | F47: =F46/F15 -> 0.01787798 | G47: =G46/G15 -> 0.030884918 | H47: =H46/H15 -> 0.045488072 | I47: =I46/I15 -> 0.049888576 | J47: =J46/J15 -> 0.046826321 | K47: =K46/K15 -> 0.043696409 | L47: =L46/L15 -> 0.074791069 | M47: =M46/M15 -> 0.068783426 | ... BA47: =BA46/BA15 -> 0.069249263
...

Sheet DRE - Contas Abertas
F3: =Dashboard!$I$3 -> Raia Drogasil ($RADL3)
A7: Páginas
A8: Dashboard
A9: WACC | F9: 2013 | G9: =H9-1 -> 2014 | H9: =I9-1 -> 2015 | I9: =J9-1 -> 2016 | J9: 2017 | K9: 2018 | L9: 2019 | M9: 2020 | N9: 2021 | O9: 2022
A10: DRE + DCF | E10: Custo das Mercadorias Vendidas | F10: -4512743 | G10: -5281377 | H10: -6183289 | I10: -7752422 | J10: -9224505 | K10: ='DRE + DCF'!K17 -> -10355923 | L10: ='DRE + DCF'!L17 -> -12367239 | M10: ='DRE + DCF'!M17 -> -14175708 | N10: -16901753 | O10: -20223406
A11: DRE - Contas Abertas | E11: Despesas com Pessoal | F11: -803348 | G11: -942024 | H11: -1144608 | I11: -1455915 | J11: -1626658 | K11: -1839906 | L11: -2167200 | M11: -2396582 | N11: -2890025 | O11: -3565669
A12: Balanço Patrimonial | E12: Despesas com Ocupação | F12: 0 | G12: 0 | H12: 0 | I12: 0 | J12: -602508 | K12: -699902 | L12: -272414 | M12: -279382 | N12: -324608 | O12: -348735
A13: Painel de Índices | E13: Descontos sobre locação de imóveis | F13: 0 | G13: 0 | H13: 0 | I13: 0 | J13: 0 | K13: 0 | L13: 0 | M13: 13804 | N13: 6390 | O13: 1105
A14: Provisões e Processos | E14: Despesas com Prestadores de Serviços | F14: -73741 | G14: -77910 | H14: -101919 | I14: -124857 | J14: -150449 | K14: -162044 | L14: -205892 | M14: -292285 | N14: -368999 | O14: -414916
A15: Projeções - Receita | E15: Depreciação e Amortização | F15: -158736 | G15: -187568 | H15: -227698 | I15: -274434 | J15: -337914 | K15: -414133 | L15: -1012403 | M15: -1148827 | N15: -1292310 | O15: -1473350
A16: Projeções - Capex | E16: Despesas com taxas de operadoras de cartões | F16: 0 | G16: 0 | H16: 0 | I16: 0 | J16: 0 | K16: 0 | L16: -212629 | M16: -249136 | N16: -307876 | O16: -412483
A17: Projeções 2022 | E17: Outras | F17: -487451 | G17: -584091 | H17: -730654 | I17: -935722 | J17: -478099 | K17: -548479 | L17: -417625 | M17: -583334 | N17: -720876 | O17: -876297
E18: Outros Resultados Operacionais | F18: -47066 | G18: -9473 | H18: -8818 | I18: -7677 | J18: 212 | K18: 0 | L18: 0 | M18: 0 | N18: 0 | O18: 0
E19: Gastos com Consultorias e Assessorias | F19: 0 | G19: 0 | H19: 0 | I19: 0 | J19: 0 | K19: -13913 | L19: -15320 | M19: -20437 | N19: 70 | O19: 0
E20: Créditos de anos anteriores, sobretudo de PIS e COFINS | F20: 0 | G20: 0 | H20: 0 | I20: 0 | J20: 0 | K20: 10698 | L20: 8193 | M20: 5417 | N20: 2238 | O20: 0
E21: Despesas adicionais devido ao encerramento do CD Barra Mansa | F21: 0 | G21: 0 | H21: 0 | I21: 0 | J21: 0 | K21: 0 | L21: -12767 | M21: 0 | N21: 0 | O21: 0
E22: Baixa de imobilizado e intangível devido ao encerramento de lojas | F22: 0 | G22: 0 | H22: 0 | I22: 0 | J22: 0 | K22: -1530 | L22: -16922 | M22: -3750 | N22: -23391 | O22: -28345
E23: Restruturação hierárquica | F23: 0 | G23: 0 | H23: 0 | I23: 0 | J23: 0 | K23: -7596 | L23: -16145 | M23: 732 | N23: 0 | O23: 0
E24: Integração da Onofre | F24: 0 | G24: 0 | H24: 0 | I24: 0 | J24: 0 | K24: 0 | L24: -95001 | M24: 0 | N24: 0 | O24: 0
E25: Apropriação de crédito de INSS de 2012 a 2015 | F25: 0 | G25: 0 | H25: 0 | I25: 0 | J25: 0 | K25: 0 | L25: 4625 | M25: 31059 | N25: 1142 | O25: 0
E26: Ganho por compra vantajosa Onofre | F26: 0 | G26: 0 | H26: 0 | I26: 0 | J26: 0 | K26: 0 | L26: 355263 | M26: 0 | N26: 0 | O26: 0
E27: Atualização Provisão Trabalhista - Taxa Selic | F27: 0 | G27: 0 | H27: 0 | I27: 0 | J27: 0 | K27: 0 | L27: 0 | M27: 0 | N27: 3410 | O27: 0
E28: Ressarcimento de ICMS-ST sobre vendas de 2020 | F28: 0 | G28: 0 | H28: 0 | I28: 0 | J28: 0 | K28: 0 | L28: 0 | M28: 0 | N28: 13706 | O28: 10210
E29: Exclusão do ICMS da base de cálculo de PIS/COFINS | F29: 0 | G29: 0 | H29: 0 | I29: 0 | J29: 0 | K29: 0 | L29: 0 | M29: 0 | N29: 58044 | O29: 15943
... E42: Doações | F42: 0 | G42: 0 | H42: 0 | I42: 0 | J42: 0 | K42: 0 | L42: 0 | M42: -29282 | N42: -15903 | O42: -884
E43: Total: | F43: =SUM(F10:F42) -> -6083085 | G43: =SUM(G10:G42) -> -7082443 | H43: =SUM(H10:H42) -> -8396986 | I43: =SUM(I10:I42) -> -10551027 | J43: =SUM(J10:J42) -> -12419921 | K43: =SUM(K10:K42) -> -14079935 | L43: =SUM(L10:L42) -> -16447131 | M43: =SUM(M10:M42) -> -19142989 | ... O43: =SUM(O10:O42) -> -27236345
F46: =G46-1 -> 2013 | G46: =H46-1 -> 2014 | H46: =I46-1 -> 2015 | I46: =J46-1 -> 2016 | J46: 2017 | K46: 2018 | L46: 2019 | M46: 2020 | N46: 2021 | O46: 2022
E47: Lucro Bruto | F47: ='DRE + DCF'!F18 -> 1720176 | G47: ='DRE + DCF'!G18 -> 2110192 | H47: ='DRE + DCF'!H18 -> 2714560 | I47: ='DRE + DCF'!I18 -> 3504143 | J47: ='DRE + DCF'!J18 -> 3988000 | K47: ='DRE + DCF'!K18 -> 4445522 | L47: ='DRE + DCF'!L18 -> 5198361 | M47: ='DRE + DCF'!M18 -> 5891132 | N47: ='DRE + DCF'!N18 -> 7206168 | O47: 8809468
E48: EBIT | F48: ='DRE + DCF'!F28 -> 149834 | G48: ='DRE + DCF'!G28 -> 309126 | H48: ='DRE + DCF'!H28 -> 500863 | I48: ='DRE + DCF'!I28 -> 705538 | J48: ='DRE + DCF'!J28 -> 792584 | K48: ='DRE + DCF'!K28 -> 721510 | L48: ='DRE + DCF'!L28 -> 1118469 | M48: ='DRE + DCF'!M28 -> 915984 | N48: ='DRE + DCF'!N28 -> 1366472 | O48: 1873830
E49: Margem EBIT | F49: =F48/'DRE + DCF'!F15 -> 0.024039138 | G49: =G48/'DRE + DCF'!G15 -> 0.041821432 | H49: =H48/'DRE + DCF'!H15 -> 0.056290346 | I49: =I48/'DRE + DCF'!I15 -> 0.062677913 | J49: =J48/'DRE + DCF'!J15 -> 0.059987413 | K49: =K48/'DRE + DCF'!K15 -> 0.048745916 | L49: =L48/'DRE + DCF'!L15 -> 0.063673828 | M49: =M48/'DRE + DCF'!M15 -> 0.045646649 | ... O49: =O48/'DRE + DCF'!O15 -> 0.064465046
E50: Eventos não recorrentes | F50: =F13+F21+F24+F25+F31+F32+F33+F34+F35+F30+F26+F35+F36+F37+F38+F27+F28+F29+F23+F40 -> 0 | G50: =G13+G21+G24+G25+G31+G32+G33+G34+G35+G30+G26+G35+G36+G37+G38+G27+G28+G29+G23+G40 -> 0 | H50: =H13+H21+H24+H25+H31+H32+H33+H34+H35+H30+H26+H35+H36+H37+H38+H27+H28+H29+H23+H40 -> 0 | I50: =I13+I21+I24+I25+I31+I32+I33+I34+I35+I30+I26+I35+I36+I37+I38+I27+I28+I29+I23+I40 -> 0 | J50: =J13+J21+J24+J25+J31+J32+J33+J34+J35+J30+J26+J35+J36+J37+J38+J27+J28+J29+J23+J40 -> 0 | K50: =K13+K21+K24+K25+K31+K32+K33+K34+K35+K30+K26+K35+K36+K37+K38+K27+K28+K29+K23+K40 -> -54803 | L50: =L13+L21+L24+L25+L31+L32+L33+L34+L35+L30+L26+L35+L36+L37+L38+L27+L28+L29+L23+L40 -> 232320 | M50: =M13+M21+M24+M25+M31+M32+M33+M34+M35+M30+M26+M35+M36+M37+M38+M27+M28+M29+M23+M40 -> 28317 | N50: =N13+N21+N24+N25+N31+N32+N33+N34+N35+N30+N26+N35+N36+N37+N38+N27+N28+N29+N23+N40 -> 84578 | O50: 91387
E51: EBIT recorrente | F51: =F48-F50 -> 149834 | G51: =G48-G50 -> 309126 | H51: =H48-H50 -> 500863 | I51: =I48-I50 -> 705538 | J51: =J48-J50 -> 792584 | K51: =K48-K50 -> 776313 | L51: =L48-L50 -> 886149 | M51: =M48-M50 -> 887667 | N51: =N48-N50 -> 1281894 | O51: 1782443
E52: Margem EBIT recorrente | F52: =F51/'DRE + DCF'!F15 -> 0.024039138 | G52: =G51/'DRE + DCF'!G15 -> 0.041821432 | H52: =H51/'DRE + DCF'!H15 -> 0.056290346 | I52: =I51/'DRE + DCF'!I15 -> 0.062677913 | J52: =J51/'DRE + DCF'!J15 -> 0.059987413 | K52: =K51/'DRE + DCF'!K15 -> 0.05244846 | L52: =L51/'DRE + DCF'!L15 -> 0.050447978 | M52: =M51/'DRE + DCF'!M15 -> 0.044235515 | ... O52: =O51/'DRE + DCF'!O15 -> 0.061321075
E53: Subvenção de Investimentos na Receita Líquida | F53: ='Projeções - Receita'!F65 -> 0 | G53: ='Projeções - Receita'!G65 -> 0 | H53: ='Projeções - Receita'!H65 -> 0 | I53: ='Projeções - Receita'!I65 -> 0 | J53: ='Projeções - Receita'!J65 -> 0 | K53: ='Projeções - Receita'!K65 -> 64344.118 | L53: ='Projeções - Receita'!L65 -> 81529.412 | M53: ='Projeções - Receita'!M65 -> 125511.76 | N53: ='Projeções - Receita'!N65 -> 165732.35 | O53: 147596.17
E54: EBIT recorrente excluindo a subvenção de investimentos | F54: =F51-F53 -> 149834 | G54: =G51-G53 -> 309126 | H54: =H51-H53 -> 500863 | I54: =I51-I53 -> 705538 | J54: =J51-J53 -> 792584 | K54: =K51-K53 -> 711968.88 | L54: =L51-L53 -> 804619.59 | M54: =M51-M53 -> 762155.24 | ... O54: =O51-O53 -> 1634846.8
E55: Margem EBIT recorrente excluindo a subvenção de investimentos | F55: =F54/'DRE + DCF'!F15 -> 0.024039138 | G55: =G54/'DRE + DCF'!G15 -> 0.041821432 | H55: =H54/'DRE + DCF'!H15 -> 0.056290346 | I55: =I54/'DRE + DCF'!I15 -> 0.062677913 | J55: =J54/'DRE + DCF'!J15 -> 0.059987413 | K55: =K54/'DRE + DCF'!K15 -> 0.048101309 | L55: =L54/'DRE + DCF'!L15 -> 0.045806553 | M55: =M54/'DRE + DCF'!M15 -> 0.03798083 | ... O55: =O54/'DRE + DCF'!O15 -> 0.05624335
F58: =G58-1 -> 2013 | G58: =H58-1 -> 2014 | H58: =I58-1 -> 2015 | I58: =J58-1 -> 2016 | J58: 2017 | K58: 2018 | L58: 2019 | M58: 2020 | N58: 2021 | O58: 2022
E59: Descontos obtidos | F59: 555 | G59: 243 | H59: 1667 | I59: 1611 | J59: 1107 | K59: 1997 | L59: 3426 | M59: 8563 | N59: 503 | O59: 8162
E60: Rendimentos de Aplicações Financeiras | F60: 8204 | G60: 16548 | H60: 27256 | I60: 19863 | J60: 24174 | K60: 10104 | L60: 7070 | M60: 6136 | N60: 9513 | O60: 27799
E61: Juros recebidos | F61: 154 | G61: 8 | H61: 0 | I61: 0 | J61: 0 | K61: 0 | L61: 0 | M61: 0 | N61: 64 | O61: 487
...

Sheet Balanço Patrimonial
F3: Raia Drogasil ($RADL3)
A7: Páginas
A8: Dashboard
A9: WACC | E9: Data do Último Resultado: | F9: 2013 | G9: 2014 | H9: 2015 | I9: 2016 | J9: 2017 | K9: 2018 | L9: 2019 | M9: 2020 | N9: 2021 | O9: 2022
A10: DRE + DCF | E10: Capital de Giro | F10: =SUM(F16,F19:F23)-SUM(F40:F41,F42,F45,F46) -> 890918.98 | G10: =SUM(G16,G19:G23)-SUM(G40:G41,G42,G45,G46) -> 1009378.2 | H10: =SUM(H16,H19:H23)-SUM(H40:H41,H42,H45,H46) -> 1126067.2 | I10: =SUM(I16,I19:I23)-SUM(I40:I41,I42,I45,I46) -> 1401613 | J10: =SUM(J16,J19:J23)-SUM(J40:J41,J42,J45,J46) -> 1668147 | K10: =SUM(K16,K19:K23)-SUM(K40:K41,K42,K45,K46) -> 1914162 | L10: =SUM(L16,L19:L23)-SUM(L40:L41,L42,L45,L46) -> 2541123 | M10: =SUM(M16,M19:M23)-SUM(M40:M41,M42,M45,M46) -> 2891515 | ... O10: =SUM(O16,O19:O23)-SUM(O40:O41,O42,O45,O46) -> 4125436.4
A11: DRE - Contas Abertas | E11: % da Receita Líquida | F11: =F10/'DRE + DCF'!F15 -> 0.14293768 | G11: =G10/'DRE + DCF'!G15 -> 0.13655805 | H11: =H10/'DRE + DCF'!H15 -> 0.12655499 | I11: =I10/'DRE + DCF'!I15 -> 0.12451516 | J11: =J10/'DRE + DCF'!J15 -> 0.12625517 | K11: =K10/'DRE + DCF'!K15 -> 0.12932264 | L11: =L10/'DRE + DCF'!L15 -> 0.14466474 | M11: =M10/'DRE + DCF'!M15 -> 0.14409419 | ... O11: =O10/'DRE + DCF'!O15 -> 0.14192667
A12: Balanço Patrimonial | E12: Ativo Total | F12: 3614094 | G12: 4079503 | H12: 4699201 | I12: 5659301 | J12: 6464250 | K12: 7352005 | L12: 12248255 | M12: 13828088 | N12: =N13+N24 -> 14775506 | O12: =O13+O24 -> 17243771
A13: Painel de Índices | E13: Ativo Circulante | F13: 1903576 | G13: 2272317 | H13: 2685844 | I13: 3427782 | J13: 3928204 | K13: 4529825 | L13: 5756046 | M13: 7020490 | N13: =N14+N19+N20+N21+N22+N23 -> 7718924 | O13: =O14+O19+O20+O21+O22+O23 -> 9577068
A14: Provisões e Processos | E14: Caixa e Equivalente de Caixa | F14: 241885 | G14: 281467 | H14: 266051 | I14: 276632 | J14: 264873 | K14: 241568 | L14: 299226 | M14: 880357 | N14: 356118 | O14: 433541
A15: Projeções - Receita | E15: % da Receita Líquida | F15: =F14/'DRE + DCF'!F15 -> 0.03880766 | G15: =G14/'DRE + DCF'!G15 -> 0.038079466 | H15: =H14/'DRE + DCF'!H15 -> 0.029900597 | I15: =I14/'DRE + DCF'!I15 -> 0.02457517 | J15: =J14/'DRE + DCF'!J15 -> 0.020047145 | K15: =K14/'DRE + DCF'!K15 -> 0.016320569 | L15: =L14/'DRE + DCF'!L15 -> 0.017034773 | M15: =M14/'DRE + DCF'!M15 -> 0.043871232 | N15: =N14/'DRE + DCF'!N15 -> 0.014760143 | O15: =O14/'DRE + DCF'!Q15 -> 0.01144432
A16: Projeções - Capex | E16: Caixa Operacional | F16: =IF(F15>2.5%,2.5%*'DRE + DCF'!F15,'DRE + DCF'!F15*'Balanço Patrimonial'!F15) -> 155822.98 | G16: =IF(G15>2.5%,2.5%*'DRE + DCF'!G15,'DRE + DCF'!G15*'Balanço Patrimonial'!G15) -> 184789.23 | H16: =IF(H15>2.5%,2.5%*'DRE + DCF'!H15,'DRE + DCF'!H15*'Balanço Patrimonial'!H15) -> 222446.23 | I16: =IF(I15>2.5%,2.5%*'DRE + DCF'!I15,'DRE + DCF'!I15*'Balanço Patrimonial'!I15) -> 276632 | J16: =IF(J15>2.5%,2.5%*'DRE + DCF'!J15,'DRE + DCF'!J15*'Balanço Patrimonial'!J15) -> 264873 | K16: =IF(K15>2.5%,2.5%*'DRE + DCF'!K15,'DRE + DCF'!K15*'Balanço Patrimonial'!K15) -> 241568 | L16: =IF(L15>2.5%,2.5%*'DRE + DCF'!L15,'DRE + DCF'!L15*'Balanço Patrimonial'!L15) -> 299226 | M16: =IF(M15>2.5%,2.5%*'DRE + DCF'!M15,'DRE + DCF'!M15*'Balanço Patrimonial'!M15) -> 501671 | ... O16: =IF(O15>2.5%,2.5%*'DRE + DCF'!O15,'DRE + DCF'!O15*'Balanço Patrimonial'!O15) -> 332656.41
A17: Projeções 2022 | E17: Excesso de Caixa | F17: =F14-F16 -> 86062.025 | G17: =G14-G16 -> 96677.775 | H17: =H14-H16 -> 43604.775 | I17: =I14-I16 -> 0 | J17: =J14-J16 -> 0 | K17: =K14-K16 -> 0 | L17: =L14-L16 -> 0 | M17: =M14-M16 -> 378686 | ... O17: =O14-O16 -> 100884.59
E18: Aplicações Financeiras | F18: 0 | G18: 0 | H18: 0 | I18: 0 | J18: 0 | K18: 0 | L18: 0 | M18: 0 | N18: 0 | O18: 0
E19: Contas a Receber | F19: 373260 | G19: 482840 | H19: 601831 | I19: 772241 | J19: 930071 | K19: 1094236 | L19: 1433446 | M19: 1816456 | N19: 2000871 | O19: 2562521
E20: Estoques | F20: 1132620 | G20: 1350971 | H20: 1650453 | I20: 2149468 | J20: 2517594 | K20: 3087275 | L20: 3851388 | M20: 4225408 | N20: 5117799 | O20: 6126056
E21: Tributos a Recuperar | F21: 38658 | G21: 39429 | H21: 59530 | I21: 111772 | J21: 78777 | K21: 84852 | L21: 145617 | M21: 61531 | N21: 195777 | O21: 393336
E22: Despesas Antecipadas | F22: 8200 | G22: 9972 | H22: 9718 | I22: 12558 | J22: 17885 | K22: 21894 | L22: 26369 | M22: 36738 | N22: 48359 | O22: 61614
E23: Outros | F23: 108953 | G23: 107638 | H23: 98261 | I23: 105111 | J23: 119004 | K23: 0 | L23: 0 | M23: 0 | N23: 0 | O23: 0
