Workbook
Name InfImp22: #REF!
Name InfImp22: '[1]Dados Complementares'!$F$11
Name InfImp22: #REF!
Name InfImp23: #REF!
Name InfImp23: '[1]Dados Complementares'!$G$11
Name InfImp23: #REF!
Name InfImp24: #REF!
Name InfImp24: '[1]Dados Complementares'!$H$11
Name InfImp24: #REF!
Name InfImp25: #REF!
Name InfImp25: '[1]Dados Complementares'!$I$11
Name InfImp25: #REF!
Name InfImp26: #REF!
Name InfImp26: '[1]Dados Complementares'!$J$11
Name InfImp26: #REF!
Name InfImp27: #REF!
Name InfImp27: '[1]Dados Complementares'!$K$11
Name InfImp27: #REF!
Name InfImp28: #REF!
Name InfImp28: '[1]Dados Complementares'!$L$11
Name InfImp28: #REF!
Name InfImp29: #REF!
Name InfImp29: '[1]Dados Complementares'!$M$11
Name InfImp29: #REF!
Name InfImp30: #REF!
Name InfImp30: '[1]Dados Complementares'!$N$11
Name InfImp30: #REF!
Name InfImp31: #REF!
Name InfImp31: #REF!
Name InfImp32: #REF!
Name InfImp32: '[1]Dados Complementares'!$P$11
Name InfImp32: #REF!
Name PIB22_China: #REF!
Name PIB22_China: #REF!
Name PIB22_Mundo: #REF!
Name PIB22_Mundo: #REF!
Name PIB23_China: #REF!
Name PIB23_China: #REF!
Name PIB23_Mundo: #REF!
Name PIB23_Mundo: #REF!
Name PIB24_China: #REF!
Name PIB24_China: #REF!
Name PIB24_Mundo: #REF!
Name PIB24_Mundo: #REF!
Name PIB25_China: #REF!
Name PIB25_China: #REF!
Name PIB25_Mundo: #REF!
Name PIB25_Mundo: #REF!
Name PIB26_ARGENTINA: #REF!
Name PIB26_ARGENTINA: #REF!
Name PIB26_BRASIL: #REF!
Name PIB26_BRASIL: '[1]Dados Complementares'!$J$14
Name PIB26_BRASIL: #REF!
Name PIB26_CHINA: #REF!
Name PIB26_CHINA: '[1]Dados Complementares'!$J$15
Name PIB26_CHINA: #REF!
Name PIB26_EUA: #REF!
Name PIB26_EUA: #REF!
Name PIB26_EUROPA: #REF!
Name PIB26_EUROPA: #REF!

Sheet Dashboard
I4: Banco do Brasil ($BBAS3)
A7: Páginas
A8: Dashboard
A9: Ke | E9: Trimestre Atual | F9: 4 | H9: Custo de Capital Próprio (Ke) | I9: =I10-0.5% -> 0.14010913 | J9: =(NPV($I9,'DRE + DCF'!$U$41:$AC$41,SUM('DRE + DCF'!$AD$41,('DRE + DCF'!$AE$38*(1-(J$18/$I9))*(1+J$18))/($I9-J$18)))+'DRE + DCF'!$S$41)/((1+$I9)^((5-$F$9)*3/12)) -> 84.68172 | K9: =(NPV($I9,'DRE + DCF'!$U$41:$AC$41,SUM('DRE + DCF'!$AD$41,('DRE + DCF'!$AE$38*(1-(K$18/$I9))*(1+K$18))/($I9-K$18)))+'DRE + DCF'!$S$41)/((1+$I9)^((5-$F$9)*3/12)) -> 84.806684 | L9: =(NPV($I9,'DRE + DCF'!$U$41:$AC$41,SUM('DRE + DCF'!$AD$41,('DRE + DCF'!$AE$38*(1-(L$18/$I9))*(1+L$18))/($I9-L$18)))+'DRE + DCF'!$S$41)/((1+$I9)^((5-$F$9)*3/12)) -> 84.931648 | M9: =(NPV($I9,'DRE + DCF'!$U$41:$AC$41,SUM('DRE + DCF'!$AD$41,('DRE + DCF'!$AE$38*(1-(M$18/$I9))*(1+M$18))/($I9-M$18)))+'DRE + DCF'!$S$41)/((1+$I9)^((5-$F$9)*3/12)) -> 85.056611 | N9: =(NPV($I9,'DRE + DCF'!$U$41:$AC$41,SUM('DRE + DCF'!$AD$41,('DRE + DCF'!$AE$38*(1-(N$18/$I9))*(1+N$18))/($I9-N$18)))+'DRE + DCF'!$S$41)/((1+$I9)^((5-$F$9)*3/12)) -> 85.181575 | O9: =(NPV($I9,'DRE + DCF'!$U$41:$AC$41,SUM('DRE + DCF'!$AD$41,('DRE + DCF'!$AE$38*(1-(O$18/$I9))*(1+O$18))/($I9-O$18)))+'DRE + DCF'!$S$41)/((1+$I9)^((5-$F$9)*3/12)) -> 85.306539 | P9: =(NPV($I9,'DRE + DCF'!$U$41:$AC$41,SUM('DRE + DCF'!$AD$41,('DRE + DCF'!$AE$38*(1-(P$18/$I9))*(1+P$18))/($I9-P$18)))+'DRE + DCF'!$S$41)/((1+$I9)^((5-$F$9)*3/12)) -> 85.431502 | Q9: =(NPV($I9,'DRE + DCF'!$U$41:$AC$41,SUM('DRE + DCF'!$AD$41,('DRE + DCF'!$AE$38*(1-(Q$18/$I9))*(1+Q$18))/($I9-Q$18)))+'DRE + DCF'!$S$41)/((1+$I9)^((5-$F$9)*3/12)) -> 85.556466 | ... S9: =(NPV($I9,'DRE + DCF'!$U$41:$AC$41,SUM('DRE + DCF'!$AD$41,('DRE + DCF'!$AE$38*(1-(S$18/$I9))*(1+S$18))/($I9-S$18)))+'DRE + DCF'!$S$41)/((1+$I9)^((5-$F$9)*3/12)) -> 85.806393
A10: DRE + DCF | E10: Ticker | F10: BBAS3 | I10: =I11-0.5% -> 0.14510913 | J10: =(NPV($I10,'DRE + DCF'!$U$41:$AC$41,SUM('DRE + DCF'!$AD$41,('DRE + DCF'!$AE$38*(1-(J$18/$I10))*(1+J$18))/($I10-J$18)))+'DRE + DCF'!$S$41)/((1+$I10)^((5-$F$9)*3/12)) -> 79.827908 | K10: =(NPV($I10,'DRE + DCF'!$U$41:$AC$41,SUM('DRE + DCF'!$AD$41,('DRE + DCF'!$AE$38*(1-(K$18/$I10))*(1+K$18))/($I10-K$18)))+'DRE + DCF'!$S$41)/((1+$I10)^((5-$F$9)*3/12)) -> 79.943273 | L10: =(NPV($I10,'DRE + DCF'!$U$41:$AC$41,SUM('DRE + DCF'!$AD$41,('DRE + DCF'!$AE$38*(1-(L$18/$I10))*(1+L$18))/($I10-L$18)))+'DRE + DCF'!$S$41)/((1+$I10)^((5-$F$9)*3/12)) -> 80.058639 | M10: =(NPV($I10,'DRE + DCF'!$U$41:$AC$41,SUM('DRE + DCF'!$AD$41,('DRE + DCF'!$AE$38*(1-(M$18/$I10))*(1+M$18))/($I10-M$18)))+'DRE + DCF'!$S$41)/((1+$I10)^((5-$F$9)*3/12)) -> 80.174004 | N10: =(NPV($I10,'DRE + DCF'!$U$41:$AC$41,SUM('DRE + DCF'!$AD$41,('DRE + DCF'!$AE$38*(1-(N$18/$I10))*(1+N$18))/($I10-N$18)))+'DRE + DCF'!$S$41)/((1+$I10)^((5-$F$9)*3/12)) -> 80.28937 | O10: =(NPV($I10,'DRE + DCF'!$U$41:$AC$41,SUM('DRE + DCF'!$AD$41,('DRE + DCF'!$AE$38*(1-(O$18/$I10))*(1+O$18))/($I10-O$18)))+'DRE + DCF'!$S$41)/((1+$I10)^((5-$F$9)*3/12)) -> 80.404735 | P10: =(NPV($I10,'DRE + DCF'!$U$41:$AC$41,SUM('DRE + DCF'!$AD$41,('DRE + DCF'!$AE$38*(1-(P$18/$I10))*(1+P$18))/($I10-P$18)))+'DRE + DCF'!$S$41)/((1+$I10)^((5-$F$9)*3/12)) -> 80.520101 | Q10: =(NPV($I10,'DRE + DCF'!$U$41:$AC$41,SUM('DRE + DCF'!$AD$41,('DRE + DCF'!$AE$38*(1-(Q$18/$I10))*(1+Q$18))/($I10-Q$18)))+'DRE + DCF'!$S$41)/((1+$I10)^((5-$F$9)*3/12)) -> 80.635466 | ... S10: =(NPV($I10,'DRE + DCF'!$U$41:$AC$41,SUM('DRE + DCF'!$AD$41,('DRE + DCF'!$AE$38*(1-(S$18/$I10))*(1+S$18))/($I10-S$18)))+'DRE + DCF'!$S$41)/((1+$I10)^((5-$F$9)*3/12)) -> 80.866197
A11: Contas Abertas | E11: Ações Emitidas (Ex-Treasury) | F11: 2853776040 | I11: =I12-0.5% -> 0.15010913 | J11: =(NPV($I11,'DRE + DCF'!$U$41:$AC$41,SUM('DRE + DCF'!$AD$41,('DRE + DCF'!$AE$38*(1-(J$18/$I11))*(1+J$18))/($I11-J$18)))+'DRE + DCF'!$S$41)/((1+$I11)^((5-$F$9)*3/12)) -> 75.380749 | K11: =(NPV($I11,'DRE + DCF'!$U$41:$AC$41,SUM('DRE + DCF'!$AD$41,('DRE + DCF'!$AE$38*(1-(K$18/$I11))*(1+K$18))/($I11-K$18)))+'DRE + DCF'!$S$41)/((1+$I11)^((5-$F$9)*3/12)) -> 75.487401 | L11: =(NPV($I11,'DRE + DCF'!$U$41:$AC$41,SUM('DRE + DCF'!$AD$41,('DRE + DCF'!$AE$38*(1-(L$18/$I11))*(1+L$18))/($I11-L$18)))+'DRE + DCF'!$S$41)/((1+$I11)^((5-$F$9)*3/12)) -> 75.594053 | M11: =(NPV($I11,'DRE + DCF'!$U$41:$AC$41,SUM('DRE + DCF'!$AD$41,('DRE + DCF'!$AE$38*(1-(M$18/$I11))*(1+M$18))/($I11-M$18)))+'DRE + DCF'!$S$41)/((1+$I11)^((5-$F$9)*3/12)) -> 75.700705 | N11: =(NPV($I11,'DRE + DCF'!$U$41:$AC$41,SUM('DRE + DCF'!$AD$41,('DRE + DCF'!$AE$38*(1-(N$18/$I11))*(1+N$18))/($I11-N$18)))+'DRE + DCF'!$S$41)/((1+$I11)^((5-$F$9)*3/12)) -> 75.807357 | O11: =(NPV($I11,'DRE + DCF'!$U$41:$AC$41,SUM('DRE + DCF'!$AD$41,('DRE + DCF'!$AE$38*(1-(O$18/$I11))*(1+O$18))/($I11-O$18)))+'DRE + DCF'!$S$41)/((1+$I11)^((5-$F$9)*3/12)) -> 75.914009 | P11: =(NPV($I11,'DRE + DCF'!$U$41:$AC$41,SUM('DRE + DCF'!$AD$41,('DRE + DCF'!$AE$38*(1-(P$18/$I11))*(1+P$18))/($I11-P$18)))+'DRE + DCF'!$S$41)/((1+$I11)^((5-$F$9)*3/12)) -> 76.020661 | Q11: =(NPV($I11,'DRE + DCF'!$U$41:$AC$41,SUM('DRE + DCF'!$AD$41,('DRE + DCF'!$AE$38*(1-(Q$18/$I11))*(1+Q$18))/($I11-Q$18)))+'DRE + DCF'!$S$41)/((1+$I11)^((5-$F$9)*3/12)) -> 76.127313 | ... S11: =(NPV($I11,'DRE + DCF'!$U$41:$AC$41,SUM('DRE + DCF'!$AD$41,('DRE + DCF'!$AE$38*(1-(S$18/$I11))*(1+S$18))/($I11-S$18)))+'DRE + DCF'!$S$41)/((1+$I11)^((5-$F$9)*3/12)) -> 76.340617
A12: Balanço Patrimonial | E12: Valor da Ação | F12: =SUM('DRE + DCF'!S43,'DRE + DCF'!U43:AE43) -> 70.46412 | I12: =I13-0.5% -> 0.15510913 | J12: =(NPV($I12,'DRE + DCF'!$U$41:$AC$41,SUM('DRE + DCF'!$AD$41,('DRE + DCF'!$AE$38*(1-(J$18/$I12))*(1+J$18))/($I12-J$18)))+'DRE + DCF'!$S$41)/((1+$I12)^((5-$F$9)*3/12)) -> 71.296907 | K12: =(NPV($I12,'DRE + DCF'!$U$41:$AC$41,SUM('DRE + DCF'!$AD$41,('DRE + DCF'!$AE$38*(1-(K$18/$I12))*(1+K$18))/($I12-K$18)))+'DRE + DCF'!$S$41)/((1+$I12)^((5-$F$9)*3/12)) -> 71.395632 | L12: =(NPV($I12,'DRE + DCF'!$U$41:$AC$41,SUM('DRE + DCF'!$AD$41,('DRE + DCF'!$AE$38*(1-(L$18/$I12))*(1+L$18))/($I12-L$18)))+'DRE + DCF'!$S$41)/((1+$I12)^((5-$F$9)*3/12)) -> 71.494357 | M12: =(NPV($I12,'DRE + DCF'!$U$41:$AC$41,SUM('DRE + DCF'!$AD$41,('DRE + DCF'!$AE$38*(1-(M$18/$I12))*(1+M$18))/($I12-M$18)))+'DRE + DCF'!$S$41)/((1+$I12)^((5-$F$9)*3/12)) -> 71.593082 | N12: =(NPV($I12,'DRE + DCF'!$U$41:$AC$41,SUM('DRE + DCF'!$AD$41,('DRE + DCF'!$AE$38*(1-(N$18/$I12))*(1+N$18))/($I12-N$18)))+'DRE + DCF'!$S$41)/((1+$I12)^((5-$F$9)*3/12)) -> 71.691807 | O12: =(NPV($I12,'DRE + DCF'!$U$41:$AC$41,SUM('DRE + DCF'!$AD$41,('DRE + DCF'!$AE$38*(1-(O$18/$I12))*(1+O$18))/($I12-O$18)))+'DRE + DCF'!$S$41)/((1+$I12)^((5-$F$9)*3/12)) -> 71.790532 | P12: =(NPV($I12,'DRE + DCF'!$U$41:$AC$41,SUM('DRE + DCF'!$AD$41,('DRE + DCF'!$AE$38*(1-(P$18/$I12))*(1+P$18))/($I12-P$18)))+'DRE + DCF'!$S$41)/((1+$I12)^((5-$F$9)*3/12)) -> 71.889258 | Q12: =(NPV($I12,'DRE + DCF'!$U$41:$AC$41,SUM('DRE + DCF'!$AD$41,('DRE + DCF'!$AE$38*(1-(Q$18/$I12))*(1+Q$18))/($I12-Q$18)))+'DRE + DCF'!$S$41)/((1+$I12)^((5-$F$9)*3/12)) -> 71.987983 | ... S12: =(NPV($I12,'DRE + DCF'!$U$41:$AC$41,SUM('DRE + DCF'!$AD$41,('DRE + DCF'!$AE$38*(1-(S$18/$I12))*(1+S$18))/($I12-S$18)))+'DRE + DCF'!$S$41)/((1+$I12)^((5-$F$9)*3/12)) -> 72.185433
A13: Projeções - Receita | E13: Cotação | F13: 49.51 | I13: =AVERAGE(Ke!F16:P16) -> 0.16010913 | J13: =(NPV($I13,'DRE + DCF'!$U$41:$AC$41,SUM('DRE + DCF'!$AD$41,('DRE + DCF'!$AE$38*(1-(J$18/$I13))*(1+J$18))/($I13-J$18)))+'DRE + DCF'!$S$41)/((1+$I13)^((5-$F$9)*3/12)) -> 67.538666 | K13: =(NPV($I13,'DRE + DCF'!$U$41:$AC$41,SUM('DRE + DCF'!$AD$41,('DRE + DCF'!$AE$38*(1-(K$18/$I13))*(1+K$18))/($I13-K$18)))+'DRE + DCF'!$S$41)/((1+$I13)^((5-$F$9)*3/12)) -> 67.630166 | L13: =(NPV($I13,'DRE + DCF'!$U$41:$AC$41,SUM('DRE + DCF'!$AD$41,('DRE + DCF'!$AE$38*(1-(L$18/$I13))*(1+L$18))/($I13-L$18)))+'DRE + DCF'!$S$41)/((1+$I13)^((5-$F$9)*3/12)) -> 67.721666 | M13: =(NPV($I13,'DRE + DCF'!$U$41:$AC$41,SUM('DRE + DCF'!$AD$41,('DRE + DCF'!$AE$38*(1-(M$18/$I13))*(1+M$18))/($I13-M$18)))+'DRE + DCF'!$S$41)/((1+$I13)^((5-$F$9)*3/12)) -> 67.813166 | N13: =(NPV($I13,'DRE + DCF'!$U$41:$AC$41,SUM('DRE + DCF'!$AD$41,('DRE + DCF'!$AE$38*(1-(N$18/$I13))*(1+N$18))/($I13-N$18)))+'DRE + DCF'!$S$41)/((1+$I13)^((5-$F$9)*3/12)) -> 67.904667 | O13: =(NPV($I13,'DRE + DCF'!$U$41:$AC$41,SUM('DRE + DCF'!$AD$41,('DRE + DCF'!$AE$38*(1-(O$18/$I13))*(1+O$18))/($I13-O$18)))+'DRE + DCF'!$S$41)/((1+$I13)^((5-$F$9)*3/12)) -> 67.996167 | P13: =(NPV($I13,'DRE + DCF'!$U$41:$AC$41,SUM('DRE + DCF'!$AD$41,('DRE + DCF'!$AE$38*(1-(P$18/$I13))*(1+P$18))/($I13-P$18)))+'DRE + DCF'!$S$41)/((1+$I13)^((5-$F$9)*3/12)) -> 68.087667 | Q13: =(NPV($I13,'DRE + DCF'!$U$41:$AC$41,SUM('DRE + DCF'!$AD$41,('DRE + DCF'!$AE$38*(1-(Q$18/$I13))*(1+Q$18))/($I13-Q$18)))+'DRE + DCF'!$S$41)/((1+$I13)^((5-$F$9)*3/12)) -> 68.179167 | ... S13: =(NPV($I13,'DRE + DCF'!$U$41:$AC$41,SUM('DRE + DCF'!$AD$41,('DRE + DCF'!$AE$38*(1-(S$18/$I13))*(1+S$18))/($I13-S$18)))+'DRE + DCF'!$S$41)/((1+$I13)^((5-$F$9)*3/12)) -> 68.362167
A14: Painel de Índices | E14: Upside | F14: =F12/F13-1 -> 0.42323006 | I14: =I13+0.5% -> 0.16510913 | J14: =(NPV($I14,'DRE + DCF'!$U$41:$AC$41,SUM('DRE + DCF'!$AD$41,('DRE + DCF'!$AE$38*(1-(J$18/$I14))*(1+J$18))/($I14-J$18)))+'DRE + DCF'!$S$41)/((1+$I14)^((5-$F$9)*3/12)) -> 64.073075 | K14: =(NPV($I14,'DRE + DCF'!$U$41:$AC$41,SUM('DRE + DCF'!$AD$41,('DRE + DCF'!$AE$38*(1-(K$18/$I14))*(1+K$18))/($I14-K$18)))+'DRE + DCF'!$S$41)/((1+$I14)^((5-$F$9)*3/12)) -> 64.157978 | L14: =(NPV($I14,'DRE + DCF'!$U$41:$AC$41,SUM('DRE + DCF'!$AD$41,('DRE + DCF'!$AE$38*(1-(L$18/$I14))*(1+L$18))/($I14-L$18)))+'DRE + DCF'!$S$41)/((1+$I14)^((5-$F$9)*3/12)) -> 64.242881 | M14: =(NPV($I14,'DRE + DCF'!$U$41:$AC$41,SUM('DRE + DCF'!$AD$41,('DRE + DCF'!$AE$38*(1-(M$18/$I14))*(1+M$18))/($I14-M$18)))+'DRE + DCF'!$S$41)/((1+$I14)^((5-$F$9)*3/12)) -> 64.327784 | N14: =(NPV($I14,'DRE + DCF'!$U$41:$AC$41,SUM('DRE + DCF'!$AD$41,('DRE + DCF'!$AE$38*(1-(N$18/$I14))*(1+N$18))/($I14-N$18)))+'DRE + DCF'!$S$41)/((1+$I14)^((5-$F$9)*3/12)) -> 64.412687 | O14: =(NPV($I14,'DRE + DCF'!$U$41:$AC$41,SUM('DRE + DCF'!$AD$41,('DRE + DCF'!$AE$38*(1-(O$18/$I14))*(1+O$18))/($I14-O$18)))+'DRE + DCF'!$S$41)/((1+$I14)^((5-$F$9)*3/12)) -> 64.49759 | P14: =(NPV($I14,'DRE + DCF'!$U$41:$AC$41,SUM('DRE + DCF'!$AD$41,('DRE + DCF'!$AE$38*(1-(P$18/$I14))*(1+P$18))/($I14-P$18)))+'DRE + DCF'!$S$41)/((1+$I14)^((5-$F$9)*3/12)) -> 64.582493 | Q14: =(NPV($I14,'DRE + DCF'!$U$41:$AC$41,SUM('DRE + DCF'!$AD$41,('DRE + DCF'!$AE$38*(1-(Q$18/$I14))*(1+Q$18))/($I14-Q$18)))+'DRE + DCF'!$S$41)/((1+$I14)^((5-$F$9)*3/12)) -> 64.667395 | ... S14: =(NPV($I14,'DRE + DCF'!$U$41:$AC$41,SUM('DRE + DCF'!$AD$41,('DRE + DCF'!$AE$38*(1-(S$18/$I14))*(1+S$18))/($I14-S$18)))+'DRE + DCF'!$S$41)/((1+$I14)^((5-$F$9)*3/12)) -> 64.837201
A15: Projeções Trimestrais | E15: TIR | F15: =VLOOKUP(MIN(TIR!C13:C3382),TIR!C13:D3382,2,0) -> 0.19350623 | I15: =I14+0.5% -> 0.17010913 | J15: =(NPV($I15,'DRE + DCF'!$U$41:$AC$41,SUM('DRE + DCF'!$AD$41,('DRE + DCF'!$AE$38*(1-(J$18/$I15))*(1+J$18))/($I15-J$18)))+'DRE + DCF'!$S$41)/((1+$I15)^((5-$F$9)*3/12)) -> 60.871235 | K15: =(NPV($I15,'DRE + DCF'!$U$41:$AC$41,SUM('DRE + DCF'!$AD$41,('DRE + DCF'!$AE$38*(1-(K$18/$I15))*(1+K$18))/($I15-K$18)))+'DRE + DCF'!$S$41)/((1+$I15)^((5-$F$9)*3/12)) -> 60.950103 | L15: =(NPV($I15,'DRE + DCF'!$U$41:$AC$41,SUM('DRE + DCF'!$AD$41,('DRE + DCF'!$AE$38*(1-(L$18/$I15))*(1+L$18))/($I15-L$18)))+'DRE + DCF'!$S$41)/((1+$I15)^((5-$F$9)*3/12)) -> 61.028971 | M15: =(NPV($I15,'DRE + DCF'!$U$41:$AC$41,SUM('DRE + DCF'!$AD$41,('DRE + DCF'!$AE$38*(1-(M$18/$I15))*(1+M$18))/($I15-M$18)))+'DRE + DCF'!$S$41)/((1+$I15)^((5-$F$9)*3/12)) -> 61.10784 | N15: =(NPV($I15,'DRE + DCF'!$U$41:$AC$41,SUM('DRE + DCF'!$AD$41,('DRE + DCF'!$AE$38*(1-(N$18/$I15))*(1+N$18))/($I15-N$18)))+'DRE + DCF'!$S$41)/((1+$I15)^((5-$F$9)*3/12)) -> 61.186708 | O15: =(NPV($I15,'DRE + DCF'!$U$41:$AC$41,SUM('DRE + DCF'!$AD$41,('DRE + DCF'!$AE$38*(1-(O$18/$I15))*(1+O$18))/($I15-O$18)))+'DRE + DCF'!$S$41)/((1+$I15)^((5-$F$9)*3/12)) -> 61.265577 | P15: =(NPV($I15,'DRE + DCF'!$U$41:$AC$41,SUM('DRE + DCF'!$AD$41,('DRE + DCF'!$AE$38*(1-(P$18/$I15))*(1+P$18))/($I15-P$18)))+'DRE + DCF'!$S$41)/((1+$I15)^((5-$F$9)*3/12)) -> 61.344445 | Q15: =(NPV($I15,'DRE + DCF'!$U$41:$AC$41,SUM('DRE + DCF'!$AD$41,('DRE + DCF'!$AE$38*(1-(Q$18/$I15))*(1+Q$18))/($I15-Q$18)))+'DRE + DCF'!$S$41)/((1+$I15)^((5-$F$9)*3/12)) -> 61.423314 | ... S15: =(NPV($I15,'DRE + DCF'!$U$41:$AC$41,SUM('DRE + DCF'!$AD$41,('DRE + DCF'!$AE$38*(1-(S$18/$I15))*(1+S$18))/($I15-S$18)))+'DRE + DCF'!$S$41)/((1+$I15)^((5-$F$9)*3/12)) -> 61.58105
E16: Preço Teto | F16: =TIR!E12 -> 60.614178 | I16: =I15+0.5% -> 0.17510913 | J16: =(NPV($I16,'DRE + DCF'!$U$41:$AC$41,SUM('DRE + DCF'!$AD$41,('DRE + DCF'!$AE$38*(1-(J$18/$I16))*(1+J$18))/($I16-J$18)))+'DRE + DCF'!$S$41)/((1+$I16)^((5-$F$9)*3/12)) -> 57.907705 | K16: =(NPV($I16,'DRE + DCF'!$U$41:$AC$41,SUM('DRE + DCF'!$AD$41,('DRE + DCF'!$AE$38*(1-(K$18/$I16))*(1+K$18))/($I16-K$18)))+'DRE + DCF'!$S$41)/((1+$I16)^((5-$F$9)*3/12)) -> 57.981045 | L16: =(NPV($I16,'DRE + DCF'!$U$41:$AC$41,SUM('DRE + DCF'!$AD$41,('DRE + DCF'!$AE$38*(1-(L$18/$I16))*(1+L$18))/($I16-L$18)))+'DRE + DCF'!$S$41)/((1+$I16)^((5-$F$9)*3/12)) -> 58.054385 | M16: =(NPV($I16,'DRE + DCF'!$U$41:$AC$41,SUM('DRE + DCF'!$AD$41,('DRE + DCF'!$AE$38*(1-(M$18/$I16))*(1+M$18))/($I16-M$18)))+'DRE + DCF'!$S$41)/((1+$I16)^((5-$F$9)*3/12)) -> 58.127725 | N16: =(NPV($I16,'DRE + DCF'!$U$41:$AC$41,SUM('DRE + DCF'!$AD$41,('DRE + DCF'!$AE$38*(1-(N$18/$I16))*(1+N$18))/($I16-N$18)))+'DRE + DCF'!$S$41)/((1+$I16)^((5-$F$9)*3/12)) -> 58.201065 | O16: =(NPV($I16,'DRE + DCF'!$U$41:$AC$41,SUM('DRE + DCF'!$AD$41,('DRE + DCF'!$AE$38*(1-(O$18/$I16))*(1+O$18))/($I16-O$18)))+'DRE + DCF'!$S$41)/((1+$I16)^((5-$F$9)*3/12)) -> 58.274405 | P16: =(NPV($I16,'DRE + DCF'!$U$41:$AC$41,SUM('DRE + DCF'!$AD$41,('DRE + DCF'!$AE$38*(1-(P$18/$I16))*(1+P$18))/($I16-P$18)))+'DRE + DCF'!$S$41)/((1+$I16)^((5-$F$9)*3/12)) -> 58.347745 | Q16: =(NPV($I16,'DRE + DCF'!$U$41:$AC$41,SUM('DRE + DCF'!$AD$41,('DRE + DCF'!$AE$38*(1-(Q$18/$I16))*(1+Q$18))/($I16-Q$18)))+'DRE + DCF'!$S$41)/((1+$I16)^((5-$F$9)*3/12)) -> 58.421085 | ... S16: =(NPV($I16,'DRE + DCF'!$U$41:$AC$41,SUM('DRE + DCF'!$AD$41,('DRE + DCF'!$AE$38*(1-(S$18/$I16))*(1+S$18))/($I16-S$18)))+'DRE + DCF'!$S$41)/((1+$I16)^((5-$F$9)*3/12)) -> 58.567765
I17: =I16+0.5% -> 0.18010913 | J17: =(NPV($I17,'DRE + DCF'!$U$41:$AC$41,SUM('DRE + DCF'!$AD$41,('DRE + DCF'!$AE$38*(1-(J$18/$I17))*(1+J$18))/($I17-J$18)))+'DRE + DCF'!$S$41)/((1+$I17)^((5-$F$9)*3/12)) -> 55.160021 | K17: =(NPV($I17,'DRE + DCF'!$U$41:$AC$41,SUM('DRE + DCF'!$AD$41,('DRE + DCF'!$AE$38*(1-(K$18/$I17))*(1+K$18))/($I17-K$18)))+'DRE + DCF'!$S$41)/((1+$I17)^((5-$F$9)*3/12)) -> 55.228288 | L17: =(NPV($I17,'DRE + DCF'!$U$41:$AC$41,SUM('DRE + DCF'!$AD$41,('DRE + DCF'!$AE$38*(1-(L$18/$I17))*(1+L$18))/($I17-L$18)))+'DRE + DCF'!$S$41)/((1+$I17)^((5-$F$9)*3/12)) -> 55.296556 | M17: =(NPV($I17,'DRE + DCF'!$U$41:$AC$41,SUM('DRE + DCF'!$AD$41,('DRE + DCF'!$AE$38*(1-(M$18/$I17))*(1+M$18))/($I17-M$18)))+'DRE + DCF'!$S$41)/((1+$I17)^((5-$F$9)*3/12)) -> 55.364823 | N17: =(NPV($I17,'DRE + DCF'!$U$41:$AC$41,SUM('DRE + DCF'!$AD$41,('DRE + DCF'!$AE$38*(1-(N$18/$I17))*(1+N$18))/($I17-N$18)))+'DRE + DCF'!$S$41)/((1+$I17)^((5-$F$9)*3/12)) -> 55.43309 | O17: =(NPV($I17,'DRE + DCF'!$U$41:$AC$41,SUM('DRE + DCF'!$AD$41,('DRE + DCF'!$AE$38*(1-(O$18/$I17))*(1+O$18))/($I17-O$18)))+'DRE + DCF'!$S$41)/((1+$I17)^((5-$F$9)*3/12)) -> 55.501358 | P17: =(NPV($I17,'DRE + DCF'!$U$41:$AC$41,SUM('DRE + DCF'!$AD$41,('DRE + DCF'!$AE$38*(1-(P$18/$I17))*(1+P$18))/($I17-P$18)))+'DRE + DCF'!$S$41)/((1+$I17)^((5-$F$9)*3/12)) -> 55.569625 | Q17: =(NPV($I17,'DRE + DCF'!$U$41:$AC$41,SUM('DRE + DCF'!$AD$41,('DRE + DCF'!$AE$38*(1-(Q$18/$I17))*(1+Q$18))/($I17-Q$18)))+'DRE + DCF'!$S$41)/((1+$I17)^((5-$F$9)*3/12)) -> 55.637892 | ... S17: =(NPV($I17,'DRE + DCF'!$U$41:$AC$41,SUM('DRE + DCF'!$AD$41,('DRE + DCF'!$AE$38*(1-(S$18/$I17))*(1+S$18))/($I17-S$18)))+'DRE + DCF'!$S$41)/((1+$I17)^((5-$F$9)*3/12)) -> 55.774427
J18: =K18-0.25% -> 0.081156229 | K18: =L18-0.25% -> 0.083656229 | L18: =M18-0.25% -> 0.086156229 | M18: =N18-0.25% -> 0.088656229 | N18: ='DRE + DCF'!AG38 -> 0.091156229 | O18: =N18+0.25% -> 0.093656229 | P18: =O18+0.25% -> 0.096156229 | Q18: =P18+0.25% -> 0.098656229 | R18: =Q18+0.25% -> 0.10115623 | S18: =R18+0.25% -> 0.10365623
J19: Growth

Sheet Ke
K4: =Dashboard!$I$4 -> Banco do Brasil ($BBAS3)
A7: Páginas
A8: Dashboard
A9: Ke | E9: Atualizado em: 13/04/2023 | F9: 2023 | G9: =F9+1 -> 2024 | H9: =G9+1 -> 2025 | I9: =H9+1 -> 2026 | J9: =I9+1 -> 2027 | K9: =J9+1 -> 2028 | L9: =K9+1 -> 2029 | M9: =L9+1 -> 2030 | N9: =M9+1 -> 2031 | ... P9: =O9+1 -> 2033 | Q9: Descrição
A10: DRE + DCF | E10: DI | F10: 0.12008 | G10: 0.1082 | H10: 0.1062 | I10: 0.10765 | J10: 0.10959 | K10: 0.1113 | L10: 0.11248 | M10: 0.1132 | N10: 0.11362 | O10: 0.1139 | P10: 0.1139 | Q10: A taxa livre de risco no Brasil pode partir do DI, que é equivalente ao prêmio de um titulo IPCA+ do governo de mesmo prazo somado à inflação implicita.
A11: Contas Abertas | E11: CDS | F11: 0.003404 | G11: 0.005705487 | H11: 0.008640829 | I11: 0.012089975 | J11: 0.016020479 | K11: 0.019942676 | L11: 0.023348119 | M11: 0.026049827 | N11: 0.027900945 | O11: 0.028754619 | P11: 0.028463991 | Q11: Credit Default Swap (CDS)
A12: Balanço Patrimonial | E12: Inflação Implícita | F12: 0.0418 | G12: 0.04217 | H12: 0.04334 | I12: 0.04552 | J12: 0.04854 | K12: 0.05087 | L12: 0.05238 | M12: 0.0543 | N12: 0.05521 | O12: 0.05562 | P12: 0.05584
A13: Projeções - Receita | E13: Taxa Livre de Risco | F13: =F10-F11 -> 0.116676 | G13: =G10-G11 -> 0.10249451 | H13: =H10-H11 -> 0.097559171 | I13: =I10-I11 -> 0.095560025 | J13: =J10-J11 -> 0.093569521 | K13: =K10-K11 -> 0.091357324 | L13: =L10-L11 -> 0.089131881 | M13: =M10-M11 -> 0.087150173 | ... P13: =P10-P11 -> 0.085436009
A14: Painel de Índices | E14: Beta | F14: =SLOPE(H23:H766,I23:I766) -> 1.0229391 | G14: =F14 -> 1.0229391 | H14: =G14 -> 1.0229391 | I14: =H14 -> 1.0229391 | J14: =I14 -> 1.0229391 | K14: =J14 -> 1.0229391 | L14: =K14 -> 1.0229391 | M14: =L14 -> 1.0229391 | N14: =M14 -> 1.0229391 | ... P14: =O14 -> 1.0229391 | Q14: Beta Clássico
A15: Projeções Trimestrais | E15: Prêmio de Risco | F15: 0.065 | G15: 0.065 | H15: 0.065 | I15: 0.065 | J15: 0.065 | K15: 0.065 | L15: 0.065 | M15: 0.065 | N15: 0.065 | O15: 0.065 | P15: 0.065 | Q15: Dados Alternativos FGV: https://goo.gl/bBfwGq
E16: Custo de Capital Próprio (Ke) | F16: =F13+F14*F15 -> 0.18316704 | G16: =G13+G14*G15 -> 0.16898555 | H16: =H13+H14*H15 -> 0.16405021 | I16: =I13+I14*I15 -> 0.16205106 | J16: =J13+J14*J15 -> 0.16006056 | K16: =K13+K14*K15 -> 0.15784836 | L16: =L13+L14*L15 -> 0.15562292 | M16: =M13+M14*M15 -> 0.15364121 | ... P16: =P13+P14*P15 -> 0.15192705
E17: Desconto | F17: =(1+F16)^((5-Dashboard!$F$9)*3/12) -> 1.0429453 | G17: =F17*(1+G16) -> 1.2191879 | H17: =G17*(1+H16) -> 1.419196 | I17: =H17*(1+I16) -> 1.6491782 | J17: =I17*(1+J16) -> 1.9131466 | K17: =J17*(1+K16) -> 2.2151336 | L17: =K17*(1+L16) -> 2.5598592 | M17: =L17*(1+M16) -> 2.9531591 | N17: =M17*(1+N16) -> 3.4026597 | ... P17: =O17*(1+P16) -> 4.5139722
E21: Data | F21: Preço BBAS3 | G21: IBOV | H21: Variação BBAS3 | I21: Variação IBOV
E22: 44144 | F22: 26.152027 | G22: 103913 | H22: - | I22: -
E23: 44145 | F23: 27.487614 | G23: 105351 | H23: =F23/F22-1 -> 0.051070114 | I23: =G23/G22-1 -> 0.0138385
E24: 44146 | F24: 27.319668 | G24: 104532 | H24: =F24/F23-1 -> -0.0061098792 | I24: =G24/G23-1 -> -0.0077740126
E25: 44147 | F25: 26.176014 | G25: 102175 | H25: =F25/F24-1 -> -0.041861929 | I25: =G25/G24-1 -> -0.022548119
E26: 44148 | F26: 26.431938 | G26: 104512 | H26: =F26/F25-1 -> 0.0097770424 | I26: =G26/G25-1 -> 0.022872523
E27: 44151 | F27: 27.111734 | G27: 106430 | H27: =F27/F26-1 -> 0.025718735 | I27: =G27/G26-1 -> 0.01835196
E28: 44152 | F28: 27.509712 | G28: 107229 | H28: =F28/F27-1 -> 0.014679179 | I28: =G28/G27-1 -> 0.0075072818
E29: 44153 | F29: 27.574066 | G29: 106483 | H29: =F29/F28-1 -> 0.0023393193 | I29: =G29/G28-1 -> -0.0069570732
E30: 44154 | F30: 27.847555 | G30: 106517 | H30: =F30/F29-1 -> 0.0099183414 | I30: =G30/G29-1 -> 0.00031929979
E31: 44158 | F31: 27.767117 | G31: 107379 | H31: =F31/F30-1 -> -0.0028885121 | I31: =G31/G30-1 -> 0.0080926049
E32: 44159 | F32: 28.507145 | G32: 109786 | H32: =F32/F31-1 -> 0.026651236 | I32: =G32/G31-1 -> 0.022415929
E33: 44160 | F33: 28.426706 | G33: 110133 | H33: =F33/F32-1 -> -0.0028217136 | I33: =G33/G32-1 -> 0.0031606944
E34: 44161 | F34: 27.976252 | G34: 110227 | H34: =F34/F33-1 -> -0.015846155 | I34: =G34/G33-1 -> 0.00085351348
... E766: 45237 | F766: 51.02 | G766: 119268 | H766: =F766/F765-1 -> 0.011298295 | I766: =G766/G765-1 -> 0.0065914404

Sheet TIR
L4: =Dashboard!$I$4 -> Banco do Brasil ($BBAS3)
A7: Páginas
A8: Dashboard
A9: Ke
A10: DRE + DCF | C10: Delta | D10: TIR | E10: Preço Justo | F10: Valor da Perpetuidade | G10: Growth | H10: Ke | S10: Taxa de Desconto
A11: Contas Abertas | H11: 2023 | I11: 2024 | J11: 2025 | K11: 2026 | L11: 2027 | M11: 2028 | N11: 2029 | O11: 2030 | P11: 2031 | Q11: 2032 | R11: 2033 | S11: 2023 | T11: 2024 | U11: 2025 | V11: 2026 | W11: 2027 | X11: 2028 | Y11: 2029 | Z11: 2030 | AA11: 2031 | AB11: 2032 | AC11: 2033
A12: Balanço Patrimonial | C12: Preço Teto | D12: =AVERAGE(AVERAGE(Ke!$F$16:$P$16),MAX(Ke!F16:P16)) -> 0.17163809 | E12: {=SUM('DRE + DCF'!$S$41/TIR!S12,'DRE + DCF'!$U$41:$AD$41/TIR!T12:AC12,TIR!F12)} -> 60.614178 | F12: ='DRE + DCF'!$AE$38*'DRE + DCF'!$AE$39*(1+G12)/(R12-G12)/AC12 -> 34.027734 | G12: =R12*(1-'DRE + DCF'!$AE$39) -> 0.10298285 | H12: =$D12 -> 0.17163809 | I12: =$D12 -> 0.17163809 | J12: =$D12 -> 0.17163809 | K12: =$D12 -> 0.17163809 | L12: =$D12 -> 0.17163809 | M12: =$D12 -> 0.17163809 | N12: =$D12 -> 0.17163809 | O12: =$D12 -> 0.17163809 | ... R12: =$D12 -> 0.17163809 | S12: =(1+H12)^((5-Dashboard!$F$9)*3/12) -> 1.0403953 | T12: =(S12)*(1+I12) -> 1.2189667 | U12: =(T12)*(1+J12) -> 1.4281878 | V12: =(U12)*(1+K12) -> 1.6733193 | W12: =(V12)*(1+L12) -> 1.9605246 | X12: =(W12)*(1+M12) -> 2.2970253 | Y12: =(X12)*(1+N12) -> 2.6912823 | Z12: =(Y12)*(1+O12) -> 3.1532089 | AA12: =(Z12)*(1+P12) -> 3.6944196 | ... AC12: =(AB12)*(1+R12) -> 5.071462
A13: Projeções - Receita | C13: =ABS(E13-Dashboard!$F$13) -> 116.4543 | D13: ='DRE + DCF'!AG38+0.00005 -> 0.091206229 | E13: {=SUM('DRE + DCF'!$S$41/TIR!S13,'DRE + DCF'!$U$41:$AD$41/TIR!T13:AC13,TIR!F13)} -> 165.9643 | F13: ='DRE + DCF'!$AE$38*'DRE + DCF'!$AE$39*(1+G13)/(R13-G13)/AC13 -> 126.93467 | G13: =R13*(1-'DRE + DCF'!$AE$39) -> 0.054723737 | H13: =$D13 -> 0.091206229 | I13: =$D13 -> 0.091206229 | J13: =$D13 -> 0.091206229 | K13: =$D13 -> 0.091206229 | L13: =$D13 -> 0.091206229 | M13: =$D13 -> 0.091206229 | N13: =$D13 -> 0.091206229 | O13: =$D13 -> 0.091206229 | ... R13: =$D13 -> 0.091206229 | S13: =(1+H13)^((5-Dashboard!$F$9)*3/12) -> 1.0220607 | T13: =(S13)*(1+I13) -> 1.1152791 | U13: =(T13)*(1+J13) -> 1.2169994 | V13: =(U13)*(1+K13) -> 1.3279974 | W13: =(V13)*(1+L13) -> 1.449119 | X13: =(W13)*(1+M13) -> 1.5812877 | Y13: =(X13)*(1+N13) -> 1.725511 | Z13: =(Y13)*(1+O13) -> 1.8828883 | AA13: =(Z13)*(1+P13) -> 2.0546195 | ... AC13: =(AB13)*(1+R13) -> 2.4464992
A14: Painel de Índices | C14: =ABS(E14-Dashboard!$F$13) -> 116.183 | D14: =D13+0.0001 -> 0.091306229 | E14: {=SUM('DRE + DCF'!$S$41/TIR!S14,'DRE + DCF'!$U$41:$AD$41/TIR!T14:AC14,TIR!F14)} -> 165.693 | F14: ='DRE + DCF'!$AE$38*'DRE + DCF'!$AE$39*(1+G14)/(R14-G14)/AC14 -> 126.68382 | G14: =R14*(1-'DRE + DCF'!$AE$39) -> 0.054783737 | H14: =$D14 -> 0.091306229 | I14: =$D14 -> 0.091306229 | J14: =$D14 -> 0.091306229 | K14: =$D14 -> 0.091306229 | L14: =$D14 -> 0.091306229 | M14: =$D14 -> 0.091306229 | N14: =$D14 -> 0.091306229 | O14: =$D14 -> 0.091306229 | ... R14: =$D14 -> 0.091306229 | S14: =(1+H14)^((5-Dashboard!$F$9)*3/12) -> 1.0220842 | T14: =(S14)*(1+I14) -> 1.1154068 | U14: =(T14)*(1+J14) -> 1.2172504 | V14: =(U14)*(1+K14) -> 1.3283929 | W14: =(V14)*(1+L14) -> 1.4496835 | X14: =(W14)*(1+M14) -> 1.5820486 | Y14: =(X14)*(1+N14) -> 1.7264995 | Z14: =(Y14)*(1+O14) -> 1.8841397 | AA14: =(Z14)*(1+P14) -> 2.0561734 | ... AC14: =(AB14)*(1+R14) -> 2.4487982
A15: Projeções Trimestrais | C15: =ABS(E15-Dashboard!$F$13) -> 115.91237 | D15: =D14+0.0001 -> 0.091406229 | E15: {=SUM('DRE + DCF'!$S$41/TIR!S15,'DRE + DCF'!$U$41:$AD$41/TIR!T15:AC15,TIR!F15)} -> 165.42237 | F15: ='DRE + DCF'!$AE$38*'DRE + DCF'!$AE$39*(1+G15)/(R15-G15)/AC15 -> 126.43362 | G15: =R15*(1-'DRE + DCF'!$AE$39) -> 0.054843737 | H15: =$D15 -> 0.091406229 | I15: =$D15 -> 0.091406229 | J15: =$D15 -> 0.091406229 | K15: =$D15 -> 0.091406229 | L15: =$D15 -> 0.091406229 | M15: =$D15 -> 0.091406229 | N15: =$D15 -> 0.091406229 | O15: =$D15 -> 0.091406229 | ... R15: =$D15 -> 0.091406229 | S15: =(1+H15)^((5-Dashboard!$F$9)*3/12) -> 1.0221076 | T15: =(S15)*(1+I15) -> 1.1155346 | U15: =(T15)*(1+J15) -> 1.2175014 | V15: =(U15)*(1+K15) -> 1.3287886 | W15: =(V15)*(1+L15) -> 1.4502481 | X15: =(W15)*(1+M15) -> 1.5828099 | Y15: =(X15)*(1+N15) -> 1.7274885 | Z15: =(Y15)*(1+O15) -> 1.8853918 | AA15: =(Z15)*(1+P15) -> 2.0577283 | ... AC15: =(AB15)*(1+R15) -> 2.4510992
C16: =ABS(E16-Dashboard!$F$13) -> 115.64242 | D16: =D15+0.0001 -> 0.091506229 | E16: {=SUM('DRE + DCF'!$S$41/TIR!S16,'DRE + DCF'!$U$41:$AD$41/TIR!T16:AC16,TIR!F16)} -> 165.15242 | F16: ='DRE + DCF'!$AE$38*'DRE + DCF'!$AE$39*(1+G16)/(R16-G16)/AC16 -> 126.18408 | G16: =R16*(1-'DRE + DCF'!$AE$39) -> 0.054903737 | H16: =$D16 -> 0.091506229 | I16: =$D16 -> 0.091506229 | J16: =$D16 -> 0.091506229 | K16: =$D16 -> 0.091506229 | L16: =$D16 -> 0.091506229 | M16: =$D16 -> 0.091506229 | N16: =$D16 -> 0.091506229 | O16: =$D16 -> 0.091506229 | ... R16: =$D16 -> 0.091506229 | S16: =(1+H16)^((5-Dashboard!$F$9)*3/12) -> 1.022131 | T16: =(S16)*(1+I16) -> 1.1156623 | U16: =(T16)*(1+J16) -> 1.2177524 | V16: =(U16)*(1+K16) -> 1.3291843 | W16: =(V16)*(1+L16) -> 1.450813 | X16: =(W16)*(1+M16) -> 1.5835714 | Y16: =(X16)*(1+N16) -> 1.728478 | Z16: =(Y16)*(1+O16) -> 1.8866445 | AA16: =(Z16)*(1+P16) -> 2.0592843 | ... AC16: =(AB16)*(1+R16) -> 2.4534021
C17: =ABS(E17-Dashboard!$F$13) -> 115.37313 | D17: =D16+0.0001 -> 0.091606229 | E17: {=SUM('DRE + DCF'!$S$41/TIR!S17,'DRE + DCF'!$U$41:$AD$41/TIR!T17:AC17,TIR!F17)} -> 164.88313 | F17: ='DRE + DCF'!$AE$38*'DRE + DCF'!$AE$39*(1+G17)/(R17-G17)/AC17 -> 125.93519 | G17: =R17*(1-'DRE + DCF'!$AE$39) -> 0.054963737 | H17: =$D17 -> 0.091606229 | I17: =$D17 -> 0.091606229 | J17: =$D17 -> 0.091606229 | K17: =$D17 -> 0.091606229 | L17: =$D17 -> 0.091606229 | M17: =$D17 -> 0.091606229 | N17: =$D17 -> 0.091606229 | O17: =$D17 -> 0.091606229 | ... R17: =$D17 -> 0.091606229 | S17: =(1+H17)^((5-Dashboard!$F$9)*3/12) -> 1.0221544 | T17: =(S17)*(1+I17) -> 1.1157901 | U17: =(T17)*(1+J17) -> 1.2180034 | V17: =(U17)*(1+K17) -> 1.3295801 | W17: =(V17)*(1+L17) -> 1.451378 | X17: =(W17)*(1+M17) -> 1.5843332 | Y17: =(X17)*(1+N17) -> 1.729468 | Z17: =(Y17)*(1+O17) -> 1.887898 | AA17: =(Z17)*(1+P17) -> 2.0608413 | ... AC17: =(AB17)*(1+R17) -> 2.455707
C18: =ABS(E18-Dashboard!$F$13) -> 115.10451 | D18: =D17+0.0001 -> 0.091706229 | E18: {=SUM('DRE + DCF'!$S$41/TIR!S18,'DRE + DCF'!$U$41:$AD$41/TIR!T18:AC18,TIR!F18)} -> 164.61451 | F18: ='DRE + DCF'!$AE$38*'DRE + DCF'!$AE$39*(1+G18)/(R18-G18)/AC18 -> 125.68695 | G18: =R18*(1-'DRE + DCF'!$AE$39) -> 0.055023737 | H18: =$D18 -> 0.091706229 | I18: =$D18 -> 0.091706229 | J18: =$D18 -> 0.091706229 | K18: =$D18 -> 0.091706229 | L18: =$D18 -> 0.091706229 | M18: =$D18 -> 0.091706229 | N18: =$D18 -> 0.091706229 | O18: =$D18 -> 0.091706229 | ... R18: =$D18 -> 0.091706229 | S18: =(1+H18)^((5-Dashboard!$F$9)*3/12) -> 1.0221778 | T18: =(S18)*(1+I18) -> 1.1159179 | U18: =(T18)*(1+J18) -> 1.2182545 | V18: =(U18)*(1+K18) -> 1.329976 | W18: =(V18)*(1+L18) -> 1.4519431 | X18: =(W18)*(1+M18) -> 1.5850953 | Y18: =(X18)*(1+N18) -> 1.7304585 | Z18: =(Y18)*(1+O18) -> 1.8891523 | AA18: =(Z18)*(1+P18) -> 2.0623993 | ... AC18: =(AB18)*(1+R18) -> 2.4580139
C19: =ABS(E19-Dashboard!$F$13) -> 114.83656 | D19: =D18+0.0001 -> 0.091806229 | E19: {=SUM('DRE + DCF'!$S$41/TIR!S19,'DRE + DCF'!$U$41:$AD$41/TIR!T19:AC19,TIR!F19)} -> 164.34656 | F19: ='DRE + DCF'!$AE$38*'DRE + DCF'!$AE$39*(1+G19)/(R19-G19)/AC19 -> 125.43936 | G19: =R19*(1-'DRE + DCF'!$AE$39) -> 0.055083737 | H19: =$D19 -> 0.091806229 | I19: =$D19 -> 0.091806229 | J19: =$D19 -> 0.091806229 | K19: =$D19 -> 0.091806229 | L19: =$D19 -> 0.091806229 | M19: =$D19 -> 0.091806229 | N19: =$D19 -> 0.091806229 | O19: =$D19 -> 0.091806229 | ... R19: =$D19 -> 0.091806229 | S19: =(1+H19)^((5-Dashboard!$F$9)*3/12) -> 1.0222012 | T19: =(S19)*(1+I19) -> 1.1160457 | U19: =(T19)*(1+J19) -> 1.2185056 | V19: =(U19)*(1+K19) -> 1.330372 | W19: =(V19)*(1+L19) -> 1.4525084 | X19: =(W19)*(1+M19) -> 1.5858578 | Y19: =(X19)*(1+N19) -> 1.7314494 | Z19: =(Y19)*(1+O19) -> 1.8904072 | AA19: =(Z19)*(1+P19) -> 2.0639584 | ... AC19: =(AB19)*(1+R19) -> 2.4603227
C20: =ABS(E20-Dashboard!$F$13) -> 114.56926 | D20: =D19+0.0001 -> 0.091906229 | E20: {=SUM('DRE + DCF'!$S$41/TIR!S20,'DRE + DCF'!$U$41:$AD$41/TIR!T20:AC20,TIR!F20)} -> 164.07926 | F20: ='DRE + DCF'!$AE$38*'DRE + DCF'!$AE$39*(1+G20)/(R20-G20)/AC20 -> 125.19242 | G20: =R20*(1-'DRE + DCF'!$AE$39) -> 0.055143737 | H20: =$D20 -> 0.091906229 | I20: =$D20 -> 0.091906229 | J20: =$D20 -> 0.091906229 | K20: =$D20 -> 0.091906229 | L20: =$D20 -> 0.091906229 | M20: =$D20 -> 0.091906229 | N20: =$D20 -> 0.091906229 | O20: =$D20 -> 0.091906229 | ... R20: =$D20 -> 0.091906229 | S20: =(1+H20)^((5-Dashboard!$F$9)*3/12) -> 1.0222246 | T20: =(S20)*(1+I20) -> 1.1161734 | U20: =(T20)*(1+J20) -> 1.2187567 | V20: =(U20)*(1+K20) -> 1.3307681 | W20: =(V20)*(1+L20) -> 1.4530739 | X20: =(W20)*(1+M20) -> 1.5866205 | Y20: =(X20)*(1+N20) -> 1.7324408 | Z20: =(Y20)*(1+O20) -> 1.8916629 | AA20: =(Z20)*(1+P20) -> 2.0655185 | ... AC20: =(AB20)*(1+R20) -> 2.4626334
C21: =ABS(E21-Dashboard!$F$13) -> 114.30263 | D21: =D20+0.0001 -> 0.092006229 | E21: {=SUM('DRE + DCF'!$S$41/TIR!S21,'DRE + DCF'!$U$41:$AD$41/TIR!T21:AC21,TIR!F21)} -> 163.81263 | F21: ='DRE + DCF'!$AE$38*'DRE + DCF'!$AE$39*(1+G21)/(R21-G21)/AC21 -> 124.94612 | G21: =R21*(1-'DRE + DCF'!$AE$39) -> 0.055203737 | H21: =$D21 -> 0.092006229 | I21: =$D21 -> 0.092006229 | J21: =$D21 -> 0.092006229 | K21: =$D21 -> 0.092006229 | L21: =$D21 -> 0.092006229 | M21: =$D21 -> 0.092006229 | N21: =$D21 -> 0.092006229 | O21: =$D21 -> 0.092006229 | ... R21: =$D21 -> 0.092006229 | S21: =(1+H21)^((5-Dashboard!$F$9)*3/12) -> 1.022248 | T21: =(S21)*(1+I21) -> 1.1163012 | U21: =(T21)*(1+J21) -> 1.2190079 | V21: =(U21)*(1+K21) -> 1.3311642 | W21: =(V21)*(1+L21) -> 1.4536396 | X21: =(W21)*(1+M21) -> 1.5873835 | Y21: =(X21)*(1+N21) -> 1.7334326 | Z21: =(Y21)*(1+O21) -> 1.8929193 | AA21: =(Z21)*(1+P21) -> 2.0670796 | ... AC21: =(AB21)*(1+R21) -> 2.4649461
C22: =ABS(E22-Dashboard!$F$13) -> 114.03665 | D22: =D21+0.0001 -> 0.092106229 | E22: {=SUM('DRE + DCF'!$S$41/TIR!S22,'DRE + DCF'!$U$41:$AD$41/TIR!T22:AC22,TIR!F22)} -> 163.54665 | F22: ='DRE + DCF'!$AE$38*'DRE + DCF'!$AE$39*(1+G22)/(R22-G22)/AC22 -> 124.70046 | G22: =R22*(1-'DRE + DCF'!$AE$39) -> 0.055263737 | H22: =$D22 -> 0.092106229 | I22: =$D22 -> 0.092106229 | J22: =$D22 -> 0.092106229 | K22: =$D22 -> 0.092106229 | L22: =$D22 -> 0.092106229 | M22: =$D22 -> 0.092106229 | N22: =$D22 -> 0.092106229 | O22: =$D22 -> 0.092106229 | ... R22: =$D22 -> 0.092106229 | S22: =(1+H22)^((5-Dashboard!$F$9)*3/12) -> 1.0222714 | T22: =(S22)*(1+I22) -> 1.116429 | U22: =(T22)*(1+J22) -> 1.2192591 | V22: =(U22)*(1+K22) -> 1.3315604 | W22: =(V22)*(1+L22) -> 1.4542054 | X22: =(W22)*(1+M22) -> 1.5881468 | Y22: =(X22)*(1+N22) -> 1.734425 | Z22: =(Y22)*(1+O22) -> 1.8941763 | AA22: =(Z22)*(1+P22) -> 2.0686418 | ... AC22: =(AB22)*(1+R22) -> 2.4672608
C23: =ABS(E23-Dashboard!$F$13) -> 113.77133 | D23: =D22+0.0001 -> 0.092206229 | E23: {=SUM('DRE + DCF'!$S$41/TIR!S23,'DRE + DCF'!$U$41:$AD$41/TIR!T23:AC23,TIR!F23)} -> 163.28133 | F23: ='DRE + DCF'!$AE$38*'DRE + DCF'!$AE$39*(1+G23)/(R23-G23)/AC23 -> 124.45545 | G23: =R23*(1-'DRE + DCF'!$AE$39) -> 0.055323737 | H23: =$D23 -> 0.092206229 | I23: =$D23 -> 0.092206229 | J23: =$D23 -> 0.092206229 | K23: =$D23 -> 0.092206229 | L23: =$D23 -> 0.092206229 | M23: =$D23 -> 0.092206229 | N23: =$D23 -> 0.092206229 | O23: =$D23 -> 0.092206229 | ... R23: =$D23 -> 0.092206229 | S23: =(1+H23)^((5-Dashboard!$F$9)*3/12) -> 1.0222948 | T23: =(S23)*(1+I23) -> 1.1165568 | U23: =(T23)*(1+J23) -> 1.2195103 | V23: =(U23)*(1+K23) -> 1.3319567 | W23: =(V23)*(1+L23) -> 1.4547714 | X23: =(W23)*(1+M23) -> 1.5889104 | Y23: =(X23)*(1+N23) -> 1.7354178 | Z23: =(Y23)*(1+O23) -> 1.8954342 | AA23: =(Z23)*(1+P23) -> 2.070205 | ... AC23: =(AB23)*(1+R23) -> 2.4695775
C24: =ABS(E24-Dashboard!$F$13) -> 113.50667 | D24: =D23+0.0001 -> 0.092306229 | E24: {=SUM('DRE + DCF'!$S$41/TIR!S24,'DRE + DCF'!$U$41:$AD$41/TIR!T24:AC24,TIR!F24)} -> 163.01667 | F24: ='DRE + DCF'!$AE$38*'DRE + DCF'!$AE$39*(1+G24)/(R24-G24)/AC24 -> 124.21107 | G24: =R24*(1-'DRE + DCF'!$AE$39) -> 0.055383737 | H24: =$D24 -> 0.092306229 | I24: =$D24 -> 0.092306229 | J24: =$D24 -> 0.092306229 | K24: =$D24 -> 0.092306229 | L24: =$D24 -> 0.092306229 | M24: =$D24 -> 0.092306229 | N24: =$D24 -> 0.092306229 | O24: =$D24 -> 0.092306229 | ... R24: =$D24 -> 0.092306229 | S24: =(1+H24)^((5-Dashboard!$F$9)*3/12) -> 1.0223182 | T24: =(S24)*(1+I24) -> 1.1166846 | U24: =(T24)*(1+J24) -> 1.2197615 | V24: =(U24)*(1+K24) -> 1.3323531 | W24: =(V24)*(1+L24) -> 1.4553376 | X24: =(W24)*(1+M24) -> 1.5896743 | Y24: =(X24)*(1+N24) -> 1.7364111 | Z24: =(Y24)*(1+O24) -> 1.8966927 | AA24: =(Z24)*(1+P24) -> 2.0717693 | ... AC24: =(AB24)*(1+R24) -> 2.4718961
C25: =ABS(E25-Dashboard!$F$13) -> 113.24265 | D25: =D24+0.0001 -> 0.092406229 | E25: {=SUM('DRE + DCF'!$S$41/TIR!S25,'DRE + DCF'!$U$41:$AD$41/TIR!T25:AC25,TIR!F25)} -> 162.75265 | F25: ='DRE + DCF'!$AE$38*'DRE + DCF'!$AE$39*(1+G25)/(R25-G25)/AC25 -> 123.96733 | G25: =R25*(1-'DRE + DCF'!$AE$39) -> 0.055443737 | H25: =$D25 -> 0.092406229 | I25: =$D25 -> 0.092406229 | J25: =$D25 -> 0.092406229 | K25: =$D25 -> 0.092406229 | L25: =$D25 -> 0.092406229 | M25: =$D25 -> 0.092406229 | N25: =$D25 -> 0.092406229 | O25: =$D25 -> 0.092406229 | ... R25: =$D25 -> 0.092406229 | S25: =(1+H25)^((5-Dashboard!$F$9)*3/12) -> 1.0223416 | T25: =(S25)*(1+I25) -> 1.1168124 | U25: =(T25)*(1+J25) -> 1.2200128 | V25: =(U25)*(1+K25) -> 1.3327496 | W25: =(V25)*(1+L25) -> 1.4559039 | X25: =(W25)*(1+M25) -> 1.5904385 | Y25: =(X25)*(1+N25) -> 1.7374049 | Z25: =(Y25)*(1+O25) -> 1.897952 | AA25: =(Z25)*(1+P25) -> 2.0733345 | ... AC25: =(AB25)*(1+R25) -> 2.4742166
C26: =ABS(E26-Dashboard!$F$13) -> 112.97928 | D26: =D25+0.0001 -> 0.092506229 | E26: {=SUM('DRE + DCF'!$S$41/TIR!S26,'DRE + DCF'!$U$41:$AD$41/TIR!T26:AC26,TIR!F26)} -> 162.48928 | F26: ='DRE + DCF'!$AE$38*'DRE + DCF'!$AE$39*(1+G26)/(R26-G26)/AC26 -> 123.72422 | G26: =R26*(1-'DRE + DCF'!$AE$39) -> 0.055503737 | H26: =$D26 -> 0.092506229 | I26: =$D26 -> 0.092506229 | J26: =$D26 -> 0.092506229 | K26: =$D26 -> 0.092506229 | L26: =$D26 -> 0.092506229 | M26: =$D26 -> 0.092506229 | N26: =$D26 -> 0.092506229 | O26: =$D26 -> 0.092506229 | ... R26: =$D26 -> 0.092506229 | S26: =(1+H26)^((5-Dashboard!$F$9)*3/12) -> 1.022365 | T26: =(S26)*(1+I26) -> 1.1169401 | U26: =(T26)*(1+J26) -> 1.2202641 | V26: =(U26)*(1+K26) -> 1.3331461 | W26: =(V26)*(1+L26) -> 1.4564704 | X26: =(W26)*(1+M26) -> 1.591203 | Y26: =(X26)*(1+N26) -> 1.7383992 | Z26: =(Y26)*(1+O26) -> 1.8992119 | AA26: =(Z26)*(1+P26) -> 2.0749009 | ... AC26: =(AB26)*(1+R26) -> 2.4765391
C27: =ABS(E27-Dashboard!$F$13) -> 112.71656 | D27: =D26+0.0001 -> 0.092606229 | E27: {=SUM('DRE + DCF'!$S$41/TIR!S27,'DRE + DCF'!$U$41:$AD$41/TIR!T27:AC27,TIR!F27)} -> 162.22656 | F27: ='DRE + DCF'!$AE$38*'DRE + DCF'!$AE$39*(1+G27)/(R27-G27)/AC27 -> 123.48174 | G27: =R27*(1-'DRE + DCF'!$AE$39) -> 0.055563737 | H27: =$D27 -> 0.092606229 | I27: =$D27 -> 0.092606229 | J27: =$D27 -> 0.092606229 | K27: =$D27 -> 0.092606229 | L27: =$D27 -> 0.092606229 | M27: =$D27 -> 0.092606229 | N27: =$D27 -> 0.092606229 | O27: =$D27 -> 0.092606229 | ... R27: =$D27 -> 0.092606229 | S27: =(1+H27)^((5-Dashboard!$F$9)*3/12) -> 1.0223884 | T27: =(S27)*(1+I27) -> 1.1170679 | U27: =(T27)*(1+J27) -> 1.2205154 | V27: =(U27)*(1+K27) -> 1.3335427 | W27: =(V27)*(1+L27) -> 1.4570371 | X27: =(W27)*(1+M27) -> 1.5919678 | Y27: =(X27)*(1+N27) -> 1.7393939 | Z27: =(Y27)*(1+O27) -> 1.9004726 | AA27: =(Z27)*(1+P27) -> 2.0764682 | ... AC27: =(AB27)*(1+R27) -> 2.4788636
... C3382: =ABS(E3382-Dashboard!$F$13) -> 36.02201 | D3382: =D3381+0.0001 -> 0.42810623 | E3382: {=SUM('DRE + DCF'!$S$41/TIR!S3382,'DRE + DCF'!$U$41:$AD$41/TIR!T3382:AC3382,TIR!F3382)} -> 13.48799 | F3382: ='DRE + DCF'!$AE$38*'DRE + DCF'!$AE$39*(1+G3382)/(R3382-G3382)/AC3382 -> 2.0438664 | G3382: =R3382*(1-'DRE + DCF'!$AE$39) -> 0.25686374 | H3382: =$D3382 -> 0.42810623 | I3382: =$D3382 -> 0.42810623 | J3382: =$D3382 -> 0.42810623 | K3382: =$D3382 -> 0.42810623 | L3382: =$D3382 -> 0.42810623 | M3382: =$D3382 -> 0.42810623 | N3382: =$D3382 -> 0.42810623 | O3382: =$D3382 -> 0.42810623 | ... R3382: =$D3382 -> 0.42810623 | S3382: =(1+H3382)^((5-Dashboard!$F$9)*3/12) -> 1.0931761 | T3382: =(S3382)*(1+I3382) -> 1.5611716 | U3382: =(T3382)*(1+J3382) -> 2.2295189 | V3382: =(U3382)*(1+K3382) -> 3.1839898 | W3382: =(V3382)*(1+L3382) -> 4.5470757 | X3382: =(W3382)*(1+M3382) -> 6.4937071 | Y3382: =(X3382)*(1+N3382) -> 9.2737035 | Z3382: =(Y3382)*(1+O3382) -> 13.243834 | AA3382: =(Z3382)*(1+P3382) -> 18.913602 | ... AC3382: =(AB3382)*(1+R3382) -> 38.574052

Sheet DRE + DCF
O4: =Dashboard!$I$4 -> Banco do Brasil ($BBAS3)
A7: Páginas
A8: Dashboard
A9: Ke | F9: 2014 | G9: 2015 | H9: 2016 | I9: 2017 | J9: 2018 | K9: 2019 | L9: 2020 | M9: 2021 | N9: 2022 | O9: 1T23 | P9: 2T23 | Q9: 3T23 | R9: 4T23 | S9: YTG23 | T9: 2023 | U9: 2024 | V9: 2025 | W9: 2026 | X9: 2027 | Y9: 2028 | Z9: 2029 | AA9: 2030 | AB9: 2031 | AC9: 2032 | AD9: 2033
A10: DRE + DCF | E10: Margem Financeira Líquida | F10: ='Projeções - Receitas'!F26 -> 2.7953349e+10 | G10: ='Projeções - Receitas'!G26 -> 2.7970373e+10 | H10: ='Projeções - Receitas'!H26 -> 2.647592e+10 | I10: ='Projeções - Receitas'!I26 -> 3.1171212e+10 | J10: ='Projeções - Receitas'!J26 -> 3.4564593e+10 | K10: ='Projeções - Receitas'!K26 -> 3.9015565e+10 | L10: ='Projeções - Receitas'!L26 -> 3.4616132e+10 | M10: ='Projeções - Receitas'!M26 -> 4.6197474e+10 | ... AD10: ='Projeções - Receitas'!AD26 -> 1.4634777e+11
A11: Contas Abertas | E11: Crescimento da Margem Financeira Líquida (YoY)¹ | F11: - | G11: =G10/F10-1 -> 0.00060900094 | H11: =H10/G10-1 -> -0.05342984 | I11: =I10/H10-1 -> 0.17734197 | J11: =J10/I10-1 -> 0.10886264 | K11: =K10/J10-1 -> 0.1287726 | L11: =L10/K10-1 -> -0.11276098 | M11: =M10/L10-1 -> 0.33456488 | N11: =N10/M10-1 -> 0.22626163 | T11: =T10/N10-1 -> 0.11634429 | U11: =U10/T10-1 -> -0.15034234 | V11: =V10/U10-1 -> 0.10608002 | W11: =W10/V10-1 -> 0.10523679 | X11: =X10/W10-1 -> 0.10494344 | Y11: =Y10/X10-1 -> 0.10478402 | Z11: =Z10/Y10-1 -> 0.10468132 | AA11: =AA10/Z10-1 -> 0.098645632 | AB11: =AB10/AA10-1 -> 0.080743461 | ... AD11: =AD10/AC10-1 -> 0.28947583
A12: Balanço Patrimonial | E12: Outras Receitas Operacionais | F12: ='Projeções - Receitas'!F133 -> 2.1778487e+10 | G12: ='Projeções - Receitas'!G133 -> 2.2047848e+10 | H12: ='Projeções - Receitas'!H133 -> 2.3794116e+10 | I12: ='Projeções - Receitas'!I133 -> 2.5941416e+10 | J12: ='Projeções - Receitas'!J133 -> 2.7452372e+10 | K12: ='Projeções - Receitas'!K133 -> 2.9208671e+10 | L12: ='Projeções - Receitas'!L133 -> 2.8701888e+10 | M12: ='Projeções - Receitas'!M133 -> 2.9343336e+10 | ... AD12: ='Projeções - Receitas'!AD133 -> 5.236836e+10
A13: Projeções - Receita | E13: Crescimento das Outra Receitas Operacionais (YoY)¹ | F13: - | G13: =G12/F12-1 -> 0.012368192 | H13: =H12/G12-1 -> 0.079203561 | I13: =I12/H12-1 -> 0.090245008 | J13: =J12/I12-1 -> 0.058244951 | K13: =K12/J12-1 -> 0.063976216 | L13: =L12/K12-1 -> -0.017350426 | M13: =M12/L12-1 -> 0.02234863 | N13: =N12/M12-1 -> 0.10189156 | T13: =T12/N12-1 -> 0.053222714 | U13: =U12/T12-1 -> 0.037387643 | V13: =V12/U12-1 -> 0.038313091 | W13: =W12/V12-1 -> 0.039999925 | X13: =X12/W12-1 -> 0.042337703 | Y13: =Y12/X12-1 -> 0.044195098 | Z13: =Z12/Y12-1 -> 0.045464175 | AA13: =AA12/Z12-1 -> 0.04706543 | AB13: =AB12/AA12-1 -> 0.047920812 | ... AD13: =AD12/AC12-1 -> 0.048740615
A14: Painel de Índices | E14: Despesas Tributárias sobre Faturamento | F14: ='DRE CMN 4.720 - Contas Abertas'!F51 -> -4.0697476e+09 | G14: ='DRE CMN 4.720 - Contas Abertas'!G51 -> -4.3215667e+09 | H14: ='DRE CMN 4.720 - Contas Abertas'!H51 -> -5.1158347e+09 | I14: ='DRE CMN 4.720 - Contas Abertas'!I51 -> -5.0005496e+09 | J14: ='DRE CMN 4.720 - Contas Abertas'!J51 -> -4.5897923e+09 | K14: ='DRE CMN 4.720 - Contas Abertas'!K51 -> -4.4577427e+09 | L14: ='DRE CMN 4.720 - Contas Abertas'!L51 -> -4.8462431e+09 | M14: ='DRE CMN 4.720 - Contas Abertas'!M51 -> -5.0006834e+09 | ... Q14: ='DRE CMN 4.720 - Contas Abertas'!Q51 -> -1.808919e+09 | R14: ='Projeções Trimestrais'!I77 -> -1.7821939e+09 | S14: =R14 -> -1.7821939e+09 | T14: =SUM(O14:R14) -> -6.8804238e+09 | U14: =U15*SUM(U10,U12) -> -7.004858e+09 | V14: =V15*SUM(V10,V12) -> -7.5596373e+09 | W14: =W15*SUM(W10,W12) -> -8.1669782e+09 | X14: =X15*SUM(X10,X12) -> -8.8362041e+09 | Y14: =Y15*SUM(Y10,Y12) -> -9.5726068e+09 | Z14: =Z15*SUM(Z10,Z12) -> -1.0381295e+10 | AA14: =AA15*SUM(AA10,AA12) -> -1.1229261e+10 | AB14: =AB15*SUM(AB10,AB12) -> -1.2018614e+10 | ... AD14: =AD15*SUM(AD10,AD12) -> -1.5629575e+10
A15: Projeções Trimestrais | E15: Despesas Tributárias sobre Fauramento como % Total de Receitas | F15: =F14/SUM(F10,F12) -> -0.081833849 | G15: =G14/SUM(G10,G12) -> -0.086399848 | H15: =H14/SUM(H10,H12) -> -0.10176708 | I15: =I14/SUM(I10,I12) -> -0.087555936 | J15: =J14/SUM(J10,J12) -> -0.074008657 | K15: =K14/SUM(K10,K12) -> -0.065339577 | L15: =L14/SUM(L10,L12) -> -0.076538134 | M15: =M14/SUM(M10,M12) -> -0.066198435 | ... T15: =T14/SUM(T10,T12) -> -0.070717028 | U15: =AVERAGE($F$15:$N$15) -> -0.078652775 | V15: =AVERAGE($F$15:$N$15) -> -0.078652775 | W15: =AVERAGE($F$15:$N$15) -> -0.078652775 | X15: =AVERAGE($F$15:$N$15) -> -0.078652775 | Y15: =AVERAGE($F$15:$N$15) -> -0.078652775 | Z15: =AVERAGE($F$15:$N$15) -> -0.078652775 | AA15: =AVERAGE($F$15:$N$15) -> -0.078652775 | AB15: =AVERAGE($F$15:$N$15) -> -0.078652775 | ... AD15: =AVERAGE($F$15:$N$15) -> -0.078652775
E16: Margem de Contribuição | F16: =F10+F12+F14 -> 4.5662089e+10 | G16: =G10+G12+G14 -> 4.5696654e+10 | H16: =H10+H12+H14 -> 4.5154201e+10 | I16: =I10+I12+I14 -> 5.2112079e+10 | J16: =J10+J12+J14 -> 5.7427173e+10 | K16: =K10+K12+K14 -> 6.3766494e+10 | L16: =L10+L12+L14 -> 5.8471777e+10 | M16: =M10+M12+M14 -> 7.0540126e+10 | ... S16: =S10+S12+S14 -> 2.3244956e+10 | T16: =SUM(O16:R16) -> 9.0414725e+10 | U16: =U10+U12+U14 -> 8.2055674e+10 | V16: =V10+V12+V14 -> 8.855442e+10 | W16: =W10+W12+W14 -> 9.5668878e+10 | X16: =X10+X12+X14 -> 1.0350826e+11 | Y16: =Y10+Y12+Y14 -> 1.1213456e+11 | Z16: =Z10+Z12+Z14 -> 1.2160763e+11 | AA16: =AA10+AA12+AA14 -> 1.3154079e+11 | AB16: =AB10+AB12+AB14 -> 1.4078736e+11 | ... AD16: =AD10+AD12+AD14 -> 1.8308656e+11
E17: Crescimento das Margem de Contribuição (YoY)¹ | F17: - | G17: =G16/F16-1 -> 0.00075697494 | H17: =H16/G16-1 -> -0.011870728 | I17: =I16/H16-1 -> 0.15409146 | J17: =J16/I16-1 -> 0.10199352 | K17: =K16/J16-1 -> 0.11038887 | L17: =L16/K16-1 -> -0.083032897 | M17: =M16/L16-1 -> 0.20639615 | N17: =N16/M16-1 -> 0.17538379 | T17: =T16/N16-1 -> 0.090493893 | U17: =U16/T16-1 -> -0.092452323 | V17: =V16/U16-1 -> 0.079199221 | W17: =W16/V16-1 -> 0.080339955 | X17: =X16/W16-1 -> 0.0819429 | Y17: =Y16/X16-1 -> 0.083339256 | Z17: =Z16/Y16-1 -> 0.084479399 | AA17: =AA16/Z16-1 -> 0.081682107 | AB17: =AB16/AA16-1 -> 0.070294313 | ... AD17: =AD16/AC16-1 -> 0.21592075
E18: Outras Despesas/Receitas Operacionais | F18: =SUM('DRE CMN 4.720 - Contas Abertas'!F53,'DRE CMN 4.720 - Contas Abertas'!F56,'DRE CMN 4.720 - Contas Abertas'!F58,'DRE CMN 4.720 - Contas Abertas'!F61) -> -2.9084322e+10 | G18: =SUM('DRE CMN 4.720 - Contas Abertas'!G53,'DRE CMN 4.720 - Contas Abertas'!G56,'DRE CMN 4.720 - Contas Abertas'!G58,'DRE CMN 4.720 - Contas Abertas'!G61) -> -2.9928889e+10 | H18: =SUM('DRE CMN 4.720 - Contas Abertas'!H53,'DRE CMN 4.720 - Contas Abertas'!H56,'DRE CMN 4.720 - Contas Abertas'!H58,'DRE CMN 4.720 - Contas Abertas'!H61) -> -3.4437793e+10 | I18: =SUM('DRE CMN 4.720 - Contas Abertas'!I53,'DRE CMN 4.720 - Contas Abertas'!I56,'DRE CMN 4.720 - Contas Abertas'!I58,'DRE CMN 4.720 - Contas Abertas'!I61) -> -3.3548637e+10 | J18: =SUM('DRE CMN 4.720 - Contas Abertas'!J53,'DRE CMN 4.720 - Contas Abertas'!J56,'DRE CMN 4.720 - Contas Abertas'!J58,'DRE CMN 4.720 - Contas Abertas'!J61) -> -3.4325727e+10 | K18: =SUM('DRE CMN 4.720 - Contas Abertas'!K53,'DRE CMN 4.720 - Contas Abertas'!K56,'DRE CMN 4.720 - Contas Abertas'!K58,'DRE CMN 4.720 - Contas Abertas'!K61) -> -3.8851252e+10 | L18: =SUM('DRE CMN 4.720 - Contas Abertas'!L53,'DRE CMN 4.720 - Contas Abertas'!L56,'DRE CMN 4.720 - Contas Abertas'!L58,'DRE CMN 4.720 - Contas Abertas'!L61) -> -3.8370837e+10 | M18: =SUM('DRE CMN 4.720 - Contas Abertas'!M53,'DRE CMN 4.720 - Contas Abertas'!M56,'DRE CMN 4.720 - Contas Abertas'!M58,'DRE CMN 4.720 - Contas Abertas'!M61) -> -3.943413e+10 | ... Q18: =SUM('DRE CMN 4.720 - Contas Abertas'!Q53,'DRE CMN 4.720 - Contas Abertas'!Q56,'DRE CMN 4.720 - Contas Abertas'!Q58,'DRE CMN 4.720 - Contas Abertas'!Q61) -> -1.0060653e+10 | R18: ='Projeções Trimestrais'!I91 -> -9.7532449e+09 | S18: =R18 -> -9.7532449e+09 | T18: =SUM(O18:R18) -> -3.8009691e+10 | U18: =T18*(1+'Projeções - Receitas'!U11) -> -3.961256e+10 | V18: =U18*(1+'Projeções - Receitas'!V11) -> -4.1329369e+10 | W18: =V18*(1+'Projeções - Receitas'!W11) -> -4.3210681e+10 | X18: =W18*(1+'Projeções - Receitas'!X11) -> -4.5308128e+10 | Y18: =X18*(1+'Projeções - Receitas'!Y11) -> -4.7612952e+10 | Z18: =Y18*(1+'Projeções - Receitas'!Z11) -> -5.0106919e+10 | AA18: =Z18*(1+'Projeções - Receitas'!AA11) -> -5.2827724e+10 | AB18: =AA18*(1+'Projeções - Receitas'!AB11) -> -5.5744343e+10 | ... AD18: =AC18*(1+'Projeções - Receitas'!AD11) -> -6.213074e+10
E19: Despesas Operacionais como % de Outras Receitas Operacionais | F19: =F18/F12 -> -1.3354611 | G19: =G18/G12 -> -1.3574517 | H19: =H18/H12 -> -1.4473239 | I19: =I18/I12 -> -1.2932462 | J19: =J18/J12 -> -1.2503738 | K19: =K18/K12 -> -1.3301273 | L19: =L18/L12 -> -1.336875 | M19: =M18/M12 -> -1.3438871 | ... AD19: =AD18/AD12 -> -1.1864175
E20: Resultado Operacional | F20: =SUM(F16,F18) -> 1.6577767e+10 | G20: =SUM(G16,G18) -> 1.5767765e+10 | H20: =SUM(H16,H18) -> 1.0716408e+10 | I20: =SUM(I16,I18) -> 1.8563442e+10 | J20: =SUM(J16,J18) -> 2.3101445e+10 | K20: =SUM(K16,K18) -> 2.4915242e+10 | L20: =SUM(L16,L18) -> 2.010094e+10 | M20: =SUM(M16,M18) -> 3.1105996e+10 | ... AD20: =SUM(AD16,AD18) -> 1.2095582e+11
E21: Crescimento do Resultado Operacional (YoY)¹ | F21: - | G21: =G20/F20-1 -> -0.048860714 | H21: =H20/G20-1 -> -0.32035975 | I21: =I20/H20-1 -> 0.73224474 | J21: =J20/I20-1 -> 0.24445918 | K21: =K20/J20-1 -> 0.078514406 | L21: =L20/K20-1 -> -0.19322717 | M21: =M20/L20-1 -> 0.54748963 | N21: =N20/M20-1 -> 0.56108785 | T21: =T20/N20-1 -> 0.079199038 | U21: =U20/T20-1 -> -0.19009472 | V21: =V20/U20-1 -> 0.11266697 | W21: =W20/V20-1 -> 0.11081291 | X21: =X20/W20-1 -> 0.10945742 | Y21: =Y20/X20-1 -> 0.10861619 | Z21: =Z20/Y20-1 -> 0.10816677 | AA21: =AA20/Z20-1 -> 0.10087119 | AB21: =AB20/AA20-1 -> 0.080418044 | ... AD21: =AD20/AC20-1 -> 0.31861312
E22: Resultado Não Operacional | F22: ='DRE CMN 4.720 - Contas Abertas'!F69 -> 1.4382725e+08 | G22: ='DRE CMN 4.720 - Contas Abertas'!G69 -> 1.6606351e+08 | H22: ='DRE CMN 4.720 - Contas Abertas'!H69 -> 2.2713104e+08 | I22: ='DRE CMN 4.720 - Contas Abertas'!I69 -> 1.8627469e+08 | J22: ='DRE CMN 4.720 - Contas Abertas'!J69 -> 2.1793005e+08 | K22: ='DRE CMN 4.720 - Contas Abertas'!K69 -> 1.2321214e+08 | L22: ='DRE CMN 4.720 - Contas Abertas'!L69 -> 1.549019e+08 | M22: ='DRE CMN 4.720 - Contas Abertas'!M69 -> 2.460578e+08 | ... O22: ='DRE CMN 4.720 - Contas Abertas'!O69 -> 1.0686121e+08
E23: Resultado Antes do IR | F23: =F20+F22 -> 1.6721594e+10 | G23: =G20+G22 -> 1.5933829e+10 | H23: =H20+H22 -> 1.0943539e+10 | I23: =I20+I22 -> 1.8749716e+10 | J23: =J20+J22 -> 2.3319375e+10 | K23: =K20+K22 -> 2.5038454e+10 | L23: =L20+L22 -> 2.0255842e+10 | M23: =M20+M22 -> 3.1352054e+10 | ... AD23: =AD20+AD22 -> 1.2095582e+11
E24: Imposto de Renda e Contribuição Social | F24: ='DRE CMN 4.720 - Contas Abertas'!F71 -> -2.4363414e+09 | G24: ='DRE CMN 4.720 - Contas Abertas'!G71 -> -8.2814101e+08 | H24: ='DRE CMN 4.720 - Contas Abertas'!H71 -> -1.1790907e+09 | I24: ='DRE CMN 4.720 - Contas Abertas'!I71 -> -4.6035192e+09 | J24: ='DRE CMN 4.720 - Contas Abertas'!J71 -> -6.6956437e+09 | K24: ='DRE CMN 4.720 - Contas Abertas'!K71 -> -3.1404959e+09 | L24: ='DRE CMN 4.720 - Contas Abertas'!L71 -> -3.0934574e+09 | M24: ='DRE CMN 4.720 - Contas Abertas'!M71 -> -6.0804538e+09 | ... Q24: ='DRE CMN 4.720 - Contas Abertas'!Q71 -> -2.1393902e+09 | R24: =R25*R20 -> -2.6472351e+09 | S24: =R24 -> -2.6472351e+09 | T24: =SUM(O24:R24) -> -9.6857172e+09 | U24: =U25*U20 -> -7.8832821e+09 | V24: =V25*V20 -> -8.814604e+09 | W24: =W25*W20 -> -9.8392925e+09 | X24: =X25*X20 -> -1.0969437e+10 | Y24: =Y25*Y20 -> -1.2219831e+10 | Z24: =Z25*Z20 -> -1.3606921e+10 | AA24: =AA25*AA20 -> -1.5051366e+10 | AB24: =AB25*AB20 -> -1.6339448e+10 | ... AD24: =AD25*AD20 -> -2.661028e+10
E25: Imposto de Renda e Contribuição Social como % do Resultado Operacional | F25: =F24/F20 -> -0.14696439 | G25: =G24/G20 -> -0.05252114 | H25: =H24/H20 -> -0.11002667 | I25: =I24/I20 -> -0.24798846 | J25: =J24/J20 -> -0.28983657 | K25: =K24/K20 -> -0.12604718 | L25: =L24/L20 -> -0.15389616 | M25: =M24/M20 -> -0.1954753 | ... Q25: =Q24/Q20 -> -0.16502913 | R25: =AVERAGE($I$25:$Q$25) -> -0.19621196 | S25: =S24/S20 -> -0.19621196 | T25: =T24/T20 -> -0.18482418 | U25: =T25+(($AD$25-$N$25)/11) -> -0.1857376 | V25: =U25+(($AD$25-$N$25)/11) -> -0.18665102 | W25: =V25+(($AD$25-$N$25)/11) -> -0.18756444 | X25: =W25+(($AD$25-$N$25)/11) -> -0.18847787 | Y25: =X25+(($AD$25-$N$25)/11) -> -0.18939129 | Z25: =Y25+(($AD$25-$N$25)/11) -> -0.19030471 | AA25: =Z25+(($AD$25-$N$25)/11) -> -0.19121813 | AB25: =AA25+(($AD$25-$N$25)/11) -> -0.19213156 | AC25: =AB25+(($AD$25-$N$25)/11) -> -0.19304498 | AD25: -0.22
E26: Resultado Antes de Participações Estatutárias e Minoritárias | F26: =F23+F24 -> 1.4285253e+10 | G26: =G23+G24 -> 1.5105688e+10 | H26: =H23+H24 -> 9.7644484e+09 | I26: =I23+I24 -> 1.4146197e+10 | J26: =J23+J24 -> 1.6623732e+10 | K26: =K23+K24 -> 2.1897958e+10 | L26: =L23+L24 -> 1.7162384e+10 | M26: =M23+M24 -> 2.52716e+10 | ... O26: =O23+O24 -> 1.0452697e+10 | P26: =P20+P24 -> 1.0704683e+10 | Q26: =Q20+Q24 -> 1.0824322e+10 | R26: =R20+R24 -> 1.0844476e+10 | S26: =R26 -> 1.0844476e+10 | T26: =SUM(O26:R26) -> 4.2826178e+10 | U26: =U20+U24 -> 3.4559832e+10 | V26: =V20+V24 -> 3.8410447e+10 | W26: =W20+W24 -> 4.2618904e+10 | X26: =X20+X24 -> 4.7230698e+10 | Y26: =Y20+Y24 -> 5.2301781e+10 | Z26: =Z20+Z24 -> 5.7893785e+10 | AA26: =AA20+AA24 -> 6.3661702e+10 | AB26: =AB20+AB24 -> 6.8703571e+10 | ... AD26: =AD20+AD24 -> 9.434554e+10
E27: Participações Estatutárias no Lucro | F27: ='DRE CMN 4.720 - Contas Abertas'!F72 -> -1.4673351e+09 | G27: ='DRE CMN 4.720 - Contas Abertas'!G72 -> -1.7896844e+09 | H27: ='DRE CMN 4.720 - Contas Abertas'!H72 -> -9.1857229e+08 | I27: ='DRE CMN 4.720 - Contas Abertas'!I72 -> -1.4362506e+09 | J27: ='DRE CMN 4.720 - Contas Abertas'!J72 -> -1.714864e+09 | K27: ='DRE CMN 4.720 - Contas Abertas'!K72 -> -2.3467088e+09 | L27: ='DRE CMN 4.720 - Contas Abertas'!L72 -> -1.7020458e+09 | M27: ='DRE CMN 4.720 - Contas Abertas'!M72 -> -2.6449656e+09 | ... Q27: ='DRE CMN 4.720 - Contas Abertas'!Q72 -> -1.1187128e+09
E28: Participações Minoritárias | F28: ='DRE CMN 4.720 - Contas Abertas'!F73 -> -1.4751949e+09 | G28: ='DRE CMN 4.720 - Contas Abertas'!G73 -> -1.721658e+09 | H28: ='DRE CMN 4.720 - Contas Abertas'!H73 -> -1.675039e+09 | I28: ='DRE CMN 4.720 - Contas Abertas'!I73 -> -1.6500334e+09 | J28: ='DRE CMN 4.720 - Contas Abertas'!J73 -> -1.395849e+09 | K28: ='DRE CMN 4.720 - Contas Abertas'!K73 -> -1.7037475e+09 | L28: ='DRE CMN 4.720 - Contas Abertas'!L73 -> -1.5765221e+09 | M28: ='DRE CMN 4.720 - Contas Abertas'!M73 -> -1.6055132e+09 | ... Q28: ='DRE CMN 4.720 - Contas Abertas'!Q73 -> -9.6186417e+08
E29: Lucro dos Acionistas Ajustado dos Acionistas Controladores | F29: =SUM(F26:F28) -> 1.1342723e+10 | G29: =SUM(G26:G28) -> 1.1594346e+10 | H29: =SUM(H26:H28) -> 7.1708371e+09 | I29: =SUM(I26:I28) -> 1.1059913e+10 | J29: =SUM(J26:J28) -> 1.3513019e+10 | K29: =SUM(K26:K28) -> 1.7847502e+10 | L29: =SUM(L26:L28) -> 1.3883817e+10 | M29: =SUM(M26:M28) -> 2.1021121e+10 | ... Q29: =SUM(Q26:Q28) -> 8.7437455e+09 | R29: =R31 -> 8.7600253e+09 | S29: =R29 -> 8.7600253e+09 | T29: =SUM(O29:R29) -> 3.4787158e+10 | U29: =U33*U26 -> 2.8072511e+10 | V29: =V33*V26 -> 3.1200316e+10 | W29: =W33*W26 -> 3.4618792e+10 | X29: =X33*X26 -> 3.8364893e+10 | Y29: =Y33*Y26 -> 4.2484069e+10 | Z29: =Z33*Z26 -> 4.7026383e+10 | AA29: =AA33*AA26 -> 5.1711588e+10 | AB29: =AB33*AB26 -> 5.5807034e+10 | ... AD29: =AD33*AD26 -> 7.6635678e+10
E30: Itens Extraordinários | F30: ='DRE CMN 4.720 - Contas Abertas'!F75 -> -97174908 | G30: ='DRE CMN 4.720 - Contas Abertas'!G75 -> 2.8052129e+09 | H30: ='DRE CMN 4.720 - Contas Abertas'!H75 -> 8.6271862e+08 | I30: ='DRE CMN 4.720 - Contas Abertas'!I75 -> -49136775 | J30: ='DRE CMN 4.720 - Contas Abertas'!J75 -> -6.5099451e+08 | K30: ='DRE CMN 4.720 - Contas Abertas'!K75 -> 3.1456721e+08 | L30: ='DRE CMN 4.720 - Contas Abertas'!L75 -> -1.1864323e+09 | M30: ='DRE CMN 4.720 - Contas Abertas'!M75 -> -1.3107195e+09 | ... Q30: ='DRE CMN 4.720 - Contas Abertas'!Q75 -> -3.8865561e+08
E31: Lucro dos Acionistas dos Acionistas Controladores | F31: =F29+F30 -> 1.1245548e+10 | G31: =G29+G30 -> 1.4399558e+10 | H31: =H29+H30 -> 8.0335558e+09 | I31: =I29+I30 -> 1.1010776e+10 | J31: =J29+J30 -> 1.2862024e+10 | K31: =K29+K30 -> 1.8162069e+10 | L31: =L29+L30 -> 1.2697384e+10 | M31: =M29+M30 -> 1.9710402e+10 | ... Q31: =Q29+Q30 -> 8.3550899e+09 | R31: =R33*R26 -> 8.7600253e+09 | S31: =R31 -> 8.7600253e+09 | T31: =SUM(O31:R31) -> 3.3624756e+10 | U31: =U29 -> 2.8072511e+10 | V31: =V29 -> 3.1200316e+10 | W31: =W29 -> 3.4618792e+10 | X31: =X29 -> 3.8364893e+10 | Y31: =Y29 -> 4.2484069e+10 | Z31: =Z29 -> 4.7026383e+10 | AA31: =AA29 -> 5.1711588e+10 | AB31: =AB29 -> 5.5807034e+10 | ... AD31: =AD29 -> 7.6635678e+10
E32: Crescimento Lucro Líquido dos Acionistas Controladoresl (YoY)¹ | F32: - | G32: =G31/F31-1 -> 0.28046749 | H32: =H31/G31-1 -> -0.44209708 | I32: =I31/H31-1 -> 0.37059809 | J32: =J31/I31-1 -> 0.16813056 | K32: =K31/J31-1 -> 0.41206924 | L32: =L31/K31-1 -> -0.30088448 | M32: =M31/L31-1 -> 0.55231988 | N32: =N31/M31-1 -> 0.5733564 | T32: =T31/N31-1 -> 0.084267787 | U32: =U31/T31-1 -> -0.16512375 | V32: =V31/U31-1 -> 0.11141881 | W32: =W31/V31-1 -> 0.10956542 | X32: =X31/W31-1 -> 0.10821005 | Y32: =Y31/X31-1 -> 0.10736837 | Z32: =Z31/Y31-1 -> 0.10691804 | AA32: =AA31/Z31-1 -> 0.099629291 | AB32: =AB31/AA31-1 -> 0.079197841 | ... AD32: =AD31/AC31-1 -> 0.27456699
E33: % do Lucro Pertencente aos Acionistas | F33: =F29/F26 -> 0.79401625 | G33: =G29/G26 -> 0.76754833 | H33: =H29/H26 -> 0.7343822 | I33: =I29/I26 -> 0.78182942 | J33: =J29/J26 -> 0.81287517 | K33: =K29/K26 -> 0.81503041 | L33: =L29/L26 -> 0.80896781 | M33: =M29/M26 -> 0.83180809 | ... Q33: =Q29/Q26 -> 0.80778687 | R33: =Q33 -> 0.80778687 | S33: =S29/S26 -> 0.80778687 | T33: =T29/T26 -> 0.81228724 | U33: =T33 -> 0.81228724 | V33: =U33 -> 0.81228724 | W33: =V33 -> 0.81228724 | X33: =W33 -> 0.81228724 | Y33: =X33 -> 0.81228724 | Z33: =Y33 -> 0.81228724 | AA33: =Z33 -> 0.81228724 | AB33: =AA33 -> 0.81228724 | ... AD33: =AC33 -> 0.81228724
E34: 1 - Ano a Ano
F37: 2014 | G37: 2015 | H37: 2016 | I37: 2017 | J37: 2018 | K37: 2019 | L37: 2020 | M37: 2021 | N37: 2022 | O37: 1T23 | P37: 2T23 | Q37: 3T23 | R37: 4T23 | S37: YTG23 | T37: 2023 | U37: 2024 | V37: 2025 | W37: 2026 | X37: 2027 | Y37: 2028 | Z37: 2029 | AA37: 2030 | AB37: 2031 | AC37: 2032 | AD37: 2033 | AE37: Perpetuidade | AF37: ROE Perp. | AG37: Growth
E38: Lucro Líquido por Ação | F38: 4.04 | G38: 5.05 | H38: 2.84 | I38: 3.91 | J38: 4.54 | K38: 6.39 | L38: 4.39 | M38: 3.86 | N38: 10.79 | O38: 2.8640131 | P38: =P31/Dashboard!$F$11 -> 2.9094951 | Q38: =Q31/Dashboard!$F$11 -> 2.9277315 | R38: =R31/Dashboard!$F$11 -> 3.069626 | S38: =SUM(R38) -> 3.069626 | T38: =SUM(O38:R38) -> 11.770866 | U38: =U31/Dashboard!$F$11 -> 9.8369704 | V38: =V31/Dashboard!$F$11 -> 10.932994 | W38: =W31/Dashboard!$F$11 -> 12.130872 | X38: =X31/Dashboard!$F$11 -> 13.443554 | Y38: =Y31/Dashboard!$F$11 -> 14.886967 | Z38: =Z31/Dashboard!$F$11 -> 16.478652 | AA38: =AA31/Dashboard!$F$11 -> 18.120409 | AB38: =AB31/Dashboard!$F$11 -> 19.555506 | ... AD38: =AD31/Dashboard!$F$11 -> 26.854132 | AE38: =AD38 -> 26.854132 | AF38: =Ke!P16 -> 0.15192705 | AG38: =AF38*AE40 -> 0.091156229
E39: Índice Payout | F39: =F41/F38 -> 0.40019064 | G39: =G41/G38 -> 0.40711069 | H39: =H41/H38 -> 0.29750971 | I39: =I41/I38 -> 0.29653105 | J39: =J41/J38 -> 0.40818347 | K39: =K41/K38 -> 0.37586022 | L39: =L41/L38 -> 0.33511472 | M39: =M41/M38 -> 0.68334784 | ... Q39: =Q41/Q38 -> 0.38337122 | R39: =Q39 -> 0.38337122 | S39: =S41/S38 -> 0.38337122 | T39: =T41/T38 -> 0.38787832 | U39: 0.4 | V39: 0.4 | W39: 0.4 | X39: 0.4 | Y39: 0.4 | Z39: 0.4 | AA39: 0.4 | AB39: 0.4 | AC39: 0.4 | AD39: 0.4 | AE39: =AD39 -> 0.4
E40: Índice Reinvestimento | F40: =1-F39 -> 0.59980936 | G40: =1-G39 -> 0.59288931 | H40: =1-H39 -> 0.70249029 | I40: =1-I39 -> 0.70346895 | J40: =1-J39 -> 0.59181653 | K40: =1-K39 -> 0.62413978 | L40: =1-L39 -> 0.66488528 | M40: =1-M39 -> 0.31665216 | ... AD40: =1-AD39 -> 0.6 | AE40: =AD40 -> 0.6
